Workbook
Name j_1: #REF!
Name j_1: #REF!
Name j_10: #REF!
Name j_10: #REF!
Name j_100: #REF!
Name j_100: #REF!
Name j_101: #REF!
Name j_101: #REF!
Name j_102: #REF!
Name j_102: #REF!
Name j_103: #REF!
Name j_103: #REF!
Name j_104: #REF!
Name j_104: #REF!
Name j_105: #REF!
Name j_105: #REF!
Name j_106: #REF!
Name j_106: #REF!
Name j_107: #REF!
Name j_107: #REF!
Name j_108: #REF!
Name j_108: #REF!
Name j_109: #REF!
Name j_109: #REF!
Name j_11: #REF!
Name j_11: #REF!
Name j_110: #REF!
Name j_110: #REF!
Name j_111: #REF!
Name j_111: #REF!
Name j_112: #REF!
Name j_112: #REF!
Name j_113: #REF!
Name j_113: #REF!
Name j_114: #REF!
Name j_114: #REF!
Name j_115: #REF!
Name j_115: #REF!
Name j_116: #REF!
Name j_116: #REF!
Name j_117: #REF!
Name j_117: #REF!
Name j_118: #REF!
Name j_118: #REF!
Name j_119: #REF!
Name j_119: #REF!
Name j_12: #REF!
Name j_12: #REF!
Name j_120: #REF!
Name j_120: #REF!
Name j_121: #REF!
Name j_121: #REF!
Name j_122: #REF!
Name j_122: #REF!
Name j_123: #REF!
Name j_123: #REF!
Name j_124: #REF!
Name j_124: #REF!
Name j_125: #REF!
Name j_125: #REF!

Sheet G2M-1_v2
A1: can_rscf4_cfg.h CAN_CFG_ID_VALUE_5_MB### | B1: can_rscf4_cfg.h CAN_CFG_ID_VALUE_5_MB###2 | C1: can_rscf4_cfg.h CAN_CFG_ID_VALUE_5_MB###3 | D1: can_rscf4_cfg.h CAN_CFG_FILTER_MASK_VALUE_# | E1: 列1 | F1: 列2 | G1: 列3 | H1: 列4 | R1: Message Inf.
C2: 0x00000013 | D2: 0x00000000 | E2: 0 | F2: 19 | H2: 0x00000013
A3: CAN_CFG_ID_VALUE_5_MB059 | B3: 59 | C3: 0x00000013 | D3: 0x00000008 | E3: 8 | F3: 19 | H3: 0x0000001b | W3: G2M-1 | X3: G2M-2 | Y3: G5M
C4: 0x00000062 | D4: 0x00000000 | E4: 0 | F4: 98 | H4: 0x00000062 | I4: CAN ID | J4: Msg. Label | K4: FDF | L4: DLC | M4: Com. Trans. Cycle | N4: KZK Message/C-DC Only | Q4: CAN ID | R4: Msg. Label | S4: FDF | T4: DLC | U4: Com. Trans. Cycle | V4: KZK Message | W4: Cockpit Domain Controller | X4: Cockpit Domain Controller | Y4: Cockpit Domain Controller | AA4: Msg. Label | AB4: CAN ID | AC4: FDF | AD4: DLC | AE4: Com. Trans. Cycle | AF4: KZK Message/C-DC Only
A5: CAN_CFG_ID_VALUE_5_MB120 | B5: 120 | C5: 0x00000062 | D5: 0x00000008 | E5: 8 | F5: 98 | H5: 0x0000006a | I5: (11bit/29bit) | K5: (0/1) | L5: (dec) | M5: (ms) | N5: (0/1) | Q5: (11bit/29bit) | S5: (0/1) | T5: (dec) | U5: (ms) | V5: (0/1) | AB5: (11bit/29bit) | AC5: (0/1) | AD5: (dec) | AE5: (ms) | AF5: (0/1)
A6: CAN_CFG_ID_VALUE_5_MB143 | B6: 143 | C6: 0x00000069 | D6: 0x00000000 | E6: 0 | F6: 105 | H6: 0x00000069 | I6: =UPPER(RIGHT(H2,3)) -> 013 | J6: =VLOOKUP($I6,$Q$6:$Y$278,2,FALSE) -> BDC1S52 | K6: =VLOOKUP($I6,$Q$6:$Y$278,3,FALSE) -> 1 | L6: =VLOOKUP($I6,$Q$6:$Y$278,4,FALSE) -> 64 | M6: =VLOOKUP($I6,$Q$6:$Y$278,5,FALSE) -> - | N6: =VLOOKUP($I6,$Q$6:$Y$278,6,FALSE) -> 0 | P6: =COUNTIF($J$6:$J$278,R6) -> 1 | Q6: 013 | R6: BDC1S52 | S6: 1 | T6: 64 | U6: - | V6: 0 | W6: R | AA6: BDC1S52 | AB6: 013 | AC6: 1 | AD6: 64 | AE6: - | AF6: 0
C7: 0x00000086 | D7: 0x00000000 | E7: 0 | F7: 134 | H7: 0x00000086 | I7: =UPPER(RIGHT(H3,3)) -> 01B | J7: =VLOOKUP($I7,$Q$6:$Y$278,2,FALSE) -> BDC1S60 | K7: =VLOOKUP($I7,$Q$6:$Y$278,3,FALSE) -> 1 | L7: =VLOOKUP($I7,$Q$6:$Y$278,4,FALSE) -> 64 | M7: =VLOOKUP($I7,$Q$6:$Y$278,5,FALSE) -> - | N7: =VLOOKUP($I7,$Q$6:$Y$278,6,FALSE) -> 0 | P7: =COUNTIF($J$6:$J$278,R7) -> 1 | Q7: 01B | R7: BDC1S60 | S7: 1 | T7: 64 | U7: - | V7: 0 | W7: R | AA7: BDC1S60 | AB7: 01B | AC7: 1 | AD7: 64 | AE7: - | AF7: 0
A8: CAN_CFG_ID_VALUE_5_MB054 | B8: 54 | C8: 0x00000086 | D8: 0x00000100 | E8: 256 | F8: 134 | H8: 0x00000186 | I8: =UPPER(RIGHT(H4,3)) -> 062 | J8: =VLOOKUP($I8,$Q$6:$Y$278,2,FALSE) -> EPS1S11 | K8: =VLOOKUP($I8,$Q$6:$Y$278,3,FALSE) -> 1 | L8: =VLOOKUP($I8,$Q$6:$Y$278,4,FALSE) -> 64 | M8: =VLOOKUP($I8,$Q$6:$Y$278,5,FALSE) -> 10 | N8: =VLOOKUP($I8,$Q$6:$Y$278,6,FALSE) -> 1 | P8: =COUNTIF($J$6:$J$278,R8) -> 1 | Q8: 062 | R8: EPS1S11 | S8: 1 | T8: 64 | U8: 10 | V8: 1 | W8: R | AA8: EPS1S11 | AB8: 062 | AC8: 1 | AD8: 64 | AE8: 10 | AF8: 1
C9: 0x0000009C | D9: 0x00000000 | E9: 0 | F9: 156 | H9: 0x0000009c | I9: =UPPER(RIGHT(H5,3)) -> 06A | J9: =VLOOKUP($I9,$Q$6:$Y$278,2,FALSE) -> VSC1F01 | K9: =VLOOKUP($I9,$Q$6:$Y$278,3,FALSE) -> 1 | L9: =VLOOKUP($I9,$Q$6:$Y$278,4,FALSE) -> 32 | M9: =VLOOKUP($I9,$Q$6:$Y$278,5,FALSE) -> 10 | N9: =VLOOKUP($I9,$Q$6:$Y$278,6,FALSE) -> 1 | P9: =COUNTIF($J$6:$J$278,R9) -> 1 | Q9: 069 | R9: VSC1G12 | S9: 1 | T9: 32 | U9: 10 | V9: 1 | W9: R | AA9: VSC1F01 | AB9: 06A | AC9: 1 | AD9: 32 | AE9: 10 | AF9: 1
A10: CAN_CFG_ID_VALUE_5_MB056 | B10: 56 | C10: 0x0000009C | D10: 0x00000002 | E10: 2 | F10: 156 | H10: 0x0000009e | I10: =UPPER(RIGHT(H6,3)) -> 069 | J10: =VLOOKUP($I10,$Q$6:$Y$278,2,FALSE) -> VSC1G12 | K10: =VLOOKUP($I10,$Q$6:$Y$278,3,FALSE) -> 1 | L10: =VLOOKUP($I10,$Q$6:$Y$278,4,FALSE) -> 32 | M10: =VLOOKUP($I10,$Q$6:$Y$278,5,FALSE) -> 10 | N10: =VLOOKUP($I10,$Q$6:$Y$278,6,FALSE) -> 1 | P10: =COUNTIF($J$6:$J$278,R10) -> 1 | Q10: 06A | R10: VSC1F01 | S10: 1 | T10: 32 | U10: 10 | V10: 1 | W10: R | AA10: VSC1G12 | AB10: 069 | AC10: 1 | AD10: 32 | AE10: 10 | AF10: 1
A11: CAN_CFG_ID_VALUE_5_MB118 | B11: 118 | C11: 0x000000A4 | D11: 0x00000000 | E11: 0 | F11: 164 | H11: 0x000000a4 | I11: =UPPER(RIGHT(H7,3)) -> 086 | J11: =VLOOKUP($I11,$Q$6:$Y$278,2,FALSE) -> ZN11S08 | K11: =VLOOKUP($I11,$Q$6:$Y$278,3,FALSE) -> 1 | L11: =VLOOKUP($I11,$Q$6:$Y$278,4,FALSE) -> 8 | M11: =VLOOKUP($I11,$Q$6:$Y$278,5,FALSE) -> 20 | N11: =VLOOKUP($I11,$Q$6:$Y$278,6,FALSE) -> 0 | P11: =COUNTIF($J$6:$J$278,R11) -> 1 | Q11: 086 | R11: ZN11S08 | S11: 1 | T11: 8 | U11: 20 | V11: 0 | W11: R | AA11: ZN11S08 | AB11: 086 | AC11: 1 | AD11: 8 | AE11: 20 | AF11: 0
A12: CAN_CFG_ID_VALUE_5_MB144 | B12: 144 | C12: 0x000000B7 | D12: 0x00000000 | E12: 0 | F12: 183 | H12: 0x000000b7 | I12: =UPPER(RIGHT(H8,3)) -> 186 | J12: =VLOOKUP($I12,$Q$6:$Y$278,2,FALSE) -> BDC1S30 | K12: =VLOOKUP($I12,$Q$6:$Y$278,3,FALSE) -> 1 | L12: =VLOOKUP($I12,$Q$6:$Y$278,4,FALSE) -> 32 | M12: =VLOOKUP($I12,$Q$6:$Y$278,5,FALSE) -> 100 | N12: =VLOOKUP($I12,$Q$6:$Y$278,6,FALSE) -> 0 | P12: =COUNTIF($J$6:$J$278,R12) -> 1 | Q12: 09C | R12: BDC1S40 | S12: 1 | T12: 32 | U12: 50 | V12: 0 | W12: R | AA12: BDC1S30 | AB12: 186 | AC12: 1 | AD12: 32 | AE12: 100 | AF12: 0
A13: CAN_CFG_ID_VALUE_5_MB099 | B13: 99 | C13: 0x000000B8 | D13: 0x00000000 | E13: 0 | F13: 184 | H13: 0x000000b8 | I13: =UPPER(RIGHT(H9,3)) -> 09C | J13: =VLOOKUP($I13,$Q$6:$Y$278,2,FALSE) -> BDC1S40 | K13: =VLOOKUP($I13,$Q$6:$Y$278,3,FALSE) -> 1 | L13: =VLOOKUP($I13,$Q$6:$Y$278,4,FALSE) -> 32 | M13: =VLOOKUP($I13,$Q$6:$Y$278,5,FALSE) -> 50 | N13: =VLOOKUP($I13,$Q$6:$Y$278,6,FALSE) -> 0 | P13: =COUNTIF($J$6:$J$278,R13) -> 1 | Q13: 09E | R13: VSC1G13 | S13: 1 | T13: 32 | U13: 20 | V13: 1 | W13: R | AA13: BDC1S40 | AB13: 09C | AC13: 1 | AD13: 32 | AE13: 50 | AF13: 0
A14: CAN_CFG_ID_VALUE_5_MB119 | B14: 119 | C14: 0x000000FC | D14: 0x00000000 | E14: 0 | F14: 252 | H14: 0x000000fc | I14: =UPPER(RIGHT(H10,3)) -> 09E | J14: =VLOOKUP($I14,$Q$6:$Y$278,2,FALSE) -> VSC1G13 | K14: =VLOOKUP($I14,$Q$6:$Y$278,3,FALSE) -> 1 | L14: =VLOOKUP($I14,$Q$6:$Y$278,4,FALSE) -> 32 | M14: =VLOOKUP($I14,$Q$6:$Y$278,5,FALSE) -> 20 | N14: =VLOOKUP($I14,$Q$6:$Y$278,6,FALSE) -> 1 | P14: =COUNTIF($J$6:$J$278,R14) -> 1 | Q14: 0A4 | R14: ENG1G03 | S14: 1 | T14: 32 | U14: 24 | V14: 1 | W14: R | AA14: VSC1G13 | AB14: 09E | AC14: 1 | AD14: 32 | AE14: 20 | AF14: 1
C15: 0x00000100 | D15: 0x00000000 | E15: 0 | F15: 256 | H15: 0x00000100 | I15: =UPPER(RIGHT(H11,3)) -> 0A4 | J15: =VLOOKUP($I15,$Q$6:$Y$278,2,FALSE) -> ENG1G03 | K15: =VLOOKUP($I15,$Q$6:$Y$278,3,FALSE) -> 1 | L15: =VLOOKUP($I15,$Q$6:$Y$278,4,FALSE) -> 32 | M15: =VLOOKUP($I15,$Q$6:$Y$278,5,FALSE) -> 24 | N15: =VLOOKUP($I15,$Q$6:$Y$278,6,FALSE) -> 1 | P15: =COUNTIF($J$6:$J$278,R15) -> 1 | Q15: 0B7 | R15: VSC1G14 | S15: 1 | T15: 32 | U15: 30 | V15: 1 | W15: R | AA15: ENG1G03 | AB15: 0A4 | AC15: 1 | AD15: 32 | AE15: 24 | AF15: 1
A16: CAN_CFG_ID_VALUE_5_MB123 | B16: 123 | C16: 0x00000100 | D16: 0x00000400 | E16: 1024 | F16: 256 | H16: 0x00000500 | I16: =UPPER(RIGHT(H12,3)) -> 0B7 | J16: =VLOOKUP($I16,$Q$6:$Y$278,2,FALSE) -> VSC1G14 | K16: =VLOOKUP($I16,$Q$6:$Y$278,3,FALSE) -> 1 | L16: =VLOOKUP($I16,$Q$6:$Y$278,4,FALSE) -> 32 | M16: =VLOOKUP($I16,$Q$6:$Y$278,5,FALSE) -> 30 | N16: =VLOOKUP($I16,$Q$6:$Y$278,6,FALSE) -> 1 | P16: =COUNTIF($J$6:$J$278,R16) -> 1 | Q16: 0B8 | R16: DDM1S12 | S16: 1 | T16: 64 | U16: 30 | V16: 1 | W16: R | AA16: VSC1G14 | AB16: 0B7 | AC16: 1 | AD16: 32 | AE16: 30 | AF16: 1
A17: CAN_CFG_ID_VALUE_5_MB104 | B17: 104 | C17: 0x00000122 | D17: 0x00000000 | E17: 0 | F17: 290 | H17: 0x00000122 | I17: =UPPER(RIGHT(H13,3)) -> 0B8 | J17: =VLOOKUP($I17,$Q$6:$Y$278,2,FALSE) -> DDM1S12 | K17: =VLOOKUP($I17,$Q$6:$Y$278,3,FALSE) -> 1 | L17: =VLOOKUP($I17,$Q$6:$Y$278,4,FALSE) -> 64 | M17: =VLOOKUP($I17,$Q$6:$Y$278,5,FALSE) -> 30 | N17: =VLOOKUP($I17,$Q$6:$Y$278,6,FALSE) -> 1 | P17: =COUNTIF($J$6:$J$278,R17) -> 1 | Q17: 0FC | R17: ENG1G92 | S17: 1 | T17: 8 | U17: 1000 | V17: 0 | W17: R | AA17: DDM1S12 | AB17: 0B8 | AC17: 1 | AD17: 64 | AE17: 30 | AF17: 1
C18: 0x00000124 | D18: 0x00000000 | E18: 0 | F18: 292 | H18: 0x00000124 | I18: =UPPER(RIGHT(H14,3)) -> 0FC | J18: =VLOOKUP($I18,$Q$6:$Y$278,2,FALSE) -> ENG1G92 | K18: =VLOOKUP($I18,$Q$6:$Y$278,3,FALSE) -> 1 | L18: =VLOOKUP($I18,$Q$6:$Y$278,4,FALSE) -> 8 | M18: =VLOOKUP($I18,$Q$6:$Y$278,5,FALSE) -> 1000 | N18: =VLOOKUP($I18,$Q$6:$Y$278,6,FALSE) -> 0 | P18: =COUNTIF($J$6:$J$278,R18) -> 1 | Q18: 100 | R18: FCM1S79 | S18: 1 | T18: 8 | U18: 50 | V18: 0 | W18: R | AA18: ENG1G92 | AB18: 0FC | AC18: 1 | AD18: 8 | AE18: 1000 | AF18: 0
A19: CAN_CFG_ID_VALUE_5_MB030 | B19: 30 | C19: 0x00000124 | D19: 0x00000080 | E19: 128 | F19: 292 | H19: 0x000001a4 | I19: =UPPER(RIGHT(H15,3)) -> 100 | J19: =VLOOKUP($I19,$Q$6:$Y$278,2,FALSE) -> FCM1S79 | K19: =VLOOKUP($I19,$Q$6:$Y$278,3,FALSE) -> 1 | L19: =VLOOKUP($I19,$Q$6:$Y$278,4,FALSE) -> 8 | M19: =VLOOKUP($I19,$Q$6:$Y$278,5,FALSE) -> 50 | N19: =VLOOKUP($I19,$Q$6:$Y$278,6,FALSE) -> 0 | P19: =COUNTIF($J$6:$J$278,R19) -> 1 | Q19: 122 | R19: DMC1S08 | S19: 1 | T19: 32 | U19: 100 | V19: 1 | W19: R | AA19: FCM1S79 | AB19: 100 | AC19: 1 | AD19: 8 | AE19: 50 | AF19: 0
A20: CAN_CFG_ID_VALUE_5_MB112 | B20: 112 | C20: 0x00000128 | D20: 0x00000000 | E20: 0 | F20: 296 | H20: 0x00000128 | I20: =UPPER(RIGHT(H16,3)) -> 500 | J20: =VLOOKUP($I20,$Q$6:$Y$278,2,FALSE) -> ZN11S38 | K20: =VLOOKUP($I20,$Q$6:$Y$278,3,FALSE) -> 1 | L20: =VLOOKUP($I20,$Q$6:$Y$278,4,FALSE) -> 32 | M20: =VLOOKUP($I20,$Q$6:$Y$278,5,FALSE) -> 2000 | N20: =VLOOKUP($I20,$Q$6:$Y$278,6,FALSE) -> 0 | P20: =COUNTIF($J$6:$J$278,R20) -> 1 | Q20: 124 | R20: BAT1S08 | S20: 1 | T20: 8 | U20: 100 | V20: 0 | W20: R | AA20: ZN11S38 | AB20: 500 | AC20: 1 | AD20: 32 | AE20: 2000 | AF20: 0
C21: 0x00000140 | D21: 0x00000000 | E21: 0 | F21: 320 | H21: 0x00000140 | I21: =UPPER(RIGHT(H17,3)) -> 122 | J21: =VLOOKUP($I21,$Q$6:$Y$278,2,FALSE) -> DMC1S08 | K21: =VLOOKUP($I21,$Q$6:$Y$278,3,FALSE) -> 1 | L21: =VLOOKUP($I21,$Q$6:$Y$278,4,FALSE) -> 32 | M21: =VLOOKUP($I21,$Q$6:$Y$278,5,FALSE) -> 100 | N21: =VLOOKUP($I21,$Q$6:$Y$278,6,FALSE) -> 1 | P21: =COUNTIF($J$6:$J$278,R21) -> 1 | Q21: 128 | R21: EHV1G30 | S21: 1 | T21: 8 | U21: 100 | V21: 0 | W21: R | AA21: DMC1S08 | AB21: 122 | AC21: 1 | AD21: 32 | AE21: 100 | AF21: 1
C22: 0x00000140 | D22: 0x00000008 | E22: 8 | F22: 320 | H22: 0x00000148 | I22: =UPPER(RIGHT(H18,3)) -> 124 | J22: =VLOOKUP($I22,$Q$6:$Y$278,2,FALSE) -> BAT1S08 | K22: =VLOOKUP($I22,$Q$6:$Y$278,3,FALSE) -> 1 | L22: =VLOOKUP($I22,$Q$6:$Y$278,4,FALSE) -> 8 | M22: =VLOOKUP($I22,$Q$6:$Y$278,5,FALSE) -> 100 | N22: =VLOOKUP($I22,$Q$6:$Y$278,6,FALSE) -> 0 | P22: =COUNTIF($J$6:$J$278,R22) -> 1 | Q22: 140 | R22: BDC1S23 | S22: 1 | T22: 8 | U22: - | V22: 0 | W22: R | AA22: BAT1S08 | AB22: 124 | AC22: 1 | AD22: 8 | AE22: 100 | AF22: 0
C23: 0x00000140 | D23: 0x00000010 | E23: 16 | F23: 320 | H23: 0x00000150 | I23: =UPPER(RIGHT(H19,3)) -> 1A4 | J23: =VLOOKUP($I23,$Q$6:$Y$278,2,FALSE) -> BDC1SA0 | K23: =VLOOKUP($I23,$Q$6:$Y$278,3,FALSE) -> 1 | L23: =VLOOKUP($I23,$Q$6:$Y$278,4,FALSE) -> 32 | M23: =VLOOKUP($I23,$Q$6:$Y$278,5,FALSE) -> 200 | N23: =VLOOKUP($I23,$Q$6:$Y$278,6,FALSE) -> 0 | P23: =COUNTIF($J$6:$J$278,R23) -> 1 | Q23: 148 | R23: BDC1S41 | S23: 1 | T23: 32 | U23: 100 | V23: 0 | W23: R | AA23: BDC1SA0 | AB23: 1A4 | AC23: 1 | AD23: 32 | AE23: 200 | AF23: 0
A24: CAN_CFG_ID_VALUE_5_MB053 | B24: 53 | C24: 0x00000140 | D24: 0x00000018 | E24: 24 | F24: 320 | H24: 0x00000158 | I24: =UPPER(RIGHT(H20,3)) -> 128 | J24: =VLOOKUP($I24,$Q$6:$Y$278,2,FALSE) -> EHV1G30 | K24: =VLOOKUP($I24,$Q$6:$Y$278,3,FALSE) -> 1 | L24: =VLOOKUP($I24,$Q$6:$Y$278,4,FALSE) -> 8 | M24: =VLOOKUP($I24,$Q$6:$Y$278,5,FALSE) -> 100 | N24: =VLOOKUP($I24,$Q$6:$Y$278,6,FALSE) -> 0 | P24: =COUNTIF($J$6:$J$278,R24) -> 1 | Q24: 14B | R24: IDT1S08 | S24: 1 | T24: 8 | U24: 100 | V24: 0 | W24: R | AA24: EHV1G30 | AB24: 128 | AC24: 1 | AD24: 8 | AE24: 100 | AF24: 0
C25: 0x0000014B | D25: 0x00000000 | E25: 0 | F25: 331 | H25: 0x0000014b | I25: =UPPER(RIGHT(H21,3)) -> 140 | J25: =VLOOKUP($I25,$Q$6:$Y$278,2,FALSE) -> BDC1S23 | K25: =VLOOKUP($I25,$Q$6:$Y$278,3,FALSE) -> 1 | L25: =VLOOKUP($I25,$Q$6:$Y$278,4,FALSE) -> 8 | M25: =VLOOKUP($I25,$Q$6:$Y$278,5,FALSE) -> - | N25: =VLOOKUP($I25,$Q$6:$Y$278,6,FALSE) -> 0 | P25: =COUNTIF($J$6:$J$278,R25) -> 1 | Q25: 14D | R25: RCP1S01 | S25: 1 | T25: 8 | U25: 100 | V25: 0 | W25: R | AA25: BDC1S23 | AB25: 140 | AC25: 1 | AD25: 8 | AE25: - | AF25: 0
A26: CAN_CFG_ID_VALUE_5_MB126 | B26: 126 | C26: 0x0000014B | D26: 0x00000004 | E26: 4 | F26: 331 | H26: 0x0000014f | I26: =UPPER(RIGHT(H22,3)) -> 148 | J26: =VLOOKUP($I26,$Q$6:$Y$278,2,FALSE) -> BDC1S41 | K26: =VLOOKUP($I26,$Q$6:$Y$278,3,FALSE) -> 1 | L26: =VLOOKUP($I26,$Q$6:$Y$278,4,FALSE) -> 32 | M26: =VLOOKUP($I26,$Q$6:$Y$278,5,FALSE) -> 100 | N26: =VLOOKUP($I26,$Q$6:$Y$278,6,FALSE) -> 0 | P26: =COUNTIF($J$6:$J$278,R26) -> 1 | Q26: 14F | R26: RCP1S03 | S26: 1 | T26: 8 | U26: 100 | V26: 0 | W26: R | AA26: BDC1S41 | AB26: 148 | AC26: 1 | AD26: 32 | AE26: 100 | AF26: 0
A27: CAN_CFG_ID_VALUE_5_MB134 | B27: 134 | C27: 0x0000014D | D27: 0x00000000 | E27: 0 | F27: 333 | H27: 0x0000014d | I27: =UPPER(RIGHT(H23,3)) -> 150 | J27: =VLOOKUP($I27,$Q$6:$Y$278,2,FALSE) -> BDC1S82 | K27: =VLOOKUP($I27,$Q$6:$Y$278,3,FALSE) -> 1 | L27: =VLOOKUP($I27,$Q$6:$Y$278,4,FALSE) -> 32 | M27: =VLOOKUP($I27,$Q$6:$Y$278,5,FALSE) -> 100 | N27: =VLOOKUP($I27,$Q$6:$Y$278,6,FALSE) -> 1 | P27: =COUNTIF($J$6:$J$278,R27) -> 1 | Q27: 150 | R27: BDC1S82 | S27: 1 | T27: 32 | U27: 100 | V27: 1 | W27: R | AA27: BDC1S82 | AB27: 150 | AC27: 1 | AD27: 32 | AE27: 100 | AF27: 1
A28: CAN_CFG_ID_VALUE_5_MB122 | B28: 122 | C28: 0x0000015A | D28: 0x00000000 | E28: 0 | F28: 346 | H28: 0x0000015a | I28: =UPPER(RIGHT(H24,3)) -> 158 | J28: =VLOOKUP($I28,$Q$6:$Y$278,2,FALSE) -> DDM1S77 | K28: =VLOOKUP($I28,$Q$6:$Y$278,3,FALSE) -> 1 | L28: =VLOOKUP($I28,$Q$6:$Y$278,4,FALSE) -> 32 | M28: =VLOOKUP($I28,$Q$6:$Y$278,5,FALSE) -> 100 | N28: =VLOOKUP($I28,$Q$6:$Y$278,6,FALSE) -> 0 | P28: =COUNTIF($J$6:$J$278,R28) -> 1 | Q28: 158 | R28: DDM1S77 | S28: 1 | T28: 32 | U28: 100 | V28: 0 | W28: R | AA28: DDM1S77 | AB28: 158 | AC28: 1 | AD28: 32 | AE28: 100 | AF28: 0
C29: 0x0000016E | D29: 0x00000000 | E29: 0 | F29: 366 | H29: 0x0000016e | I29: =UPPER(RIGHT(H25,3)) -> 14B | J29: =VLOOKUP($I29,$Q$6:$Y$278,2,FALSE) -> IDT1S08 | K29: =VLOOKUP($I29,$Q$6:$Y$278,3,FALSE) -> 1 | L29: =VLOOKUP($I29,$Q$6:$Y$278,4,FALSE) -> 8 | M29: =VLOOKUP($I29,$Q$6:$Y$278,5,FALSE) -> 100 | N29: =VLOOKUP($I29,$Q$6:$Y$278,6,FALSE) -> 0 | P29: =COUNTIF($J$6:$J$278,R29) -> 1 | Q29: 15A | R29: FCM1S78 | S29: 1 | T29: 8 | U29: 100 | V29: 0 | W29: R | AA29: IDT1S08 | AB29: 14B | AC29: 1 | AD29: 8 | AE29: 100 | AF29: 0
A30: CAN_CFG_ID_VALUE_5_MB022 | B30: 22 | C30: 0x0000016E | D30: 0x00000010 | E30: 16 | F30: 366 | H30: 0x0000017e | I30: =UPPER(RIGHT(H26,3)) -> 14F | J30: =VLOOKUP($I30,$Q$6:$Y$278,2,FALSE) -> RCP1S03 | K30: =VLOOKUP($I30,$Q$6:$Y$278,3,FALSE) -> 1 | L30: =VLOOKUP($I30,$Q$6:$Y$278,4,FALSE) -> 8 | M30: =VLOOKUP($I30,$Q$6:$Y$278,5,FALSE) -> 100 | N30: =VLOOKUP($I30,$Q$6:$Y$278,6,FALSE) -> 0 | P30: =COUNTIF($J$6:$J$278,R30) -> 1 | Q30: 16E | R30: BAT1E45 | S30: 1 | T30: 32 | U30: 100 | V30: 0 | W30: R | AA30: RCP1S03 | AB30: 14F | AC30: 1 | AD30: 8 | AE30: 100 | AF30: 0
A31: CAN_CFG_ID_VALUE_5_MB094 | B31: 94 | C31: 0x0000018D | D31: 0x00000000 | E31: 0 | F31: 397 | H31: 0x0000018d | I31: =UPPER(RIGHT(H27,3)) -> 14D | J31: =VLOOKUP($I31,$Q$6:$Y$278,2,FALSE) -> RCP1S01 | K31: =VLOOKUP($I31,$Q$6:$Y$278,3,FALSE) -> 1 | L31: =VLOOKUP($I31,$Q$6:$Y$278,4,FALSE) -> 8 | M31: =VLOOKUP($I31,$Q$6:$Y$278,5,FALSE) -> 100 | N31: =VLOOKUP($I31,$Q$6:$Y$278,6,FALSE) -> 0 | P31: =COUNTIF($J$6:$J$278,R31) -> 1 | Q31: 17E | R31: ADC1S11 | S31: 1 | T31: 32 | U31: 100 | V31: 0 | W31: R | AA31: RCP1S01 | AB31: 14D | AC31: 1 | AD31: 8 | AE31: 100 | AF31: 0
A32: CAN_CFG_ID_VALUE_5_MB095 | B32: 95 | C32: 0x0000019A | D32: 0x00000000 | E32: 0 | F32: 410 | H32: 0x0000019a | I32: =UPPER(RIGHT(H28,3)) -> 15A | J32: =VLOOKUP($I32,$Q$6:$Y$278,2,FALSE) -> FCM1S78 | K32: =VLOOKUP($I32,$Q$6:$Y$278,3,FALSE) -> 1 | L32: =VLOOKUP($I32,$Q$6:$Y$278,4,FALSE) -> 8 | M32: =VLOOKUP($I32,$Q$6:$Y$278,5,FALSE) -> 100 | N32: =VLOOKUP($I32,$Q$6:$Y$278,6,FALSE) -> 0 | P32: =COUNTIF($J$6:$J$278,R32) -> 1 | Q32: 186 | R32: BDC1S30 | S32: 1 | T32: 32 | U32: 100 | V32: 0 | W32: R | AA32: FCM1S78 | AB32: 15A | AC32: 1 | AD32: 8 | AE32: 100 | AF32: 0
A33: CAN_CFG_ID_VALUE_5_MB063 | B33: 63 | C33: 0x000001A0 | D33: 0x00000000 | E33: 0 | F33: 416 | H33: 0x000001a0 | I33: =UPPER(RIGHT(H29,3)) -> 16E | J33: =VLOOKUP($I33,$Q$6:$Y$278,2,FALSE) -> BAT1E45 | K33: =VLOOKUP($I33,$Q$6:$Y$278,3,FALSE) -> 1 | L33: =VLOOKUP($I33,$Q$6:$Y$278,4,FALSE) -> 32 | M33: =VLOOKUP($I33,$Q$6:$Y$278,5,FALSE) -> 100 | N33: =VLOOKUP($I33,$Q$6:$Y$278,6,FALSE) -> 0 | P33: =COUNTIF($J$6:$J$278,R33) -> 1 | Q33: 18D | R33: BDF3S02 | S33: 1 | T33: 32 | U33: 100 | V33: 0 | W33: R | AA33: BAT1E45 | AB33: 16E | AC33: 1 | AD33: 32 | AE33: 100 | AF33: 0
A34: CAN_CFG_ID_VALUE_5_MB124 | B34: 124 | C34: 0x000001B2 | D34: 0x00000000 | E34: 0 | F34: 434 | H34: 0x000001b2 | I34: =UPPER(RIGHT(H30,3)) -> 17E | J34: =VLOOKUP($I34,$Q$6:$Y$278,2,FALSE) -> ADC1S11 | K34: =VLOOKUP($I34,$Q$6:$Y$278,3,FALSE) -> 1 | L34: =VLOOKUP($I34,$Q$6:$Y$278,4,FALSE) -> 32 | M34: =VLOOKUP($I34,$Q$6:$Y$278,5,FALSE) -> 100 | N34: =VLOOKUP($I34,$Q$6:$Y$278,6,FALSE) -> 0 | P34: =COUNTIF($J$6:$J$278,R34) -> 1 | Q34: 19A | R34: BDR3S02 | S34: 1 | T34: 32 | U34: 200 | V34: 0 | W34: R | AA34: ADC1S11 | AB34: 17E | AC34: 1 | AD34: 32 | AE34: 100 | AF34: 0
A35: CAN_CFG_ID_VALUE_5_MB138 | B35: 138 | C35: 0x000001BB | D35: 0x00000000 | E35: 0 | F35: 443 | H35: 0x000001bb | I35: =UPPER(RIGHT(H31,3)) -> 18D | J35: =VLOOKUP($I35,$Q$6:$Y$278,2,FALSE) -> BDF3S02 | K35: =VLOOKUP($I35,$Q$6:$Y$278,3,FALSE) -> 1 | L35: =VLOOKUP($I35,$Q$6:$Y$278,4,FALSE) -> 32 | M35: =VLOOKUP($I35,$Q$6:$Y$278,5,FALSE) -> 100 | N35: =VLOOKUP($I35,$Q$6:$Y$278,6,FALSE) -> 0 | P35: =COUNTIF($J$6:$J$278,R35) -> 1 | Q35: 1A0 | R35: BDC1S87 | S35: 1 | T35: 8 | U35: 200 | V35: 0 | W35: R | AA35: BDF3S02 | AB35: 18D | AC35: 1 | AD35: 32 | AE35: 100 | AF35: 0
C36: 0x000001BC | D36: 0x00000000 | E36: 0 | F36: 444 | H36: 0x000001bc | I36: =UPPER(RIGHT(H32,3)) -> 19A | J36: =VLOOKUP($I36,$Q$6:$Y$278,2,FALSE) -> BDR3S02 | K36: =VLOOKUP($I36,$Q$6:$Y$278,3,FALSE) -> 1 | L36: =VLOOKUP($I36,$Q$6:$Y$278,4,FALSE) -> 32 | M36: =VLOOKUP($I36,$Q$6:$Y$278,5,FALSE) -> 200 | N36: =VLOOKUP($I36,$Q$6:$Y$278,6,FALSE) -> 0 | P36: =COUNTIF($J$6:$J$278,R36) -> 1 | Q36: 1A4 | R36: BDC1SA0 | S36: 1 | T36: 32 | U36: 200 | V36: 0 | W36: R | AA36: BDR3S02 | AB36: 19A | AC36: 1 | AD36: 32 | AE36: 200 | AF36: 0
A37: CAN_CFG_ID_VALUE_5_MB111 | B37: 111 | C37: 0x000001BC | D37: 0x00000002 | E37: 2 | F37: 444 | H37: 0x000001be | I37: =UPPER(RIGHT(H33,3)) -> 1A0 | J37: =VLOOKUP($I37,$Q$6:$Y$278,2,FALSE) -> BDC1S87 | K37: =VLOOKUP($I37,$Q$6:$Y$278,3,FALSE) -> 1 | L37: =VLOOKUP($I37,$Q$6:$Y$278,4,FALSE) -> 8 | M37: =VLOOKUP($I37,$Q$6:$Y$278,5,FALSE) -> 200 | N37: =VLOOKUP($I37,$Q$6:$Y$278,6,FALSE) -> 0 | P37: =COUNTIF($J$6:$J$278,R37) -> 1 | Q37: 1B2 | R37: FCM1S90 | S37: 1 | T37: 32 | U37: 200 | V37: 0 | W37: R | AA37: BDC1S87 | AB37: 1A0 | AC37: 1 | AD37: 8 | AE37: 200 | AF37: 0
C38: 0x000001C0 | D38: 0x00000000 | E38: 0 | F38: 448 | H38: 0x000001c0 | I38: =UPPER(RIGHT(H34,3)) -> 1B2 | J38: =VLOOKUP($I38,$Q$6:$Y$278,2,FALSE) -> FCM1S90 | K38: =VLOOKUP($I38,$Q$6:$Y$278,3,FALSE) -> 1 | L38: =VLOOKUP($I38,$Q$6:$Y$278,4,FALSE) -> 32 | M38: =VLOOKUP($I38,$Q$6:$Y$278,5,FALSE) -> 200 | N38: =VLOOKUP($I38,$Q$6:$Y$278,6,FALSE) -> 0 | P38: =COUNTIF($J$6:$J$278,R38) -> 1 | Q38: 1BB | R38: SOL1S06 | S38: 1 | T38: 8 | U38: 200 | V38: 0 | W38: R | AA38: FCM1S90 | AB38: 1B2 | AC38: 1 | AD38: 32 | AE38: 200 | AF38: 0
C39: 0x000001C0 | D39: 0x00000001 | E39: 1 | F39: 448 | H39: 0x000001c1 | I39: =UPPER(RIGHT(H35,3)) -> 1BB | J39: =VLOOKUP($I39,$Q$6:$Y$278,2,FALSE) -> SOL1S06 | K39: =VLOOKUP($I39,$Q$6:$Y$278,3,FALSE) -> 1 | L39: =VLOOKUP($I39,$Q$6:$Y$278,4,FALSE) -> 8 | M39: =VLOOKUP($I39,$Q$6:$Y$278,5,FALSE) -> 200 | N39: =VLOOKUP($I39,$Q$6:$Y$278,6,FALSE) -> 0 | P39: =COUNTIF($J$6:$J$278,R39) -> 1 | Q39: 1BC | R39: EHV1E96 | S39: 1 | T39: 32 | U39: 200 | V39: 0 | W39: R | AA39: SOL1S06 | AB39: 1BB | AC39: 1 | AD39: 8 | AE39: 200 | AF39: 0
C40: 0x000001C0 | D40: 0x00000010 | E40: 16 | F40: 448 | H40: 0x000001d0 | I40: =UPPER(RIGHT(H36,3)) -> 1BC | J40: =VLOOKUP($I40,$Q$6:$Y$278,2,FALSE) -> EHV1E96 | K40: =VLOOKUP($I40,$Q$6:$Y$278,3,FALSE) -> 1 | L40: =VLOOKUP($I40,$Q$6:$Y$278,4,FALSE) -> 32 | M40: =VLOOKUP($I40,$Q$6:$Y$278,5,FALSE) -> 200 | N40: =VLOOKUP($I40,$Q$6:$Y$278,6,FALSE) -> 0 | P40: =COUNTIF($J$6:$J$278,R40) -> 1 | Q40: 1BE | R40: ZN21S28 | S40: 1 | T40: 32 | U40: 200 | V40: 1 | W40: R | AA40: EHV1E96 | AB40: 1BC | AC40: 1 | AD40: 32 | AE40: 200 | AF40: 0
...

Sheet CANRx_G2M-1_v2
A1: Message Inf. | K1: =L1+1 -> 12 | L1: =M1+1 -> 11 | M1: =N1+1 -> 10 | N1: =O1+1 -> 9 | O1: =P1+1 -> 8 | P1: =Q1+1 -> 7 | Q1: =R1+1 -> 6 | R1: =S1+1 -> 5 | ... V1: =W1+1 -> 1 | W1: 0
K2: =MAX(K6:K286) -> 0 | L2: =MAX(L6:L286) -> 1 | M2: =MAX(M6:M286) -> 1 | N2: =MAX(N6:N286) -> 1 | O2: =MAX(O6:O286) -> 0 | P2: =MAX(P6:P286) -> 0 | Q2: =MAX(Q6:Q286) -> 0 | R2: =MAX(R6:R286) -> 0 | ... W2: =MAX(W6:W286) -> 0 | X2: =SUM(K2:W2) -> 4 | Z2: EPUD-ID
G3: G2M-1 | H3: G2M-2 | I3: G5M | K3: =L3*2 -> 4096 | L3: =M3*2 -> 2048 | M3: =N3*2 -> 1024 | N3: =O3*2 -> 512 | O3: =P3*2 -> 256 | P3: =Q3*2 -> 128 | Q3: =R3*2 -> 64 | R3: =S3*2 -> 32 | ... V3: =W3*2 -> 2 | W3: 1 | X3: 3 | Z3: Egress #0 | AA3: Egress #1 | AB3: Egress #2
A4: Msg. Label | B4: CAN ID | C4: FDF | D4: DLC | E4: Com. Trans. Cycle | F4: KZK Message/C-DC Only | G4: Cockpit Domain Controller | H4: Cockpit Domain Controller | I4: Cockpit Domain Controller | K4: CAN_LPR_REGR_EN_PHY_RX_G2M2 | L4: CAN_LPR_REGR_EN_PHY_RX_G2M1 | M4: CAN_LPR_REGR_EN_UDS_TX_VIR_0 | N4: CAN_LPR_REGR_EN_VIR_TX_0 | O4: CAN_LPR_REGR_EN_PHY_TX_LOCA | P4: CAN_LPR_REGR_EN_PHY_TX_G5M | Q4: CAN_LPR_REGR_EN_PHY_TX_G2M1 | R4: CAN_LPR_REGR_EN_UDS_FQ_G2M1 | S4: CAN_LPR_REGR_EN_PHY_FQ_LOCA | T4: CAN_LPR_REGR_EN_PHY_FQ_G5M | U4: CAN_LPR_REGR_EN_PHY_FQ_G2M1 | V4: CAN_LPR_REGR_EN_SECOC_RX | W4: CAN_LPR_REGR_EN_SECOC_TX | X4: Number of EPDU-ID | Y4: Row of u2p_EPDU_ID[] | Z4: CAN_LPR_REGR_EN_SECOC_RX | AA4: CAN_LPR_REGR_EN_VIR_TX_0 bit#15-#8 : Controller bit#7-#0:Message Box | AB4: CAN_LPR_REGR_EN_UDS_TX_VIR_0 | AF4: Routing Rule Table Index/ CAN-ID Min | AG4: Routing Rule Table Index/ CAN-ID Max | AH4: CAN ID Hex | AI4: CAN ID Dec | AJ4: Range Min | AK4: Range Max | AL4: Data Length Min
B5: (11bit/29bit) | C5: (0/1) | D5: (dec) | E5: (ms) | F5: (0/1) | K5: # | L5: # | M5: # | N5: # | O5: # | P5: # | Q5: # | R5: # | S5: # | T5: # | U5: # | V5: # | W5: # | X5: # | Y5: # | Z5: # | AA5: # | AB5: # | AC5: # | AD5: # | AE5: # | AF5: # | AG5: # | AH5: # | AI5: # | AJ5: # | AK5: # | AM5: # | AN5: #
A6: BDC1S52 | B6: 013 | C6: 1 | D6: 64 | E6: - | F6: 0 | G6: R | K6: 0 | L6: 0 | M6: 0 | N6: 1 | O6: 0 | P6: 0 | Q6: 0 | R6: 0 | S6: 0 | T6: 0 | U6: 0 | V6: 0 | W6: 0 | Y6: 29 | Z6: 65535 | AA6: 32768 | AB6: 65535 | AF6: =IF(AF5="#",0,IF(AND(D5=D6,K5=K6,L5=L6,M5=M6,N5=N6,O5=O6,P5=P6,Q5=Q6,R5=R6,S5=S6,T5=T6,U5=U6,V5=V6,W5=W6,HEX2DEC(SUBSTITUTE(AH5,"0x",""))<HEX2DEC(SUBSTITUTE(AH6,"0x",""))),"",MAX($AF$6:AF6)+1)) -> 0 | AG6: =IF(MAX(INDEX($AF:$AF,ROW($AG$6)):INDEX($AF:$AF,ROW(AG6)))+1=AF7,MAX(INDEX($AF:$AF,ROW($AG$6)):INDEX($AF:$AF,ROW(AG6))),"") | AH6: =LOWER(IF(C6="1", "0x40000"&B6,"0x00000"&B6)) -> 0x40000013 | AI6: =HEX2DEC(RIGHT(AH6,8)) -> 1073741843 | AJ6: =IF(AF6<>"",AH6,"") -> 0x40000013 | AK6: =IF(AF6<>"",VLOOKUP(AF6,$AG$6:$AH$286,2,TRUE),"") -> 0x40000062 | AL6: =IF($AF6<>"",MIN($D6:$D6),"") -> 64
A7: BDC1S60 | B7: 01B | C7: 1 | D7: 64 | E7: - | F7: 0 | G7: R | K7: 0 | L7: 0 | M7: 0 | N7: 1 | O7: 0 | P7: 0 | Q7: 0 | R7: 0 | S7: 0 | T7: 0 | U7: 0 | V7: 0 | W7: 0 | Y7: 29 | Z7: 65535 | AA7: 32768 | AB7: 65535 | AF7: =IF(V7=1,MAX($AF$6:AF6)+1,IF(AF6="#",0,IF(AND(D6=D7,K6=K7,L6=L7,M6=M7,N6=N7,O6=O7,P6=P7,Q6=Q7,R6=R7,S6=S7,T6=T7,U6=U7,V6=V7,W6=W7,HEX2DEC(SUBSTITUTE(AH6,"0x",""))<HEX2DEC(SUBSTITUTE(AH7,"0x",""))),"",MAX($AF$6:AF6)+1))) | AG7: =IF(MAX(INDEX($AF:$AF,ROW($AG$6)):INDEX($AF:$AF,ROW(AG7)))+1=AF8,MAX(INDEX($AF:$AF,ROW($AG$6)):INDEX($AF:$AF,ROW(AG7))),"") | AH7: =LOWER(IF(C7="1", "0x40000"&B7,"0x00000"&B7)) -> 0x4000001b | AI7: =HEX2DEC(RIGHT(AH7,8)) -> 1073741851 | AJ7: =IF(AF7<>"",AH7,"") | AK7: =IF(AF7<>"",VLOOKUP(AF7,$AG$6:$AH$286,2,TRUE),"") | AL7: =IF($AF7<>"",MIN($D7:$D7),"") | AN7: =IF(AI6<AI7,"ok","not ok") -> ok | AO7: CAN_CFG_ID_VALUE_5_MB
A8: EPS1S11 | B8: 062 | C8: 1 | D8: 64 | E8: 10 | F8: 1 | G8: R | K8: 0 | L8: 0 | M8: 0 | N8: 1 | O8: 0 | P8: 0 | Q8: 0 | R8: 0 | S8: 0 | T8: 0 | U8: 0 | V8: 0 | W8: 0 | Y8: 29 | Z8: 65535 | AA8: 32768 | AB8: 65535 | AF8: =IF(V8=1,MAX($AF$6:AF7)+1,IF(AF7="#",0,IF(AND(D7=D8,K7=K8,L7=L8,M7=M8,N7=N8,O7=O8,P7=P8,Q7=Q8,R7=R8,S7=S8,T7=T8,U7=U8,V7=V8,W7=W8,HEX2DEC(SUBSTITUTE(AH7,"0x",""))<HEX2DEC(SUBSTITUTE(AH8,"0x",""))),"",MAX($AF$6:AF7)+1))) | AG8: =IF(MAX(INDEX($AF:$AF,ROW($AG$6)):INDEX($AF:$AF,ROW(AG8)))+1=AF9,MAX(INDEX($AF:$AF,ROW($AG$6)):INDEX($AF:$AF,ROW(AG8))),"") -> 0 | AH8: =LOWER(IF(C8="1", "0x40000"&B8,"0x00000"&B8)) -> 0x40000062 | AI8: =HEX2DEC(RIGHT(AH8,8)) -> 1073741922 | AJ8: =IF(AF8<>"",AH8,"") | AK8: =IF(AF8<>"",VLOOKUP(AF8,$AG$6:$AH$286,2,TRUE),"") | AL8: =IF($AF8<>"",MIN($D8:$D8),"") | AN8: =IF(AI7<AI8,"ok","not ok") -> ok
A9: VSC1F01 | B9: 06A | C9: 1 | D9: 32 | E9: 10 | F9: 1 | G9: R | K9: 0 | L9: 0 | M9: 0 | N9: 1 | O9: 0 | P9: 0 | Q9: 0 | R9: 0 | S9: 0 | T9: 0 | U9: 0 | V9: 0 | W9: 0 | Y9: 29 | Z9: 65535 | AA9: 32768 | AB9: 65535 | AF9: =IF(V9=1,MAX($AF$6:AF8)+1,IF(AF8="#",0,IF(AND(D8=D9,K8=K9,L8=L9,M8=M9,N8=N9,O8=O9,P8=P9,Q8=Q9,R8=R9,S8=S9,T8=T9,U8=U9,V8=V9,W8=W9,HEX2DEC(SUBSTITUTE(AH8,"0x",""))<HEX2DEC(SUBSTITUTE(AH9,"0x",""))),"",MAX($AF$6:AF8)+1))) -> 1 | AG9: =IF(MAX(INDEX($AF:$AF,ROW($AG$6)):INDEX($AF:$AF,ROW(AG9)))+1=AF10,MAX(INDEX($AF:$AF,ROW($AG$6)):INDEX($AF:$AF,ROW(AG9))),"") -> 1 | AH9: =LOWER(IF(C9="1", "0x40000"&B9,"0x00000"&B9)) -> 0x4000006a | AI9: =HEX2DEC(RIGHT(AH9,8)) -> 1073741930 | AJ9: =IF(AF9<>"",AH9,"") -> 0x4000006a | AK9: =IF(AF9<>"",VLOOKUP(AF9,$AG$6:$AH$286,2,TRUE),"") -> 0x4000006a | AL9: =IF($AF9<>"",MIN($D9:$D9),"") -> 32 | AN9: =IF(AI8<AI9,"ok","not ok") -> ok | AO9: CAN_CFG_ID_VALUE_5_MB
A10: VSC1G12 | B10: 069 | C10: 1 | D10: 32 | E10: 10 | F10: 1 | G10: R | K10: 0 | L10: 0 | M10: 0 | N10: 1 | O10: 0 | P10: 0 | Q10: 0 | R10: 0 | S10: 0 | T10: 0 | U10: 0 | V10: 0 | W10: 0 | Y10: 29 | Z10: 65535 | AA10: 32768 | AB10: 65535 | AF10: =IF(V10=1,MAX($AF$6:AF9)+1,IF(AF9="#",0,IF(AND(D9=D10,K9=K10,L9=L10,M9=M10,N9=N10,O9=O10,P9=P10,Q9=Q10,R9=R10,S9=S10,T9=T10,U9=U10,V9=V10,W9=W10,HEX2DEC(SUBSTITUTE(AH9,"0x",""))<HEX2DEC(SUBSTITUTE(AH10,"0x",""))),"",MAX($AF$6:AF9)+1))) -> 2 | AG10: =IF(MAX(INDEX($AF:$AF,ROW($AG$6)):INDEX($AF:$AF,ROW(AG10)))+1=AF11,MAX(INDEX($AF:$AF,ROW($AG$6)):INDEX($AF:$AF,ROW(AG10))),"") -> 2 | AH10: =LOWER(IF(C10="1", "0x40000"&B10,"0x00000"&B10)) -> 0x40000069 | AI10: =HEX2DEC(RIGHT(AH10,8)) -> 1073741929 | AJ10: =IF(AF10<>"",AH10,"") -> 0x40000069 | AK10: =IF(AF10<>"",VLOOKUP(AF10,$AG$6:$AH$286,2,TRUE),"") -> 0x40000069 | AL10: =IF($AF10<>"",MIN($D10:$D10),"") -> 32 | AN10: =IF(AI9<AI10,"ok","not ok") -> not ok | AO10: CAN_CFG_ID_VALUE_5_MB
A11: ZN11S08 | B11: 086 | C11: 1 | D11: 8 | E11: 20 | F11: 0 | G11: R | K11: 0 | L11: 0 | M11: 0 | N11: 1 | O11: 0 | P11: 0 | Q11: 0 | R11: 0 | S11: 0 | T11: 0 | U11: 0 | V11: 0 | W11: 0 | Y11: 29 | Z11: 65535 | AA11: 32768 | AB11: 65535 | AF11: =IF(V11=1,MAX($AF$6:AF10)+1,IF(AF10="#",0,IF(AND(D10=D11,K10=K11,L10=L11,M10=M11,N10=N11,O10=O11,P10=P11,Q10=Q11,R10=R11,S10=S11,T10=T11,U10=U11,V10=V11,W10=W11,HEX2DEC(SUBSTITUTE(AH10,"0x",""))<HEX2DEC(SUBSTITUTE(AH11,"0x",""))),"",MAX($AF$6:AF10)+1))) -> 3 | AG11: =IF(MAX(INDEX($AF:$AF,ROW($AG$6)):INDEX($AF:$AF,ROW(AG11)))+1=AF12,MAX(INDEX($AF:$AF,ROW($AG$6)):INDEX($AF:$AF,ROW(AG11))),"") -> 3 | AH11: =LOWER(IF(C11="1", "0x40000"&B11,"0x00000"&B11)) -> 0x40000086 | AI11: =HEX2DEC(RIGHT(AH11,8)) -> 1073741958 | AJ11: =IF(AF11<>"",AH11,"") -> 0x40000086 | AK11: =IF(AF11<>"",VLOOKUP(AF11,$AG$6:$AH$286,2,TRUE),"") -> 0x40000086 | AL11: =IF($AF11<>"",MIN($D11:$D11),"") -> 8 | AN11: =IF(AI10<AI11,"ok","not ok") -> ok
A12: BDC1S30 | B12: 186 | C12: 1 | D12: 32 | E12: 100 | F12: 0 | G12: R | K12: 0 | L12: 0 | M12: 0 | N12: 1 | O12: 0 | P12: 0 | Q12: 0 | R12: 0 | S12: 0 | T12: 0 | U12: 0 | V12: 0 | W12: 0 | Y12: 29 | Z12: 65535 | AA12: 32768 | AB12: 65535 | AF12: =IF(V12=1,MAX($AF$6:AF11)+1,IF(AF11="#",0,IF(AND(D11=D12,K11=K12,L11=L12,M11=M12,N11=N12,O11=O12,P11=P12,Q11=Q12,R11=R12,S11=S12,T11=T12,U11=U12,V11=V12,W11=W12,HEX2DEC(SUBSTITUTE(AH11,"0x",""))<HEX2DEC(SUBSTITUTE(AH12,"0x",""))),"",MAX($AF$6:AF11)+1))) -> 4 | AG12: =IF(MAX(INDEX($AF:$AF,ROW($AG$6)):INDEX($AF:$AF,ROW(AG12)))+1=AF13,MAX(INDEX($AF:$AF,ROW($AG$6)):INDEX($AF:$AF,ROW(AG12))),"") -> 4 | AH12: =LOWER(IF(C12="1", "0x40000"&B12,"0x00000"&B12)) -> 0x40000186 | AI12: =HEX2DEC(RIGHT(AH12,8)) -> 1073742214 | AJ12: =IF(AF12<>"",AH12,"") -> 0x40000186 | AK12: =IF(AF12<>"",VLOOKUP(AF12,$AG$6:$AH$286,2,TRUE),"") -> 0x40000186 | AL12: =IF($AF12<>"",MIN($D12:$D12),"") -> 32 | AN12: =IF(AI11<AI12,"ok","not ok") -> ok | AO12: CAN_CFG_ID_VALUE_5_MB
A13: BDC1S40 | B13: 09C | C13: 1 | D13: 32 | E13: 50 | F13: 0 | G13: R | K13: 0 | L13: 0 | M13: 0 | N13: 1 | O13: 0 | P13: 0 | Q13: 0 | R13: 0 | S13: 0 | T13: 0 | U13: 0 | V13: 0 | W13: 0 | Y13: 29 | Z13: 65535 | AA13: 32768 | AB13: 65535 | AF13: =IF(V13=1,MAX($AF$6:AF12)+1,IF(AF12="#",0,IF(AND(D12=D13,K12=K13,L12=L13,M12=M13,N12=N13,O12=O13,P12=P13,Q12=Q13,R12=R13,S12=S13,T12=T13,U12=U13,V12=V13,W12=W13,HEX2DEC(SUBSTITUTE(AH12,"0x",""))<HEX2DEC(SUBSTITUTE(AH13,"0x",""))),"",MAX($AF$6:AF12)+1))) -> 5 | AG13: =IF(MAX(INDEX($AF:$AF,ROW($AG$6)):INDEX($AF:$AF,ROW(AG13)))+1=AF14,MAX(INDEX($AF:$AF,ROW($AG$6)):INDEX($AF:$AF,ROW(AG13))),"") | AH13: =LOWER(IF(C13="1", "0x40000"&B13,"0x00000"&B13)) -> 0x4000009c | AI13: =HEX2DEC(RIGHT(AH13,8)) -> 1073741980 | AJ13: =IF(AF13<>"",AH13,"") -> 0x4000009c | AK13: =IF(AF13<>"",VLOOKUP(AF13,$AG$6:$AH$286,2,TRUE),"") -> 0x400000b7 | AL13: =IF($AF13<>"",MIN($D13:$D13),"") -> 32 | AN13: =IF(AI12<AI13,"ok","not ok") -> not ok
A14: VSC1G13 | B14: 09E | C14: 1 | D14: 32 | E14: 20 | F14: 1 | G14: R | K14: 0 | L14: 0 | M14: 0 | N14: 1 | O14: 0 | P14: 0 | Q14: 0 | R14: 0 | S14: 0 | T14: 0 | U14: 0 | V14: 0 | W14: 0 | Y14: 29 | Z14: 65535 | AA14: 32768 | AB14: 65535 | AF14: =IF(V14=1,MAX($AF$6:AF13)+1,IF(AF13="#",0,IF(AND(D13=D14,K13=K14,L13=L14,M13=M14,N13=N14,O13=O14,P13=P14,Q13=Q14,R13=R14,S13=S14,T13=T14,U13=U14,V13=V14,W13=W14,HEX2DEC(SUBSTITUTE(AH13,"0x",""))<HEX2DEC(SUBSTITUTE(AH14,"0x",""))),"",MAX($AF$6:AF13)+1))) | AG14: =IF(MAX(INDEX($AF:$AF,ROW($AG$6)):INDEX($AF:$AF,ROW(AG14)))+1=AF15,MAX(INDEX($AF:$AF,ROW($AG$6)):INDEX($AF:$AF,ROW(AG14))),"") | AH14: =LOWER(IF(C14="1", "0x40000"&B14,"0x00000"&B14)) -> 0x4000009e | AI14: =HEX2DEC(RIGHT(AH14,8)) -> 1073741982 | AJ14: =IF(AF14<>"",AH14,"") | AK14: =IF(AF14<>"",VLOOKUP(AF14,$AG$6:$AH$286,2,TRUE),"") | AL14: =IF($AF14<>"",MIN($D14:$D14),"") | AN14: =IF(AI13<AI14,"ok","not ok") -> ok | AO14: CAN_CFG_ID_VALUE_5_MB
A15: ENG1G03 | B15: 0A4 | C15: 1 | D15: 32 | E15: 24 | F15: 1 | G15: R | K15: 0 | L15: 0 | M15: 0 | N15: 1 | O15: 0 | P15: 0 | Q15: 0 | R15: 0 | S15: 0 | T15: 0 | U15: 0 | V15: 0 | W15: 0 | Y15: 29 | Z15: 65535 | AA15: 32768 | AB15: 65535 | AF15: =IF(V15=1,MAX($AF$6:AF14)+1,IF(AF14="#",0,IF(AND(D14=D15,K14=K15,L14=L15,M14=M15,N14=N15,O14=O15,P14=P15,Q14=Q15,R14=R15,S14=S15,T14=T15,U14=U15,V14=V15,W14=W15,HEX2DEC(SUBSTITUTE(AH14,"0x",""))<HEX2DEC(SUBSTITUTE(AH15,"0x",""))),"",MAX($AF$6:AF14)+1))) | AG15: =IF(MAX(INDEX($AF:$AF,ROW($AG$6)):INDEX($AF:$AF,ROW(AG15)))+1=AF16,MAX(INDEX($AF:$AF,ROW($AG$6)):INDEX($AF:$AF,ROW(AG15))),"") | AH15: =LOWER(IF(C15="1", "0x40000"&B15,"0x00000"&B15)) -> 0x400000a4 | AI15: =HEX2DEC(RIGHT(AH15,8)) -> 1073741988 | AJ15: =IF(AF15<>"",AH15,"") | AK15: =IF(AF15<>"",VLOOKUP(AF15,$AG$6:$AH$286,2,TRUE),"") | AL15: =IF($AF15<>"",MIN($D15:$D15),"") | AN15: =IF(AI14<AI15,"ok","not ok") -> ok | AO15: CAN_CFG_ID_VALUE_5_MB
A16: VSC1G14 | B16: 0B7 | C16: 1 | D16: 32 | E16: 30 | F16: 1 | G16: R | K16: 0 | L16: 0 | M16: 0 | N16: 1 | O16: 0 | P16: 0 | Q16: 0 | R16: 0 | S16: 0 | T16: 0 | U16: 0 | V16: 0 | W16: 0 | Y16: 29 | Z16: 65535 | AA16: 32768 | AB16: 65535 | AF16: =IF(V16=1,MAX($AF$6:AF15)+1,IF(AF15="#",0,IF(AND(D15=D16,K15=K16,L15=L16,M15=M16,N15=N16,O15=O16,P15=P16,Q15=Q16,R15=R16,S15=S16,T15=T16,U15=U16,V15=V16,W15=W16,HEX2DEC(SUBSTITUTE(AH15,"0x",""))<HEX2DEC(SUBSTITUTE(AH16,"0x",""))),"",MAX($AF$6:AF15)+1))) | AG16: =IF(MAX(INDEX($AF:$AF,ROW($AG$6)):INDEX($AF:$AF,ROW(AG16)))+1=AF17,MAX(INDEX($AF:$AF,ROW($AG$6)):INDEX($AF:$AF,ROW(AG16))),"") -> 5 | AH16: =LOWER(IF(C16="1", "0x40000"&B16,"0x00000"&B16)) -> 0x400000b7 | AI16: =HEX2DEC(RIGHT(AH16,8)) -> 1073742007 | AJ16: =IF(AF16<>"",AH16,"") | AK16: =IF(AF16<>"",VLOOKUP(AF16,$AG$6:$AH$286,2,TRUE),"") | AL16: =IF($AF16<>"",MIN($D16:$D16),"") | AN16: =IF(AI15<AI16,"ok","not ok") -> ok | AO16: CAN_CFG_ID_VALUE_5_MB
A17: DDM1S12 | B17: 0B8 | C17: 1 | D17: 64 | E17: 30 | F17: 1 | G17: R | K17: 0 | L17: 0 | M17: 0 | N17: 1 | O17: 0 | P17: 0 | Q17: 0 | R17: 0 | S17: 0 | T17: 0 | U17: 0 | V17: 0 | W17: 0 | Y17: 29 | Z17: 65535 | AA17: 32768 | AB17: 65535 | AF17: =IF(V17=1,MAX($AF$6:AF16)+1,IF(AF16="#",0,IF(AND(D16=D17,K16=K17,L16=L17,M16=M17,N16=N17,O16=O17,P16=P17,Q16=Q17,R16=R17,S16=S17,T16=T17,U16=U17,V16=V17,W16=W17,HEX2DEC(SUBSTITUTE(AH16,"0x",""))<HEX2DEC(SUBSTITUTE(AH17,"0x",""))),"",MAX($AF$6:AF16)+1))) -> 6 | AG17: =IF(MAX(INDEX($AF:$AF,ROW($AG$6)):INDEX($AF:$AF,ROW(AG17)))+1=AF18,MAX(INDEX($AF:$AF,ROW($AG$6)):INDEX($AF:$AF,ROW(AG17))),"") -> 6 | AH17: =LOWER(IF(C17="1", "0x40000"&B17,"0x00000"&B17)) -> 0x400000b8 | AI17: =HEX2DEC(RIGHT(AH17,8)) -> 1073742008 | AJ17: =IF(AF17<>"",AH17,"") -> 0x400000b8 | AK17: =IF(AF17<>"",VLOOKUP(AF17,$AG$6:$AH$286,2,TRUE),"") -> 0x400000b8 | AL17: =IF($AF17<>"",MIN($D17:$D17),"") -> 64 | AN17: =IF(AI16<AI17,"ok","not ok") -> ok | AO17: CAN_CFG_ID_VALUE_5_MB
A18: ENG1G92 | B18: 0FC | C18: 1 | D18: 8 | E18: 1000 | F18: 0 | G18: R | K18: 0 | L18: 0 | M18: 0 | N18: 1 | O18: 0 | P18: 0 | Q18: 0 | R18: 0 | S18: 0 | T18: 0 | U18: 0 | V18: 0 | W18: 0 | Y18: 29 | Z18: 65535 | AA18: 32768 | AB18: 65535 | AF18: =IF(V18=1,MAX($AF$6:AF17)+1,IF(AF17="#",0,IF(AND(D17=D18,K17=K18,L17=L18,M17=M18,N17=N18,O17=O18,P17=P18,Q17=Q18,R17=R18,S17=S18,T17=T18,U17=U18,V17=V18,W17=W18,HEX2DEC(SUBSTITUTE(AH17,"0x",""))<HEX2DEC(SUBSTITUTE(AH18,"0x",""))),"",MAX($AF$6:AF17)+1))) -> 7 | AG18: =IF(MAX(INDEX($AF:$AF,ROW($AG$6)):INDEX($AF:$AF,ROW(AG18)))+1=AF19,MAX(INDEX($AF:$AF,ROW($AG$6)):INDEX($AF:$AF,ROW(AG18))),"") | AH18: =LOWER(IF(C18="1", "0x40000"&B18,"0x00000"&B18)) -> 0x400000fc | AI18: =HEX2DEC(RIGHT(AH18,8)) -> 1073742076 | AJ18: =IF(AF18<>"",AH18,"") -> 0x400000fc | AK18: =IF(AF18<>"",VLOOKUP(AF18,$AG$6:$AH$286,2,TRUE),"") -> 0x40000100 | AL18: =IF($AF18<>"",MIN($D18:$D18),"") -> 8 | AN18: =IF(AI17<AI18,"ok","not ok") -> ok | AO18: CAN_CFG_ID_VALUE_5_MB
A19: FCM1S79 | B19: 100 | C19: 1 | D19: 8 | E19: 50 | F19: 0 | G19: R | K19: 0 | L19: 0 | M19: 0 | N19: 1 | O19: 0 | P19: 0 | Q19: 0 | R19: 0 | S19: 0 | T19: 0 | U19: 0 | V19: 0 | W19: 0 | Y19: 29 | Z19: 65535 | AA19: 32768 | AB19: 65535 | AF19: =IF(V19=1,MAX($AF$6:AF18)+1,IF(AF18="#",0,IF(AND(D18=D19,K18=K19,L18=L19,M18=M19,N18=N19,O18=O19,P18=P19,Q18=Q19,R18=R19,S18=S19,T18=T19,U18=U19,V18=V19,W18=W19,HEX2DEC(SUBSTITUTE(AH18,"0x",""))<HEX2DEC(SUBSTITUTE(AH19,"0x",""))),"",MAX($AF$6:AF18)+1))) | AG19: =IF(MAX(INDEX($AF:$AF,ROW($AG$6)):INDEX($AF:$AF,ROW(AG19)))+1=AF20,MAX(INDEX($AF:$AF,ROW($AG$6)):INDEX($AF:$AF,ROW(AG19))),"") -> 7 | AH19: =LOWER(IF(C19="1", "0x40000"&B19,"0x00000"&B19)) -> 0x40000100 | AI19: =HEX2DEC(RIGHT(AH19,8)) -> 1073742080 | AJ19: =IF(AF19<>"",AH19,"") | AK19: =IF(AF19<>"",VLOOKUP(AF19,$AG$6:$AH$286,2,TRUE),"") | AL19: =IF($AF19<>"",MIN($D19:$D19),"") | AN19: =IF(AI18<AI19,"ok","not ok") -> ok
A20: ZN11S38 | B20: 500 | C20: 1 | D20: 32 | E20: 2000 | F20: 0 | G20: R | K20: 0 | L20: 0 | M20: 0 | N20: 1 | O20: 0 | P20: 0 | Q20: 0 | R20: 0 | S20: 0 | T20: 0 | U20: 0 | V20: 0 | W20: 0 | Y20: 29 | Z20: 65535 | AA20: 32768 | AB20: 65535 | AF20: =IF(V20=1,MAX($AF$6:AF19)+1,IF(AF19="#",0,IF(AND(D19=D20,K19=K20,L19=L20,M19=M20,N19=N20,O19=O20,P19=P20,Q19=Q20,R19=R20,S19=S20,T19=T20,U19=U20,V19=V20,W19=W20,HEX2DEC(SUBSTITUTE(AH19,"0x",""))<HEX2DEC(SUBSTITUTE(AH20,"0x",""))),"",MAX($AF$6:AF19)+1))) -> 8 | AG20: =IF(MAX(INDEX($AF:$AF,ROW($AG$6)):INDEX($AF:$AF,ROW(AG20)))+1=AF21,MAX(INDEX($AF:$AF,ROW($AG$6)):INDEX($AF:$AF,ROW(AG20))),"") -> 8 | AH20: =LOWER(IF(C20="1", "0x40000"&B20,"0x00000"&B20)) -> 0x40000500 | AI20: =HEX2DEC(RIGHT(AH20,8)) -> 1073743104 | AJ20: =IF(AF20<>"",AH20,"") -> 0x40000500 | AK20: =IF(AF20<>"",VLOOKUP(AF20,$AG$6:$AH$286,2,TRUE),"") -> 0x40000500 | AL20: =IF($AF20<>"",MIN($D20:$D20),"") -> 32 | AN20: =IF(AI19<AI20,"ok","not ok") -> ok | AO20: CAN_CFG_ID_VALUE_5_MB
A21: DMC1S08 | B21: 122 | C21: 1 | D21: 32 | E21: 100 | F21: 1 | G21: R | K21: 0 | L21: 0 | M21: 0 | N21: 1 | O21: 0 | P21: 0 | Q21: 0 | R21: 0 | S21: 0 | T21: 0 | U21: 0 | V21: 0 | W21: 0 | Y21: 29 | Z21: 65535 | AA21: 32768 | AB21: 65535 | AF21: =IF(V21=1,MAX($AF$6:AF20)+1,IF(AF20="#",0,IF(AND(D20=D21,K20=K21,L20=L21,M20=M21,N20=N21,O20=O21,P20=P21,Q20=Q21,R20=R21,S20=S21,T20=T21,U20=U21,V20=V21,W20=W21,HEX2DEC(SUBSTITUTE(AH20,"0x",""))<HEX2DEC(SUBSTITUTE(AH21,"0x",""))),"",MAX($AF$6:AF20)+1))) -> 9 | AG21: =IF(MAX(INDEX($AF:$AF,ROW($AG$6)):INDEX($AF:$AF,ROW(AG21)))+1=AF22,MAX(INDEX($AF:$AF,ROW($AG$6)):INDEX($AF:$AF,ROW(AG21))),"") -> 9 | AH21: =LOWER(IF(C21="1", "0x40000"&B21,"0x00000"&B21)) -> 0x40000122 | AI21: =HEX2DEC(RIGHT(AH21,8)) -> 1073742114 | AJ21: =IF(AF21<>"",AH21,"") -> 0x40000122 | AK21: =IF(AF21<>"",VLOOKUP(AF21,$AG$6:$AH$286,2,TRUE),"") -> 0x40000122 | AL21: =IF($AF21<>"",MIN($D21:$D21),"") -> 32 | AN21: =IF(AI20<AI21,"ok","not ok") -> not ok | AO21: CAN_CFG_ID_VALUE_5_MB
A22: BAT1S08 | B22: 124 | C22: 1 | D22: 8 | E22: 100 | F22: 0 | G22: R | K22: 0 | L22: 0 | M22: 0 | N22: 1 | O22: 0 | P22: 0 | Q22: 0 | R22: 0 | S22: 0 | T22: 0 | U22: 0 | V22: 0 | W22: 0 | Y22: 29 | Z22: 65535 | AA22: 32768 | AB22: 65535 | AF22: =IF(V22=1,MAX($AF$6:AF21)+1,IF(AF21="#",0,IF(AND(D21=D22,K21=K22,L21=L22,M21=M22,N21=N22,O21=O22,P21=P22,Q21=Q22,R21=R22,S21=S22,T21=T22,U21=U22,V21=V22,W21=W22,HEX2DEC(SUBSTITUTE(AH21,"0x",""))<HEX2DEC(SUBSTITUTE(AH22,"0x",""))),"",MAX($AF$6:AF21)+1))) -> 10 | AG22: =IF(MAX(INDEX($AF:$AF,ROW($AG$6)):INDEX($AF:$AF,ROW(AG22)))+1=AF23,MAX(INDEX($AF:$AF,ROW($AG$6)):INDEX($AF:$AF,ROW(AG22))),"") -> 10 | AH22: =LOWER(IF(C22="1", "0x40000"&B22,"0x00000"&B22)) -> 0x40000124 | AI22: =HEX2DEC(RIGHT(AH22,8)) -> 1073742116 | AJ22: =IF(AF22<>"",AH22,"") -> 0x40000124 | AK22: =IF(AF22<>"",VLOOKUP(AF22,$AG$6:$AH$286,2,TRUE),"") -> 0x40000124 | AL22: =IF($AF22<>"",MIN($D22:$D22),"") -> 8 | AN22: =IF(AI21<AI22,"ok","not ok") -> ok
A23: BDC1SA0 | B23: 1A4 | C23: 1 | D23: 32 | E23: 200 | F23: 0 | G23: R | K23: 0 | L23: 0 | M23: 0 | N23: 1 | O23: 0 | P23: 0 | Q23: 0 | R23: 0 | S23: 0 | T23: 0 | U23: 0 | V23: 0 | W23: 0 | Y23: 29 | Z23: 65535 | AA23: 32768 | AB23: 65535 | AF23: =IF(V23=1,MAX($AF$6:AF22)+1,IF(AF22="#",0,IF(AND(D22=D23,K22=K23,L22=L23,M22=M23,N22=N23,O22=O23,P22=P23,Q22=Q23,R22=R23,S22=S23,T22=T23,U22=U23,V22=V23,W22=W23,HEX2DEC(SUBSTITUTE(AH22,"0x",""))<HEX2DEC(SUBSTITUTE(AH23,"0x",""))),"",MAX($AF$6:AF22)+1))) -> 11 | AG23: =IF(MAX(INDEX($AF:$AF,ROW($AG$6)):INDEX($AF:$AF,ROW(AG23)))+1=AF24,MAX(INDEX($AF:$AF,ROW($AG$6)):INDEX($AF:$AF,ROW(AG23))),"") -> 11 | AH23: =LOWER(IF(C23="1", "0x40000"&B23,"0x00000"&B23)) -> 0x400001a4 | AI23: =HEX2DEC(RIGHT(AH23,8)) -> 1073742244 | AJ23: =IF(AF23<>"",AH23,"") -> 0x400001a4 | AK23: =IF(AF23<>"",VLOOKUP(AF23,$AG$6:$AH$286,2,TRUE),"") -> 0x400001a4 | AL23: =IF($AF23<>"",MIN($D23:$D23),"") -> 32 | AN23: =IF(AI22<AI23,"ok","not ok") -> ok | AO23: CAN_CFG_ID_VALUE_5_MB
A24: EHV1G30 | B24: 128 | C24: 1 | D24: 8 | E24: 100 | F24: 0 | G24: R | K24: 0 | L24: 0 | M24: 0 | N24: 1 | O24: 0 | P24: 0 | Q24: 0 | R24: 0 | S24: 0 | T24: 0 | U24: 0 | V24: 0 | W24: 0 | Y24: 29 | Z24: 65535 | AA24: 32768 | AB24: 65535 | AF24: =IF(V24=1,MAX($AF$6:AF23)+1,IF(AF23="#",0,IF(AND(D23=D24,K23=K24,L23=L24,M23=M24,N23=N24,O23=O24,P23=P24,Q23=Q24,R23=R24,S23=S24,T23=T24,U23=U24,V23=V24,W23=W24,HEX2DEC(SUBSTITUTE(AH23,"0x",""))<HEX2DEC(SUBSTITUTE(AH24,"0x",""))),"",MAX($AF$6:AF23)+1))) -> 12 | AG24: =IF(MAX(INDEX($AF:$AF,ROW($AG$6)):INDEX($AF:$AF,ROW(AG24)))+1=AF25,MAX(INDEX($AF:$AF,ROW($AG$6)):INDEX($AF:$AF,ROW(AG24))),"") | AH24: =LOWER(IF(C24="1", "0x40000"&B24,"0x00000"&B24)) -> 0x40000128 | AI24: =HEX2DEC(RIGHT(AH24,8)) -> 1073742120 | AJ24: =IF(AF24<>"",AH24,"") -> 0x40000128 | AK24: =IF(AF24<>"",VLOOKUP(AF24,$AG$6:$AH$286,2,TRUE),"") -> 0x40000140 | AL24: =IF($AF24<>"",MIN($D24:$D24),"") -> 8 | AN24: =IF(AI23<AI24,"ok","not ok") -> not ok | AO24: CAN_CFG_ID_VALUE_5_MB
A25: BDC1S23 | B25: 140 | C25: 1 | D25: 8 | E25: - | F25: 0 | G25: R | K25: 0 | L25: 0 | M25: 0 | N25: 1 | O25: 0 | P25: 0 | Q25: 0 | R25: 0 | S25: 0 | T25: 0 | U25: 0 | V25: 0 | W25: 0 | Y25: 29 | Z25: 65535 | AA25: 32768 | AB25: 65535 | AF25: =IF(V25=1,MAX($AF$6:AF24)+1,IF(AF24="#",0,IF(AND(D24=D25,K24=K25,L24=L25,M24=M25,N24=N25,O24=O25,P24=P25,Q24=Q25,R24=R25,S24=S25,T24=T25,U24=U25,V24=V25,W24=W25,HEX2DEC(SUBSTITUTE(AH24,"0x",""))<HEX2DEC(SUBSTITUTE(AH25,"0x",""))),"",MAX($AF$6:AF24)+1))) | AG25: =IF(MAX(INDEX($AF:$AF,ROW($AG$6)):INDEX($AF:$AF,ROW(AG25)))+1=AF26,MAX(INDEX($AF:$AF,ROW($AG$6)):INDEX($AF:$AF,ROW(AG25))),"") -> 12 | AH25: =LOWER(IF(C25="1", "0x40000"&B25,"0x00000"&B25)) -> 0x40000140 | AI25: =HEX2DEC(RIGHT(AH25,8)) -> 1073742144 | AJ25: =IF(AF25<>"",AH25,"") | AK25: =IF(AF25<>"",VLOOKUP(AF25,$AG$6:$AH$286,2,TRUE),"") | AL25: =IF($AF25<>"",MIN($D25:$D25),"") | AN25: =IF(AI24<AI25,"ok","not ok") -> ok
A26: BDC1S41 | B26: 148 | C26: 1 | D26: 32 | E26: 100 | F26: 0 | G26: R | K26: 0 | L26: 0 | M26: 0 | N26: 1 | O26: 0 | P26: 0 | Q26: 0 | R26: 0 | S26: 0 | T26: 0 | U26: 0 | V26: 0 | W26: 0 | Y26: 29 | Z26: 65535 | AA26: 32768 | AB26: 65535 | AF26: =IF(V26=1,MAX($AF$6:AF25)+1,IF(AF25="#",0,IF(AND(D25=D26,K25=K26,L25=L26,M25=M26,N25=N26,O25=O26,P25=P26,Q25=Q26,R25=R26,S25=S26,T25=T26,U25=U26,V25=V26,W25=W26,HEX2DEC(SUBSTITUTE(AH25,"0x",""))<HEX2DEC(SUBSTITUTE(AH26,"0x",""))),"",MAX($AF$6:AF25)+1))) -> 13 | AG26: =IF(MAX(INDEX($AF:$AF,ROW($AG$6)):INDEX($AF:$AF,ROW(AG26)))+1=AF27,MAX(INDEX($AF:$AF,ROW($AG$6)):INDEX($AF:$AF,ROW(AG26))),"") | AH26: =LOWER(IF(C26="1", "0x40000"&B26,"0x00000"&B26)) -> 0x40000148 | AI26: =HEX2DEC(RIGHT(AH26,8)) -> 1073742152 | AJ26: =IF(AF26<>"",AH26,"") -> 0x40000148 | AK26: =IF(AF26<>"",VLOOKUP(AF26,$AG$6:$AH$286,2,TRUE),"") -> 0x40000158 | AL26: =IF($AF26<>"",MIN($D26:$D26),"") -> 32 | AN26: =IF(AI25<AI26,"ok","not ok") -> ok
A27: BDC1S82 | B27: 150 | C27: 1 | D27: 32 | E27: 100 | F27: 1 | G27: R | K27: 0 | L27: 0 | M27: 0 | N27: 1 | O27: 0 | P27: 0 | Q27: 0 | R27: 0 | S27: 0 | T27: 0 | U27: 0 | V27: 0 | W27: 0 | Y27: 29 | Z27: 65535 | AA27: 32768 | AB27: 65535 | AF27: =IF(V27=1,MAX($AF$6:AF26)+1,IF(AF26="#",0,IF(AND(D26=D27,K26=K27,L26=L27,M26=M27,N26=N27,O26=O27,P26=P27,Q26=Q27,R26=R27,S26=S27,T26=T27,U26=U27,V26=V27,W26=W27,HEX2DEC(SUBSTITUTE(AH26,"0x",""))<HEX2DEC(SUBSTITUTE(AH27,"0x",""))),"",MAX($AF$6:AF26)+1))) | AG27: =IF(MAX(INDEX($AF:$AF,ROW($AG$6)):INDEX($AF:$AF,ROW(AG27)))+1=AF28,MAX(INDEX($AF:$AF,ROW($AG$6)):INDEX($AF:$AF,ROW(AG27))),"") | AH27: =LOWER(IF(C27="1", "0x40000"&B27,"0x00000"&B27)) -> 0x40000150 | AI27: =HEX2DEC(RIGHT(AH27,8)) -> 1073742160 | AJ27: =IF(AF27<>"",AH27,"") | AK27: =IF(AF27<>"",VLOOKUP(AF27,$AG$6:$AH$286,2,TRUE),"") | AL27: =IF($AF27<>"",MIN($D27:$D27),"") | AN27: =IF(AI26<AI27,"ok","not ok") -> ok
A28: DDM1S77 | B28: 158 | C28: 1 | D28: 32 | E28: 100 | F28: 0 | G28: R | K28: 0 | L28: 0 | M28: 0 | N28: 1 | O28: 0 | P28: 0 | Q28: 0 | R28: 0 | S28: 0 | T28: 0 | U28: 0 | V28: 0 | W28: 0 | Y28: 29 | Z28: 65535 | AA28: 32768 | AB28: 65535 | AF28: =IF(V28=1,MAX($AF$6:AF27)+1,IF(AF27="#",0,IF(AND(D27=D28,K27=K28,L27=L28,M27=M28,N27=N28,O27=O28,P27=P28,Q27=Q28,R27=R28,S27=S28,T27=T28,U27=U28,V27=V28,W27=W28,HEX2DEC(SUBSTITUTE(AH27,"0x",""))<HEX2DEC(SUBSTITUTE(AH28,"0x",""))),"",MAX($AF$6:AF27)+1))) | AG28: =IF(MAX(INDEX($AF:$AF,ROW($AG$6)):INDEX($AF:$AF,ROW(AG28)))+1=AF29,MAX(INDEX($AF:$AF,ROW($AG$6)):INDEX($AF:$AF,ROW(AG28))),"") -> 13 | AH28: =LOWER(IF(C28="1", "0x40000"&B28,"0x00000"&B28)) -> 0x40000158 | AI28: =HEX2DEC(RIGHT(AH28,8)) -> 1073742168 | AJ28: =IF(AF28<>"",AH28,"") | AK28: =IF(AF28<>"",VLOOKUP(AF28,$AG$6:$AH$286,2,TRUE),"") | AL28: =IF($AF28<>"",MIN($D28:$D28),"") | AN28: =IF(AI27<AI28,"ok","not ok") -> ok | AO28: CAN_CFG_ID_VALUE_5_MB
A29: IDT1S08 | B29: 14B | C29: 1 | D29: 8 | E29: 100 | F29: 0 | G29: R | K29: 0 | L29: 0 | M29: 0 | N29: 1 | O29: 0 | P29: 0 | Q29: 0 | R29: 0 | S29: 0 | T29: 0 | U29: 0 | V29: 0 | W29: 0 | Y29: 29 | Z29: 65535 | AA29: 32768 | AB29: 65535 | AF29: =IF(V29=1,MAX($AF$6:AF28)+1,IF(AF28="#",0,IF(AND(D28=D29,K28=K29,L28=L29,M28=M29,N28=N29,O28=O29,P28=P29,Q28=Q29,R28=R29,S28=S29,T28=T29,U28=U29,V28=V29,W28=W29,HEX2DEC(SUBSTITUTE(AH28,"0x",""))<HEX2DEC(SUBSTITUTE(AH29,"0x",""))),"",MAX($AF$6:AF28)+1))) -> 14 | AG29: =IF(MAX(INDEX($AF:$AF,ROW($AG$6)):INDEX($AF:$AF,ROW(AG29)))+1=AF30,MAX(INDEX($AF:$AF,ROW($AG$6)):INDEX($AF:$AF,ROW(AG29))),"") | AH29: =LOWER(IF(C29="1", "0x40000"&B29,"0x00000"&B29)) -> 0x4000014b | AI29: =HEX2DEC(RIGHT(AH29,8)) -> 1073742155 | AJ29: =IF(AF29<>"",AH29,"") -> 0x4000014b | AK29: =IF(AF29<>"",VLOOKUP(AF29,$AG$6:$AH$286,2,TRUE),"") -> 0x4000014f | AL29: =IF($AF29<>"",MIN($D29:$D29),"") -> 8 | AN29: =IF(AI28<AI29,"ok","not ok") -> not ok
A30: RCP1S03 | B30: 14F | C30: 1 | D30: 8 | E30: 100 | F30: 0 | G30: R | K30: 0 | L30: 0 | M30: 0 | N30: 1 | O30: 0 | P30: 0 | Q30: 0 | R30: 0 | S30: 0 | T30: 0 | U30: 0 | V30: 0 | W30: 0 | Y30: 29 | Z30: 65535 | AA30: 32768 | AB30: 65535 | AF30: =IF(V30=1,MAX($AF$6:AF29)+1,IF(AF29="#",0,IF(AND(D29=D30,K29=K30,L29=L30,M29=M30,N29=N30,O29=O30,P29=P30,Q29=Q30,R29=R30,S29=S30,T29=T30,U29=U30,V29=V30,W29=W30,HEX2DEC(SUBSTITUTE(AH29,"0x",""))<HEX2DEC(SUBSTITUTE(AH30,"0x",""))),"",MAX($AF$6:AF29)+1))) | AG30: =IF(MAX(INDEX($AF:$AF,ROW($AG$6)):INDEX($AF:$AF,ROW(AG30)))+1=AF31,MAX(INDEX($AF:$AF,ROW($AG$6)):INDEX($AF:$AF,ROW(AG30))),"") -> 14 | AH30: =LOWER(IF(C30="1", "0x40000"&B30,"0x00000"&B30)) -> 0x4000014f | AI30: =HEX2DEC(RIGHT(AH30,8)) -> 1073742159 | AJ30: =IF(AF30<>"",AH30,"") | AK30: =IF(AF30<>"",VLOOKUP(AF30,$AG$6:$AH$286,2,TRUE),"") | AL30: =IF($AF30<>"",MIN($D30:$D30),"") | AN30: =IF(AI29<AI30,"ok","not ok") -> ok | AO30: CAN_CFG_ID_VALUE_5_MB
A31: RCP1S01 | B31: 14D | C31: 1 | D31: 8 | E31: 100 | F31: 0 | G31: R | K31: 0 | L31: 0 | M31: 0 | N31: 1 | O31: 0 | P31: 0 | Q31: 0 | R31: 0 | S31: 0 | T31: 0 | U31: 0 | V31: 0 | W31: 0 | Y31: 29 | Z31: 65535 | AA31: 32768 | AB31: 65535 | AF31: =IF(V31=1,MAX($AF$6:AF30)+1,IF(AF30="#",0,IF(AND(D30=D31,K30=K31,L30=L31,M30=M31,N30=N31,O30=O31,P30=P31,Q30=Q31,R30=R31,S30=S31,T30=T31,U30=U31,V30=V31,W30=W31,HEX2DEC(SUBSTITUTE(AH30,"0x",""))<HEX2DEC(SUBSTITUTE(AH31,"0x",""))),"",MAX($AF$6:AF30)+1))) -> 15 | AG31: =IF(MAX(INDEX($AF:$AF,ROW($AG$6)):INDEX($AF:$AF,ROW(AG31)))+1=AF32,MAX(INDEX($AF:$AF,ROW($AG$6)):INDEX($AF:$AF,ROW(AG31))),"") | AH31: =LOWER(IF(C31="1", "0x40000"&B31,"0x00000"&B31)) -> 0x4000014d | AI31: =HEX2DEC(RIGHT(AH31,8)) -> 1073742157 | AJ31: =IF(AF31<>"",AH31,"") -> 0x4000014d | AK31: =IF(AF31<>"",VLOOKUP(AF31,$AG$6:$AH$286,2,TRUE),"") -> 0x4000015a | AL31: =IF($AF31<>"",MIN($D31:$D31),"") -> 8 | AN31: =IF(AI30<AI31,"ok","not ok") -> not ok
A32: FCM1S78 | B32: 15A | C32: 1 | D32: 8 | E32: 100 | F32: 0 | G32: R | K32: 0 | L32: 0 | M32: 0 | N32: 1 | O32: 0 | P32: 0 | Q32: 0 | R32: 0 | S32: 0 | T32: 0 | U32: 0 | V32: 0 | W32: 0 | Y32: 29 | Z32: 65535 | AA32: 32768 | AB32: 65535 | AF32: =IF(V32=1,MAX($AF$6:AF31)+1,IF(AF31="#",0,IF(AND(D31=D32,K31=K32,L31=L32,M31=M32,N31=N32,O31=O32,P31=P32,Q31=Q32,R31=R32,S31=S32,T31=T32,U31=U32,V31=V32,W31=W32,HEX2DEC(SUBSTITUTE(AH31,"0x",""))<HEX2DEC(SUBSTITUTE(AH32,"0x",""))),"",MAX($AF$6:AF31)+1))) | AG32: =IF(MAX(INDEX($AF:$AF,ROW($AG$6)):INDEX($AF:$AF,ROW(AG32)))+1=AF33,MAX(INDEX($AF:$AF,ROW($AG$6)):INDEX($AF:$AF,ROW(AG32))),"") -> 15 | AH32: =LOWER(IF(C32="1", "0x40000"&B32,"0x00000"&B32)) -> 0x4000015a | AI32: =HEX2DEC(RIGHT(AH32,8)) -> 1073742170 | AJ32: =IF(AF32<>"",AH32,"") | AK32: =IF(AF32<>"",VLOOKUP(AF32,$AG$6:$AH$286,2,TRUE),"") | AL32: =IF($AF32<>"",MIN($D32:$D32),"") | AN32: =IF(AI31<AI32,"ok","not ok") -> ok | AO32: CAN_CFG_ID_VALUE_5_MB
A33: BAT1E45 | B33: 16E | C33: 1 | D33: 32 | E33: 100 | F33: 0 | G33: R | K33: 0 | L33: 0 | M33: 0 | N33: 1 | O33: 0 | P33: 0 | Q33: 0 | R33: 0 | S33: 0 | T33: 0 | U33: 0 | V33: 0 | W33: 0 | Y33: 29 | Z33: 65535 | AA33: 32768 | AB33: 65535 | AF33: =IF(V33=1,MAX($AF$6:AF32)+1,IF(AF32="#",0,IF(AND(D32=D33,K32=K33,L32=L33,M32=M33,N32=N33,O32=O33,P32=P33,Q32=Q33,R32=R33,S32=S33,T32=T33,U32=U33,V32=V33,W32=W33,HEX2DEC(SUBSTITUTE(AH32,"0x",""))<HEX2DEC(SUBSTITUTE(AH33,"0x",""))),"",MAX($AF$6:AF32)+1))) -> 16 | AG33: =IF(MAX(INDEX($AF:$AF,ROW($AG$6)):INDEX($AF:$AF,ROW(AG33)))+1=AF34,MAX(INDEX($AF:$AF,ROW($AG$6)):INDEX($AF:$AF,ROW(AG33))),"") | AH33: =LOWER(IF(C33="1", "0x40000"&B33,"0x00000"&B33)) -> 0x4000016e | AI33: =HEX2DEC(RIGHT(AH33,8)) -> 1073742190 | AJ33: =IF(AF33<>"",AH33,"") -> 0x4000016e | AK33: =IF(AF33<>"",VLOOKUP(AF33,$AG$6:$AH$286,2,TRUE),"") -> 0x4000019a | AL33: =IF($AF33<>"",MIN($D33:$D33),"") -> 32 | AN33: =IF(AI32<AI33,"ok","not ok") -> ok | AO33: CAN_CFG_ID_VALUE_5_MB
A34: ADC1S11 | B34: 17E | C34: 1 | D34: 32 | E34: 100 | F34: 0 | G34: R | K34: 0 | L34: 0 | M34: 0 | N34: 1 | O34: 0 | P34: 0 | Q34: 0 | R34: 0 | S34: 0 | T34: 0 | U34: 0 | V34: 0 | W34: 0 | Y34: 29 | Z34: 65535 | AA34: 32768 | AB34: 65535 | AF34: =IF(V34=1,MAX($AF$6:AF33)+1,IF(AF33="#",0,IF(AND(D33=D34,K33=K34,L33=L34,M33=M34,N33=N34,O33=O34,P33=P34,Q33=Q34,R33=R34,S33=S34,T33=T34,U33=U34,V33=V34,W33=W34,HEX2DEC(SUBSTITUTE(AH33,"0x",""))<HEX2DEC(SUBSTITUTE(AH34,"0x",""))),"",MAX($AF$6:AF33)+1))) | AG34: =IF(MAX(INDEX($AF:$AF,ROW($AG$6)):INDEX($AF:$AF,ROW(AG34)))+1=AF35,MAX(INDEX($AF:$AF,ROW($AG$6)):INDEX($AF:$AF,ROW(AG34))),"") | AH34: =LOWER(IF(C34="1", "0x40000"&B34,"0x00000"&B34)) -> 0x4000017e | AI34: =HEX2DEC(RIGHT(AH34,8)) -> 1073742206 | AJ34: =IF(AF34<>"",AH34,"") | AK34: =IF(AF34<>"",VLOOKUP(AF34,$AG$6:$AH$286,2,TRUE),"") | AL34: =IF($AF34<>"",MIN($D34:$D34),"") | AN34: =IF(AI33<AI34,"ok","not ok") -> ok | AO34: CAN_CFG_ID_VALUE_5_MB
A35: BDF3S02 | B35: 18D | C35: 1 | D35: 32 | E35: 100 | F35: 0 | G35: R | K35: 0 | L35: 0 | M35: 0 | N35: 1 | O35: 0 | P35: 0 | Q35: 0 | R35: 0 | S35: 0 | T35: 0 | U35: 0 | V35: 0 | W35: 0 | Y35: 29 | Z35: 65535 | AA35: 32768 | AB35: 65535 | AF35: =IF(V35=1,MAX($AF$6:AF34)+1,IF(AF34="#",0,IF(AND(D34=D35,K34=K35,L34=L35,M34=M35,N34=N35,O34=O35,P34=P35,Q34=Q35,R34=R35,S34=S35,T34=T35,U34=U35,V34=V35,W34=W35,HEX2DEC(SUBSTITUTE(AH34,"0x",""))<HEX2DEC(SUBSTITUTE(AH35,"0x",""))),"",MAX($AF$6:AF34)+1))) | AG35: =IF(MAX(INDEX($AF:$AF,ROW($AG$6)):INDEX($AF:$AF,ROW(AG35)))+1=AF36,MAX(INDEX($AF:$AF,ROW($AG$6)):INDEX($AF:$AF,ROW(AG35))),"") | AH35: =LOWER(IF(C35="1", "0x40000"&B35,"0x00000"&B35)) -> 0x4000018d | AI35: =HEX2DEC(RIGHT(AH35,8)) -> 1073742221 | AJ35: =IF(AF35<>"",AH35,"") | AK35: =IF(AF35<>"",VLOOKUP(AF35,$AG$6:$AH$286,2,TRUE),"") | AL35: =IF($AF35<>"",MIN($D35:$D35),"") | AN35: =IF(AI34<AI35,"ok","not ok") -> ok | AO35: CAN_CFG_ID_VALUE_5_MB
A36: BDR3S02 | B36: 19A | C36: 1 | D36: 32 | E36: 200 | F36: 0 | G36: R | K36: 0 | L36: 0 | M36: 0 | N36: 1 | O36: 0 | P36: 0 | Q36: 0 | R36: 0 | S36: 0 | T36: 0 | U36: 0 | V36: 0 | W36: 0 | Y36: 29 | Z36: 65535 | AA36: 32768 | AB36: 65535 | AF36: =IF(V36=1,MAX($AF$6:AF35)+1,IF(AF35="#",0,IF(AND(D35=D36,K35=K36,L35=L36,M35=M36,N35=N36,O35=O36,P35=P36,Q35=Q36,R35=R36,S35=S36,T35=T36,U35=U36,V35=V36,W35=W36,HEX2DEC(SUBSTITUTE(AH35,"0x",""))<HEX2DEC(SUBSTITUTE(AH36,"0x",""))),"",MAX($AF$6:AF35)+1))) | AG36: =IF(MAX(INDEX($AF:$AF,ROW($AG$6)):INDEX($AF:$AF,ROW(AG36)))+1=AF37,MAX(INDEX($AF:$AF,ROW($AG$6)):INDEX($AF:$AF,ROW(AG36))),"") -> 16 | AH36: =LOWER(IF(C36="1", "0x40000"&B36,"0x00000"&B36)) -> 0x4000019a | AI36: =HEX2DEC(RIGHT(AH36,8)) -> 1073742234 | AJ36: =IF(AF36<>"",AH36,"") | AK36: =IF(AF36<>"",VLOOKUP(AF36,$AG$6:$AH$286,2,TRUE),"") | AL36: =IF($AF36<>"",MIN($D36:$D36),"") | AN36: =IF(AI35<AI36,"ok","not ok") -> ok
A37: BDC1S87 | B37: 1A0 | C37: 1 | D37: 8 | E37: 200 | F37: 0 | G37: R | K37: 0 | L37: 0 | M37: 0 | N37: 1 | O37: 0 | P37: 0 | Q37: 0 | R37: 0 | S37: 0 | T37: 0 | U37: 0 | V37: 0 | W37: 0 | Y37: 29 | Z37: 65535 | AA37: 32768 | AB37: 65535 | AF37: =IF(V37=1,MAX($AF$6:AF36)+1,IF(AF36="#",0,IF(AND(D36=D37,K36=K37,L36=L37,M36=M37,N36=N37,O36=O37,P36=P37,Q36=Q37,R36=R37,S36=S37,T36=T37,U36=U37,V36=V37,W36=W37,HEX2DEC(SUBSTITUTE(AH36,"0x",""))<HEX2DEC(SUBSTITUTE(AH37,"0x",""))),"",MAX($AF$6:AF36)+1))) -> 17 | AG37: =IF(MAX(INDEX($AF:$AF,ROW($AG$6)):INDEX($AF:$AF,ROW(AG37)))+1=AF38,MAX(INDEX($AF:$AF,ROW($AG$6)):INDEX($AF:$AF,ROW(AG37))),"") -> 17 | AH37: =LOWER(IF(C37="1", "0x40000"&B37,"0x00000"&B37)) -> 0x400001a0 | AI37: =HEX2DEC(RIGHT(AH37,8)) -> 1073742240 | AJ37: =IF(AF37<>"",AH37,"") -> 0x400001a0 | AK37: =IF(AF37<>"",VLOOKUP(AF37,$AG$6:$AH$286,2,TRUE),"") -> 0x400001a0 | AL37: =IF($AF37<>"",MIN($D37:$D37),"") -> 8 | AN37: =IF(AI36<AI37,"ok","not ok") -> ok | AO37: CAN_CFG_ID_VALUE_5_MB
A38: FCM1S90 | B38: 1B2 | C38: 1 | D38: 32 | E38: 200 | F38: 0 | G38: R | K38: 0 | L38: 0 | M38: 0 | N38: 1 | O38: 0 | P38: 0 | Q38: 0 | R38: 0 | S38: 0 | T38: 0 | U38: 0 | V38: 0 | W38: 0 | Y38: 29 | Z38: 65535 | AA38: 32768 | AB38: 65535 | AF38: =IF(V38=1,MAX($AF$6:AF37)+1,IF(AF37="#",0,IF(AND(D37=D38,K37=K38,L37=L38,M37=M38,N37=N38,O37=O38,P37=P38,Q37=Q38,R37=R38,S37=S38,T37=T38,U37=U38,V37=V38,W37=W38,HEX2DEC(SUBSTITUTE(AH37,"0x",""))<HEX2DEC(SUBSTITUTE(AH38,"0x",""))),"",MAX($AF$6:AF37)+1))) -> 18 | AG38: =IF(MAX(INDEX($AF:$AF,ROW($AG$6)):INDEX($AF:$AF,ROW(AG38)))+1=AF39,MAX(INDEX($AF:$AF,ROW($AG$6)):INDEX($AF:$AF,ROW(AG38))),"") -> 18 | AH38: =LOWER(IF(C38="1", "0x40000"&B38,"0x00000"&B38)) -> 0x400001b2 | AI38: =HEX2DEC(RIGHT(AH38,8)) -> 1073742258 | AJ38: =IF(AF38<>"",AH38,"") -> 0x400001b2 | AK38: =IF(AF38<>"",VLOOKUP(AF38,$AG$6:$AH$286,2,TRUE),"") -> 0x400001b2 | AL38: =IF($AF38<>"",MIN($D38:$D38),"") -> 32 | AN38: =IF(AI37<AI38,"ok","not ok") -> ok | AO38: CAN_CFG_ID_VALUE_5_MB
A39: SOL1S06 | B39: 1BB | C39: 1 | D39: 8 | E39: 200 | F39: 0 | G39: R | K39: 0 | L39: 0 | M39: 0 | N39: 1 | O39: 0 | P39: 0 | Q39: 0 | R39: 0 | S39: 0 | T39: 0 | U39: 0 | V39: 0 | W39: 0 | Y39: 29 | Z39: 65535 | AA39: 32768 | AB39: 65535 | AF39: =IF(V39=1,MAX($AF$6:AF38)+1,IF(AF38="#",0,IF(AND(D38=D39,K38=K39,L38=L39,M38=M39,N38=N39,O38=O39,P38=P39,Q38=Q39,R38=R39,S38=S39,T38=T39,U38=U39,V38=V39,W38=W39,HEX2DEC(SUBSTITUTE(AH38,"0x",""))<HEX2DEC(SUBSTITUTE(AH39,"0x",""))),"",MAX($AF$6:AF38)+1))) -> 19 | AG39: =IF(MAX(INDEX($AF:$AF,ROW($AG$6)):INDEX($AF:$AF,ROW(AG39)))+1=AF40,MAX(INDEX($AF:$AF,ROW($AG$6)):INDEX($AF:$AF,ROW(AG39))),"") -> 19 | AH39: =LOWER(IF(C39="1", "0x40000"&B39,"0x00000"&B39)) -> 0x400001bb | AI39: =HEX2DEC(RIGHT(AH39,8)) -> 1073742267 | AJ39: =IF(AF39<>"",AH39,"") -> 0x400001bb | AK39: =IF(AF39<>"",VLOOKUP(AF39,$AG$6:$AH$286,2,TRUE),"") -> 0x400001bb | AL39: =IF($AF39<>"",MIN($D39:$D39),"") -> 8 | AN39: =IF(AI38<AI39,"ok","not ok") -> ok | AO39: CAN_CFG_ID_VALUE_5_MB
A40: EHV1E96 | B40: 1BC | C40: 1 | D40: 32 | E40: 200 | F40: 0 | G40: R | K40: 0 | L40: 0 | M40: 0 | N40: 1 | O40: 0 | P40: 0 | Q40: 0 | R40: 0 | S40: 0 | T40: 0 | U40: 0 | V40: 0 | W40: 0 | Y40: 29 | Z40: 65535 | AA40: 32768 | AB40: 65535 | AF40: =IF(V40=1,MAX($AF$6:AF39)+1,IF(AF39="#",0,IF(AND(D39=D40,K39=K40,L39=L40,M39=M40,N39=N40,O39=O40,P39=P40,Q39=Q40,R39=R40,S39=S40,T39=T40,U39=U40,V39=V40,W39=W40,HEX2DEC(SUBSTITUTE(AH39,"0x",""))<HEX2DEC(SUBSTITUTE(AH40,"0x",""))),"",MAX($AF$6:AF39)+1))) -> 20 | AG40: =IF(MAX(INDEX($AF:$AF,ROW($AG$6)):INDEX($AF:$AF,ROW(AG40)))+1=AF41,MAX(INDEX($AF:$AF,ROW($AG$6)):INDEX($AF:$AF,ROW(AG40))),"") | AH40: =LOWER(IF(C40="1", "0x40000"&B40,"0x00000"&B40)) -> 0x400001bc | AI40: =HEX2DEC(RIGHT(AH40,8)) -> 1073742268 | AJ40: =IF(AF40<>"",AH40,"") -> 0x400001bc | AK40: =IF(AF40<>"",VLOOKUP(AF40,$AG$6:$AH$286,2,TRUE),"") -> 0x400001c1 | AL40: =IF($AF40<>"",MIN($D40:$D40),"") -> 32 | AN40: =IF(AI39<AI40,"ok","not ok") -> ok | AO40: CAN_CFG_ID_VALUE_5_MB
...

Sheet RRMB_G2M-1
A1: CAN ID | B1: Routing Rule Table Index/ CAN-ID Min | D1: can_rscf4_cfg.h CAN_CFG_ID_VALUE_5_MB### | E1: can_rscf4_cfg.h CAN_CFG_ID_VALUE_5_MB### | F1: can_rscf4_cfg.h CAN_CFG_ID_VALUE_5_MB### | G1: can_rscf4_cfg.h CAN_CFG_FILTER_MASK_VALUE_# | K1: st_sp_CAN_LPR_RRMB_G2M_1[] | L1: st_sp_CAN_LPR_RRMB_G2M_1[] | M1: st_sp_CAN_LPR_RRMB_G2M_1[]
A2: ="0x00000"&'CANRx_G2M-1_v2'!B6 -> 0x00000013 | B2: =IF('CANRx_G2M-1_v2'!AF6<>"",'CANRx_G2M-1_v2'!AF6,B1) -> 0 | D2: CAN_CFG_ID_VALUE_5_MB010 | E2: 10 | F2: 0x0000042C | G2: 0x00000090 | H2: =IF(G2<>"NOUSE",HEX2DEC(RIGHT(F2,3))+HEX2DEC(RIGHT(G2,3)),"") -> 1212 | I2: =IF(H2<>"","0x"&DEC2HEX(H2,8),F2) -> 0x000004BC | K2: ="{(U2)"&VLOOKUP(F2,$A$2:$B$282,2,FALSE)&"U," -> {(U2)141U, | L2: ="(U2)"&(VLOOKUP(I2,$A$2:$B$282,2,FALSE)-VLOOKUP(F2,$A$2:$B$282,2,FALSE)+1)&"U}," -> (U2)3U}, | M2: ="/* MBOX = "&E2&" / "&LOWER(F2)&" : Rx Mask = "&G2&" */" -> /* MBOX = 10 / 0x0000042c : Rx Mask = 0x00000090 */
A3: ="0x00000"&'CANRx_G2M-1_v2'!B7 -> 0x0000001B | B3: =IF('CANRx_G2M-1_v2'!AF7<>"",'CANRx_G2M-1_v2'!AF7,B2) -> 0 | D3: CAN_CFG_ID_VALUE_5_MB011 | E3: 11 | F3: 0x000003B0 | G3: 0x00000003 | H3: =IF(G3<>"NOUSE",HEX2DEC(RIGHT(F3,3))+HEX2DEC(RIGHT(G3,3)),"") -> 947 | I3: =IF(H3<>"","0x"&DEC2HEX(H3,8),F3) -> 0x000003B3 | K3: ="{(U2)"&VLOOKUP(F3,$A$2:$B$282,2,FALSE)&"U," -> {(U2)109U, | L3: ="(U2)"&(VLOOKUP(I3,$A$2:$B$282,2,FALSE)-VLOOKUP(F3,$A$2:$B$282,2,FALSE)+1)&"U}," -> (U2)3U}, | M3: ="/* MBOX = "&E3&" / "&LOWER(F3)&" : Rx Mask = "&G3&" */" -> /* MBOX = 11 / 0x000003b0 : Rx Mask = 0x00000003 */
A4: ="0x00000"&'CANRx_G2M-1_v2'!B8 -> 0x00000062 | B4: =IF('CANRx_G2M-1_v2'!AF8<>"",'CANRx_G2M-1_v2'!AF8,B3) -> 0 | D4: CAN_CFG_ID_VALUE_5_MB012 | E4: 12 | F4: 0x00000438 | G4: 0x00000081 | H4: =IF(G4<>"NOUSE",HEX2DEC(RIGHT(F4,3))+HEX2DEC(RIGHT(G4,3)),"") -> 1209 | I4: =IF(H4<>"","0x"&DEC2HEX(H4,8),F4) -> 0x000004B9 | K4: ="{(U2)"&VLOOKUP(F4,$A$2:$B$282,2,FALSE)&"U," -> {(U2)149U, | L4: ="(U2)"&(VLOOKUP(I4,$A$2:$B$282,2,FALSE)-VLOOKUP(F4,$A$2:$B$282,2,FALSE)+1)&"U}," -> (U2)2U}, | M4: ="/* MBOX = "&E4&" / "&LOWER(F4)&" : Rx Mask = "&G4&" */" -> /* MBOX = 12 / 0x00000438 : Rx Mask = 0x00000081 */
