Workbook
Name _1920: [1]前提書情報!#REF!
Name A: [3]!A
Name A_研究: [4]工数ｺｰﾄﾞﾘｽﾄ!$B$4:$B$5
Name A_研究0: [4]工数ｺｰﾄﾞﾘｽﾄ!$F$4
Name another: [3]!another
Name anotherB: [3]!anotherB
Name B: [3]!B
Name BODY: [3]!BODY
Name BODY_B: [3]!BODY_B
Name CACY: [3]!CACY
Name CACY_B: [3]!CACY_B
Name Calculation: [3]!Calculation
Name Calculation2: [3]!Calculation2
Name CB: [5]リソーセス算出!$B$6
Name CC: #REF!
Name ccc: #REF!
Name CON: #REF!
Name CONN: #REF!
Name DAINITTEI1: [5]リソーセス算出!$E$5:$I$14
Name DAINITTEI2: [5]リソーセス算出!$J$5:$P$14
Name DAINITTEI3: [5]定義!$H$4:$K$13
Name DAINITTEI4: [5]定義!$C$4:$F$13
Name DCU: #REF!
Name dengi: [3]!dengi
Name dengi_B: [3]!dengi_B
Name design: [3]!design
Name design_B: [3]!design_B
Name drivet: [3]!drivet
Name drivet_B: [3]!drivet_B
Name ENGINE: [3]!ENGINE
Name ENGINE_B: [3]!ENGINE_B
Name EstimateEffectImpact: OFFSET([7]ｲﾝﾊﾟｸﾄ影響台数集計表!$B$7,0,0,COUNTA([7]ｲﾝﾊﾟｸﾄ影響台数集計表!$B$7:$B$65535),COUNTA([7]ｲﾝﾊﾟｸﾄ影響台数集計表!$A$7:$IV$7))
Name EstimateEffectImpactDomest: OFFSET('[7]実勢(売上)台数表'!$B$7,0,0,COUNTIF('[7]実勢(売上)台数表'!$B$8:$B$65229,"A*")+COUNTIF('[7]実勢(売上)台数表'!$B$8:$B$65229,"B*")+1,COUNTA('[7]実勢(売上)台数表'!$A$7:$IV$7))
Name EstimateImpact: OFFSET('[7]実勢(売上)台数表'!$B$7,0,0,COUNTA('[7]実勢(売上)台数表'!$B$7:$B$65535),COUNTA('[7]実勢(売上)台数表'!$A$7:$IV$7))
Name EstimateNoImpact: OFFSET([7]月別企画台数表!$B$7,0,0,COUNTA([7]月別企画台数表!$B$7:$B$65535),COUNTA([7]月別企画台数表!$A$7:$IV$7))
Name ExistingProjectList: OFFSET('[7]プロジェクト一覧表(現行)'!$B$7,0,0,COUNTA('[7]プロジェクト一覧表(現行)'!$B$7:$B$65535),COUNTA('[7]プロジェクト一覧表(現行)'!$A$7:$IV$7))
Name FILEDATE: [5]リソーセス算出!$R$4:$T$14
Name G_0_kousu: [3]!G_0_kousu
Name G_0_kousu_B: [3]!G_0_kousu_B
Name G_0_soksu: [8]!G_0_soksu
Name G_0_soksu: [8]!G_0_soksu
Name G_n_shokig: [3]!G_n_shokig
Name G_n_shokig_B: [3]!G_n_shokig_B
Name G_基盤技術: [4]工数ｺｰﾄﾞﾘｽﾄ!$D$4:$D$38
Name G_基盤技術H: [4]工数ｺｰﾄﾞﾘｽﾄ!$N$4:$N$10
Name GenDate: [9]Data!$C$1
Name genka: [3]!genka
Name genka_B: [3]!genka_B
Name GR12.3inch_0dial: [1]前提書情報!#REF!
Name graphcopy: [3]!graphcopy
Name graphcopy_B: [3]!graphcopy_B
Name grfselect: [3]!grfselect
Name ITAKU: [5]リソーセス算出!$B$7
Name J_号口対策: [4]工数ｺｰﾄﾞﾘｽﾄ!$E$4:$E$41
Name J_号口対策部: [4]工数ｺｰﾄﾞﾘｽﾄ!$R$4:$R$7
Name JIKEN: [3]!JIKEN
Name JIKEN_B: [3]!JIKEN_B
Name katacheck: [3]!katacheck
Name katacheck_B: [3]!katacheck_B
Name LastMonthFull: [9]Data!$B$1

Sheet Revision history
A1: 標準仕様履歴/Revision history | G1: 個車仕様品番
A2: 19電子PF ver3_24MY / BEVStep3
A3: バリ品番 | B3: メジャー品番 | C3: 改訂日 | D3: 改訂内容 | E3: 改訂者 | G3: ver | H3: 改訂日 | I3: 改訂内容 | J3: 改訂者
A4: A0 | B4: 000 | C4: 44781 | D4: ePF3.0phase1向け初版発行 | E4: CSF2G浜崎
A5: A0 | B5: 001 | C5: 44812 | D5: FuelとILLOUTとILLCNTの確認用シート追加、バリ表＆制御仕様書の重複定数の表記統一（レオスタットSW,フューエルサブセンダ）、調光定数のTR1とIL2の分離。 | E5: CSF2G浜崎
A6: A0 | B6: 002 | C6: 44833 | D6: ①Fuelリッド開閉信号有無の定数追加。リッド開閉信号有無で給油判定ロジックの分かれるため、この定数は必要と判断。 ②調光制御仕様書のDR結果反映。定数追加はなし | E6: CSF2G浜崎
A7: A0 | B7: 003 | C7: 44872 | D7: リッド開閉信号有無の誤記修正（0⇔1定義逆転、11/7大部屋DN車担確認済み） | E7: CSF2G浜崎
A8: A0 | B8: 004 | C8: 44995 | D8: ①XV認証モード許可フラグ追加 →これまで仕入先での定数として切り替えていた、定数の追加。 ②航続可能距離(電子遅延方式) 学習燃費上限値,下限値の単位変更[km/l]→[%] →定数仕様上単位が[km/l]だが実際はデフォルト燃費×%で指示していた。ソフト実装でkm/l変換し、定数仕様上は[%]表記とする ③燃費最大値の定数定義変更 →燃費を直接記載するのではなく、従来の6パターンの中から、選択する方式に戻す。 ④夜間のILL_OF信号出力時入力(レオスタット位置)、夜間のILL_OF信号出力ｷｬﾝｾﾙ時入力(レオスタット位置)の定数化 →一旦定数化不要との検討をしたが、定数に定義を戻す。昼は0固定。 ⑤シートベルトINDの定数追加 →国コード標準化により新たに定数として追加された。 ⑥REVIND仕様書ドロップにより定数削除 ⑦ONOFF判定仕様書 走行可能フラグの入力切替フラグ（パワトレ判定→定数管理に変更） ⑨ブザー仕様書のブザー項目をePF3.0最新仕様に追従 ⑩データ定義Max値を物理値「LSB×データ型MAX+オフセット」に変更 | E8: CSF2G浜崎
A9: A0 | B9: 005 | C9: 45000 | D9: ①フューエル仕様書ver1.4（’22/12）修正に伴う定数仕様書の追従 ＜定数の定義変更＞ 変更前：リッド開閉信号有無 0＝無、1=有 変更後：フューエルリッド開信号種別 0＝リッドなし、1＝LSTM、2=LST1 | E9: CSF2G浜崎
A10: A0 | B10: 006 | C10: 45007 | D10: ①タコメータ制御仕様書ver1.5（’23/3E）修正に伴う定数仕様書の追従 ＜新規定数の追加＞ Revピーク設定回転数【RevSet】 Revピーク表示判断回転数UP側（rpm）【RevDispHys】 Revピーク表示判断回転数DOWN側（rpm）【RevNoiseHys】 Revピーク表示時間【RevDispTime】 | E10: CSF2G浜崎
A11: A0 | B11: 007 | C11: 45013 | D11: ①070D特殊定数の追加 ＜新規定数の追加＞ 定数名：【070D識別】 値： 1d・・・070D 0d・・・070D以外 | E11: CSF2G浜崎
A12: A0 | B12: 008 | C12: 45016 | D12: ①スポーツ車用の定数追加（制御仕様書追加のため） MET-P_GRTFOLP-A0-00-A-C1 MET-P_GRTFOLT-CSTD-A0-00-A-C1 MET-P_GRTEMP-A0-00-A-C1 MET-P_FRAMESGAGE-CSTD-A0-00-A-C1 | E12: CSF2G浜崎
A13: A0 | B13: 009 | C13: 45133 | D13: 19PFv3向けに新設 | E13: CSF2G浜崎
A14: A0 | B14: 010 | C14: 45197 | D14: ①シート「MCU定数一覧_概要説明」を追加 ②19PFver3向けに定数の追加と削除 | E14: CSF2G大石
A15: A0 | B15: 011 | C15: 45226 | D15: ①シート「MCU定数一覧_概要説明」ヘッダーの仕様書№を更新 ②定数新規追加(MCUID：647~660) ③記載レベルアップ ・MCUID00024「ブランド」：「定数適合方法欄」に追記 ・MCUID00024「ブランド」：「使用する制御仕様書名」に追記 | E15: 5DPV5G金成
... A17: A0 | B17: 013 | C17: 45287 | D17: ①「MCUCONST」 定数新規追加 １．MCUID0757~0796：”MET-M_SP-CSTD”仕様書修正に伴う定数追加 ２．MUCID0797：定数ソフト書込フラグを追加 ②「MCUCONST」 既存定数修正／削除 １．MCUID0040~0066：”MET-M_CONTBUZZ-CSTD”の一部定数を削除 ２．MCUID0187~0204：定数適合方法に文言追記 ３．MCUID0587：制御仕様書にて固定値化のため削除 ４．MCUID0615~0621：定数重複のため削除 ５．MCUID0241、MCUID0244、MCUID0245：定数のMAX値を変更 ・4294967.295 → 84.200 ６．MCUID0433~MCUID0450, MCUID0469~MCUID0486, MCUID0505~MCUID0517, MCUID0531~MCUID0543：定数のMAX値を変更 ・655.35 → 350.00 ７．MCUID0023：”定数選択肢の定義”に追加、定数のMAX値を変更 ・定数選択しの定義追加：4=8.8インチ ・定数のMAX値：4 ８．MCUID0258~0259：”MET-M_SP-CSTD”仕様書修正に伴い削除 ９．MCUID0256, MCUID0257, MCUID0260, MCUID0261：”MET-M_SP-CSTD”仕様書修正に伴い定数名変更 10．MUCID0001~0012：ソフト品番の【TMC車担用】欄の固定化 | E17: 5DPV5G 長島／金成
D18: ③「MCUCONST」 ロジックに関わらない誤記訂正 １．MCUID00430：定数名を変更（SW有無→SWタイプ） ２．MCUID0024：使用している制御仕様書Noに”MET-C_GMN-CSTD-A0”を追加 ３．MCUID0025：使用している制御仕様書Noの対象制御仕様書名を変更 ・誤）MET-M_GMN-CSTD-A0 → 正）MET-C_GMN-CSTD-A0 ４．MCUID0219：定数名を変更（G球体→Gボール） ④「MCUCONST」：フォーマット修正 １．定数ソフト列追加（B列） ２．VARI*の名称を削除、「自由記入欄」に変更 ⑤その他 １．「MCU定数一覧_概要説明」を再設置に伴う更新 ・シート名を”MCUCONST_運用ルール”に変更 ・項目及び内容を追加（使用している制御仕様書No～（定数記載欄）まで） ・項目「出荷時定数項目」に内容を一部追加
A19: A0 | B19: 014 | C19: 45322 | D19: ①「MCUCONST」 既存定数修正／削除 １．MCUID0562：出荷時定数を変更 ・10.0 → 2.0 ２．MCUID0469：Unit（単位）を変更 ・”-” → ”L” ②「MCUCONST」：フォーマット修正 １．ソフト変換ツールバージョン列追加（ACX列） | E19: 5DPV5G 長島／金成
A20: A0 | B20: 015 | C20: 45351 | D20: ①「MCUCONST」 定数新規追加 １．MCUID0798：バリエーション表の品番増に伴い一部のバリをMCUCONSTに定数として追加 ②「MCUCONST」 既存定数修正／削除 １．MCUID0216：19v3としてSLP_POS採用となる車両の予定が無いため非適用化、削除 ２．MCUID0237："Name（定数名）"を変更 ・”走行可能フラグの入力信号切替” → ”ｴﾝｼﾞﾝ回転数【NE1】、運転可能表示【RDYIND】” ３．MCUID0262、0263："定数適合方法"を変更 ・”空白” → パターン選択用の文言を新規追加 ③その他 １．”MCUCONST_変更履歴(車担用)”シートの追加 ２．”MCUCONST_運用ルール”シートのヘッダーの仕様書№を削除 | E20: 5DPV5G 長島／金成
A21: A0 | B21: 016 | C21: 45387 | D21: ①「MCUCONST」 既存定数修正／削除 １．MCUID0027~MCUID0208： 出荷時定数値、Ofs（オフセット）、Unit（単位）、Min、Max、定数適合方法を変更 ２．MCUID0139~MCUID0146、MCUID0155~MCUID0162、 MCUID0171~MCUID0178："Name（定数名）"を変更 ３．MCUID0035、MCUID0147~MCUID0154、MCUID0163~MCUID0170、 MCUID0179~MCUID0186：削除 | E21: 5DPV5G 長島／金成
A22: 0 | B22: 000 | C22: 45429 | D22: ①BEVStep3向けにブランチ バリエーション：A0 → 0 メジャー品番：016 → 000 シート「MCUCONST」：BEVStep3要否欄を追加 | E22: 5DPV2G 磯部／手塚
A23: 0 | B23: 001 | C23: 45457 | D23: ①「MCUCONST」SOCゲージ 充電口位置指示の値入力規則を修正 １．定数選択肢の定義(0=無,1=右,2=左)に対して、値入力規則のMaxが1だったため、2に修正 ２．非表示となっていた7行目を再表示 ３．メジャー品番：000 → 001 ②「改訂履歴」ファイル名の付け方を誤記訂正 | E23: 5DPV2G 杉山／手塚
A24: 0 | B24: 002 | C24: 45667 | D24: ①「MCUCONST」定数追加／修正／削除 １．MCUID0364～0385（昼輝度）、MCUID0408～0429（夜輝度）：RGB調光対応（目標輝度割合(%)→透明度へ変更） ２．MCUID0250～MCUID0255：Max、Minを変更 ３．MCUID0605：定数名を変更 ４．MCUID0256、MCUID0260：Maxを変更 MCUID0257、MCUID0261：Max、Minを変更 ５．MCUID0238：削除 ６．MCUID0652：削除 ７．MCUID0722：削除 ８．MCUID0011、MCUID0012：Minを変更 ９．MCUID0219、MCUID0221：Maxを変更 １０．MCUID0222、MCUID0223：削除 １１．MCUID0809、MCUID0810：新規追加 １２．MCUID0342~MCUID0363、MCUID0386~MCUID0407：定数適合方法を変更 １３．MCUID0592：”【TMC設計用】使用している制御仕様書No.”を変更 １４．MCUID0340：Maxを変更 １５．MCUID0001~MCUID0010、MCUID0013~MCUID0020：出荷時定数値を変更 １６．MCUID0029~MCUID0033,MCUID0067~MCUID0208,MCUID0745~MCUID0750,MCUID3002~MCUID3019：”Type(データ型)”、”LSB/Prec”を変更 １７．MCUID0235：”Max”を変更 １８．MCUID0262：”定数適合方法”を変更（スピードメータ最高車速図を更新） １９．MCUID0268：”定数選択肢の定義”、”出荷時定数値”、”Max”を変更 | E24: 5DPV6G 浜崎／手塚
D25: ２０．MCUID0757～MCUID0796：”Max”を変更 ２１．MCUCONSTを使用している制御仕様書の点検 ２２．MCUID0798：”使用している制御仕様書No.”を変更 ２３．MCUID0738：”使用している制御仕様書No.”を変更 ２４．MCUID0320：新規追加 ２５．MCUID0217～0221：”使用している制御仕様書No.”を変更 ２６．MCUID0720～0723, 0726, 0732, 0735：削除 ２７．MCUID0660：”使用している制御仕様書No.”を変更 ２８．MCUID0001～0021, MCUID0023, MCUID0430, MCUID0797：”使用している制御仕様書No.”を変更 ２９．MCUID0238：削除 ３０．MCUID0268：”使用している制御仕様書No.”を変更 ３１．MCUID0432, 0557, 0573：削除 ３２．MCUID3000,MCUID3001：削除 ３３．MCUID0023：”使用している制御仕様書No.”を変更 ３４．MCUID0592：”使用している制御仕様書No.”を変更 ３５．MCUID0590：”使用している制御仕様書No.”を変更 ３６．MCUID3002～MCUID0208(左記MCUIDに挟まれたIDすべて)：”使用している制御仕様書No.”を変更 ３７．MCUID0035～MCUID0039, MCUID0751～MCUID0753：削除 ３８．MCUID3021~3024：新規追加 ３９．MCUID0027, MCUID0744：削除 ４０．MCUID0028, MCUID0745：削除 ４１．MCUID0029, MCUID0746：定数名変更 ４２．MCUID0025：”定数選択肢の定義”およびMax値を修正
D26: ４３．MCUID0338, 0339：削除 ４４．OMUSVI判定列を追加 ②「改訂履歴」ファイル名のつけ方修正
A27: 0 | B27: 003 | C27: 45755 | D27: １．19v3追従対応 ①フォーマット変更 ・車担入力シートの名称変更 旧）MCUCONST ⇒ 新）MCUCONST(編集用 For Editing) ・MCUCONST(編集用 For Editing)シートを以下のように変更 ・従来仕様のMCUID横並びから縦並びに変更（列と行を入れ替え） ・アドレスID（A列）、入力順（B列）を追加 ・予約定数を追加（U1：570個、U2：570個、U4：60個） ・定数ソフト変換ツール用のシートとして”MCUCONST"シート新設 ・フォーマット変更に伴い、「MCUCONST_rules」シートを修正 ・バリ分け条件 Vari. split conditionsシートを新設 ・全シート：英語併記対応 ②「MCUCONST_rules」シート：”４．MCUCONSTAD 定数入力ルール【TMC車担用】”を変更 ③「MCUCONST(編集用 For Editing)」シート 定数追加/修正/削除 ・MCUID0013～MCUID0020：”適合定数方法”を変更 ・MCUID0915~MCUID0922：新規追加 ・MCUID0738：Typeを変更 ・MCUID211：定数適合方法を変更 ・MCUID0336,MCUID0337：定数適合方法にそれぞれ以下を追加 MCUID0336：（MCUID0337の1ステップ高い値を設定すること。） MCUID0337：（MCUID0336の1ステップ低い値を設定すること。） ・MCUID0269：削除 ２．MCUID3025：コンビネーションスイッチ位置 新規追加 ３．MCUID0340~0430：昼輝度、夜輝度テーブル 使用している制御仕様書名変更 ４．MCUID0798：自車意匠のターンシグナルランプ色 使用している制御仕様書名変更 ５．OMUSVIIDを全角から半角へ変更 ６．以下シートを削除 ・確認用)Fuel燃料特性(アナログ) ・確認用)Fuel燃料特性 (8セグ) ・参考)Fuel定数マニュアル ・参考)Fuel評価仕様 | E27: 5DPV6G 浜崎／手塚
A29: 0 | B29: 004 | C29: 45817 | D29: １．19v3追従対応 ①シート「MCUCONST」/Sheet "MCUCONST" 編集用シートの"A列:アドレスID","B列:入力順"を転記対象に含まないよう、数式を変更 ２．MCUID0430 出荷時定数値を"1"→"3"へ変更 ３．MCUID0592, MCUID0603：削除 MCUID1135~MCUID1138：新規追加 ４．MCUID0923~MCUID1082, MCUID1093~1112：定数新規追加 ５．MCUID0217, MCUID0218：削除 | E29: 5DPV6G 浜崎／手塚
A30: 0 | B30: 005 | C30: 45855 | D30: １．19v3追従対応 ①MCUCONST(編集用 For Editing)シート ・MCUID0336,MCUID0337：定数名欄、定数適合方法欄を修正 ・MCUID0262：定数適合方法欄を修正 ・セルM24~AP24、M25~AP25の数式をSWITCH文へ修正 ②MCUCONST_rulesシート ・フォーマット変更、法規適合欄追加に伴い、説明の指定列を修正 ２．MCUID0576~MCUID0586：新規追加 ３．MET-GRIS管理No.欄を追加 | E30: 5DPV6G 浜崎／手塚
A31: 0 | B31: 006 | C31: 45876 | D31: MCUCONST(編集用 For Editing)シート １．MCUID0023：新規追加 | E31: 5DPV6G 浜崎／手塚
A32: 0 | B32: 007 | C32: 45947 | D32: １．19v3追従 ①「MCUCONST_rules」シート ・"２．定数ソフト生成プロセスの概要"を変更 ・”４．MCUCONST 定数入力ルール【TMC車担用】 / 4. MCUCONST constants entry rules [for TMC Shatan]”の章タイトル修正 ・”5．MCUCONST 定数更新ルール【TMC標準用】 / 5. MCUCONST constants update rules [for TMC standards design]”の章タイトルを修正 ②「MCUCONST(編集用 For Editing)」シート ・MCUID0029-0033,0035-0039,0067-0146,0155-0162,0171-0178,0187-0208,0746-0753,0799-0808,0847-0913,0915-0922,1125-1132：出荷時定数値、定数適合方法を修正 ・MCUID0031,0748,0896,0897,1131,1132：定数名を修正 ・MCUID0923-0932：定数適合方法を修正 ③「Ref) Sound Pressure Limit」シート：新規追加 ２．MCUID0025：使用している制御仕様書No.追記 | E32: 5DPV6G 浜崎／手塚
B33: ファイル名の付け方：
B34: MET-M_MCUCONST（MCU個別部の定数）-CSTD_0_007（標準仕様品番）_310D_01 （個車仕様品番）
B38: 編集タイミング：
B39: 標準仕様品番： | C39: データ定義の変更、定数の追加、定数仕様書の順番変更 【※注意】定数の順番やデータ定義は、全てDNのMCUソフトに紐づいているため、DN側との許可なしに変更不可
B40: 個車仕様品番： | C40: 定数値の変更 【※注意】prjが変わると、原則リセットすること

Sheet Revision his. for Shatan
A1: MCUCONST変更履歴 / MCUCONST revision history
C2: <記載ルール/Entry rules:>
C3: ①記載を修正・削除する場合は、二重線(取り消し線)表記はしない。上書き更新とする。 (1) When revising or deleting an entry, do not use double lines to indicate a deletion. Update entries by overwriting them.
C4: ②制御仕様書ファイル名は、下記に入力する車両コード、Ver（A～W）に合わせること。 (2) The file names of control specifications must adopt the vehicle code and version (A to W) as described below.
C5: ※ファイル名の命名規則は「MET-SPCRULE-XSTD-*」に準ずる。 * Refer to MET-SPCRULE-XSTD-* for the naming rules of file names.
C7: 車両名 / Vehicle name （XXXX） | D7: Ver. （-X） | E7: 改訂日 Date of revision | F7: 変更内容 Details of changes | G7: 作成 Created | H7: 調査 Checked | I7: 承認 Approved
B8: 例 E.g. | C8: 310D | D8: -A | E8: 2024/2/29 2024/Feb/29 | F8: 変更対象：MCUID0660 対象セル：ZV10 変更内容：”1”→”0” 変更理由：X-MODE適用→非適用対応による変更 Subject of change: MCUID0660 Applicable cells: ZV10 Details of change: “1” changed to “0”. Reasons for change: Changed in response to X-mode changing from applicable to not applicable. | G8: 5PD5G*** | H8: 5PD5G*** | I8: 5PD5G***
C21: 以降は行挿入で追加ください After this row is filled, enter revisions by adding new rows.
C22: ↑ここへ挿入 Insert here ↑.

Sheet MCUCONST_rules
B1: メーターECU 制御標準仕様書 / Meter ECU standard control specifications | Q1: MCU定数一覧 / List of MCU Constants
A3: １．概要 / 1. Outline
B4: 本書では定数仕様について規定する。 仕入先様は下記２点を行う。 ①本仕様書の定数情報及びその定数を使用する制御仕様書に基づき車両跨ぎの共通ソフトを実装する。 ②定数領域(Logical Block2)における、アドレス値を指定しメータ標準仕様設計部署に提出する。 TMCメータ車担は、アドレス値が入力された本仕様書に対し定数設定を行い、そのファイルを基にソフト部品を生成する。 尚、車担が行うソフト部品生成のやり方については、別途メータ標準仕様設計から示す。 | AM4: This document describes constants specifications. Suppliers are expected to carry out the following two items. (1) Implement the common vehicle software based on the control specifications that use the constants information and constants described in this document. (2) Specify the address values in the constants domain (Logical Block 2) and submit them to the department in charge of designing the standard meter specifications. The project meter engineer at Toyota Motor Corporation (TMC) will set the constants in accordance with this document using the entered address values and generate the software part based on that file. Note that the software generation method carried out by the engineer in charge of the model (“Shatan”) will be instructed by a separate standard meter specifications design department.
A6: ２．定数ソフト生成プロセスの概要 / 2. Outline of constants software generation process
C8: TMCメータ標準設計 / TMC meter standards design dept.
C12: TMCメータ車担 / TMC project meter engineer (MET Shatan)
C17: 仕入先様 / Supplier
A21: ３．"MCUCONST(編集用 For Editing)"シートの説明 / 3. Description of "MCUCONST(編集用 For Editing)" sheet
B22: 【TMC設計用】【TMC車担用】の項目は、設計時の参考記載。仕入先様は制御／評価に使用しないこと。 / Fields marked [For TMC design dept.] and [For TMC Shatan] show reference information for the design process. This information must not be used for control or evaluation.
B24: 項目 / Item | N24: 説明 / Description
B25: アドレスID＊1 / Address ID*1 | N25: 予約分含めた全定数に対し、仕入先様の実装アドレスと1対1に対応するID。 ID that corresponds one-to-one with the supplier's implementation address for all constants, including reserved ones.
B26: 入力順＊1 / Input Order*1 | N26: TMC車担が入力しやすいように定数を並び替えるための連番。発行の度にTMC標準側で付与し直す。 A sequential number used to rearrange constants for easier input by TMC Shatan. Reassigned on the by TMC standards design with each issuance.
B27: ユニークID＊1 / Unique ID*1 | N27: 定数に付与されるID。/ ID assigned to constant.
B28: Name(定数名)＊1 / Name (of constant)*1 | N28: 定数固有の名称。 / Unique name given to the constant.
B29: 【TMC設計用】 代表的な制御仕様書名＊1 [For TMC design dept.] Typical control specifications name*1 | N29: 可読性を上げるための参考記載。 Reference information to enhance readability.
B30: 【TMC設計用】 使用している制御仕様書No.＊1 [For TMC design dept.] Typical control specifications name*1 | N30: TMC設計が、定数変更時に影響する制御仕様書を洗い出す使用するための参考記載。 仕入先様は制御／評価に使用しないこと。 Reference information used to identify the control specifications affected if the TMC design department changes the constant. This information must not be used for control or evaluation.
B31: 【TMC設計用】 定数の適用条件＊1 [For TMC design dept.] Constant applicability*1 | N31: TMC車担が、記載必要な項目を見分けるための車両適用条件の参考記載。 Reference information showing vehicle applicability so that the TMC Shatan can identify the items requiring entry.
B32: 【TMC設計用】 定数設定値のバリ分け条件＊1 [For TMC design dept.] Variation separation conditions for constant settings*1 | N32: TMC車担が、定数ソフト品番数を見積もるためのバリ分けの条件の参考記載。 Reference information showing the conditions for separating the variations so that the number of constants software part numbers can be estimated.
B33: 定数選択肢の定義＊1 / Definition of constants options*1 | N33: 値に対して定数として意味する内容を記載。 例)Fuelゲージ フューエルセンダサブ有無 0=なし、1=あり ←個車定数として0、1を選択 Enter the details describing the meaning of the constant values. E.g.) Fuel gauge: fuel sender sub presence 0 = Not present, 1 = Present ← Select 0 or 1 as a constant for individual vehicles.
B34: 【TMC車担用】 判定式の説明 [For TMC Shatan] Description of determination expression | N34: TMC車担が、判定式の根拠を記載しておくための項目。 Item for TMC Shatan to enter the basis for the formula used to make a judgment.
B35: 【TMC車担用】 1つめの品番の判定式 [For TMC Shatan] Determination expression for the first part number. | N35: TMC車担が、仕様レビューに便利に使用するための計算式表示行。 (参考)固定値の場合、"=1"と記載しなければ表示されない。 Row used to indicate the calculation formula that makes it more convenient for TMC Shatan to review the specifications. Reference: When the expression is a fixed value, no description is shown in this row unless “= 1” is entered.
B36: (定数記載欄) / (Fields for entering constants) | N36: メータ車担が設定する定数値。 e組付け時にメータソフトの「出荷時定数」をこの値に上書きする。 Constants set by the project meter engineer. For e-assembly, the meter software shipment constants are written over these values.
N37: データ処理に関する入力値の記載ルール。 ・10進数で記入すること。(除、ASCII10進数等の指定がある場合) ・LSBの整数倍とすること。 理由：整数倍でない場合、ソフト生成ツールでエラーが発生する。 ・オフセットを含めない値とすること。 理由：オフセットは定数ソフト変換ツールで計算処理される。 e.g. オフセット2000に対して2024を示す場合も、 オフセット0に対して2024を示す場合も、入力値は2024とする。 ・Minより大きい値を記述すること。 ・Maxより小さい値を記述すること。 Entry rules for input values related to data processing: - Must be entered as a decimal value (unless entry as an ASCII decimal value or the like is specified). - Least significant bits (LSB) must be whole-number multiples. Reasons: An error will be generated by the software generation tool unless a whole-number multiple is used. - Values must not include offsets. Reasons: Offsets are calculated and processed by the constants software conversion tool. E.g., the input value will be regarded as 2,024 regardless of whether 2,024 was entered incorporating an offset value of 2,000 or 0. - Entered values must be greater than the minimum value. - Entered values must be smaller than the maximum value.
B38: 出荷時定数＊1 / Shipment constants*1 | N38: サプライヤから出荷する際にソフトに書き込まれている定数。TMC標準メータ設計が指定する。 出荷時定数は、e組付けの際に個車定数に上書きされる。 設定値のルールは前述の定数記載欄に同じ。 Constants written into the software when shipped from the supplier. Specified by the TMC standard meter design dept. The shipment constants are written over the individual vehicle constants when e-assembly occurs. The rules for the settings values are the same as for the constants entry fields described above.
B39: Type(データ型)＊1 / Type (data type)*1 | N39: その定数の選択肢数/範囲を決めるデータ型、S1、S2、S4、U1、U2、U4のいずれかが設定される。 ※フラグはU1型とする。 The data type (S1, S2, S4, U1, U2, or U4) that determines the number of options or range of the constants is entered. * Flags must be type U1.
N40: <参考> / Reference:
B41: LSB＊1 | N41: 入力値の最小単位を示す。入力値はLSBの整数倍とせねばならない。 The minimum unit of the input value. Input values must be whole-number multiples of the LSB.
B42: ofs(オフセット)＊1 / ofs (offset)*1 | N42: ソフト容量を最適化するために、データ型の基準を0から変更する場合に使用する値。 e.g. ofs無しの場合、2000~2099の値を設定するためにはu2型もしくはs2型(2byte)が必要。 ofsを2000とすれば、基準が2000となりu1(1byte)となり、LB2の使用領域を1byte節約できる。 ofsについて車担は考慮不要。理由：オフセットの処理機能は定数ソフト変換ツールに織り込まれているため。 Value used when the basis of the data type is changed from 0 to optimize the software capacity. E.g., if no “ofs” is set, data types u2 or s2 must be adopted to set a value between 2,000 and 2,099. However, if an “ofs” of 2,000 is set, that offset of 2,000 becomes the basis of the data type, meaning that u1 (1-byte) can be adopted and the applicable range of LB2 can be minimized to 1-byte. Shatan does not have to factor in “ofs” values. Reasons: This is because the offset processing function is incorporated into the constants software conversion tool.
B43: unit(単位)＊1 / Unit*1 | N43: 対象定数の単位。/ Unit of the applicable constant.
B44: Min＊1 | N44: 定数設定が可能な最小値。 車担定数設定時は、この値以上を設定すること。 Lowest value constant that may be set. When Shatan sets a constant, its value must be this value or higher.
B45: Max＊1 | N45: 定数設定が可能な最大値。 車担定数設定時は、この値以下を設定をすること Highest value constant that may be set. When Shatan sets a constant, its value must be this value or lower.
B46: 【TMC車担用】定数適合方法 [For TMC Shatan] Constants calibration method | N46: 個車定数を決める際の参考情報。 Reference information used when the individual vehicle constants are determined.
B47: 【仕入先様記入欄】 アドレス値＊1 [Supplier entry fields] Address values*1 | N47: 仕入先様が記載する、定数ソフト領域におけるデータの格納先アドレス。 These fields are entered by the supplier and are the data storage addresses in the constants software domain.
AP48: *1：標準部署が設定している項目のため、車担は変更しないこと。Items defined by the dept. in charge of standards and must not be changed by Shatan.
A50: ４．MCUCONST 定数入力ルール【TMC車担用】 / 4. MCUCONST constants entry rules [for TMC Shatan]
B51: ・"バリ分け条件 Vari. split conditions"シートと"MCUCONST(編集用 For Editing)"シートで編集すること。 "MCUCONST"シートはツール読込みのための変換シートのため、編集しないこと。 ・PJTとして新規に定数を作成するときは、入力順を昇順に並び替え、入力実施すること（定数の並び順などが整理され、入力ミスが減らせるため）。 ・定数を過去のRで作成しており、その内容を引き継いで以降のRで差分箇所を編集する場合 （例：CVでR5定数仕様で定数作成しており、その内容を引き継いで1AでR6定数を作成する場合） 1.旧定数・新定数共にアドレスIDの昇順に並び替え実施 2.旧定数の定数入力部（L39~AO1997）を範囲選択しコピー、新定数側の同じ部分に貼り付け 3."バリ分け条件 Vari. split conditions"シートを記載。 4."ユニークID=空白以外"かつ"車担定数入力部（L列）=空白"でフィルタし、該当部分の定数を検討 （新規定数やソフト影響のある変更が入った定数がソート結果で出てきます。） ※その他ソフトバリ増加や車両側変更のあった内容は、編集ください。 ・バリ分けに使用する「バリ分け条件 Vari. split conditions」シートは手入力禁止。（AISAC部品表のエクスポートをコピーペーストで入力する） ・ひとつの項目(列)に対する各ソフト品番(行)の値入力は、 「車両大分類コードの値を切分条件としたSWICH文」 もしくは「すべて同じ固定値を"=固定値"」 とし、 ソフト品番(行)毎の異なる値の設定や手入力は行わないこと。 (参考) SWITCH文を使用する理由は、切分パターンの定義モレを気付きやすいようにするため ・定数設計後のチェックはチーフが次の2点を確認すること。 - L列に出力されている1品番目の判定式(M列の式)が全定数に対し、正しいか。 - 1品番目以外のソフトバリ(N～AP列)には1品番目(M列)と同じ式が設定されているか。 ※数式処理をRC形式とすれば、その列の1品番目(M列)と異なる式が入力されている行をオレンジにハイライトする条件付き書式設定あり。 但し、この条件付き書式は「"="を付けない手入力の値」のチェックはできないため注意。 | AQ51: - Edit in the "バリ分け条件 Vari. split conditions" sheet and "MCUCONST (編集用 For Editing)" sheet. The "MCUCONST" sheet is a conversion sheet for tool loading, so do not edit it. - When creating new constants as a project, rearrange the Input Order in ascending order and then proceed with the input (this helps organize the order of constants and reduces input errors). - If constants were created in a previous release and you want to carry over that information to edit the differences in a subsequent release (for example, if constants were created in R5 specifications in CV and you want to create R6 constants in 1A), follow these steps: 1. Sort both old and new MCUCONST in ascending order by address ID. 2. Select and copy the constant input section of the old constants (from L39 to AO1997) and paste it into the same section of the new constants. 3. Fill in the "バリ分け条件 Vari. split conditions" sheet. 4. Filter by "Unique ID = not blank" and "Vehicle Handling Constant Input Section (Column L) = blank" to review the relevant constants. (New constants or constants with changes that affect the software will appear in the sorted results.) *Please make necessary edits for any additional software variant increases or changes on the vehicle side. - The "バリ分け条件 Vari. split conditions" sheet that is used for separating variations must not be entered manually. (Enter by copying and pasting exports from the AISAC parts list.) - Values entered for each software part number (row) with respect to single items (columns) must have the SWITCH statement with the main vehicle category code value as the condition or all the same fixed values must be set to “= fixed value”. Different settings values or manual input are not permitted for each software part number (row). (reference)The reason for using the SWITCH statement is to make it easier to identify any missing definitions in the segmentation patterns. - The person in charge of checks after constants design must confirm the following two points. - Whether the judgment formula for the first part number outputted in column L (the formula in column M) is correct for all constants. - Whether the same formula as for the first part number (column M) is adopted in the software variations (columns N to AP) other than the first part number. * If the “Working with formulas” setting is set to the RC format, rows entered using a different formula than the first part number in that column (row 9) will be highlighted in orange by a conditional expression. However, care should be taken since that conditional expression cannot check whether the value has been entered manually without using “=”.
E53: (参考)RC形式にするにはExcelオプションの下記チェックを入れる。 / Reference: To adopt the RC format, select the following Excel option.
A71: 5．MCUCONST 定数更新ルール【TMC標準用】 / 5. MCUCONST constants update rules [for TMC standards design]
B72: ※更新時にフォーマットに記載されているアドレスID、Type(データ型)は絶対に変更しないこと ※以下変更を全て反映した後、入力順を昇順に並び替え、上から連番を付与し直すこと。 （ただし"xB-Reservation"と"EXx"には変えないように、範囲は手で行うこと） A.新規の定数を追加する場合 １．アドレスIDで昇順に並べ替え ２．Type(データ型)を決める e.g. U2 ３．決めた型とType(データ型)の予約定数（入力順が"xB-Reservation"のもの）の内一番上の行のものを、今回の追加行とする ４．追加行に標準担当で入力する各列の項目を埋める（MCUIDは既存IDの最大値+1を取得し埋める） ５．既存定数やその仕様書とのつながりを考え、入力しやすい定数の位置（入力順で昇順に並び替えた際の定数の位置）を検討し、 それに合わせて入力順の値を"Reservation"→任意の数値に変更する。 （一旦は少数を使って入れておく※例７５と76の間に入れたい定数の場合は75.1など） B.既存定数を廃止する場合 １．廃止行の入力番号／MCUIDを「廃止」に変更 C.既存定数を変更する場合 C-1. ソフトに影響する項目を変更する場合 対象項目："定数選択肢の定義","Type(データ型)","LSB/Prec","Ofs(オフセット)","Unit","Min.","Max." １．アドレスIDで昇順に並べ替え ２．変更後のType(データ型)の予約定数（入力順が"xB-Reservation"のもの）の内一番上の行のものを、今回の変更後の行とする ３．変更前の行の入力順(B列)～定数適合方法(AX列)をコピー、追加行にペースト（MCUIDも変更しない） ただし、定数のType(データ型)を変更する場合はそれ以外の項目のみコピペすること ４．変更前の行の入力順(B列)とユニークID(C列)を「廃止」に変更 ５．変更後の行に今回の変更内容を反映 C-2. ソフトに影響しない項目を変更する場合 対象項目：C-1の対象項目以外 １．対象の行に対し、変更箇所を上書きで反映する | AQ72: *Do not change the Address ID and Type (data type) specified in the format during updates. *After reflecting all the changes below, sort the input order in ascending order and reassign sequential numbers from the top. (However, do not change "xB-Reservation" and "EXx"; make sure to do this manually.) A. When add new constant 1. Sort by address ID in ascending order. 2. Determine the Type (data type), e.g., U2. 3. Use the top row of the reserved constant with the determined type and Type (data type) where the input order is "xB-Reservation" as the new addition. 4. Fill in the items for each column in the new row, entering the MCUID as the maximum existing ID + 1. 5. Consider the connection with existing constants and their specifications, and think about the position of the constants for easy input (the position of constants when sorted in ascending order). Change the input order value from "Reservation" to an arbitrary number that reflects this position. (For now, use decimals to place it; for example, if you want to insert a constant between 75 and 76, you could use 75.1.) B. When disard existing constant 1. Change the Input Order/Unique ID of the discarded row to "Discontinued". C. When change existing constant C-1. If change items that affect the software Target items: "Definition of constants options", "Type (data type)", "LSB/Prec", "Ofs (offset)", "Unit", "Min." and "Max." 1. Sort by Address ID in ascending order. 2. Use the top row of the reserved constant with the changed Type (data type) where the input order is "xB-Reservation" as the new row after the change. 3. Copy the input order (Column B) to the constant adaptation method (Column AW) from the row before the change and paste it into the new row (do not change the MCUID). However, if changing the Type (data type) of the constant, only copy and paste the other items. 4. Change the input order (Column B) and unique ID (Column C) of the row before the change to "Discontinued." 5. Reflect the change details in the new row. C-2. If change items that do not affect the software Target items: Any items other than those in C-1. 1. Overwrite the changes in the target row.

Sheet バリ分け条件 Vari. split conditions
B3: ソフト品番 分類条件
B4: ソフト品番 分類細目

Sheet MCUCONST(編集用 For Editing)
A1: アドレスID (変更禁止) Address ID (Change prohibited) | B1: 入力順 (変更禁止) Input Order (Change prohibited) | C1: ユニークID (変更禁止) Unique ID (Change prohibited) | D1: Name (定数名/Constant name) | E1: 【TMC設計用】 MET-GRIS管理No. [For TMC design dept.] MET-GRIS management No. | F1: 【TMC設計用】 代表的な制御仕様書名 [For TMC design dept.] Typical control specifications name | G1: 【TMC設計用】 使用している制御仕様書No. [For TMC design dept.] Applicable control Spec. No. | H1: OMUSVIを用いた動的切替有無 （※読み替え方法は、MET-M_OMUSVIVARI-*を参照すること） Dynamic switching with/without OMUSVI (*Refer to MET-M_OMUSVIVARI-* for the reading method) | I1: 【TMC設計用】 定数の適用条件 [For TMC design dept.] Constant applicability | J1: 定数選択肢の定義 Definition of constants options | K1: 【TMC車担用】 判定式の説明 [For TMC Shatan] Description of determination expression | L1: 【TMC車担用】 1つめの品番の判定式 [For TMC Shatan] Determination expression for the first part number. | AQ1: 出荷時定数値 | AR1: Type (データ型) (data type) | AS1: LSB/Prec | AT1: Ofs (オフセット) | AU1: Unit (単位) | AV1: Min | AW1: Max | AX1: 【TMC車担用】 定数適合方法 [For TMC engineer in charge] Constants calibration method | AY1: 【仕入先様記入欄】 アドレス値 [Supplier's entry field] Address value | AZ1: DENSO Address (Change prohibited) | BA1: XXX Address (Change prohibited) (Reserved) | BB1: YYY Address (Change prohibited) (Reserved) | BC1: DENSO 出荷時定数値 DENSO shipment target value (Change prohibited) | BD1: XXX 出荷時定数値 XXX shipment target value (Change prohibited) (Reserved) | BE1: YYY 出荷時定数値 YYY shipment target value (Change prohibited) (Reserved)
A2: A01 | B2: 0.01 | E2: - | L2: 定数ソフト品番 【注意】品番10桁を"-"無しで入力すること この行に記載された列のみソフトを出力します Constants software part number Note: Enter the 10-digit part number without using hyphens “-”. Only the columns entered for these rows will be outputted to the software.
A3: A02 | B3: 0.02 | D3: 仕入先選択※必ず選択すること Select Supplier *Please make sure to select one. | E3: - | L3: 仕向車型 Destination vehicle code | M3: A | N3: A | O3: A | P3: A | Q3: W | R3: W | S3: W | T3: W | U3: W | V3: W | W3: W | X3: W | Y3: C | Z3: C
A4: A03 | B4: 0.03 | D4: DENSO | E4: - | L4: ハンドル Steering wheel | M4: L | N4: L | O4: L | P4: L | Q4: L | R4: L | S4: L | T4: L | U4: R | V4: R | W4: R | X4: R | Y4: L | Z4: L
A5: A04 | B5: 0.04 | E5: - | L5: パワトレ Powertrain | M5: CONV | N5: HEV | O5: CONV | P5: HEV | Q5: CONV | R5: HEV | S5: CONV | T5: HEV | U5: CONV | V5: HEV | W5: CONV | X5: HEV | Y5: HEV | Z5: HEV
A6: A05 | B6: 0.05 | E6: - | L6: ボデー形状 Body shape | M6: SDN | N6: CUPE | O6: 4ドア | P6: 5ドア | Q6: 3ドア | R6: SDN | S6: CUPE | T6: 4ドア | U6: 5ドア | V6: 3ドア | W6: SDN | X6: CUPE | Y6: 4ドア | Z6: 5ドア
A7: A06 | B7: 0.06 | E7: - | L7: メータグレード Meter grade | M7: N | N7: N | O7: F | P7: F | Q7: N | R7: N | S7: F | T7: F | U7: N | V7: N | W7: F | X7: F | Y7: N | Z7: F
A8: A07 | B8: 0.07 | E8: - | L8: {=IF(INDEX('バリ分け条件 Vari. split conditions'!$C$3:'バリ分け条件 Vari. split conditions'!$R$33, COLUMNS('バリ分け条件 Vari. split conditions'!$C$3:'バリ分け条件 Vari. split conditions'!C3), ROWS('バリ分け条件 Vari. split conditions'!$C$3:'バリ分け条件 Vari. split conditions'!C3))="", "", INDEX('バリ分け条件 Vari. split conditions'!$C$3:'バリ分け条件 Vari. split conditions'!$R$33, COLUMNS('バリ分け条件 Vari. split conditions'!$C$3:'バリ分け条件 Vari. split conditions'!C3), ROWS('バリ分け条件 Vari. split conditions'!$C$3:'バリ分け条件 Vari. split conditions'!C3)))} | M8: {=IF(INDEX('バリ分け条件 Vari. split conditions'!$C$3:'バリ分け条件 Vari. split conditions'!$R$33, COLUMNS('バリ分け条件 Vari. split conditions'!$C$3:'バリ分け条件 Vari. split conditions'!D3), ROWS('バリ分け条件 Vari. split conditions'!$C$3:'バリ分け条件 Vari. split conditions'!D3))="", "", INDEX('バリ分け条件 Vari. split conditions'!$C$3:'バリ分け条件 Vari. split conditions'!$R$33, COLUMNS('バリ分け条件 Vari. split conditions'!$C$3:'バリ分け条件 Vari. split conditions'!D3), ROWS('バリ分け条件 Vari. split conditions'!$C$3:'バリ分け条件 Vari. split conditions'!D3)))} | N8: {=IF(INDEX('バリ分け条件 Vari. split conditions'!$C$3:'バリ分け条件 Vari. split conditions'!$R$33, COLUMNS('バリ分け条件 Vari. split conditions'!$C$3:'バリ分け条件 Vari. split conditions'!E3), ROWS('バリ分け条件 Vari. split conditions'!$C$3:'バリ分け条件 Vari. split conditions'!E3))="", "", INDEX('バリ分け条件 Vari. split conditions'!$C$3:'バリ分け条件 Vari. split conditions'!$R$33, COLUMNS('バリ分け条件 Vari. split conditions'!$C$3:'バリ分け条件 Vari. split conditions'!E3), ROWS('バリ分け条件 Vari. split conditions'!$C$3:'バリ分け条件 Vari. split conditions'!E3)))} | O8: {=IF(INDEX('バリ分け条件 Vari. split conditions'!$C$3:'バリ分け条件 Vari. split conditions'!$R$33, COLUMNS('バリ分け条件 Vari. split conditions'!$C$3:'バリ分け条件 Vari. split conditions'!F3), ROWS('バリ分け条件 Vari. split conditions'!$C$3:'バリ分け条件 Vari. split conditions'!F3))="", "", INDEX('バリ分け条件 Vari. split conditions'!$C$3:'バリ分け条件 Vari. split conditions'!$R$33, COLUMNS('バリ分け条件 Vari. split conditions'!$C$3:'バリ分け条件 Vari. split conditions'!F3), ROWS('バリ分け条件 Vari. split conditions'!$C$3:'バリ分け条件 Vari. split conditions'!F3)))} | P8: {=IF(INDEX('バリ分け条件 Vari. split conditions'!$C$3:'バリ分け条件 Vari. split conditions'!$R$33, COLUMNS('バリ分け条件 Vari. split conditions'!$C$3:'バリ分け条件 Vari. split conditions'!G3), ROWS('バリ分け条件 Vari. split conditions'!$C$3:'バリ分け条件 Vari. split conditions'!G3))="", "", INDEX('バリ分け条件 Vari. split conditions'!$C$3:'バリ分け条件 Vari. split conditions'!$R$33, COLUMNS('バリ分け条件 Vari. split conditions'!$C$3:'バリ分け条件 Vari. split conditions'!G3), ROWS('バリ分け条件 Vari. split conditions'!$C$3:'バリ分け条件 Vari. split conditions'!G3)))} | Q8: {=IF(INDEX('バリ分け条件 Vari. split conditions'!$C$3:'バリ分け条件 Vari. split conditions'!$R$33, COLUMNS('バリ分け条件 Vari. split conditions'!$C$3:'バリ分け条件 Vari. split conditions'!H3), ROWS('バリ分け条件 Vari. split conditions'!$C$3:'バリ分け条件 Vari. split conditions'!H3))="", "", INDEX('バリ分け条件 Vari. split conditions'!$C$3:'バリ分け条件 Vari. split conditions'!$R$33, COLUMNS('バリ分け条件 Vari. split conditions'!$C$3:'バリ分け条件 Vari. split conditions'!H3), ROWS('バリ分け条件 Vari. split conditions'!$C$3:'バリ分け条件 Vari. split conditions'!H3)))} | R8: {=IF(INDEX('バリ分け条件 Vari. split conditions'!$C$3:'バリ分け条件 Vari. split conditions'!$R$33, COLUMNS('バリ分け条件 Vari. split conditions'!$C$3:'バリ分け条件 Vari. split conditions'!I3), ROWS('バリ分け条件 Vari. split conditions'!$C$3:'バリ分け条件 Vari. split conditions'!I3))="", "", INDEX('バリ分け条件 Vari. split conditions'!$C$3:'バリ分け条件 Vari. split conditions'!$R$33, COLUMNS('バリ分け条件 Vari. split conditions'!$C$3:'バリ分け条件 Vari. split conditions'!I3), ROWS('バリ分け条件 Vari. split conditions'!$C$3:'バリ分け条件 Vari. split conditions'!I3)))} | S8: {=IF(INDEX('バリ分け条件 Vari. split conditions'!$C$3:'バリ分け条件 Vari. split conditions'!$R$33, COLUMNS('バリ分け条件 Vari. split conditions'!$C$3:'バリ分け条件 Vari. split conditions'!J3), ROWS('バリ分け条件 Vari. split conditions'!$C$3:'バリ分け条件 Vari. split conditions'!J3))="", "", INDEX('バリ分け条件 Vari. split conditions'!$C$3:'バリ分け条件 Vari. split conditions'!$R$33, COLUMNS('バリ分け条件 Vari. split conditions'!$C$3:'バリ分け条件 Vari. split conditions'!J3), ROWS('バリ分け条件 Vari. split conditions'!$C$3:'バリ分け条件 Vari. split conditions'!J3)))} | ... AP8: {=IF(INDEX('バリ分け条件 Vari. split conditions'!$C$3:'バリ分け条件 Vari. split conditions'!$R$33, COLUMNS('バリ分け条件 Vari. split conditions'!$C$3:'バリ分け条件 Vari. split conditions'!AG3), ROWS('バリ分け条件 Vari. split conditions'!$C$3:'バリ分け条件 Vari. split conditions'!AG3))="", "", INDEX('バリ分け条件 Vari. split conditions'!$C$3:'バリ分け条件 Vari. split conditions'!$R$33, COLUMNS('バリ分け条件 Vari. split conditions'!$C$3:'バリ分け条件 Vari. split conditions'!AG3), ROWS('バリ分け条件 Vari. split conditions'!$C$3:'バリ分け条件 Vari. split conditions'!AG3)))}
A9: A08 | B9: 0.08 | E9: - | L9: {=IF(INDEX('バリ分け条件 Vari. split conditions'!$C$3:'バリ分け条件 Vari. split conditions'!$R$33, COLUMNS('バリ分け条件 Vari. split conditions'!$C$3:'バリ分け条件 Vari. split conditions'!C4), ROWS('バリ分け条件 Vari. split conditions'!$C$3:'バリ分け条件 Vari. split conditions'!C4))="", "", INDEX('バリ分け条件 Vari. split conditions'!$C$3:'バリ分け条件 Vari. split conditions'!$R$33, COLUMNS('バリ分け条件 Vari. split conditions'!$C$3:'バリ分け条件 Vari. split conditions'!C4), ROWS('バリ分け条件 Vari. split conditions'!$C$3:'バリ分け条件 Vari. split conditions'!C4)))} | M9: {=IF(INDEX('バリ分け条件 Vari. split conditions'!$C$3:'バリ分け条件 Vari. split conditions'!$R$33, COLUMNS('バリ分け条件 Vari. split conditions'!$C$3:'バリ分け条件 Vari. split conditions'!D4), ROWS('バリ分け条件 Vari. split conditions'!$C$3:'バリ分け条件 Vari. split conditions'!D4))="", "", INDEX('バリ分け条件 Vari. split conditions'!$C$3:'バリ分け条件 Vari. split conditions'!$R$33, COLUMNS('バリ分け条件 Vari. split conditions'!$C$3:'バリ分け条件 Vari. split conditions'!D4), ROWS('バリ分け条件 Vari. split conditions'!$C$3:'バリ分け条件 Vari. split conditions'!D4)))} | N9: {=IF(INDEX('バリ分け条件 Vari. split conditions'!$C$3:'バリ分け条件 Vari. split conditions'!$R$33, COLUMNS('バリ分け条件 Vari. split conditions'!$C$3:'バリ分け条件 Vari. split conditions'!E4), ROWS('バリ分け条件 Vari. split conditions'!$C$3:'バリ分け条件 Vari. split conditions'!E4))="", "", INDEX('バリ分け条件 Vari. split conditions'!$C$3:'バリ分け条件 Vari. split conditions'!$R$33, COLUMNS('バリ分け条件 Vari. split conditions'!$C$3:'バリ分け条件 Vari. split conditions'!E4), ROWS('バリ分け条件 Vari. split conditions'!$C$3:'バリ分け条件 Vari. split conditions'!E4)))} | O9: {=IF(INDEX('バリ分け条件 Vari. split conditions'!$C$3:'バリ分け条件 Vari. split conditions'!$R$33, COLUMNS('バリ分け条件 Vari. split conditions'!$C$3:'バリ分け条件 Vari. split conditions'!F4), ROWS('バリ分け条件 Vari. split conditions'!$C$3:'バリ分け条件 Vari. split conditions'!F4))="", "", INDEX('バリ分け条件 Vari. split conditions'!$C$3:'バリ分け条件 Vari. split conditions'!$R$33, COLUMNS('バリ分け条件 Vari. split conditions'!$C$3:'バリ分け条件 Vari. split conditions'!F4), ROWS('バリ分け条件 Vari. split conditions'!$C$3:'バリ分け条件 Vari. split conditions'!F4)))} | P9: {=IF(INDEX('バリ分け条件 Vari. split conditions'!$C$3:'バリ分け条件 Vari. split conditions'!$R$33, COLUMNS('バリ分け条件 Vari. split conditions'!$C$3:'バリ分け条件 Vari. split conditions'!G4), ROWS('バリ分け条件 Vari. split conditions'!$C$3:'バリ分け条件 Vari. split conditions'!G4))="", "", INDEX('バリ分け条件 Vari. split conditions'!$C$3:'バリ分け条件 Vari. split conditions'!$R$33, COLUMNS('バリ分け条件 Vari. split conditions'!$C$3:'バリ分け条件 Vari. split conditions'!G4), ROWS('バリ分け条件 Vari. split conditions'!$C$3:'バリ分け条件 Vari. split conditions'!G4)))} | Q9: {=IF(INDEX('バリ分け条件 Vari. split conditions'!$C$3:'バリ分け条件 Vari. split conditions'!$R$33, COLUMNS('バリ分け条件 Vari. split conditions'!$C$3:'バリ分け条件 Vari. split conditions'!H4), ROWS('バリ分け条件 Vari. split conditions'!$C$3:'バリ分け条件 Vari. split conditions'!H4))="", "", INDEX('バリ分け条件 Vari. split conditions'!$C$3:'バリ分け条件 Vari. split conditions'!$R$33, COLUMNS('バリ分け条件 Vari. split conditions'!$C$3:'バリ分け条件 Vari. split conditions'!H4), ROWS('バリ分け条件 Vari. split conditions'!$C$3:'バリ分け条件 Vari. split conditions'!H4)))} | R9: {=IF(INDEX('バリ分け条件 Vari. split conditions'!$C$3:'バリ分け条件 Vari. split conditions'!$R$33, COLUMNS('バリ分け条件 Vari. split conditions'!$C$3:'バリ分け条件 Vari. split conditions'!I4), ROWS('バリ分け条件 Vari. split conditions'!$C$3:'バリ分け条件 Vari. split conditions'!I4))="", "", INDEX('バリ分け条件 Vari. split conditions'!$C$3:'バリ分け条件 Vari. split conditions'!$R$33, COLUMNS('バリ分け条件 Vari. split conditions'!$C$3:'バリ分け条件 Vari. split conditions'!I4), ROWS('バリ分け条件 Vari. split conditions'!$C$3:'バリ分け条件 Vari. split conditions'!I4)))} | S9: {=IF(INDEX('バリ分け条件 Vari. split conditions'!$C$3:'バリ分け条件 Vari. split conditions'!$R$33, COLUMNS('バリ分け条件 Vari. split conditions'!$C$3:'バリ分け条件 Vari. split conditions'!J4), ROWS('バリ分け条件 Vari. split conditions'!$C$3:'バリ分け条件 Vari. split conditions'!J4))="", "", INDEX('バリ分け条件 Vari. split conditions'!$C$3:'バリ分け条件 Vari. split conditions'!$R$33, COLUMNS('バリ分け条件 Vari. split conditions'!$C$3:'バリ分け条件 Vari. split conditions'!J4), ROWS('バリ分け条件 Vari. split conditions'!$C$3:'バリ分け条件 Vari. split conditions'!J4)))} | ... AP9: {=IF(INDEX('バリ分け条件 Vari. split conditions'!$C$3:'バリ分け条件 Vari. split conditions'!$R$33, COLUMNS('バリ分け条件 Vari. split conditions'!$C$3:'バリ分け条件 Vari. split conditions'!AG4), ROWS('バリ分け条件 Vari. split conditions'!$C$3:'バリ分け条件 Vari. split conditions'!AG4))="", "", INDEX('バリ分け条件 Vari. split conditions'!$C$3:'バリ分け条件 Vari. split conditions'!$R$33, COLUMNS('バリ分け条件 Vari. split conditions'!$C$3:'バリ分け条件 Vari. split conditions'!AG4), ROWS('バリ分け条件 Vari. split conditions'!$C$3:'バリ分け条件 Vari. split conditions'!AG4)))}
A10: A09 | B10: 0.09 | E10: - | L10: {=IF(INDEX('バリ分け条件 Vari. split conditions'!$C$3:'バリ分け条件 Vari. split conditions'!$R$33, COLUMNS('バリ分け条件 Vari. split conditions'!$C$3:'バリ分け条件 Vari. split conditions'!C5), ROWS('バリ分け条件 Vari. split conditions'!$C$3:'バリ分け条件 Vari. split conditions'!C5))="", "", INDEX('バリ分け条件 Vari. split conditions'!$C$3:'バリ分け条件 Vari. split conditions'!$R$33, COLUMNS('バリ分け条件 Vari. split conditions'!$C$3:'バリ分け条件 Vari. split conditions'!C5), ROWS('バリ分け条件 Vari. split conditions'!$C$3:'バリ分け条件 Vari. split conditions'!C5)))} | M10: {=IF(INDEX('バリ分け条件 Vari. split conditions'!$C$3:'バリ分け条件 Vari. split conditions'!$R$33, COLUMNS('バリ分け条件 Vari. split conditions'!$C$3:'バリ分け条件 Vari. split conditions'!D5), ROWS('バリ分け条件 Vari. split conditions'!$C$3:'バリ分け条件 Vari. split conditions'!D5))="", "", INDEX('バリ分け条件 Vari. split conditions'!$C$3:'バリ分け条件 Vari. split conditions'!$R$33, COLUMNS('バリ分け条件 Vari. split conditions'!$C$3:'バリ分け条件 Vari. split conditions'!D5), ROWS('バリ分け条件 Vari. split conditions'!$C$3:'バリ分け条件 Vari. split conditions'!D5)))} | N10: {=IF(INDEX('バリ分け条件 Vari. split conditions'!$C$3:'バリ分け条件 Vari. split conditions'!$R$33, COLUMNS('バリ分け条件 Vari. split conditions'!$C$3:'バリ分け条件 Vari. split conditions'!E5), ROWS('バリ分け条件 Vari. split conditions'!$C$3:'バリ分け条件 Vari. split conditions'!E5))="", "", INDEX('バリ分け条件 Vari. split conditions'!$C$3:'バリ分け条件 Vari. split conditions'!$R$33, COLUMNS('バリ分け条件 Vari. split conditions'!$C$3:'バリ分け条件 Vari. split conditions'!E5), ROWS('バリ分け条件 Vari. split conditions'!$C$3:'バリ分け条件 Vari. split conditions'!E5)))} | O10: {=IF(INDEX('バリ分け条件 Vari. split conditions'!$C$3:'バリ分け条件 Vari. split conditions'!$R$33, COLUMNS('バリ分け条件 Vari. split conditions'!$C$3:'バリ分け条件 Vari. split conditions'!F5), ROWS('バリ分け条件 Vari. split conditions'!$C$3:'バリ分け条件 Vari. split conditions'!F5))="", "", INDEX('バリ分け条件 Vari. split conditions'!$C$3:'バリ分け条件 Vari. split conditions'!$R$33, COLUMNS('バリ分け条件 Vari. split conditions'!$C$3:'バリ分け条件 Vari. split conditions'!F5), ROWS('バリ分け条件 Vari. split conditions'!$C$3:'バリ分け条件 Vari. split conditions'!F5)))} | P10: {=IF(INDEX('バリ分け条件 Vari. split conditions'!$C$3:'バリ分け条件 Vari. split conditions'!$R$33, COLUMNS('バリ分け条件 Vari. split conditions'!$C$3:'バリ分け条件 Vari. split conditions'!G5), ROWS('バリ分け条件 Vari. split conditions'!$C$3:'バリ分け条件 Vari. split conditions'!G5))="", "", INDEX('バリ分け条件 Vari. split conditions'!$C$3:'バリ分け条件 Vari. split conditions'!$R$33, COLUMNS('バリ分け条件 Vari. split conditions'!$C$3:'バリ分け条件 Vari. split conditions'!G5), ROWS('バリ分け条件 Vari. split conditions'!$C$3:'バリ分け条件 Vari. split conditions'!G5)))} | Q10: {=IF(INDEX('バリ分け条件 Vari. split conditions'!$C$3:'バリ分け条件 Vari. split conditions'!$R$33, COLUMNS('バリ分け条件 Vari. split conditions'!$C$3:'バリ分け条件 Vari. split conditions'!H5), ROWS('バリ分け条件 Vari. split conditions'!$C$3:'バリ分け条件 Vari. split conditions'!H5))="", "", INDEX('バリ分け条件 Vari. split conditions'!$C$3:'バリ分け条件 Vari. split conditions'!$R$33, COLUMNS('バリ分け条件 Vari. split conditions'!$C$3:'バリ分け条件 Vari. split conditions'!H5), ROWS('バリ分け条件 Vari. split conditions'!$C$3:'バリ分け条件 Vari. split conditions'!H5)))} | R10: {=IF(INDEX('バリ分け条件 Vari. split conditions'!$C$3:'バリ分け条件 Vari. split conditions'!$R$33, COLUMNS('バリ分け条件 Vari. split conditions'!$C$3:'バリ分け条件 Vari. split conditions'!I5), ROWS('バリ分け条件 Vari. split conditions'!$C$3:'バリ分け条件 Vari. split conditions'!I5))="", "", INDEX('バリ分け条件 Vari. split conditions'!$C$3:'バリ分け条件 Vari. split conditions'!$R$33, COLUMNS('バリ分け条件 Vari. split conditions'!$C$3:'バリ分け条件 Vari. split conditions'!I5), ROWS('バリ分け条件 Vari. split conditions'!$C$3:'バリ分け条件 Vari. split conditions'!I5)))} | S10: {=IF(INDEX('バリ分け条件 Vari. split conditions'!$C$3:'バリ分け条件 Vari. split conditions'!$R$33, COLUMNS('バリ分け条件 Vari. split conditions'!$C$3:'バリ分け条件 Vari. split conditions'!J5), ROWS('バリ分け条件 Vari. split conditions'!$C$3:'バリ分け条件 Vari. split conditions'!J5))="", "", INDEX('バリ分け条件 Vari. split conditions'!$C$3:'バリ分け条件 Vari. split conditions'!$R$33, COLUMNS('バリ分け条件 Vari. split conditions'!$C$3:'バリ分け条件 Vari. split conditions'!J5), ROWS('バリ分け条件 Vari. split conditions'!$C$3:'バリ分け条件 Vari. split conditions'!J5)))} | ... AP10: {=IF(INDEX('バリ分け条件 Vari. split conditions'!$C$3:'バリ分け条件 Vari. split conditions'!$R$33, COLUMNS('バリ分け条件 Vari. split conditions'!$C$3:'バリ分け条件 Vari. split conditions'!AG5), ROWS('バリ分け条件 Vari. split conditions'!$C$3:'バリ分け条件 Vari. split conditions'!AG5))="", "", INDEX('バリ分け条件 Vari. split conditions'!$C$3:'バリ分け条件 Vari. split conditions'!$R$33, COLUMNS('バリ分け条件 Vari. split conditions'!$C$3:'バリ分け条件 Vari. split conditions'!AG5), ROWS('バリ分け条件 Vari. split conditions'!$C$3:'バリ分け条件 Vari. split conditions'!AG5)))}
A11: A10 | B11: 0.1 | E11: - | L11: {=IF(INDEX('バリ分け条件 Vari. split conditions'!$C$3:'バリ分け条件 Vari. split conditions'!$R$33, COLUMNS('バリ分け条件 Vari. split conditions'!$C$3:'バリ分け条件 Vari. split conditions'!C6), ROWS('バリ分け条件 Vari. split conditions'!$C$3:'バリ分け条件 Vari. split conditions'!C6))="", "", INDEX('バリ分け条件 Vari. split conditions'!$C$3:'バリ分け条件 Vari. split conditions'!$R$33, COLUMNS('バリ分け条件 Vari. split conditions'!$C$3:'バリ分け条件 Vari. split conditions'!C6), ROWS('バリ分け条件 Vari. split conditions'!$C$3:'バリ分け条件 Vari. split conditions'!C6)))} | M11: {=IF(INDEX('バリ分け条件 Vari. split conditions'!$C$3:'バリ分け条件 Vari. split conditions'!$R$33, COLUMNS('バリ分け条件 Vari. split conditions'!$C$3:'バリ分け条件 Vari. split conditions'!D6), ROWS('バリ分け条件 Vari. split conditions'!$C$3:'バリ分け条件 Vari. split conditions'!D6))="", "", INDEX('バリ分け条件 Vari. split conditions'!$C$3:'バリ分け条件 Vari. split conditions'!$R$33, COLUMNS('バリ分け条件 Vari. split conditions'!$C$3:'バリ分け条件 Vari. split conditions'!D6), ROWS('バリ分け条件 Vari. split conditions'!$C$3:'バリ分け条件 Vari. split conditions'!D6)))} | N11: {=IF(INDEX('バリ分け条件 Vari. split conditions'!$C$3:'バリ分け条件 Vari. split conditions'!$R$33, COLUMNS('バリ分け条件 Vari. split conditions'!$C$3:'バリ分け条件 Vari. split conditions'!E6), ROWS('バリ分け条件 Vari. split conditions'!$C$3:'バリ分け条件 Vari. split conditions'!E6))="", "", INDEX('バリ分け条件 Vari. split conditions'!$C$3:'バリ分け条件 Vari. split conditions'!$R$33, COLUMNS('バリ分け条件 Vari. split conditions'!$C$3:'バリ分け条件 Vari. split conditions'!E6), ROWS('バリ分け条件 Vari. split conditions'!$C$3:'バリ分け条件 Vari. split conditions'!E6)))} | O11: {=IF(INDEX('バリ分け条件 Vari. split conditions'!$C$3:'バリ分け条件 Vari. split conditions'!$R$33, COLUMNS('バリ分け条件 Vari. split conditions'!$C$3:'バリ分け条件 Vari. split conditions'!F6), ROWS('バリ分け条件 Vari. split conditions'!$C$3:'バリ分け条件 Vari. split conditions'!F6))="", "", INDEX('バリ分け条件 Vari. split conditions'!$C$3:'バリ分け条件 Vari. split conditions'!$R$33, COLUMNS('バリ分け条件 Vari. split conditions'!$C$3:'バリ分け条件 Vari. split conditions'!F6), ROWS('バリ分け条件 Vari. split conditions'!$C$3:'バリ分け条件 Vari. split conditions'!F6)))} | P11: {=IF(INDEX('バリ分け条件 Vari. split conditions'!$C$3:'バリ分け条件 Vari. split conditions'!$R$33, COLUMNS('バリ分け条件 Vari. split conditions'!$C$3:'バリ分け条件 Vari. split conditions'!G6), ROWS('バリ分け条件 Vari. split conditions'!$C$3:'バリ分け条件 Vari. split conditions'!G6))="", "", INDEX('バリ分け条件 Vari. split conditions'!$C$3:'バリ分け条件 Vari. split conditions'!$R$33, COLUMNS('バリ分け条件 Vari. split conditions'!$C$3:'バリ分け条件 Vari. split conditions'!G6), ROWS('バリ分け条件 Vari. split conditions'!$C$3:'バリ分け条件 Vari. split conditions'!G6)))} | Q11: {=IF(INDEX('バリ分け条件 Vari. split conditions'!$C$3:'バリ分け条件 Vari. split conditions'!$R$33, COLUMNS('バリ分け条件 Vari. split conditions'!$C$3:'バリ分け条件 Vari. split conditions'!H6), ROWS('バリ分け条件 Vari. split conditions'!$C$3:'バリ分け条件 Vari. split conditions'!H6))="", "", INDEX('バリ分け条件 Vari. split conditions'!$C$3:'バリ分け条件 Vari. split conditions'!$R$33, COLUMNS('バリ分け条件 Vari. split conditions'!$C$3:'バリ分け条件 Vari. split conditions'!H6), ROWS('バリ分け条件 Vari. split conditions'!$C$3:'バリ分け条件 Vari. split conditions'!H6)))} | R11: {=IF(INDEX('バリ分け条件 Vari. split conditions'!$C$3:'バリ分け条件 Vari. split conditions'!$R$33, COLUMNS('バリ分け条件 Vari. split conditions'!$C$3:'バリ分け条件 Vari. split conditions'!I6), ROWS('バリ分け条件 Vari. split conditions'!$C$3:'バリ分け条件 Vari. split conditions'!I6))="", "", INDEX('バリ分け条件 Vari. split conditions'!$C$3:'バリ分け条件 Vari. split conditions'!$R$33, COLUMNS('バリ分け条件 Vari. split conditions'!$C$3:'バリ分け条件 Vari. split conditions'!I6), ROWS('バリ分け条件 Vari. split conditions'!$C$3:'バリ分け条件 Vari. split conditions'!I6)))} | S11: {=IF(INDEX('バリ分け条件 Vari. split conditions'!$C$3:'バリ分け条件 Vari. split conditions'!$R$33, COLUMNS('バリ分け条件 Vari. split conditions'!$C$3:'バリ分け条件 Vari. split conditions'!J6), ROWS('バリ分け条件 Vari. split conditions'!$C$3:'バリ分け条件 Vari. split conditions'!J6))="", "", INDEX('バリ分け条件 Vari. split conditions'!$C$3:'バリ分け条件 Vari. split conditions'!$R$33, COLUMNS('バリ分け条件 Vari. split conditions'!$C$3:'バリ分け条件 Vari. split conditions'!J6), ROWS('バリ分け条件 Vari. split conditions'!$C$3:'バリ分け条件 Vari. split conditions'!J6)))} | ... AP11: {=IF(INDEX('バリ分け条件 Vari. split conditions'!$C$3:'バリ分け条件 Vari. split conditions'!$R$33, COLUMNS('バリ分け条件 Vari. split conditions'!$C$3:'バリ分け条件 Vari. split conditions'!AG6), ROWS('バリ分け条件 Vari. split conditions'!$C$3:'バリ分け条件 Vari. split conditions'!AG6))="", "", INDEX('バリ分け条件 Vari. split conditions'!$C$3:'バリ分け条件 Vari. split conditions'!$R$33, COLUMNS('バリ分け条件 Vari. split conditions'!$C$3:'バリ分け条件 Vari. split conditions'!AG6), ROWS('バリ分け条件 Vari. split conditions'!$C$3:'バリ分け条件 Vari. split conditions'!AG6)))}
A12: A11 | B12: 0.11 | E12: - | L12: {=IF(INDEX('バリ分け条件 Vari. split conditions'!$C$3:'バリ分け条件 Vari. split conditions'!$R$33, COLUMNS('バリ分け条件 Vari. split conditions'!$C$3:'バリ分け条件 Vari. split conditions'!C7), ROWS('バリ分け条件 Vari. split conditions'!$C$3:'バリ分け条件 Vari. split conditions'!C7))="", "", INDEX('バリ分け条件 Vari. split conditions'!$C$3:'バリ分け条件 Vari. split conditions'!$R$33, COLUMNS('バリ分け条件 Vari. split conditions'!$C$3:'バリ分け条件 Vari. split conditions'!C7), ROWS('バリ分け条件 Vari. split conditions'!$C$3:'バリ分け条件 Vari. split conditions'!C7)))} | M12: {=IF(INDEX('バリ分け条件 Vari. split conditions'!$C$3:'バリ分け条件 Vari. split conditions'!$R$33, COLUMNS('バリ分け条件 Vari. split conditions'!$C$3:'バリ分け条件 Vari. split conditions'!D7), ROWS('バリ分け条件 Vari. split conditions'!$C$3:'バリ分け条件 Vari. split conditions'!D7))="", "", INDEX('バリ分け条件 Vari. split conditions'!$C$3:'バリ分け条件 Vari. split conditions'!$R$33, COLUMNS('バリ分け条件 Vari. split conditions'!$C$3:'バリ分け条件 Vari. split conditions'!D7), ROWS('バリ分け条件 Vari. split conditions'!$C$3:'バリ分け条件 Vari. split conditions'!D7)))} | N12: {=IF(INDEX('バリ分け条件 Vari. split conditions'!$C$3:'バリ分け条件 Vari. split conditions'!$R$33, COLUMNS('バリ分け条件 Vari. split conditions'!$C$3:'バリ分け条件 Vari. split conditions'!E7), ROWS('バリ分け条件 Vari. split conditions'!$C$3:'バリ分け条件 Vari. split conditions'!E7))="", "", INDEX('バリ分け条件 Vari. split conditions'!$C$3:'バリ分け条件 Vari. split conditions'!$R$33, COLUMNS('バリ分け条件 Vari. split conditions'!$C$3:'バリ分け条件 Vari. split conditions'!E7), ROWS('バリ分け条件 Vari. split conditions'!$C$3:'バリ分け条件 Vari. split conditions'!E7)))} | O12: {=IF(INDEX('バリ分け条件 Vari. split conditions'!$C$3:'バリ分け条件 Vari. split conditions'!$R$33, COLUMNS('バリ分け条件 Vari. split conditions'!$C$3:'バリ分け条件 Vari. split conditions'!F7), ROWS('バリ分け条件 Vari. split conditions'!$C$3:'バリ分け条件 Vari. split conditions'!F7))="", "", INDEX('バリ分け条件 Vari. split conditions'!$C$3:'バリ分け条件 Vari. split conditions'!$R$33, COLUMNS('バリ分け条件 Vari. split conditions'!$C$3:'バリ分け条件 Vari. split conditions'!F7), ROWS('バリ分け条件 Vari. split conditions'!$C$3:'バリ分け条件 Vari. split conditions'!F7)))} | P12: {=IF(INDEX('バリ分け条件 Vari. split conditions'!$C$3:'バリ分け条件 Vari. split conditions'!$R$33, COLUMNS('バリ分け条件 Vari. split conditions'!$C$3:'バリ分け条件 Vari. split conditions'!G7), ROWS('バリ分け条件 Vari. split conditions'!$C$3:'バリ分け条件 Vari. split conditions'!G7))="", "", INDEX('バリ分け条件 Vari. split conditions'!$C$3:'バリ分け条件 Vari. split conditions'!$R$33, COLUMNS('バリ分け条件 Vari. split conditions'!$C$3:'バリ分け条件 Vari. split conditions'!G7), ROWS('バリ分け条件 Vari. split conditions'!$C$3:'バリ分け条件 Vari. split conditions'!G7)))} | Q12: {=IF(INDEX('バリ分け条件 Vari. split conditions'!$C$3:'バリ分け条件 Vari. split conditions'!$R$33, COLUMNS('バリ分け条件 Vari. split conditions'!$C$3:'バリ分け条件 Vari. split conditions'!H7), ROWS('バリ分け条件 Vari. split conditions'!$C$3:'バリ分け条件 Vari. split conditions'!H7))="", "", INDEX('バリ分け条件 Vari. split conditions'!$C$3:'バリ分け条件 Vari. split conditions'!$R$33, COLUMNS('バリ分け条件 Vari. split conditions'!$C$3:'バリ分け条件 Vari. split conditions'!H7), ROWS('バリ分け条件 Vari. split conditions'!$C$3:'バリ分け条件 Vari. split conditions'!H7)))} | R12: {=IF(INDEX('バリ分け条件 Vari. split conditions'!$C$3:'バリ分け条件 Vari. split conditions'!$R$33, COLUMNS('バリ分け条件 Vari. split conditions'!$C$3:'バリ分け条件 Vari. split conditions'!I7), ROWS('バリ分け条件 Vari. split conditions'!$C$3:'バリ分け条件 Vari. split conditions'!I7))="", "", INDEX('バリ分け条件 Vari. split conditions'!$C$3:'バリ分け条件 Vari. split conditions'!$R$33, COLUMNS('バリ分け条件 Vari. split conditions'!$C$3:'バリ分け条件 Vari. split conditions'!I7), ROWS('バリ分け条件 Vari. split conditions'!$C$3:'バリ分け条件 Vari. split conditions'!I7)))} | S12: {=IF(INDEX('バリ分け条件 Vari. split conditions'!$C$3:'バリ分け条件 Vari. split conditions'!$R$33, COLUMNS('バリ分け条件 Vari. split conditions'!$C$3:'バリ分け条件 Vari. split conditions'!J7), ROWS('バリ分け条件 Vari. split conditions'!$C$3:'バリ分け条件 Vari. split conditions'!J7))="", "", INDEX('バリ分け条件 Vari. split conditions'!$C$3:'バリ分け条件 Vari. split conditions'!$R$33, COLUMNS('バリ分け条件 Vari. split conditions'!$C$3:'バリ分け条件 Vari. split conditions'!J7), ROWS('バリ分け条件 Vari. split conditions'!$C$3:'バリ分け条件 Vari. split conditions'!J7)))} | ... AP12: {=IF(INDEX('バリ分け条件 Vari. split conditions'!$C$3:'バリ分け条件 Vari. split conditions'!$R$33, COLUMNS('バリ分け条件 Vari. split conditions'!$C$3:'バリ分け条件 Vari. split conditions'!AG7), ROWS('バリ分け条件 Vari. split conditions'!$C$3:'バリ分け条件 Vari. split conditions'!AG7))="", "", INDEX('バリ分け条件 Vari. split conditions'!$C$3:'バリ分け条件 Vari. split conditions'!$R$33, COLUMNS('バリ分け条件 Vari. split conditions'!$C$3:'バリ分け条件 Vari. split conditions'!AG7), ROWS('バリ分け条件 Vari. split conditions'!$C$3:'バリ分け条件 Vari. split conditions'!AG7)))}
A13: A12 | B13: 0.12 | E13: - | L13: {=IF(INDEX('バリ分け条件 Vari. split conditions'!$C$3:'バリ分け条件 Vari. split conditions'!$R$33, COLUMNS('バリ分け条件 Vari. split conditions'!$C$3:'バリ分け条件 Vari. split conditions'!C8), ROWS('バリ分け条件 Vari. split conditions'!$C$3:'バリ分け条件 Vari. split conditions'!C8))="", "", INDEX('バリ分け条件 Vari. split conditions'!$C$3:'バリ分け条件 Vari. split conditions'!$R$33, COLUMNS('バリ分け条件 Vari. split conditions'!$C$3:'バリ分け条件 Vari. split conditions'!C8), ROWS('バリ分け条件 Vari. split conditions'!$C$3:'バリ分け条件 Vari. split conditions'!C8)))} | M13: {=IF(INDEX('バリ分け条件 Vari. split conditions'!$C$3:'バリ分け条件 Vari. split conditions'!$R$33, COLUMNS('バリ分け条件 Vari. split conditions'!$C$3:'バリ分け条件 Vari. split conditions'!D8), ROWS('バリ分け条件 Vari. split conditions'!$C$3:'バリ分け条件 Vari. split conditions'!D8))="", "", INDEX('バリ分け条件 Vari. split conditions'!$C$3:'バリ分け条件 Vari. split conditions'!$R$33, COLUMNS('バリ分け条件 Vari. split conditions'!$C$3:'バリ分け条件 Vari. split conditions'!D8), ROWS('バリ分け条件 Vari. split conditions'!$C$3:'バリ分け条件 Vari. split conditions'!D8)))} | N13: {=IF(INDEX('バリ分け条件 Vari. split conditions'!$C$3:'バリ分け条件 Vari. split conditions'!$R$33, COLUMNS('バリ分け条件 Vari. split conditions'!$C$3:'バリ分け条件 Vari. split conditions'!E8), ROWS('バリ分け条件 Vari. split conditions'!$C$3:'バリ分け条件 Vari. split conditions'!E8))="", "", INDEX('バリ分け条件 Vari. split conditions'!$C$3:'バリ分け条件 Vari. split conditions'!$R$33, COLUMNS('バリ分け条件 Vari. split conditions'!$C$3:'バリ分け条件 Vari. split conditions'!E8), ROWS('バリ分け条件 Vari. split conditions'!$C$3:'バリ分け条件 Vari. split conditions'!E8)))} | O13: {=IF(INDEX('バリ分け条件 Vari. split conditions'!$C$3:'バリ分け条件 Vari. split conditions'!$R$33, COLUMNS('バリ分け条件 Vari. split conditions'!$C$3:'バリ分け条件 Vari. split conditions'!F8), ROWS('バリ分け条件 Vari. split conditions'!$C$3:'バリ分け条件 Vari. split conditions'!F8))="", "", INDEX('バリ分け条件 Vari. split conditions'!$C$3:'バリ分け条件 Vari. split conditions'!$R$33, COLUMNS('バリ分け条件 Vari. split conditions'!$C$3:'バリ分け条件 Vari. split conditions'!F8), ROWS('バリ分け条件 Vari. split conditions'!$C$3:'バリ分け条件 Vari. split conditions'!F8)))} | P13: {=IF(INDEX('バリ分け条件 Vari. split conditions'!$C$3:'バリ分け条件 Vari. split conditions'!$R$33, COLUMNS('バリ分け条件 Vari. split conditions'!$C$3:'バリ分け条件 Vari. split conditions'!G8), ROWS('バリ分け条件 Vari. split conditions'!$C$3:'バリ分け条件 Vari. split conditions'!G8))="", "", INDEX('バリ分け条件 Vari. split conditions'!$C$3:'バリ分け条件 Vari. split conditions'!$R$33, COLUMNS('バリ分け条件 Vari. split conditions'!$C$3:'バリ分け条件 Vari. split conditions'!G8), ROWS('バリ分け条件 Vari. split conditions'!$C$3:'バリ分け条件 Vari. split conditions'!G8)))} | Q13: {=IF(INDEX('バリ分け条件 Vari. split conditions'!$C$3:'バリ分け条件 Vari. split conditions'!$R$33, COLUMNS('バリ分け条件 Vari. split conditions'!$C$3:'バリ分け条件 Vari. split conditions'!H8), ROWS('バリ分け条件 Vari. split conditions'!$C$3:'バリ分け条件 Vari. split conditions'!H8))="", "", INDEX('バリ分け条件 Vari. split conditions'!$C$3:'バリ分け条件 Vari. split conditions'!$R$33, COLUMNS('バリ分け条件 Vari. split conditions'!$C$3:'バリ分け条件 Vari. split conditions'!H8), ROWS('バリ分け条件 Vari. split conditions'!$C$3:'バリ分け条件 Vari. split conditions'!H8)))} | R13: {=IF(INDEX('バリ分け条件 Vari. split conditions'!$C$3:'バリ分け条件 Vari. split conditions'!$R$33, COLUMNS('バリ分け条件 Vari. split conditions'!$C$3:'バリ分け条件 Vari. split conditions'!I8), ROWS('バリ分け条件 Vari. split conditions'!$C$3:'バリ分け条件 Vari. split conditions'!I8))="", "", INDEX('バリ分け条件 Vari. split conditions'!$C$3:'バリ分け条件 Vari. split conditions'!$R$33, COLUMNS('バリ分け条件 Vari. split conditions'!$C$3:'バリ分け条件 Vari. split conditions'!I8), ROWS('バリ分け条件 Vari. split conditions'!$C$3:'バリ分け条件 Vari. split conditions'!I8)))} | S13: {=IF(INDEX('バリ分け条件 Vari. split conditions'!$C$3:'バリ分け条件 Vari. split conditions'!$R$33, COLUMNS('バリ分け条件 Vari. split conditions'!$C$3:'バリ分け条件 Vari. split conditions'!J8), ROWS('バリ分け条件 Vari. split conditions'!$C$3:'バリ分け条件 Vari. split conditions'!J8))="", "", INDEX('バリ分け条件 Vari. split conditions'!$C$3:'バリ分け条件 Vari. split conditions'!$R$33, COLUMNS('バリ分け条件 Vari. split conditions'!$C$3:'バリ分け条件 Vari. split conditions'!J8), ROWS('バリ分け条件 Vari. split conditions'!$C$3:'バリ分け条件 Vari. split conditions'!J8)))} | ... AP13: {=IF(INDEX('バリ分け条件 Vari. split conditions'!$C$3:'バリ分け条件 Vari. split conditions'!$R$33, COLUMNS('バリ分け条件 Vari. split conditions'!$C$3:'バリ分け条件 Vari. split conditions'!AG8), ROWS('バリ分け条件 Vari. split conditions'!$C$3:'バリ分け条件 Vari. split conditions'!AG8))="", "", INDEX('バリ分け条件 Vari. split conditions'!$C$3:'バリ分け条件 Vari. split conditions'!$R$33, COLUMNS('バリ分け条件 Vari. split conditions'!$C$3:'バリ分け条件 Vari. split conditions'!AG8), ROWS('バリ分け条件 Vari. split conditions'!$C$3:'バリ分け条件 Vari. split conditions'!AG8)))}
