Workbook
Name A: #REF!
Name B: #REF!
Name d: #REF!
Name K: #REF!
Name LED: #REF!
Name ｓ: #REF!
Name Sheet_dspmaincfg_Top: #REF!
Name Sheet_ユーザーカスタマイズ手順_Top: #REF!
Name Sheet_基礎知識_dispdomain: #REF!
Name Sheet_基礎知識_dispdomain_Diagram: #REF!
Name Sheet_基礎知識_dspmgr: #REF!
Name Sheet_基礎知識_dspmgr_Contents: #REF!
Name Sheet_基礎知識_dspmgr_STM: #REF!
Name Sheet_基礎知識_dspmgr_Struct: #REF!
Name Sheet_基礎知識_dspmgr_SwCancel: #REF!
Name Sheet_基礎知識_mainscrl: #REF!
Name Sheet_基礎知識_mainscrl_Contents: #REF!
Name Sheet_基礎知識_mainscrl_MainSub: #REF!
Name Sheet_基礎知識_mainscrl_Struct: #REF!
Name Sheet_基礎知識_swdtctr: #REF!
Name Sheet_基礎知識_Top: #REF!
Name xlo1: #REF!
Name xlo2: #REF!
Name xlo3: #REF!
Name xlo4: #REF!
Name xup1: #REF!
Name xup2: #REF!
Name xup3: #REF!
Name xup4: #REF!
Name ylo1: #REF!
Name ylo2: #REF!
Name ylo3: #REF!
Name ylo4: #REF!
Name yup1: #REF!
Name yup2: #REF!
Name yup3: #REF!
Name yup4: #REF!
Name テスト: #REF!
Name 関数名_確定_BON: '[4]Config - dspmgr'!#REF!
Name 関数名_確定_IGOFF: '[4]Config - dspmgr'!#REF!
Name 関数名_確定_IGON: '[4]Config - dspmgr'!#REF!
Name 関数名_確定_WKUP: '[4]Config - dspmgr'!#REF!
Name 関数名_確定_状態遷移_0: '[4]Config - dspmgr'!#REF!
Name 関数名_確定_状態遷移_1: '[4]Config - dspmgr'!#REF!
Name 関数名_確定_状態遷移_2: '[4]Config - dspmgr'!#REF!
Name 関数名_確定_状態遷移_3: '[4]Config - dspmgr'!#REF!
Name 関数名_確定_状態遷移_4: '[4]Config - dspmgr'!#REF!
Name 関数名_確定_定期: '[4]Config - dspmgr'!#REF!
Name 駆動回路: #REF!
Name 品番: #REF!

Sheet 表紙（承認欄）
T13: =MID(CELL("filename",A1),FIND("[",CELL("filename",A1))+1,FIND("]",CELL("filename",A1))-FIND("[",CELL("filename",A1))-1) -> alert_S_TMBZR-CSTD-0-01-A-C0.xlsx
Y34: (株)デンソー
Y35: 承認 | AD35: 検討 | AI35: 作成
AA38: <DN確認印> | AF38: <DN検討印> | AK38: <OS作成印>
Y42: デンソーテクノ(株)
Y43: 承認 | AD43: 検討 | AI43: 作成
AA46: <DT確認印> | AF46: <DT検討印> | AK46: <DT作成印>
Y50: DENSO TECHNO PHIL., INC.
Y51: 承認 | AD51: 検討 | AI51: 作成
AA54: <OS確認印> | AF54: <OS検討印> | AK54: <OS作成印>

Sheet 表紙
H2: コンポーネント | I2: Vom::Alert
D3: =REPLACE(LEFT(CELL("filename",$B$1),FIND(".xls",CELL("filename",$B$1))-1),1,FIND("[",CELL("filename",$B$1)),) -> alert_S_TMBZR-CSTD-0-01-A-C0 | H3: Gitリポジトリ | I3: https://aip01.dndev.net/bitbucket/scm/aip_tp/tmcapp_ict1_alert.git
E4: =DGET(B8:C14,"Ver.",H4:H5) -> 1.0.0 | H4: ROW
H5: =MAX(B9:B14) -> 1
C7: 更新履歴 | E7: 対象ソフトVer | G7: 承認欄 [DENSO] | M7: 承認欄 [NTTデータMSE] | S7: 承認欄 [DT]
B8: ROW | C8: Ver. | D8: 更新内容 | E8: Git(CommitID) | F8: Component Version | G8: 承認者 | H8: 承認日 | I8: 検討者 | J8: 検討日 | K8: 作成者 | L8: 作成日 | M8: 承認者 | N8: 承認日 | O8: 検討者 | P8: 検討日 | Q8: 作成者 | R8: 作成日 | S8: 承認者 | T8: 承認日 | U8: 検討者 | V8: 検討日 | W8: 作成者 | X8: 作成日
B9: =IF(C9=0,0,ROW()-ROW($B$8)) -> 1 | C9: 1.0.0 | D9: 新規作成 | E9: - | F9: 5.0.0 | W9: DTPH Harry | X9: 45979
B10: =IF(C10=0,0,ROW()-ROW($B$8)) -> 0
B11: =IF(C11=0,0,ROW()-ROW($B$8)) -> 0
B12: =IF(C12=0,0,ROW()-ROW($B$8)) -> 0
B13: =IF(C13=0,0,ROW()-ROW($B$8)) -> 0

Sheet はじめに
B2: １．本書の目的
C3: TMC Specを分析した結果で、Vom::Alertの実装に必要となる情報を抽出し、Alert Config Toolのインプットとする。
B6: ２．上位文書
C7: # | E7: path
C8: 0 | D8: Alert設計資料 | E8: https://aip01.dndev.net/svn/aip/tmcapp/sd/evidence/trunk/02_Design/01_Vom/Alert/03_Component/alert_design.pptx
B12: ３．用語の説明
C13: # | D13: 用語 | E13: 説明
C14: 0 | D14: Alert Config Tool | E14: TMC Specと本設計書のトレースをデータベース管理するTool。
C15: 1 | D15: TT | E15: Telltale
C16: 2 | D16: PD | E16: Pop-up Display
C17: 3 | D17: BC | E17: Buzzer/Chime
C18: 4 | D18: RW | E18: Remote Warning
C19: 5 | D19: CH | E19: Alert Channel。 各Specを分析した結果で決定されるモジュール内分割単位。
C20: 6 | D20: VOM | E20: Vehicle Operation Mode
B24: ４．各シートの説明
C25: # | D25: 用語 | E25: 説明
C26: 0 | D26: Matrix | E26: 対象となるTMC Specならびに分析した結果で決定されるAlert Channel情報について記載する。 Alert Config Toolのインプットとする。
C27: 1 | D27: CH_Design | E27: 対象のTMC Specにおいて、Vom::Alertが外部に提供する各CHの出力(REQ)について記載する。 機能判定欄については、出力先によって実施責務が異なるため、出力先毎に有無を記載する。 TT機能判定、BC機能判定、PD機能判定 ： VSV側にて参照 RW機能判定 ： Vom::Alertにて参照 TMC Specにて定義される機能有無判定の要否について抽出した結果で記載する。 ※機種(e.x.775B)毎の要否ではないため、対象機種に応じた更新(メンテナンス)は行わない。 PD欄については、Alert制御仕様書にて定義されるWarning Noを記載する。 Alert Config Toolのインプットとする。
C28: 2 | D28: Config_IF | E28: 対象のTMC Specにおいて、 Vom::Alertが使用する外部ドメインIF Vom::Alertが使用するConfig IF、定義 について記載する。 Alert Config Toolのインプットとする。
C29: 3 | D29: TT/BC | E29: シート名は各CH名を採用する。 対象のTMC Specを分析した結果で、各CHのインプット/アウトプットの判定条件について記載する。 コーディング時のインプットとする。
C30: 4 | D30: Reference | E30: 対象のTMC Specを分析した際の中間成果物。参考情報として記載。メンテナンス対象外。
C31: 5 | D31: History | E31: テンプレート変更履歴
B37: ５．入力セルの凡例
E38: ユーザ入力セル
E39: 自動計算セル

Sheet Matrix
B2: 対象仕様書 | D2: MET-S_TMBZR-CSTD-0-01-A-C0.xlsx
B3: ロケーション | D3: https://svn.geniie.net/bevs3/bevs3cdc/ 仕様書/MET/#1/tags/00.Product/v1.19/制御仕様/MET-S_TMBZR-CSTD-0-01-A-C0
B4: モジュール名 | D4: =表紙!D3&".c" -> alert_S_TMBZR-CSTD-0-01-A-C0.c
D5: =IF(LEN(表紙!D3&".c") = LENB(表紙!D3&".c"),"※モジュール名 全角チェックOK","※モジュール名 全角チェックNG：ファイル名に全角文字が使用されています！") -> ※モジュール名 全角チェックOK
B6: 機能名 | D6: =MID(D4, LEN("alert_") + 1, FIND("-",D4,1) - LEN("alert_") - 1) -> S_TMBZR
B7: 判定要素数 | D7: =COUNTA($D$13:$D$37) -> 2
B8: Matrix名 | D8: ="st_gp_ALERT_"&UPPER(D6)&"_MTRX" -> st_gp_ALERT_S_TMBZR_MTRX
B9: 初期化関数名 | D9: NULL
B10: 処理時間 | D10: -
B12: No | C12: CH Name | D12: VOM | E12: RW | F12: Srcchk | G12: RwTx | H12: CH | I12: REQ | K12: VOM | L12: 初期化関数名 | M12: CH名称中間データ
B13: 1 | C13: BC_AD | D13: ALERT_VOM_IGN_ON | E13: － | F13: =IF($D13<>"","u4_s_Alert"&UPPER(LEFT($D$6,1))&LOWER(MID($D$6,2,100))&IF($D$7=1,"",N13)&"Srcchk","") -> u4_s_AlertS_tmbzrBcAdSrcchk | G13: =IF($D13<>"",IF($E13="○","vd_s_Alert"&UPPER(LEFT($D$6,1))&LOWER(MID($D$6,2,100))&IF($D$7=1,"",N13)&"RwTx","NULL"),"") -> NULL | H13: =IF($D13<>"","ALERT_CH_"&UPPER($D$6)&IF($D$7=1,"","_"&UPPER($C13)),"") -> ALERT_CH_S_TMBZR_BC_AD | I13: =IF($D13<>"","ALERT_REQ_"&UPPER($D$6)&IF($D$7=1,"","_"&UPPER($C13)),"") -> ALERT_REQ_S_TMBZR_BC_AD | K13: ALERT_VOM_BAT_AO | L13: NULL | M13: =FIND("_",C13,1) -> 3 | N13: =IF(IFERROR(M13,0),UPPER(LEFT(C13,1))&LOWER(MID(C13,2,M13-2))&UPPER(MID(C13,M13+1,1))&LOWER(MID(C13,M13+2,100)),UPPER(LEFT(C13,1))&LOWER(MID(C13,2,100))) -> BcAd
B14: 2 | C14: BC_DOT | D14: ALERT_VOM_IGN_ON | E14: － | F14: =IF($D14<>"","u4_s_Alert"&UPPER(LEFT($D$6,1))&LOWER(MID($D$6,2,100))&IF($D$7=1,"",N14)&"Srcchk","") -> u4_s_AlertS_tmbzrBcDotSrcchk | G14: =IF($D14<>"",IF($E14="○","vd_s_Alert"&UPPER(LEFT($D$6,1))&LOWER(MID($D$6,2,100))&IF($D$7=1,"",N14)&"RwTx","NULL"),"") -> NULL | H14: =IF($D14<>"","ALERT_CH_"&UPPER($D$6)&IF($D$7=1,"","_"&UPPER($C14)),"") -> ALERT_CH_S_TMBZR_BC_DOT | I14: =IF($D14<>"","ALERT_REQ_"&UPPER($D$6)&IF($D$7=1,"","_"&UPPER($C14)),"") -> ALERT_REQ_S_TMBZR_BC_DOT | K14: ALERT_VOM_BAT_WT | L14: ="vd_g_Alert"&UPPER(LEFT(D6,1))&LOWER(MID(D6,2,100))&"Init" -> vd_g_AlertS_tmbzrInit | M14: =FIND("_",C14,1) -> 3 | N14: =IF(IFERROR(M14,0),UPPER(LEFT(C14,1))&LOWER(MID(C14,2,M14-2))&UPPER(MID(C14,M14+1,1))&LOWER(MID(C14,M14+2,100)),UPPER(LEFT(C14,1))&LOWER(MID(C14,2,100))) -> BcDot
B15: 3 | F15: =IF($D15<>"","u4_s_Alert"&UPPER(LEFT($D$6,1))&LOWER(MID($D$6,2,100))&IF($D$7=1,"",N15)&"Srcchk","") | G15: =IF($D15<>"",IF($E15="○","vd_s_Alert"&UPPER(LEFT($D$6,1))&LOWER(MID($D$6,2,100))&IF($D$7=1,"",N15)&"RwTx","NULL"),"") | H15: =IF($D15<>"","ALERT_CH_"&UPPER($D$6)&IF($D$7=1,"","_"&UPPER($C15)),"") | I15: =IF($D15<>"","ALERT_REQ_"&UPPER($D$6)&IF($D$7=1,"","_"&UPPER($C15)),"") | K15: ALERT_VOM_IGN_OFF | M15: =FIND("_",C15,1) -> #VALUE! | N15: =IF(IFERROR(M15,0),UPPER(LEFT(C15,1))&LOWER(MID(C15,2,M15-2))&UPPER(MID(C15,M15+1,1))&LOWER(MID(C15,M15+2,100)),UPPER(LEFT(C15,1))&LOWER(MID(C15,2,100)))
B16: 4 | F16: =IF($D16<>"","u4_s_Alert"&UPPER(LEFT($D$6,1))&LOWER(MID($D$6,2,100))&IF($D$7=1,"",N16)&"Srcchk","") | G16: =IF($D16<>"",IF($E16="○","vd_s_Alert"&UPPER(LEFT($D$6,1))&LOWER(MID($D$6,2,100))&IF($D$7=1,"",N16)&"RwTx","NULL"),"") | H16: =IF($D16<>"","ALERT_CH_"&UPPER($D$6)&IF($D$7=1,"","_"&UPPER($C16)),"") | I16: =IF($D16<>"","ALERT_REQ_"&UPPER($D$6)&IF($D$7=1,"","_"&UPPER($C16)),"") | K16: ALERT_VOM_IGN_OFF_WT | M16: =FIND("_",C16,1) -> #VALUE! | N16: =IF(IFERROR(M16,0),UPPER(LEFT(C16,1))&LOWER(MID(C16,2,M16-2))&UPPER(MID(C16,M16+1,1))&LOWER(MID(C16,M16+2,100)),UPPER(LEFT(C16,1))&LOWER(MID(C16,2,100)))
B17: 5 | F17: =IF($D17<>"","u4_s_Alert"&UPPER(LEFT($D$6,1))&LOWER(MID($D$6,2,100))&IF($D$7=1,"",N17)&"Srcchk","") | G17: =IF($D17<>"",IF($E17="○","vd_s_Alert"&UPPER(LEFT($D$6,1))&LOWER(MID($D$6,2,100))&IF($D$7=1,"",N17)&"RwTx","NULL"),"") | H17: =IF($D17<>"","ALERT_CH_"&UPPER($D$6)&IF($D$7=1,"","_"&UPPER($C17)),"") | I17: =IF($D17<>"","ALERT_REQ_"&UPPER($D$6)&IF($D$7=1,"","_"&UPPER($C17)),"") | K17: ALERT_VOM_IGN_ON | M17: =FIND("_",C17,1) -> #VALUE! | N17: =IF(IFERROR(M17,0),UPPER(LEFT(C17,1))&LOWER(MID(C17,2,M17-2))&UPPER(MID(C17,M17+1,1))&LOWER(MID(C17,M17+2,100)),UPPER(LEFT(C17,1))&LOWER(MID(C17,2,100)))
B18: 6 | F18: =IF($D18<>"","u4_s_Alert"&UPPER(LEFT($D$6,1))&LOWER(MID($D$6,2,100))&IF($D$7=1,"",N18)&"Srcchk","") | G18: =IF($D18<>"",IF($E18="○","vd_s_Alert"&UPPER(LEFT($D$6,1))&LOWER(MID($D$6,2,100))&IF($D$7=1,"",N18)&"RwTx","NULL"),"") | H18: =IF($D18<>"","ALERT_CH_"&UPPER($D$6)&IF($D$7=1,"","_"&UPPER($C18)),"") | I18: =IF($D18<>"","ALERT_REQ_"&UPPER($D$6)&IF($D$7=1,"","_"&UPPER($C18)),"") | K18: ALERT_VOM_VCS_ON | M18: =FIND("_",C18,1) -> #VALUE! | N18: =IF(IFERROR(M18,0),UPPER(LEFT(C18,1))&LOWER(MID(C18,2,M18-2))&UPPER(MID(C18,M18+1,1))&LOWER(MID(C18,M18+2,100)),UPPER(LEFT(C18,1))&LOWER(MID(C18,2,100)))
B19: 7 | F19: =IF($D19<>"","u4_s_Alert"&UPPER(LEFT($D$6,1))&LOWER(MID($D$6,2,100))&IF($D$7=1,"",N19)&"Srcchk","") | G19: =IF($D19<>"",IF($E19="○","vd_s_Alert"&UPPER(LEFT($D$6,1))&LOWER(MID($D$6,2,100))&IF($D$7=1,"",N19)&"RwTx","NULL"),"") | H19: =IF($D19<>"","ALERT_CH_"&UPPER($D$6)&IF($D$7=1,"","_"&UPPER($C19)),"") | I19: =IF($D19<>"","ALERT_REQ_"&UPPER($D$6)&IF($D$7=1,"","_"&UPPER($C19)),"") | K19: ALERT_VOM_VCS_ON | M19: =FIND("_",C19,1) -> #VALUE! | N19: =IF(IFERROR(M19,0),UPPER(LEFT(C19,1))&LOWER(MID(C19,2,M19-2))&UPPER(MID(C19,M19+1,1))&LOWER(MID(C19,M19+2,100)),UPPER(LEFT(C19,1))&LOWER(MID(C19,2,100)))
B20: 8 | F20: =IF($D20<>"","u4_s_Alert"&UPPER(LEFT($D$6,1))&LOWER(MID($D$6,2,100))&IF($D$7=1,"",N20)&"Srcchk","") | G20: =IF($D20<>"",IF($E20="○","vd_s_Alert"&UPPER(LEFT($D$6,1))&LOWER(MID($D$6,2,100))&IF($D$7=1,"",N20)&"RwTx","NULL"),"") | H20: =IF($D20<>"","ALERT_CH_"&UPPER($D$6)&IF($D$7=1,"","_"&UPPER($C20)),"") | I20: =IF($D20<>"","ALERT_REQ_"&UPPER($D$6)&IF($D$7=1,"","_"&UPPER($C20)),"") | K20: ALERT_VOM_VCS_ON | M20: =FIND("_",C20,1) -> #VALUE! | N20: =IF(IFERROR(M20,0),UPPER(LEFT(C20,1))&LOWER(MID(C20,2,M20-2))&UPPER(MID(C20,M20+1,1))&LOWER(MID(C20,M20+2,100)),UPPER(LEFT(C20,1))&LOWER(MID(C20,2,100)))
B21: 9 | F21: =IF($D21<>"","u4_s_Alert"&UPPER(LEFT($D$6,1))&LOWER(MID($D$6,2,100))&IF($D$7=1,"",N21)&"Srcchk","") | G21: =IF($D21<>"",IF($E21="○","vd_s_Alert"&UPPER(LEFT($D$6,1))&LOWER(MID($D$6,2,100))&IF($D$7=1,"",N21)&"RwTx","NULL"),"") | H21: =IF($D21<>"","ALERT_CH_"&UPPER($D$6)&IF($D$7=1,"","_"&UPPER($C21)),"") | I21: =IF($D21<>"","ALERT_REQ_"&UPPER($D$6)&IF($D$7=1,"","_"&UPPER($C21)),"") | K21: ALERT_VOM_VCS_ON | M21: =FIND("_",C21,1) -> #VALUE! | N21: =IF(IFERROR(M21,0),UPPER(LEFT(C21,1))&LOWER(MID(C21,2,M21-2))&UPPER(MID(C21,M21+1,1))&LOWER(MID(C21,M21+2,100)),UPPER(LEFT(C21,1))&LOWER(MID(C21,2,100)))
B22: 10 | F22: =IF($D22<>"","u4_s_Alert"&UPPER(LEFT($D$6,1))&LOWER(MID($D$6,2,100))&IF($D$7=1,"",N22)&"Srcchk","") | G22: =IF($D22<>"",IF($E22="○","vd_s_Alert"&UPPER(LEFT($D$6,1))&LOWER(MID($D$6,2,100))&IF($D$7=1,"",N22)&"RwTx","NULL"),"") | H22: =IF($D22<>"","ALERT_CH_"&UPPER($D$6)&IF($D$7=1,"","_"&UPPER($C22)),"") | I22: =IF($D22<>"","ALERT_REQ_"&UPPER($D$6)&IF($D$7=1,"","_"&UPPER($C22)),"") | K22: ALERT_VOM_VCS_ON | M22: =FIND("_",C22,1) -> #VALUE! | N22: =IF(IFERROR(M22,0),UPPER(LEFT(C22,1))&LOWER(MID(C22,2,M22-2))&UPPER(MID(C22,M22+1,1))&LOWER(MID(C22,M22+2,100)),UPPER(LEFT(C22,1))&LOWER(MID(C22,2,100)))
B23: 11 | F23: =IF($D23<>"","u4_s_Alert"&UPPER(LEFT($D$6,1))&LOWER(MID($D$6,2,100))&IF($D$7=1,"",N23)&"Srcchk","") | G23: =IF($D23<>"",IF($E23="○","vd_s_Alert"&UPPER(LEFT($D$6,1))&LOWER(MID($D$6,2,100))&IF($D$7=1,"",N23)&"RwTx","NULL"),"") | H23: =IF($D23<>"","ALERT_CH_"&UPPER($D$6)&IF($D$7=1,"","_"&UPPER($C23)),"") | I23: =IF($D23<>"","ALERT_REQ_"&UPPER($D$6)&IF($D$7=1,"","_"&UPPER($C23)),"") | K23: ALERT_VOM_VCS_ON | M23: =FIND("_",C23,1) -> #VALUE! | N23: =IF(IFERROR(M23,0),UPPER(LEFT(C23,1))&LOWER(MID(C23,2,M23-2))&UPPER(MID(C23,M23+1,1))&LOWER(MID(C23,M23+2,100)),UPPER(LEFT(C23,1))&LOWER(MID(C23,2,100)))
B24: 12 | F24: =IF($D24<>"","u4_s_Alert"&UPPER(LEFT($D$6,1))&LOWER(MID($D$6,2,100))&IF($D$7=1,"",N24)&"Srcchk","") | G24: =IF($D24<>"",IF($E24="○","vd_s_Alert"&UPPER(LEFT($D$6,1))&LOWER(MID($D$6,2,100))&IF($D$7=1,"",N24)&"RwTx","NULL"),"") | H24: =IF($D24<>"","ALERT_CH_"&UPPER($D$6)&IF($D$7=1,"","_"&UPPER($C24)),"") | I24: =IF($D24<>"","ALERT_REQ_"&UPPER($D$6)&IF($D$7=1,"","_"&UPPER($C24)),"") | K24: ALERT_VOM_VCS_ON | M24: =FIND("_",C24,1) -> #VALUE! | N24: =IF(IFERROR(M24,0),UPPER(LEFT(C24,1))&LOWER(MID(C24,2,M24-2))&UPPER(MID(C24,M24+1,1))&LOWER(MID(C24,M24+2,100)),UPPER(LEFT(C24,1))&LOWER(MID(C24,2,100)))
B25: 13 | F25: =IF($D25<>"","u4_s_Alert"&UPPER(LEFT($D$6,1))&LOWER(MID($D$6,2,100))&IF($D$7=1,"",N25)&"Srcchk","") | G25: =IF($D25<>"",IF($E25="○","vd_s_Alert"&UPPER(LEFT($D$6,1))&LOWER(MID($D$6,2,100))&IF($D$7=1,"",N25)&"RwTx","NULL"),"") | H25: =IF($D25<>"","ALERT_CH_"&UPPER($D$6)&IF($D$7=1,"","_"&UPPER($C25)),"") | I25: =IF($D25<>"","ALERT_REQ_"&UPPER($D$6)&IF($D$7=1,"","_"&UPPER($C25)),"") | K25: ALERT_VOM_VCS_ON | M25: =FIND("_",C25,1) -> #VALUE! | N25: =IF(IFERROR(M25,0),UPPER(LEFT(C25,1))&LOWER(MID(C25,2,M25-2))&UPPER(MID(C25,M25+1,1))&LOWER(MID(C25,M25+2,100)),UPPER(LEFT(C25,1))&LOWER(MID(C25,2,100)))
B26: 14 | F26: =IF($D26<>"","u4_s_Alert"&UPPER(LEFT($D$6,1))&LOWER(MID($D$6,2,100))&IF($D$7=1,"",N26)&"Srcchk","") | G26: =IF($D26<>"",IF($E26="○","vd_s_Alert"&UPPER(LEFT($D$6,1))&LOWER(MID($D$6,2,100))&IF($D$7=1,"",N26)&"RwTx","NULL"),"") | H26: =IF($D26<>"","ALERT_CH_"&UPPER($D$6)&IF($D$7=1,"","_"&UPPER($C26)),"") | I26: =IF($D26<>"","ALERT_REQ_"&UPPER($D$6)&IF($D$7=1,"","_"&UPPER($C26)),"") | K26: ALERT_VOM_VCS_ON | M26: =FIND("_",C26,1) -> #VALUE! | N26: =IF(IFERROR(M26,0),UPPER(LEFT(C26,1))&LOWER(MID(C26,2,M26-2))&UPPER(MID(C26,M26+1,1))&LOWER(MID(C26,M26+2,100)),UPPER(LEFT(C26,1))&LOWER(MID(C26,2,100)))
... B37: 25 | F37: =IF($D37<>"","u4_s_Alert"&UPPER(LEFT($D$6,1))&LOWER(MID($D$6,2,100))&IF($D$7=1,"",N37)&"Srcchk","") | G37: =IF($D37<>"",IF($E37="○","vd_s_Alert"&UPPER(LEFT($D$6,1))&LOWER(MID($D$6,2,100))&IF($D$7=1,"",N37)&"RwTx","NULL"),"") | H37: =IF($D37<>"","ALERT_CH_"&UPPER($D$6)&IF($D$7=1,"","_"&UPPER($C37)),"") | I37: =IF($D37<>"","ALERT_REQ_"&UPPER($D$6)&IF($D$7=1,"","_"&UPPER($C37)),"") | K37: ALERT_VOM_VCS_ON | M37: =FIND("_",C37,1) -> #VALUE! | N37: =IF(IFERROR(M37,0),UPPER(LEFT(C37,1))&LOWER(MID(C37,2,M37-2))&UPPER(MID(C37,M37+1,1))&LOWER(MID(C37,M37+2,100)),UPPER(LEFT(C37,1))&LOWER(MID(C37,2,100)))

Sheet Config_IF
B2: Other Domain Define | O2: Alert Config IF List
B3: No | C3: define Name | D3: class | E3: define | F3: comment | G3: 文字数 | O3: No | P3: Return | Q3: Config Function Name | R3: comment
B4: 0 | C4: なし | O4: 0 | P4: なし | Q4: なし
B5: 1 | E5: =IF($C5<>"","ALERT_" & D5 & "_ID_"&UPPER(Matrix!$D$6) & "_" & $C5,"") | G5: =IF(E5<>"",LEN(E5),"") | O5: 1
B6: 2 | E6: =IF($C6<>"","ALERT_" & D6 & "_ID_"&UPPER(Matrix!$D$6) & "_" & $C6,"") | G6: =IF(E6<>"",LEN(E6),"") | O6: 2
B7: 3 | E7: =IF($C7<>"","ALERT_" & D7 & "_ID_"&UPPER(Matrix!$D$6) & "_" & $C7,"") | G7: =IF(E7<>"",LEN(E7),"") | O7: 3
B8: 4 | E8: =IF($C8<>"","ALERT_" & D8 & "_ID_"&UPPER(Matrix!$D$6) & "_" & $C8,"") | G8: =IF(E8<>"",LEN(E8),"") | O8: 4
B9: 5 | E9: =IF($C9<>"","ALERT_" & D9 & "_ID_"&UPPER(Matrix!$D$6) & "_" & $C9,"") | G9: =IF(E9<>"",LEN(E9),"") | O9: 5
B10: 6 | E10: =IF($C10<>"","ALERT_" & D10 & "_ID_"&UPPER(Matrix!$D$6) & "_" & $C10,"") | G10: =IF(E10<>"",LEN(E10),"") | O10: 6
B11: 7 | E11: =IF($C11<>"","ALERT_" & D11 & "_ID_"&UPPER(Matrix!$D$6) & "_" & $C11,"") | G11: =IF(E11<>"",LEN(E11),"") | O11: 7
B12: 8 | E12: =IF($C12<>"","ALERT_" & D12 & "_ID_"&UPPER(Matrix!$D$6) & "_" & $C12,"") | G12: =IF(E12<>"",LEN(E12),"") | O12: 8
B13: 9 | E13: =IF($C13<>"","ALERT_" & D13 & "_ID_"&UPPER(Matrix!$D$6) & "_" & $C13,"") | G13: =IF(E13<>"",LEN(E13),"") | O13: 9
B14: 10 | E14: =IF($C14<>"","ALERT_" & D14 & "_ID_"&UPPER(Matrix!$D$6) & "_" & $C14,"") | G14: =IF(E14<>"",LEN(E14),"") | O14: 10
B15: 11 | E15: =IF($C15<>"","ALERT_" & D15 & "_ID_"&UPPER(Matrix!$D$6) & "_" & $C15,"") | G15: =IF(E15<>"",LEN(E15),"") | O15: 11
B16: 12 | E16: =IF($C16<>"","ALERT_" & D16 & "_ID_"&UPPER(Matrix!$D$6) & "_" & $C16,"") | G16: =IF(E16<>"",LEN(E16),"") | O16: 12
... B29: 25 | E29: =IF($C29<>"","ALERT_" & D29 & "_ID_"&UPPER(Matrix!$D$6) & "_" & $C29,"") | G29: =IF(E29<>"",LEN(E29),"") | O29: 25
B32: Alert Domain Define | O32: Constant Externs List
B33: No | C33: define Name | D33: calss | E33: define | F33: Value | G33: 文字数 | O33: No | P33: Type | Q33: Constant define | R33: comment
B34: 0 | C34: なし | F34: なし | O34: 0 | P34: なし | Q34: なし | R34: なし
B35: 1 | E35: =IF($C35<>"","ALERT_" & UPPER(Matrix!$D$6) & "_" & $C35,"") | G35: =IF(E35<>"",LEN(E35),"") | O35: 1
B36: 2 | E36: =IF($C36<>"","ALERT_" & UPPER(Matrix!$D$6) & "_" & $C36,"") | G36: =IF(E36<>"",LEN(E36),"") | O36: 2
B37: 3 | E37: =IF($C37<>"","ALERT_" & UPPER(Matrix!$D$6) & "_" & $C37,"") | G37: =IF(E37<>"",LEN(E37),"") | O37: 3
B38: 4 | E38: =IF($C38<>"","ALERT_" & UPPER(Matrix!$D$6) & "_" & $C38,"") | G38: =IF(E38<>"",LEN(E38),"") | O38: 4
B39: 5 | E39: =IF($C39<>"","ALERT_" & UPPER(Matrix!$D$6) & "_" & $C39,"") | G39: =IF(E39<>"",LEN(E39),"") | O39: 5
B40: 6 | E40: =IF($C40<>"","ALERT_" & UPPER(Matrix!$D$6) & "_" & $C40,"") | G40: =IF(E40<>"",LEN(E40),"") | O40: 6
B41: 7 | E41: =IF($C41<>"","ALERT_" & UPPER(Matrix!$D$6) & "_" & $C41,"") | G41: =IF(E41<>"",LEN(E41),"") | O41: 7
B42: 8 | E42: =IF($C42<>"","ALERT_" & UPPER(Matrix!$D$6) & "_" & $C42,"") | G42: =IF(E42<>"",LEN(E42),"") | O42: 8
B43: 9 | E43: =IF($C43<>"","ALERT_" & UPPER(Matrix!$D$6) & "_" & $C43,"") | G43: =IF(E43<>"",LEN(E43),"") | O43: 9
B44: 10 | E44: =IF($C44<>"","ALERT_" & UPPER(Matrix!$D$6) & "_" & $C44,"") | G44: =IF(E44<>"",LEN(E44),"") | O44: 10
B45: 11 | E45: =IF($C45<>"","ALERT_" & UPPER(Matrix!$D$6) & "_" & $C45,"") | G45: =IF(E45<>"",LEN(E45),"") | O45: 11
B46: 12 | E46: =IF($C46<>"","ALERT_" & UPPER(Matrix!$D$6) & "_" & $C46,"") | G46: =IF(E46<>"",LEN(E46),"") | O46: 12
... B59: 25 | E59: =IF($C59<>"","ALERT_" & UPPER(Matrix!$D$6) & "_" & $C59,"") | G59: =IF(E59<>"",LEN(E59),"") | O59: 25

Sheet CH_Design
C1: 出力なしは、ここでは定義しないこと。システム共通のALERT_REQ_UNKNOWNを使用するため。
B2: ALERT CH | C2: REQ | D2: Value | E2: TT機能判定 | F2: TT | G2: BC機能判定 | H2: BC | I2: PD機能判定 | J2: PD | K2: RW機能判定 | L2: RW | M2: 文字数 | N2: 定義名 | O2: Code for alert_mtrx.h
C3: UNKNOWN | U3: 電源状態一覧
B4: ALERT_CH_S_TMBZR_BC_AD | C4: ANN_0 | D4: 0 | E4: なし | F4: - | G4: なし | H4: S_TMBZR-CSTD-0-BZR01-REQ02- | I4: なし | J4: - | K4: なし | L4: - | M4: =LEN(N4) -> 29 | N4: =VLOOKUP($B4,Matrix!$H$13:$I$37,2,FALSE)&"_"&C4 -> ALERT_REQ_S_TMBZR_BC_AD_ANN_0 | O4: ="#define "&N4&REPT(" ",48-M4)&"("&D4&"U)" -> #define ALERT_REQ_S_TMBZR_BC_AD_ANN_0 (0U) | U4: 電源状態一覧
B5: ALERT_CH_S_TMBZR_BC_AD | C5: ANN_1 | D5: 1 | E5: なし | F5: - | G5: なし | H5: S_TMBZR-CSTD-0-BZR01-REQ03- | I5: なし | J5: - | K5: なし | L5: - | M5: =LEN(N5) -> 29 | N5: =VLOOKUP($B5,Matrix!$H$13:$I$37,2,FALSE)&"_"&C5 -> ALERT_REQ_S_TMBZR_BC_AD_ANN_1 | O5: ="#define "&N5&REPT(" ",48-M5)&"("&D5&"U)" -> #define ALERT_REQ_S_TMBZR_BC_AD_ANN_1 (1U) | U5: ＋B
B6: ALERT_CH_S_TMBZR_BC_AD | C6: ANN_2 | D6: 2 | E6: なし | F6: - | G6: なし | H6: S_TMBZR-CSTD-0-BZR01-REQ04- | I6: なし | J6: - | K6: なし | L6: - | M6: =LEN(N6) -> 29 | N6: =VLOOKUP($B6,Matrix!$H$13:$I$37,2,FALSE)&"_"&C6 -> ALERT_REQ_S_TMBZR_BC_AD_ANN_2 | O6: ="#define "&N6&REPT(" ",48-M6)&"("&D6&"U)" -> #define ALERT_REQ_S_TMBZR_BC_AD_ANN_2 (2U) | U6: IG-ON
B7: ALERT_CH_S_TMBZR_BC_AD | C7: ANN_3 | D7: 3 | E7: なし | F7: - | G7: なし | H7: S_TMBZR-CSTD-0-BZR01-REQ05- | I7: なし | J7: - | K7: なし | L7: - | M7: =LEN(N7) -> 29 | N7: =VLOOKUP($B7,Matrix!$H$13:$I$37,2,FALSE)&"_"&C7 -> ALERT_REQ_S_TMBZR_BC_AD_ANN_3 | O7: ="#define "&N7&REPT(" ",48-M7)&"("&D7&"U)" -> #define ALERT_REQ_S_TMBZR_BC_AD_ANN_3 (3U) | U7: IG-OFF
B8: ALERT_CH_S_TMBZR_BC_AD | C8: ANN_4 | D8: 4 | E8: なし | F8: - | G8: なし | H8: S_TMBZR-CSTD-0-BZR01-REQ06- | I8: なし | J8: - | K8: なし | L8: - | M8: =LEN(N8) -> 29 | N8: =VLOOKUP($B8,Matrix!$H$13:$I$37,2,FALSE)&"_"&C8 -> ALERT_REQ_S_TMBZR_BC_AD_ANN_4 | O8: ="#define "&N8&REPT(" ",48-M8)&"("&D8&"U)" -> #define ALERT_REQ_S_TMBZR_BC_AD_ANN_4 (4U) | U8: ACC-ON
B9: ALERT_CH_S_TMBZR_BC_AD | C9: ANN_4P5 | D9: 5 | E9: なし | F9: - | G9: なし | H9: S_TMBZR-CSTD-0-BZR01-REQ07- | I9: なし | J9: - | K9: なし | L9: - | M9: =LEN(N9) -> 31 | N9: =VLOOKUP($B9,Matrix!$H$13:$I$37,2,FALSE)&"_"&C9 -> ALERT_REQ_S_TMBZR_BC_AD_ANN_4P5 | O9: ="#define "&N9&REPT(" ",48-M9)&"("&D9&"U)" -> #define ALERT_REQ_S_TMBZR_BC_AD_ANN_4P5 (5U) | U9: ACC-OFF
B10: ALERT_CH_S_TMBZR_BC_AD | C10: RCV_0 | D10: 6 | E10: なし | F10: - | G10: なし | H10: S_TMBZR-CSTD-0-BZR01-REQ08- | I10: なし | J10: - | K10: なし | L10: - | M10: =LEN(N10) -> 29 | N10: =VLOOKUP($B10,Matrix!$H$13:$I$37,2,FALSE)&"_"&C10 -> ALERT_REQ_S_TMBZR_BC_AD_RCV_0 | O10: ="#define "&N10&REPT(" ",48-M10)&"("&D10&"U)" -> #define ALERT_REQ_S_TMBZR_BC_AD_RCV_0 (6U)
B11: ALERT_CH_S_TMBZR_BC_AD | C11: RCV_1 | D11: 7 | E11: なし | F11: - | G11: なし | H11: S_TMBZR-CSTD-0-BZR01-REQ09- | I11: なし | J11: - | K11: なし | L11: - | M11: =LEN(N11) -> 29 | N11: =VLOOKUP($B11,Matrix!$H$13:$I$37,2,FALSE)&"_"&C11 -> ALERT_REQ_S_TMBZR_BC_AD_RCV_1 | O11: ="#define "&N11&REPT(" ",48-M11)&"("&D11&"U)" -> #define ALERT_REQ_S_TMBZR_BC_AD_RCV_1 (7U)
B12: ALERT_CH_S_TMBZR_BC_AD | C12: RCV_2 | D12: 8 | E12: なし | F12: - | G12: なし | H12: S_TMBZR-CSTD-0-BZR01-REQ010- | I12: なし | J12: - | K12: なし | L12: - | M12: =LEN(N12) -> 29 | N12: =VLOOKUP($B12,Matrix!$H$13:$I$37,2,FALSE)&"_"&C12 -> ALERT_REQ_S_TMBZR_BC_AD_RCV_2 | O12: ="#define "&N12&REPT(" ",48-M12)&"("&D12&"U)" -> #define ALERT_REQ_S_TMBZR_BC_AD_RCV_2 (8U)
B13: ALERT_CH_S_TMBZR_BC_AD | C13: RCV_3 | D13: 9 | E13: なし | F13: - | G13: なし | H13: S_TMBZR-CSTD-0-BZR01-REQ011- | I13: なし | J13: - | K13: なし | L13: - | M13: =LEN(N13) -> 29 | N13: =VLOOKUP($B13,Matrix!$H$13:$I$37,2,FALSE)&"_"&C13 -> ALERT_REQ_S_TMBZR_BC_AD_RCV_3 | O13: ="#define "&N13&REPT(" ",48-M13)&"("&D13&"U)" -> #define ALERT_REQ_S_TMBZR_BC_AD_RCV_3 (9U)
B14: ALERT_CH_S_TMBZR_BC_AD | C14: RCV_4 | D14: 10 | E14: なし | F14: - | G14: なし | H14: S_TMBZR-CSTD-0-BZR01-REQ012- | I14: なし | J14: - | K14: なし | L14: - | M14: =LEN(N14) -> 29 | N14: =VLOOKUP($B14,Matrix!$H$13:$I$37,2,FALSE)&"_"&C14 -> ALERT_REQ_S_TMBZR_BC_AD_RCV_4 | O14: ="#define "&N14&REPT(" ",48-M14)&"("&D14&"U)" -> #define ALERT_REQ_S_TMBZR_BC_AD_RCV_4 (10U)
B15: ALERT_CH_S_TMBZR_BC_AD | C15: RCV_4P5 | D15: 11 | E15: なし | F15: - | G15: なし | H15: S_TMBZR-CSTD-0-BZR01-REQ013- | I15: なし | J15: - | K15: なし | L15: - | M15: =LEN(N15) -> 31 | N15: =VLOOKUP($B15,Matrix!$H$13:$I$37,2,FALSE)&"_"&C15 -> ALERT_REQ_S_TMBZR_BC_AD_RCV_4P5 | O15: ="#define "&N15&REPT(" ",48-M15)&"("&D15&"U)" -> #define ALERT_REQ_S_TMBZR_BC_AD_RCV_4P5 (11U)
B16: ALERT_CH_S_TMBZR_BC_AD | C16: RJT_0 | D16: 12 | E16: なし | F16: - | G16: なし | H16: S_TMBZR-CSTD-0-BZR01-REQ014- | I16: なし | J16: - | K16: なし | L16: - | M16: =LEN(N16) -> 29 | N16: =VLOOKUP($B16,Matrix!$H$13:$I$37,2,FALSE)&"_"&C16 -> ALERT_REQ_S_TMBZR_BC_AD_RJT_0 | O16: ="#define "&N16&REPT(" ",48-M16)&"("&D16&"U)" -> #define ALERT_REQ_S_TMBZR_BC_AD_RJT_0 (12U)
B17: ALERT_CH_S_TMBZR_BC_AD | C17: RJT_1 | D17: 13 | E17: なし | F17: - | G17: なし | H17: S_TMBZR-CSTD-0-BZR01-REQ015- | I17: なし | J17: - | K17: なし | L17: - | M17: =LEN(N17) -> 29 | N17: =VLOOKUP($B17,Matrix!$H$13:$I$37,2,FALSE)&"_"&C17 -> ALERT_REQ_S_TMBZR_BC_AD_RJT_1 | O17: ="#define "&N17&REPT(" ",48-M17)&"("&D17&"U)" -> #define ALERT_REQ_S_TMBZR_BC_AD_RJT_1 (13U)
B18: ALERT_CH_S_TMBZR_BC_AD | C18: RJT_2 | D18: 14 | E18: なし | F18: - | G18: なし | H18: S_TMBZR-CSTD-0-BZR01-REQ016- | I18: なし | J18: - | K18: なし | L18: - | M18: =LEN(N18) -> 29 | N18: =VLOOKUP($B18,Matrix!$H$13:$I$37,2,FALSE)&"_"&C18 -> ALERT_REQ_S_TMBZR_BC_AD_RJT_2 | O18: ="#define "&N18&REPT(" ",48-M18)&"("&D18&"U)" -> #define ALERT_REQ_S_TMBZR_BC_AD_RJT_2 (14U)
B19: ALERT_CH_S_TMBZR_BC_AD | C19: RJT_3 | D19: 15 | E19: なし | F19: - | G19: なし | H19: S_TMBZR-CSTD-0-BZR01-REQ017- | I19: なし | J19: - | K19: なし | L19: - | M19: =LEN(N19) -> 29 | N19: =VLOOKUP($B19,Matrix!$H$13:$I$37,2,FALSE)&"_"&C19 -> ALERT_REQ_S_TMBZR_BC_AD_RJT_3 | O19: ="#define "&N19&REPT(" ",48-M19)&"("&D19&"U)" -> #define ALERT_REQ_S_TMBZR_BC_AD_RJT_3 (15U)
B20: ALERT_CH_S_TMBZR_BC_AD | C20: RJT_4 | D20: 16 | E20: なし | F20: - | G20: なし | H20: S_TMBZR-CSTD-0-BZR01-REQ018- | I20: なし | J20: - | K20: なし | L20: - | M20: =LEN(N20) -> 29 | N20: =VLOOKUP($B20,Matrix!$H$13:$I$37,2,FALSE)&"_"&C20 -> ALERT_REQ_S_TMBZR_BC_AD_RJT_4 | O20: ="#define "&N20&REPT(" ",48-M20)&"("&D20&"U)" -> #define ALERT_REQ_S_TMBZR_BC_AD_RJT_4 (16U)
B21: ALERT_CH_S_TMBZR_BC_AD | C21: RJT_4P5 | D21: 17 | E21: なし | F21: - | G21: なし | H21: S_TMBZR-CSTD-0-BZR01-REQ019- | I21: なし | J21: - | K21: なし | L21: - | M21: =LEN(N21) -> 31 | N21: =VLOOKUP($B21,Matrix!$H$13:$I$37,2,FALSE)&"_"&C21 -> ALERT_REQ_S_TMBZR_BC_AD_RJT_4P5 | O21: ="#define "&N21&REPT(" ",48-M21)&"("&D21&"U)" -> #define ALERT_REQ_S_TMBZR_BC_AD_RJT_4P5 (17U)
... B38: ALERT_CH_S_TMBZR_BC_DOT | C38: DOHREQ | D38: 0 | E38: なし | F38: - | G38: なし | H38: S_TMBZR-CSTD-0-BZR01-REQ037- | I38: なし | J38: - | K38: なし | L38: - | M38: =LEN(N38) -> 31 | N38: =VLOOKUP($B38,Matrix!$H$13:$I$37,2,FALSE)&"_"&C38 -> ALERT_REQ_S_TMBZR_BC_DOT_DOHREQ | O38: ="#define "&N38&REPT(" ",48-M38)&"("&D38&"U)" -> #define ALERT_REQ_S_TMBZR_BC_DOT_DOHREQ (0U)
M39: =LEN(N39) -> #N/A | N39: =VLOOKUP($B39,Matrix!$H$13:$I$37,2,FALSE)&"_"&C39 -> #N/A | O39: ="#define "&N39&REPT(" ",48-M39)&"("&D39&"U)" -> #N/A
M40: =LEN(N40) -> #N/A | N40: =VLOOKUP($B40,Matrix!$H$13:$I$37,2,FALSE)&"_"&C40 -> #N/A | O40: ="#define "&N40&REPT(" ",48-M40)&"("&D40&"U)" -> #N/A
M41: =LEN(N41) -> #N/A | N41: =VLOOKUP($B41,Matrix!$H$13:$I$37,2,FALSE)&"_"&C41 -> #N/A | O41: ="#define "&N41&REPT(" ",48-M41)&"("&D41&"U)" -> #N/A
M42: =LEN(N42) -> #N/A | N42: =VLOOKUP($B42,Matrix!$H$13:$I$37,2,FALSE)&"_"&C42 -> #N/A | O42: ="#define "&N42&REPT(" ",48-M42)&"("&D42&"U)" -> #N/A
M43: =LEN(N43) -> #N/A | N43: =VLOOKUP($B43,Matrix!$H$13:$I$37,2,FALSE)&"_"&C43 -> #N/A | O43: ="#define "&N43&REPT(" ",48-M43)&"("&D43&"U)" -> #N/A
M44: =LEN(N44) -> #N/A | N44: =VLOOKUP($B44,Matrix!$H$13:$I$37,2,FALSE)&"_"&C44 -> #N/A | O44: ="#define "&N44&REPT(" ",48-M44)&"("&D44&"U)" -> #N/A
M45: =LEN(N45) -> #N/A | N45: =VLOOKUP($B45,Matrix!$H$13:$I$37,2,FALSE)&"_"&C45 -> #N/A | O45: ="#define "&N45&REPT(" ",48-M45)&"("&D45&"U)" -> #N/A
M46: =LEN(N46) -> #N/A | N46: =VLOOKUP($B46,Matrix!$H$13:$I$37,2,FALSE)&"_"&C46 -> #N/A | O46: ="#define "&N46&REPT(" ",48-M46)&"("&D46&"U)" -> #N/A
M47: =LEN(N47) -> #N/A | N47: =VLOOKUP($B47,Matrix!$H$13:$I$37,2,FALSE)&"_"&C47 -> #N/A | O47: ="#define "&N47&REPT(" ",48-M47)&"("&D47&"U)" -> #N/A
M48: =LEN(N48) -> #N/A | N48: =VLOOKUP($B48,Matrix!$H$13:$I$37,2,FALSE)&"_"&C48 -> #N/A | O48: ="#define "&N48&REPT(" ",48-M48)&"("&D48&"U)" -> #N/A
M49: =LEN(N49) -> #N/A | N49: =VLOOKUP($B49,Matrix!$H$13:$I$37,2,FALSE)&"_"&C49 -> #N/A | O49: ="#define "&N49&REPT(" ",48-M49)&"("&D49&"U)" -> #N/A
M50: =LEN(N50) -> #N/A | N50: =VLOOKUP($B50,Matrix!$H$13:$I$37,2,FALSE)&"_"&C50 -> #N/A | O50: ="#define "&N50&REPT(" ",48-M50)&"("&D50&"U)" -> #N/A
... M103: =LEN(N103) -> #N/A | N103: =VLOOKUP($B103,Matrix!$H$13:$I$37,2,FALSE)&"_"&C103 -> #N/A | O103: ="#define "&N103&REPT(" ",48-M103)&"("&D103&"U)" -> #N/A

Sheet BC_AD
AH1: → | AI1: bit
B2: Table Type | C2: SEARCH | D2: 31 | E2: 30 | F2: 29 | G2: 28 | H2: 27 | I2: 26 | J2: 25 | K2: 24 | L2: 23 | M2: 22 | N2: 21 | O2: 20 | P2: 19 | Q2: 18 | R2: 17 | S2: 16 | T2: 15 | U2: 14 | V2: 13 | W2: 12 | X2: 11 | Y2: 10 | Z2: 9 | AA2: 8 | AB2: 7 | AC2: 6 | AD2: 5 | AE2: 4 | AF2: 3 | AG2: 2 | AH2: 1 | AI2: 0 | AJ2: REQ
B3: =IF(OR(IF(COUNTIF(D6:AC69,"0")<>0,TRUE,FALSE),IF(COUNTIF(D6:AC69,"1")<>0,TRUE,FALSE)),"Search Table","Index Table") -> Search Table | D3: ALERT_VOM_RWT_EN | E3: [reserved] | F3: ALERT_VOM_VCS_ON | G3: ALERT_VOM_IGN_ON | H3: ALERT_VOM_IGN_OFF_WT | I3: ALERT_VOM_IGN_OFF | J3: ALERT_VOM_BAT_WT | K3: ALERT_VOM_BAT_AO | L3: [reserved] | M3: [reserved] | N3: [reserved] | O3: [reserved] | P3: [reserved] | Q3: [reserved] | R3: [reserved] | S3: [reserved] | T3: [reserved] | U3: [reserved] | V3: [reserved] | W3: [reserved] | X3: [reserved] | Y3: [reserved] | Z3: ADC1S14_STS | AB3: ADBZRQ_SIG | AR3: シート名称は、CH Nameと同じにすること。 1CHしか存在しない場合、機能名と同じにすること。
A4: Master Table | AR4: 貼り付けコード
AR5: ="static const U4 "&AW8&"["&AW10&"]"&" = {" -> static const U4 u4_sp_ALERT_S_TMBZR_BC_AD_CRIT[ALERT_S_TMBZR_BC_AD_NUM_DST] = { | AS5: ="static const U4 "&$AW$9&"["&$AW$10&"] = {" -> static const U4 u4_sp_ALERT_S_TMBZR_BC_AD_MASK[ALERT_S_TMBZR_BC_AD_NUM_DST] = { | AT5: ="static const U1 "&$AW$11&"["&$AW$10&"] = {" -> static const U1 u1_sp_ALERT_S_TMBZR_BC_AD_DST[ALERT_S_TMBZR_BC_AD_NUM_DST] = { | AU5: ="const ST_ALERT_MTRX "&$AW$12&" = {" -> const ST_ALERT_MTRX st_gp_ALERT_S_TMBZR_MTRX[2] = { | AV5: ="#define "&AW10&REPT(" ",41-LEN(AW10))&"("&AW13&"U)" -> #define ALERT_S_TMBZR_BC_AD_NUM_DST (36U)
B6: ="Table "&$AW$6 -> Table BC_AD | C6: =ROW()-ROW($C$6) -> 0 | D6: × | E6: × | F6: × | G6: × | H6: × | I6: × | J6: × | K6: × | L6: × | M6: × | N6: × | O6: × | P6: × | Q6: × | R6: × | S6: × | T6: × | U6: × | V6: × | W6: × | X6: × | Y6: × | Z6: 1 | AA6: × | AB6: × | AC6: × | AD6: × | AE6: × | AF6: × | AG6: × | AH6: × | AI6: × | AJ6: UNKNOWN | AL6: =IF($AJ6="UNKNOWN"," (U1)ALERT_REQ_UNKNOWN"," (U1)"&"ALERT_REQ_"&$AW$17&"_"&IF($AW$6<>$AW$17,$AW$6&"_","")&AJ6) -> (U1)ALERT_REQ_UNKNOWN | AR6: =IF(AQ71<>"",AQ71,IF(AQ70<>"","};","")) -> (U4)0x00000200U, /* 00 UNKNOWN */ | AS6: =IF(AQ136<>"",AQ136,IF(AQ135<>"","};","")) -> (U4)0x00000200U, /* 00 UNKNOWN */ | AT6: =IF(AJ6<>"",AL6&IF(AJ7<>"",","," ")&REPT(" ",78-LEN(AL6))&"/* "&IF(C6<10,"0"&C6,C6)&" "&AJ6&REPT(" ",48-LEN(AJ6))&"*/",IF(AJ5<>"","};","")) -> (U1)ALERT_REQ_UNKNOWN, /* 00 UNKNOWN */ | AU6: { | AV6: MtxSrch変数名 | AW6: =UPPER(RIGHT(CELL("filename",A1),LEN(CELL("filename",A1))-FIND("]",CELL("filename",A1)))) -> BC_AD
C7: =ROW()-ROW($C$6) -> 1 | D7: × | E7: × | F7: × | G7: × | H7: × | I7: × | J7: × | K7: × | L7: × | M7: × | N7: × | O7: × | P7: × | Q7: × | R7: × | S7: × | T7: × | U7: × | V7: × | W7: × | X7: × | Y7: × | Z7: 0 | AA7: 1 | AB7: × | AC7: × | AD7: × | AE7: × | AF7: × | AG7: × | AH7: × | AI7: × | AJ7: UNKNOWN | AL7: =IF($AJ7="UNKNOWN"," (U1)ALERT_REQ_UNKNOWN"," (U1)"&"ALERT_REQ_"&$AW$17&"_"&IF($AW$6<>$AW$17,$AW$6&"_","")&AJ7) -> (U1)ALERT_REQ_UNKNOWN | AR7: =IF(AQ72<>"",AQ72,IF(AQ71<>"","};","")) -> (U4)0x00000100U, /* 01 UNKNOWN */ | AS7: =IF(AQ137<>"",AQ137,IF(AQ136<>"","};","")) -> (U4)0x00000300U, /* 01 UNKNOWN */ | AT7: =IF(AJ7<>"",AL7&IF(AJ8<>"",","," ")&REPT(" ",78-LEN(AL7))&"/* "&IF(C7<10,"0"&C7,C7)&" "&AJ7&REPT(" ",48-LEN(AJ7))&"*/",IF(AJ6<>"","};","")) -> (U1)ALERT_REQ_UNKNOWN, /* 01 UNKNOWN */ | AU7: =" &"&$AW$14&","&REPT(" ",69-LEN($AW$14))&"/* fp_u4_SRC_CHK */" -> &u4_s_AlertS_tmbzrBcAdSrcchk, /* fp_u4_SRC_CHK */ | AV7: Use MtxSrch | AW7: =IF(B3="Search Table",1,0) -> 1
C8: =ROW()-ROW($C$6) -> 2 | D8: × | E8: × | F8: × | G8: × | H8: × | I8: × | J8: × | K8: × | L8: × | M8: × | N8: × | O8: × | P8: × | Q8: × | R8: × | S8: × | T8: × | U8: × | V8: × | W8: × | X8: × | Y8: × | Z8: 0 | AA8: 0 | AB8: 0 | AC8: 0 | AD8: 0 | AE8: 0 | AF8: 0 | AG8: 0 | AH8: 0 | AI8: 1 | AJ8: CONT_0 | AL8: =IF($AJ8="UNKNOWN"," (U1)ALERT_REQ_UNKNOWN"," (U1)"&"ALERT_REQ_"&$AW$17&"_"&IF($AW$6<>$AW$17,$AW$6&"_","")&AJ8) -> (U1)ALERT_REQ_S_TMBZR_BC_AD_CONT_0 | AR8: =IF(AQ73<>"",AQ73,IF(AQ72<>"","};","")) -> (U4)0x00000001U, /* 02 CONT_0 */ | AS8: =IF(AQ138<>"",AQ138,IF(AQ137<>"","};","")) -> (U4)0x000003FFU, /* 02 CONT_0 */ | AT8: =IF(AJ8<>"",AL8&IF(AJ9<>"",","," ")&REPT(" ",78-LEN(AL8))&"/* "&IF(C8<10,"0"&C8,C8)&" "&AJ8&REPT(" ",48-LEN(AJ8))&"*/",IF(AJ7<>"","};","")) -> (U1)ALERT_REQ_S_TMBZR_BC_AD_CONT_0, /* 02 CONT_0 */ | AU8: =IF($AW$15<>"NULL"," &"&$AW$15&","&REPT(" ",69-LEN($AW$15))&"/* fp_vd_XDST */"," vdp_PTR_NA, /* fp_vd_XDST */") -> vdp_PTR_NA, /* fp_vd_XDST */ | AV8: CRIT_NAME | AW8: ="u4_sp_ALERT_"&IF(AW6<>AW17,$AW$17&"_"&$AW$6,AW17)&"_CRIT" -> u4_sp_ALERT_S_TMBZR_BC_AD_CRIT
C9: =ROW()-ROW($C$6) -> 3 | D9: × | E9: × | F9: × | G9: × | H9: × | I9: × | J9: × | K9: × | L9: × | M9: × | N9: × | O9: × | P9: × | Q9: × | R9: × | S9: × | T9: × | U9: × | V9: × | W9: × | X9: × | Y9: × | Z9: 0 | AA9: 0 | AB9: 0 | AC9: 0 | AD9: 0 | AE9: 0 | AF9: 0 | AG9: 0 | AH9: 1 | AI9: 0 | AJ9: TEN_0 | AL9: =IF($AJ9="UNKNOWN"," (U1)ALERT_REQ_UNKNOWN"," (U1)"&"ALERT_REQ_"&$AW$17&"_"&IF($AW$6<>$AW$17,$AW$6&"_","")&AJ9) -> (U1)ALERT_REQ_S_TMBZR_BC_AD_TEN_0 | AR9: =IF(AQ74<>"",AQ74,IF(AQ73<>"","};","")) -> (U4)0x00000002U, /* 03 TEN_0 */ | AS9: =IF(AQ139<>"",AQ139,IF(AQ138<>"","};","")) -> (U4)0x000003FFU, /* 03 TEN_0 */ | AT9: =IF(AJ9<>"",AL9&IF(AJ10<>"",","," ")&REPT(" ",78-LEN(AL9))&"/* "&IF(C9<10,"0"&C9,C9)&" "&AJ9&REPT(" ",48-LEN(AJ9))&"*/",IF(AJ8<>"","};","")) -> (U1)ALERT_REQ_S_TMBZR_BC_AD_TEN_0, /* 03 TEN_0 */ | AV9: MASK_NAME | AW9: ="u4_sp_ALERT_"&IF(AW6<>AW17,$AW$17&"_"&$AW$6,AW17)&"_MASK" -> u4_sp_ALERT_S_TMBZR_BC_AD_MASK
C10: =ROW()-ROW($C$6) -> 4 | D10: × | E10: × | F10: × | G10: × | H10: × | I10: × | J10: × | K10: × | L10: × | M10: × | N10: × | O10: × | P10: × | Q10: × | R10: × | S10: × | T10: × | U10: × | V10: × | W10: × | X10: × | Y10: × | Z10: 0 | AA10: 0 | AB10: 0 | AC10: 0 | AD10: 0 | AE10: 0 | AF10: 0 | AG10: 1 | AH10: 0 | AI10: 1 | AJ10: RJT_0 | AL10: =IF($AJ10="UNKNOWN"," (U1)ALERT_REQ_UNKNOWN"," (U1)"&"ALERT_REQ_"&$AW$17&"_"&IF($AW$6<>$AW$17,$AW$6&"_","")&AJ10) -> (U1)ALERT_REQ_S_TMBZR_BC_AD_RJT_0 | AR10: =IF(AQ75<>"",AQ75,IF(AQ74<>"","};","")) -> (U4)0x00000005U, /* 04 RJT_0 */ | AS10: =IF(AQ140<>"",AQ140,IF(AQ139<>"","};","")) -> (U4)0x000003FFU, /* 04 RJT_0 */ | AT10: =IF(AJ10<>"",AL10&IF(AJ11<>"",","," ")&REPT(" ",78-LEN(AL10))&"/* "&IF(C10<10,"0"&C10,C10)&" "&AJ10&REPT(" ",48-LEN(AJ10))&"*/",IF(AJ9<>"","};","")) -> (U1)ALERT_REQ_S_TMBZR_BC_AD_RJT_0, /* 04 RJT_0 */ | AU10: =IF($AW$7=1," &"&$AW$9&"[0],"&REPT(" ",66-LEN($AW$9))&"/* u4p_MASK */"," (const U4 *)vdp_PTR_NA, /* u4p_MASK */") -> &u4_sp_ALERT_S_TMBZR_BC_AD_MASK[0], /* u4p_MASK */ | AV10: MTXSRCH_DEF | AW10: ="ALERT_"&IF(AW6<>AW17,$AW$17&"_"&$AW$6,AW17)&"_NUM_DST" -> ALERT_S_TMBZR_BC_AD_NUM_DST
C11: =ROW()-ROW($C$6) -> 5 | D11: × | E11: × | F11: × | G11: × | H11: × | I11: × | J11: × | K11: × | L11: × | M11: × | N11: × | O11: × | P11: × | Q11: × | R11: × | S11: × | T11: × | U11: × | V11: × | W11: × | X11: × | Y11: × | Z11: 0 | AA11: 0 | AB11: 0 | AC11: 0 | AD11: 0 | AE11: 0 | AF11: 0 | AG11: 1 | AH11: 1 | AI11: 0 | AJ11: RCV_0 | AL11: =IF($AJ11="UNKNOWN"," (U1)ALERT_REQ_UNKNOWN"," (U1)"&"ALERT_REQ_"&$AW$17&"_"&IF($AW$6<>$AW$17,$AW$6&"_","")&AJ11) -> (U1)ALERT_REQ_S_TMBZR_BC_AD_RCV_0 | AR11: =IF(AQ76<>"",AQ76,IF(AQ75<>"","};","")) -> (U4)0x00000006U, /* 05 RCV_0 */ | AS11: =IF(AQ141<>"",AQ141,IF(AQ140<>"","};","")) -> (U4)0x000003FFU, /* 05 RCV_0 */ | AT11: =IF(AJ11<>"",AL11&IF(AJ12<>"",","," ")&REPT(" ",78-LEN(AL11))&"/* "&IF(C11<10,"0"&C11,C11)&" "&AJ11&REPT(" ",48-LEN(AJ11))&"*/",IF(AJ10<>"","};","")) -> (U1)ALERT_REQ_S_TMBZR_BC_AD_RCV_0, /* 05 RCV_0 */ | AU11: =IF($AW$7=1," &"&$AW$8&"[0],"&REPT(" ",66-LEN($AW$8))&"/* u4p_CRIT */"," (const U4 *)vdp_PTR_NA, /* u4p_CRIT */") -> &u4_sp_ALERT_S_TMBZR_BC_AD_CRIT[0], /* u4p_CRIT */ | AV11: MTXSRCH_OUT_DEF | AW11: ="u1_sp_ALERT_"&IF(AW6<>AW17,$AW$17&"_"&$AW$6,AW17)&"_DST" -> u1_sp_ALERT_S_TMBZR_BC_AD_DST
C12: =ROW()-ROW($C$6) -> 6 | D12: × | E12: × | F12: × | G12: × | H12: × | I12: × | J12: × | K12: × | L12: × | M12: × | N12: × | O12: × | P12: × | Q12: × | R12: × | S12: × | T12: × | U12: × | V12: × | W12: × | X12: × | Y12: × | Z12: 0 | AA12: 0 | AB12: 0 | AC12: 0 | AD12: 0 | AE12: 0 | AF12: 0 | AG12: 1 | AH12: 1 | AI12: 1 | AJ12: ANN_0 | AL12: =IF($AJ12="UNKNOWN"," (U1)ALERT_REQ_UNKNOWN"," (U1)"&"ALERT_REQ_"&$AW$17&"_"&IF($AW$6<>$AW$17,$AW$6&"_","")&AJ12) -> (U1)ALERT_REQ_S_TMBZR_BC_AD_ANN_0 | AR12: =IF(AQ77<>"",AQ77,IF(AQ76<>"","};","")) -> (U4)0x00000007U, /* 06 ANN_0 */ | AS12: =IF(AQ142<>"",AQ142,IF(AQ141<>"","};","")) -> (U4)0x000003FFU, /* 06 ANN_0 */ | AT12: =IF(AJ12<>"",AL12&IF(AJ13<>"",","," ")&REPT(" ",78-LEN(AL12))&"/* "&IF(C12<10,"0"&C12,C12)&" "&AJ12&REPT(" ",48-LEN(AJ12))&"*/",IF(AJ11<>"","};","")) -> (U1)ALERT_REQ_S_TMBZR_BC_AD_ANN_0, /* 06 ANN_0 */ | AV12: ALERT_MTRX_NAME | AW12: =Matrix!D8&"["&Matrix!D7&"]" -> st_gp_ALERT_S_TMBZR_MTRX[2]
C13: =ROW()-ROW($C$6) -> 7 | D13: × | E13: × | F13: × | G13: × | H13: × | I13: × | J13: × | K13: × | L13: × | M13: × | N13: × | O13: × | P13: × | Q13: × | R13: × | S13: × | T13: × | U13: × | V13: × | W13: × | X13: × | Y13: × | Z13: 0 | AA13: 0 | AB13: 0 | AC13: 0 | AD13: 0 | AE13: 1 | AF13: 0 | AG13: 0 | AH13: 0 | AI13: 1 | AJ13: CONT_1 | AL13: =IF($AJ13="UNKNOWN"," (U1)ALERT_REQ_UNKNOWN"," (U1)"&"ALERT_REQ_"&$AW$17&"_"&IF($AW$6<>$AW$17,$AW$6&"_","")&AJ13) -> (U1)ALERT_REQ_S_TMBZR_BC_AD_CONT_1 | AR13: =IF(AQ78<>"",AQ78,IF(AQ77<>"","};","")) -> (U4)0x00000011U, /* 07 CONT_1 */ | AS13: =IF(AQ143<>"",AQ143,IF(AQ142<>"","};","")) -> (U4)0x000003FFU, /* 07 CONT_1 */ | AT13: =IF(AJ13<>"",AL13&IF(AJ14<>"",","," ")&REPT(" ",78-LEN(AL13))&"/* "&IF(C13<10,"0"&C13,C13)&" "&AJ13&REPT(" ",48-LEN(AJ13))&"*/",IF(AJ12<>"","};","")) -> (U1)ALERT_REQ_S_TMBZR_BC_AD_CONT_1, /* 07 CONT_1 */ | AU13: =" &"&$AW$11&"[0],"&REPT(" ",66-LEN($AW$11))&"/* u1p_DST */" -> &u1_sp_ALERT_S_TMBZR_BC_AD_DST[0], /* u1p_DST */ | AV13: SRCH_NUM | AW13: =COUNTA($AJ$6:$AJ$69) -> 36
C14: =ROW()-ROW($C$6) -> 8 | D14: × | E14: × | F14: × | G14: × | H14: × | I14: × | J14: × | K14: × | L14: × | M14: × | N14: × | O14: × | P14: × | Q14: × | R14: × | S14: × | T14: × | U14: × | V14: × | W14: × | X14: × | Y14: × | Z14: 0 | AA14: 0 | AB14: 0 | AC14: 0 | AD14: 0 | AE14: 1 | AF14: 0 | AG14: 0 | AH14: 1 | AI14: 0 | AJ14: TEN_1 | AL14: =IF($AJ14="UNKNOWN"," (U1)ALERT_REQ_UNKNOWN"," (U1)"&"ALERT_REQ_"&$AW$17&"_"&IF($AW$6<>$AW$17,$AW$6&"_","")&AJ14) -> (U1)ALERT_REQ_S_TMBZR_BC_AD_TEN_1 | AR14: =IF(AQ79<>"",AQ79,IF(AQ78<>"","};","")) -> (U4)0x00000012U, /* 08 TEN_1 */ | AS14: =IF(AQ144<>"",AQ144,IF(AQ143<>"","};","")) -> (U4)0x000003FFU, /* 08 TEN_1 */ | AT14: =IF(AJ14<>"",AL14&IF(AJ15<>"",","," ")&REPT(" ",78-LEN(AL14))&"/* "&IF(C14<10,"0"&C14,C14)&" "&AJ14&REPT(" ",48-LEN(AJ14))&"*/",IF(AJ13<>"","};","")) -> (U1)ALERT_REQ_S_TMBZR_BC_AD_TEN_1, /* 08 TEN_1 */ | AU14: =" (U2)"&$AW$10&","&REPT(" ",66-LEN($AW$10))&"/* u2_num_srch */" -> (U2)ALERT_S_TMBZR_BC_AD_NUM_DST, /* u2_num_srch */ | AV14: SRC CHK | AW14: =IF(AW6<>AW17,VLOOKUP(AW6,Matrix!$C$13:$G$37,4,FALSE),Matrix!F13) -> u4_s_AlertS_tmbzrBcAdSrcchk
C15: =ROW()-ROW($C$6) -> 9 | D15: × | E15: × | F15: × | G15: × | H15: × | I15: × | J15: × | K15: × | L15: × | M15: × | N15: × | O15: × | P15: × | Q15: × | R15: × | S15: × | T15: × | U15: × | V15: × | W15: × | X15: × | Y15: × | Z15: 0 | AA15: 0 | AB15: 0 | AC15: 0 | AD15: 0 | AE15: 1 | AF15: 0 | AG15: 1 | AH15: 0 | AI15: 1 | AJ15: RJT_1 | AL15: =IF($AJ15="UNKNOWN"," (U1)ALERT_REQ_UNKNOWN"," (U1)"&"ALERT_REQ_"&$AW$17&"_"&IF($AW$6<>$AW$17,$AW$6&"_","")&AJ15) -> (U1)ALERT_REQ_S_TMBZR_BC_AD_RJT_1 | AR15: =IF(AQ80<>"",AQ80,IF(AQ79<>"","};","")) -> (U4)0x00000015U, /* 09 RJT_1 */ | AS15: =IF(AQ145<>"",AQ145,IF(AQ144<>"","};","")) -> (U4)0x000003FFU, /* 09 RJT_1 */ | AT15: =IF(AJ15<>"",AL15&IF(AJ16<>"",","," ")&REPT(" ",78-LEN(AL15))&"/* "&IF(C15<10,"0"&C15,C15)&" "&AJ15&REPT(" ",48-LEN(AJ15))&"*/",IF(AJ14<>"","};","")) -> (U1)ALERT_REQ_S_TMBZR_BC_AD_RJT_1, /* 09 RJT_1 */ | AU15: =" (U1)"&$AW$16&REPT(" ",67-LEN($AW$16))&"/* u1_vom_act */" -> (U1)ALERT_VOM_IGN_ON /* u1_vom_act */ | AV15: RWTX | AW15: =IF(AW6<>AW17,VLOOKUP(AW6,Matrix!$C$13:$G$37,5,FALSE),Matrix!G13) -> NULL
C16: =ROW()-ROW($C$6) -> 10 | D16: × | E16: × | F16: × | G16: × | H16: × | I16: × | J16: × | K16: × | L16: × | M16: × | N16: × | O16: × | P16: × | Q16: × | R16: × | S16: × | T16: × | U16: × | V16: × | W16: × | X16: × | Y16: × | Z16: 0 | AA16: 0 | AB16: 0 | AC16: 0 | AD16: 0 | AE16: 1 | AF16: 0 | AG16: 1 | AH16: 1 | AI16: 0 | AJ16: RCV_1 | AL16: =IF($AJ16="UNKNOWN"," (U1)ALERT_REQ_UNKNOWN"," (U1)"&"ALERT_REQ_"&$AW$17&"_"&IF($AW$6<>$AW$17,$AW$6&"_","")&AJ16) -> (U1)ALERT_REQ_S_TMBZR_BC_AD_RCV_1 | AR16: =IF(AQ81<>"",AQ81,IF(AQ80<>"","};","")) -> (U4)0x00000016U, /* 10 RCV_1 */ | AS16: =IF(AQ146<>"",AQ146,IF(AQ145<>"","};","")) -> (U4)0x000003FFU, /* 10 RCV_1 */ | AT16: =IF(AJ16<>"",AL16&IF(AJ17<>"",","," ")&REPT(" ",78-LEN(AL16))&"/* "&IF(C16<10,"0"&C16,C16)&" "&AJ16&REPT(" ",48-LEN(AJ16))&"*/",IF(AJ15<>"","};","")) -> (U1)ALERT_REQ_S_TMBZR_BC_AD_RCV_1, /* 10 RCV_1 */ | AU16: } | AV16: ACT | AW16: =IF(AW6<>AW17,VLOOKUP(AW6,Matrix!$C$13:$G$37,2,FALSE),Matrix!D13) -> ALERT_VOM_IGN_ON
C17: =ROW()-ROW($C$6) -> 11 | D17: × | E17: × | F17: × | G17: × | H17: × | I17: × | J17: × | K17: × | L17: × | M17: × | N17: × | O17: × | P17: × | Q17: × | R17: × | S17: × | T17: × | U17: × | V17: × | W17: × | X17: × | Y17: × | Z17: 0 | AA17: 0 | AB17: 0 | AC17: 0 | AD17: 0 | AE17: 1 | AF17: 0 | AG17: 1 | AH17: 1 | AI17: 1 | AJ17: ANN_1 | AL17: =IF($AJ17="UNKNOWN"," (U1)ALERT_REQ_UNKNOWN"," (U1)"&"ALERT_REQ_"&$AW$17&"_"&IF($AW$6<>$AW$17,$AW$6&"_","")&AJ17) -> (U1)ALERT_REQ_S_TMBZR_BC_AD_ANN_1 | AR17: =IF(AQ82<>"",AQ82,IF(AQ81<>"","};","")) -> (U4)0x00000017U, /* 11 ANN_1 */ | AS17: =IF(AQ147<>"",AQ147,IF(AQ146<>"","};","")) -> (U4)0x000003FFU, /* 11 ANN_1 */ | AT17: =IF(AJ17<>"",AL17&IF(AJ18<>"",","," ")&REPT(" ",78-LEN(AL17))&"/* "&IF(C17<10,"0"&C17,C17)&" "&AJ17&REPT(" ",48-LEN(AJ17))&"*/",IF(AJ16<>"","};","")) -> (U1)ALERT_REQ_S_TMBZR_BC_AD_ANN_1, /* 11 ANN_1 */ | AU17: }; | AV17: ALERT_MTRX変数名 | AW17: =UPPER(Matrix!$D$6) -> S_TMBZR
C18: =ROW()-ROW($C$6) -> 12 | D18: × | E18: × | F18: × | G18: × | H18: × | I18: × | J18: × | K18: × | L18: × | M18: × | N18: × | O18: × | P18: × | Q18: × | R18: × | S18: × | T18: × | U18: × | V18: × | W18: × | X18: × | Y18: × | Z18: 0 | AA18: 0 | AB18: 0 | AC18: 0 | AD18: 1 | AE18: 0 | AF18: 0 | AG18: 0 | AH18: 0 | AI18: 1 | AJ18: CONT_2 | AL18: =IF($AJ18="UNKNOWN"," (U1)ALERT_REQ_UNKNOWN"," (U1)"&"ALERT_REQ_"&$AW$17&"_"&IF($AW$6<>$AW$17,$AW$6&"_","")&AJ18) -> (U1)ALERT_REQ_S_TMBZR_BC_AD_CONT_2 | AR18: =IF(AQ83<>"",AQ83,IF(AQ82<>"","};","")) -> (U4)0x00000021U, /* 12 CONT_2 */ | AS18: =IF(AQ148<>"",AQ148,IF(AQ147<>"","};","")) -> (U4)0x000003FFU, /* 12 CONT_2 */ | AT18: =IF(AJ18<>"",AL18&IF(AJ19<>"",","," ")&REPT(" ",78-LEN(AL18))&"/* "&IF(C18<10,"0"&C18,C18)&" "&AJ18&REPT(" ",48-LEN(AJ18))&"*/",IF(AJ17<>"","};","")) -> (U1)ALERT_REQ_S_TMBZR_BC_AD_CONT_2, /* 12 CONT_2 */
C19: =ROW()-ROW($C$6) -> 13 | D19: × | E19: × | F19: × | G19: × | H19: × | I19: × | J19: × | K19: × | L19: × | M19: × | N19: × | O19: × | P19: × | Q19: × | R19: × | S19: × | T19: × | U19: × | V19: × | W19: × | X19: × | Y19: × | Z19: 0 | AA19: 0 | AB19: 0 | AC19: 0 | AD19: 1 | AE19: 0 | AF19: 0 | AG19: 0 | AH19: 1 | AI19: 0 | AJ19: TEN_2 | AL19: =IF($AJ19="UNKNOWN"," (U1)ALERT_REQ_UNKNOWN"," (U1)"&"ALERT_REQ_"&$AW$17&"_"&IF($AW$6<>$AW$17,$AW$6&"_","")&AJ19) -> (U1)ALERT_REQ_S_TMBZR_BC_AD_TEN_2 | AR19: =IF(AQ84<>"",AQ84,IF(AQ83<>"","};","")) -> (U4)0x00000022U, /* 13 TEN_2 */ | AS19: =IF(AQ149<>"",AQ149,IF(AQ148<>"","};","")) -> (U4)0x000003FFU, /* 13 TEN_2 */ | AT19: =IF(AJ19<>"",AL19&IF(AJ20<>"",","," ")&REPT(" ",78-LEN(AL19))&"/* "&IF(C19<10,"0"&C19,C19)&" "&AJ19&REPT(" ",48-LEN(AJ19))&"*/",IF(AJ18<>"","};","")) -> (U1)ALERT_REQ_S_TMBZR_BC_AD_TEN_2, /* 13 TEN_2 */
C20: =ROW()-ROW($C$6) -> 14 | D20: × | E20: × | F20: × | G20: × | H20: × | I20: × | J20: × | K20: × | L20: × | M20: × | N20: × | O20: × | P20: × | Q20: × | R20: × | S20: × | T20: × | U20: × | V20: × | W20: × | X20: × | Y20: × | Z20: 0 | AA20: 0 | AB20: 0 | AC20: 0 | AD20: 1 | AE20: 0 | AF20: 0 | AG20: 1 | AH20: 0 | AI20: 1 | AJ20: RJT_2 | AL20: =IF($AJ20="UNKNOWN"," (U1)ALERT_REQ_UNKNOWN"," (U1)"&"ALERT_REQ_"&$AW$17&"_"&IF($AW$6<>$AW$17,$AW$6&"_","")&AJ20) -> (U1)ALERT_REQ_S_TMBZR_BC_AD_RJT_2 | AR20: =IF(AQ85<>"",AQ85,IF(AQ84<>"","};","")) -> (U4)0x00000025U, /* 14 RJT_2 */ | AS20: =IF(AQ150<>"",AQ150,IF(AQ149<>"","};","")) -> (U4)0x000003FFU, /* 14 RJT_2 */ | AT20: =IF(AJ20<>"",AL20&IF(AJ21<>"",","," ")&REPT(" ",78-LEN(AL20))&"/* "&IF(C20<10,"0"&C20,C20)&" "&AJ20&REPT(" ",48-LEN(AJ20))&"*/",IF(AJ19<>"","};","")) -> (U1)ALERT_REQ_S_TMBZR_BC_AD_RJT_2, /* 14 RJT_2 */
C21: =ROW()-ROW($C$6) -> 15 | D21: × | E21: × | F21: × | G21: × | H21: × | I21: × | J21: × | K21: × | L21: × | M21: × | N21: × | O21: × | P21: × | Q21: × | R21: × | S21: × | T21: × | U21: × | V21: × | W21: × | X21: × | Y21: × | Z21: 0 | AA21: 0 | AB21: 0 | AC21: 0 | AD21: 1 | AE21: 0 | AF21: 0 | AG21: 1 | AH21: 1 | AI21: 0 | AJ21: RCV_2 | AL21: =IF($AJ21="UNKNOWN"," (U1)ALERT_REQ_UNKNOWN"," (U1)"&"ALERT_REQ_"&$AW$17&"_"&IF($AW$6<>$AW$17,$AW$6&"_","")&AJ21) -> (U1)ALERT_REQ_S_TMBZR_BC_AD_RCV_2 | AR21: =IF(AQ86<>"",AQ86,IF(AQ85<>"","};","")) -> (U4)0x00000026U, /* 15 RCV_2 */ | AS21: =IF(AQ151<>"",AQ151,IF(AQ150<>"","};","")) -> (U4)0x000003FFU, /* 15 RCV_2 */ | AT21: =IF(AJ21<>"",AL21&IF(AJ22<>"",","," ")&REPT(" ",78-LEN(AL21))&"/* "&IF(C21<10,"0"&C21,C21)&" "&AJ21&REPT(" ",48-LEN(AJ21))&"*/",IF(AJ20<>"","};","")) -> (U1)ALERT_REQ_S_TMBZR_BC_AD_RCV_2, /* 15 RCV_2 */
C22: =ROW()-ROW($C$6) -> 16 | D22: × | E22: × | F22: × | G22: × | H22: × | I22: × | J22: × | K22: × | L22: × | M22: × | N22: × | O22: × | P22: × | Q22: × | R22: × | S22: × | T22: × | U22: × | V22: × | W22: × | X22: × | Y22: × | Z22: 0 | AA22: 0 | AB22: 0 | AC22: 0 | AD22: 1 | AE22: 0 | AF22: 0 | AG22: 1 | AH22: 1 | AI22: 1 | AJ22: ANN_2 | AL22: =IF($AJ22="UNKNOWN"," (U1)ALERT_REQ_UNKNOWN"," (U1)"&"ALERT_REQ_"&$AW$17&"_"&IF($AW$6<>$AW$17,$AW$6&"_","")&AJ22) -> (U1)ALERT_REQ_S_TMBZR_BC_AD_ANN_2 | AR22: =IF(AQ87<>"",AQ87,IF(AQ86<>"","};","")) -> (U4)0x00000027U, /* 16 ANN_2 */ | AS22: =IF(AQ152<>"",AQ152,IF(AQ151<>"","};","")) -> (U4)0x000003FFU, /* 16 ANN_2 */ | AT22: =IF(AJ22<>"",AL22&IF(AJ23<>"",","," ")&REPT(" ",78-LEN(AL22))&"/* "&IF(C22<10,"0"&C22,C22)&" "&AJ22&REPT(" ",48-LEN(AJ22))&"*/",IF(AJ21<>"","};","")) -> (U1)ALERT_REQ_S_TMBZR_BC_AD_ANN_2, /* 16 ANN_2 */
C23: =ROW()-ROW($C$6) -> 17 | D23: × | E23: × | F23: × | G23: × | H23: × | I23: × | J23: × | K23: × | L23: × | M23: × | N23: × | O23: × | P23: × | Q23: × | R23: × | S23: × | T23: × | U23: × | V23: × | W23: × | X23: × | Y23: × | Z23: 0 | AA23: 0 | AB23: 0 | AC23: 0 | AD23: 1 | AE23: 1 | AF23: 0 | AG23: 0 | AH23: 0 | AI23: 1 | AJ23: CONT_3 | AL23: =IF($AJ23="UNKNOWN"," (U1)ALERT_REQ_UNKNOWN"," (U1)"&"ALERT_REQ_"&$AW$17&"_"&IF($AW$6<>$AW$17,$AW$6&"_","")&AJ23) -> (U1)ALERT_REQ_S_TMBZR_BC_AD_CONT_3 | AR23: =IF(AQ88<>"",AQ88,IF(AQ87<>"","};","")) -> (U4)0x00000031U, /* 17 CONT_3 */ | AS23: =IF(AQ153<>"",AQ153,IF(AQ152<>"","};","")) -> (U4)0x000003FFU, /* 17 CONT_3 */ | AT23: =IF(AJ23<>"",AL23&IF(AJ24<>"",","," ")&REPT(" ",78-LEN(AL23))&"/* "&IF(C23<10,"0"&C23,C23)&" "&AJ23&REPT(" ",48-LEN(AJ23))&"*/",IF(AJ22<>"","};","")) -> (U1)ALERT_REQ_S_TMBZR_BC_AD_CONT_3, /* 17 CONT_3 */
C24: =ROW()-ROW($C$6) -> 18 | D24: × | E24: × | F24: × | G24: × | H24: × | I24: × | J24: × | K24: × | L24: × | M24: × | N24: × | O24: × | P24: × | Q24: × | R24: × | S24: × | T24: × | U24: × | V24: × | W24: × | X24: × | Y24: × | Z24: 0 | AA24: 0 | AB24: 0 | AC24: 0 | AD24: 1 | AE24: 1 | AF24: 0 | AG24: 0 | AH24: 1 | AI24: 0 | AJ24: TEN_3 | AL24: =IF($AJ24="UNKNOWN"," (U1)ALERT_REQ_UNKNOWN"," (U1)"&"ALERT_REQ_"&$AW$17&"_"&IF($AW$6<>$AW$17,$AW$6&"_","")&AJ24) -> (U1)ALERT_REQ_S_TMBZR_BC_AD_TEN_3 | AR24: =IF(AQ89<>"",AQ89,IF(AQ88<>"","};","")) -> (U4)0x00000032U, /* 18 TEN_3 */ | AS24: =IF(AQ154<>"",AQ154,IF(AQ153<>"","};","")) -> (U4)0x000003FFU, /* 18 TEN_3 */ | AT24: =IF(AJ24<>"",AL24&IF(AJ25<>"",","," ")&REPT(" ",78-LEN(AL24))&"/* "&IF(C24<10,"0"&C24,C24)&" "&AJ24&REPT(" ",48-LEN(AJ24))&"*/",IF(AJ23<>"","};","")) -> (U1)ALERT_REQ_S_TMBZR_BC_AD_TEN_3, /* 18 TEN_3 */
C25: =ROW()-ROW($C$6) -> 19 | D25: × | E25: × | F25: × | G25: × | H25: × | I25: × | J25: × | K25: × | L25: × | M25: × | N25: × | O25: × | P25: × | Q25: × | R25: × | S25: × | T25: × | U25: × | V25: × | W25: × | X25: × | Y25: × | Z25: 0 | AA25: 0 | AB25: 0 | AC25: 0 | AD25: 1 | AE25: 1 | AF25: 0 | AG25: 1 | AH25: 0 | AI25: 1 | AJ25: RJT_3 | AL25: =IF($AJ25="UNKNOWN"," (U1)ALERT_REQ_UNKNOWN"," (U1)"&"ALERT_REQ_"&$AW$17&"_"&IF($AW$6<>$AW$17,$AW$6&"_","")&AJ25) -> (U1)ALERT_REQ_S_TMBZR_BC_AD_RJT_3 | AR25: =IF(AQ90<>"",AQ90,IF(AQ89<>"","};","")) -> (U4)0x00000035U, /* 19 RJT_3 */ | AS25: =IF(AQ155<>"",AQ155,IF(AQ154<>"","};","")) -> (U4)0x000003FFU, /* 19 RJT_3 */ | AT25: =IF(AJ25<>"",AL25&IF(AJ26<>"",","," ")&REPT(" ",78-LEN(AL25))&"/* "&IF(C25<10,"0"&C25,C25)&" "&AJ25&REPT(" ",48-LEN(AJ25))&"*/",IF(AJ24<>"","};","")) -> (U1)ALERT_REQ_S_TMBZR_BC_AD_RJT_3, /* 19 RJT_3 */
C26: =ROW()-ROW($C$6) -> 20 | D26: × | E26: × | F26: × | G26: × | H26: × | I26: × | J26: × | K26: × | L26: × | M26: × | N26: × | O26: × | P26: × | Q26: × | R26: × | S26: × | T26: × | U26: × | V26: × | W26: × | X26: × | Y26: × | Z26: 0 | AA26: 0 | AB26: 0 | AC26: 0 | AD26: 1 | AE26: 1 | AF26: 0 | AG26: 1 | AH26: 1 | AI26: 0 | AJ26: RCV_3 | AL26: =IF($AJ26="UNKNOWN"," (U1)ALERT_REQ_UNKNOWN"," (U1)"&"ALERT_REQ_"&$AW$17&"_"&IF($AW$6<>$AW$17,$AW$6&"_","")&AJ26) -> (U1)ALERT_REQ_S_TMBZR_BC_AD_RCV_3 | AR26: =IF(AQ91<>"",AQ91,IF(AQ90<>"","};","")) -> (U4)0x00000036U, /* 20 RCV_3 */ | AS26: =IF(AQ156<>"",AQ156,IF(AQ155<>"","};","")) -> (U4)0x000003FFU, /* 20 RCV_3 */ | AT26: =IF(AJ26<>"",AL26&IF(AJ27<>"",","," ")&REPT(" ",78-LEN(AL26))&"/* "&IF(C26<10,"0"&C26,C26)&" "&AJ26&REPT(" ",48-LEN(AJ26))&"*/",IF(AJ25<>"","};","")) -> (U1)ALERT_REQ_S_TMBZR_BC_AD_RCV_3, /* 20 RCV_3 */
C27: =ROW()-ROW($C$6) -> 21 | D27: × | E27: × | F27: × | G27: × | H27: × | I27: × | J27: × | K27: × | L27: × | M27: × | N27: × | O27: × | P27: × | Q27: × | R27: × | S27: × | T27: × | U27: × | V27: × | W27: × | X27: × | Y27: × | Z27: 0 | AA27: 0 | AB27: 0 | AC27: 0 | AD27: 1 | AE27: 1 | AF27: 0 | AG27: 1 | AH27: 1 | AI27: 1 | AJ27: ANN_3 | AL27: =IF($AJ27="UNKNOWN"," (U1)ALERT_REQ_UNKNOWN"," (U1)"&"ALERT_REQ_"&$AW$17&"_"&IF($AW$6<>$AW$17,$AW$6&"_","")&AJ27) -> (U1)ALERT_REQ_S_TMBZR_BC_AD_ANN_3 | AR27: =IF(AQ92<>"",AQ92,IF(AQ91<>"","};","")) -> (U4)0x00000037U, /* 21 ANN_3 */ | AS27: =IF(AQ157<>"",AQ157,IF(AQ156<>"","};","")) -> (U4)0x000003FFU, /* 21 ANN_3 */ | AT27: =IF(AJ27<>"",AL27&IF(AJ28<>"",","," ")&REPT(" ",78-LEN(AL27))&"/* "&IF(C27<10,"0"&C27,C27)&" "&AJ27&REPT(" ",48-LEN(AJ27))&"*/",IF(AJ26<>"","};","")) -> (U1)ALERT_REQ_S_TMBZR_BC_AD_ANN_3, /* 21 ANN_3 */
C28: =ROW()-ROW($C$6) -> 22 | D28: × | E28: × | F28: × | G28: × | H28: × | I28: × | J28: × | K28: × | L28: × | M28: × | N28: × | O28: × | P28: × | Q28: × | R28: × | S28: × | T28: × | U28: × | V28: × | W28: × | X28: × | Y28: × | Z28: 0 | AA28: 0 | AB28: 0 | AC28: 1 | AD28: 0 | AE28: 0 | AF28: 0 | AG28: 0 | AH28: 0 | AI28: 1 | AJ28: CONT_4 | AL28: =IF($AJ28="UNKNOWN"," (U1)ALERT_REQ_UNKNOWN"," (U1)"&"ALERT_REQ_"&$AW$17&"_"&IF($AW$6<>$AW$17,$AW$6&"_","")&AJ28) -> (U1)ALERT_REQ_S_TMBZR_BC_AD_CONT_4 | AR28: =IF(AQ93<>"",AQ93,IF(AQ92<>"","};","")) -> (U4)0x00000041U, /* 22 CONT_4 */ | AS28: =IF(AQ158<>"",AQ158,IF(AQ157<>"","};","")) -> (U4)0x000003FFU, /* 22 CONT_4 */ | AT28: =IF(AJ28<>"",AL28&IF(AJ29<>"",","," ")&REPT(" ",78-LEN(AL28))&"/* "&IF(C28<10,"0"&C28,C28)&" "&AJ28&REPT(" ",48-LEN(AJ28))&"*/",IF(AJ27<>"","};","")) -> (U1)ALERT_REQ_S_TMBZR_BC_AD_CONT_4, /* 22 CONT_4 */
C29: =ROW()-ROW($C$6) -> 23 | D29: × | E29: × | F29: × | G29: × | H29: × | I29: × | J29: × | K29: × | L29: × | M29: × | N29: × | O29: × | P29: × | Q29: × | R29: × | S29: × | T29: × | U29: × | V29: × | W29: × | X29: × | Y29: × | Z29: 0 | AA29: 0 | AB29: 0 | AC29: 1 | AD29: 0 | AE29: 0 | AF29: 0 | AG29: 0 | AH29: 1 | AI29: 0 | AJ29: TEN_4 | AL29: =IF($AJ29="UNKNOWN"," (U1)ALERT_REQ_UNKNOWN"," (U1)"&"ALERT_REQ_"&$AW$17&"_"&IF($AW$6<>$AW$17,$AW$6&"_","")&AJ29) -> (U1)ALERT_REQ_S_TMBZR_BC_AD_TEN_4 | AR29: =IF(AQ94<>"",AQ94,IF(AQ93<>"","};","")) -> (U4)0x00000042U, /* 23 TEN_4 */ | AS29: =IF(AQ159<>"",AQ159,IF(AQ158<>"","};","")) -> (U4)0x000003FFU, /* 23 TEN_4 */ | AT29: =IF(AJ29<>"",AL29&IF(AJ30<>"",","," ")&REPT(" ",78-LEN(AL29))&"/* "&IF(C29<10,"0"&C29,C29)&" "&AJ29&REPT(" ",48-LEN(AJ29))&"*/",IF(AJ28<>"","};","")) -> (U1)ALERT_REQ_S_TMBZR_BC_AD_TEN_4, /* 23 TEN_4 */
... C41: =ROW()-ROW($C$6) -> 35 | D41: × | E41: × | F41: × | G41: × | H41: × | I41: × | J41: × | K41: × | L41: × | M41: × | N41: × | O41: × | P41: × | Q41: × | R41: × | S41: × | T41: × | U41: × | V41: × | W41: × | X41: × | Y41: × | Z41: 0 | AA41: 0 | AB41: 1 | AC41: 0 | AD41: 1 | AE41: 0 | AF41: 0 | AG41: 1 | AH41: 0 | AI41: 0 | AJ41: TEN_8 | AL41: =IF($AJ41="UNKNOWN"," (U1)ALERT_REQ_UNKNOWN"," (U1)"&"ALERT_REQ_"&$AW$17&"_"&IF($AW$6<>$AW$17,$AW$6&"_","")&AJ41) -> (U1)ALERT_REQ_S_TMBZR_BC_AD_TEN_8 | AR41: =IF(AQ106<>"",AQ106,IF(AQ105<>"","};","")) -> (U4)0x000000A4U /* 35 TEN_8 */ | AS41: =IF(AQ171<>"",AQ171,IF(AQ170<>"","};","")) -> (U4)0x000003FFU /* 35 TEN_8 */ | AT41: =IF(AJ41<>"",AL41&IF(AJ42<>"",","," ")&REPT(" ",78-LEN(AL41))&"/* "&IF(C41<10,"0"&C41,C41)&" "&AJ41&REPT(" ",48-LEN(AJ41))&"*/",IF(AJ40<>"","};","")) -> (U1)ALERT_REQ_S_TMBZR_BC_AD_TEN_8 /* 35 TEN_8 */
C42: =ROW()-ROW($C$6) -> 36 | D42: × | E42: × | F42: × | G42: × | H42: × | I42: × | J42: × | K42: × | L42: × | M42: × | N42: × | O42: × | P42: × | Q42: × | R42: × | S42: × | T42: × | U42: × | V42: × | W42: × | X42: × | Y42: × | Z42: × | AA42: × | AB42: × | AC42: × | AD42: × | AE42: × | AF42: × | AG42: × | AH42: × | AI42: × | AL42: =IF($AJ42="UNKNOWN"," (U1)ALERT_REQ_UNKNOWN"," (U1)"&"ALERT_REQ_"&$AW$17&"_"&IF($AW$6<>$AW$17,$AW$6&"_","")&AJ42) -> (U1)ALERT_REQ_S_TMBZR_BC_AD_ | AR42: =IF(AQ107<>"",AQ107,IF(AQ106<>"","};","")) -> }; | AS42: =IF(AQ172<>"",AQ172,IF(AQ171<>"","};","")) -> }; | AT42: =IF(AJ42<>"",AL42&IF(AJ43<>"",","," ")&REPT(" ",78-LEN(AL42))&"/* "&IF(C42<10,"0"&C42,C42)&" "&AJ42&REPT(" ",48-LEN(AJ42))&"*/",IF(AJ41<>"","};","")) -> };
C43: =ROW()-ROW($C$6) -> 37 | D43: × | E43: × | F43: × | G43: × | H43: × | I43: × | J43: × | K43: × | L43: × | M43: × | N43: × | O43: × | P43: × | Q43: × | R43: × | S43: × | T43: × | U43: × | V43: × | W43: × | X43: × | Y43: × | Z43: × | AA43: × | AB43: × | AC43: × | AD43: × | AE43: × | AF43: × | AG43: × | AH43: × | AI43: × | AL43: =IF($AJ43="UNKNOWN"," (U1)ALERT_REQ_UNKNOWN"," (U1)"&"ALERT_REQ_"&$AW$17&"_"&IF($AW$6<>$AW$17,$AW$6&"_","")&AJ43) -> (U1)ALERT_REQ_S_TMBZR_BC_AD_ | AR43: =IF(AQ108<>"",AQ108,IF(AQ107<>"","};","")) | AS43: =IF(AQ173<>"",AQ173,IF(AQ172<>"","};","")) | AT43: =IF(AJ43<>"",AL43&IF(AJ44<>"",","," ")&REPT(" ",78-LEN(AL43))&"/* "&IF(C43<10,"0"&C43,C43)&" "&AJ43&REPT(" ",48-LEN(AJ43))&"*/",IF(AJ42<>"","};",""))
C44: =ROW()-ROW($C$6) -> 38 | D44: × | E44: × | F44: × | G44: × | H44: × | I44: × | J44: × | K44: × | L44: × | M44: × | N44: × | O44: × | P44: × | Q44: × | R44: × | S44: × | T44: × | U44: × | V44: × | W44: × | X44: × | Y44: × | Z44: × | AA44: × | AB44: × | AC44: × | AD44: × | AE44: × | AF44: × | AG44: × | AH44: × | AI44: × | AL44: =IF($AJ44="UNKNOWN"," (U1)ALERT_REQ_UNKNOWN"," (U1)"&"ALERT_REQ_"&$AW$17&"_"&IF($AW$6<>$AW$17,$AW$6&"_","")&AJ44) -> (U1)ALERT_REQ_S_TMBZR_BC_AD_ | AR44: =IF(AQ109<>"",AQ109,IF(AQ108<>"","};","")) | AS44: =IF(AQ174<>"",AQ174,IF(AQ173<>"","};","")) | AT44: =IF(AJ44<>"",AL44&IF(AJ45<>"",","," ")&REPT(" ",78-LEN(AL44))&"/* "&IF(C44<10,"0"&C44,C44)&" "&AJ44&REPT(" ",48-LEN(AJ44))&"*/",IF(AJ43<>"","};",""))
C45: =ROW()-ROW($C$6) -> 39 | D45: × | E45: × | F45: × | G45: × | H45: × | I45: × | J45: × | K45: × | L45: × | M45: × | N45: × | O45: × | P45: × | Q45: × | R45: × | S45: × | T45: × | U45: × | V45: × | W45: × | X45: × | Y45: × | Z45: × | AA45: × | AB45: × | AC45: × | AD45: × | AE45: × | AF45: × | AG45: × | AH45: × | AI45: × | AL45: =IF($AJ45="UNKNOWN"," (U1)ALERT_REQ_UNKNOWN"," (U1)"&"ALERT_REQ_"&$AW$17&"_"&IF($AW$6<>$AW$17,$AW$6&"_","")&AJ45) -> (U1)ALERT_REQ_S_TMBZR_BC_AD_ | AR45: =IF(AQ110<>"",AQ110,IF(AQ109<>"","};","")) | AS45: =IF(AQ175<>"",AQ175,IF(AQ174<>"","};","")) | AT45: =IF(AJ45<>"",AL45&IF(AJ46<>"",","," ")&REPT(" ",78-LEN(AL45))&"/* "&IF(C45<10,"0"&C45,C45)&" "&AJ45&REPT(" ",48-LEN(AJ45))&"*/",IF(AJ44<>"","};",""))
C46: =ROW()-ROW($C$6) -> 40 | D46: × | E46: × | F46: × | G46: × | H46: × | I46: × | J46: × | K46: × | L46: × | M46: × | N46: × | O46: × | P46: × | Q46: × | R46: × | S46: × | T46: × | U46: × | V46: × | W46: × | X46: × | Y46: × | Z46: × | AA46: × | AB46: × | AC46: × | AD46: × | AE46: × | AF46: × | AG46: × | AH46: × | AI46: × | AL46: =IF($AJ46="UNKNOWN"," (U1)ALERT_REQ_UNKNOWN"," (U1)"&"ALERT_REQ_"&$AW$17&"_"&IF($AW$6<>$AW$17,$AW$6&"_","")&AJ46) -> (U1)ALERT_REQ_S_TMBZR_BC_AD_ | AR46: =IF(AQ111<>"",AQ111,IF(AQ110<>"","};","")) | AS46: =IF(AQ176<>"",AQ176,IF(AQ175<>"","};","")) | AT46: =IF(AJ46<>"",AL46&IF(AJ47<>"",","," ")&REPT(" ",78-LEN(AL46))&"/* "&IF(C46<10,"0"&C46,C46)&" "&AJ46&REPT(" ",48-LEN(AJ46))&"*/",IF(AJ45<>"","};",""))
C47: =ROW()-ROW($C$6) -> 41 | D47: × | E47: × | F47: × | G47: × | H47: × | I47: × | J47: × | K47: × | L47: × | M47: × | N47: × | O47: × | P47: × | Q47: × | R47: × | S47: × | T47: × | U47: × | V47: × | W47: × | X47: × | Y47: × | Z47: × | AA47: × | AB47: × | AC47: × | AD47: × | AE47: × | AF47: × | AG47: × | AH47: × | AI47: × | AL47: =IF($AJ47="UNKNOWN"," (U1)ALERT_REQ_UNKNOWN"," (U1)"&"ALERT_REQ_"&$AW$17&"_"&IF($AW$6<>$AW$17,$AW$6&"_","")&AJ47) -> (U1)ALERT_REQ_S_TMBZR_BC_AD_ | AR47: =IF(AQ112<>"",AQ112,IF(AQ111<>"","};","")) | AS47: =IF(AQ177<>"",AQ177,IF(AQ176<>"","};","")) | AT47: =IF(AJ47<>"",AL47&IF(AJ48<>"",","," ")&REPT(" ",78-LEN(AL47))&"/* "&IF(C47<10,"0"&C47,C47)&" "&AJ47&REPT(" ",48-LEN(AJ47))&"*/",IF(AJ46<>"","};",""))
C48: =ROW()-ROW($C$6) -> 42 | D48: × | E48: × | F48: × | G48: × | H48: × | I48: × | J48: × | K48: × | L48: × | M48: × | N48: × | O48: × | P48: × | Q48: × | R48: × | S48: × | T48: × | U48: × | V48: × | W48: × | X48: × | Y48: × | Z48: × | AA48: × | AB48: × | AC48: × | AD48: × | AE48: × | AF48: × | AG48: × | AH48: × | AI48: × | AL48: =IF($AJ48="UNKNOWN"," (U1)ALERT_REQ_UNKNOWN"," (U1)"&"ALERT_REQ_"&$AW$17&"_"&IF($AW$6<>$AW$17,$AW$6&"_","")&AJ48) -> (U1)ALERT_REQ_S_TMBZR_BC_AD_ | AR48: =IF(AQ113<>"",AQ113,IF(AQ112<>"","};","")) | AS48: =IF(AQ178<>"",AQ178,IF(AQ177<>"","};","")) | AT48: =IF(AJ48<>"",AL48&IF(AJ49<>"",","," ")&REPT(" ",78-LEN(AL48))&"/* "&IF(C48<10,"0"&C48,C48)&" "&AJ48&REPT(" ",48-LEN(AJ48))&"*/",IF(AJ47<>"","};",""))
C49: =ROW()-ROW($C$6) -> 43 | D49: × | E49: × | F49: × | G49: × | H49: × | I49: × | J49: × | K49: × | L49: × | M49: × | N49: × | O49: × | P49: × | Q49: × | R49: × | S49: × | T49: × | U49: × | V49: × | W49: × | X49: × | Y49: × | Z49: × | AA49: × | AB49: × | AC49: × | AD49: × | AE49: × | AF49: × | AG49: × | AH49: × | AI49: × | AL49: =IF($AJ49="UNKNOWN"," (U1)ALERT_REQ_UNKNOWN"," (U1)"&"ALERT_REQ_"&$AW$17&"_"&IF($AW$6<>$AW$17,$AW$6&"_","")&AJ49) -> (U1)ALERT_REQ_S_TMBZR_BC_AD_ | AR49: =IF(AQ114<>"",AQ114,IF(AQ113<>"","};","")) | AS49: =IF(AQ179<>"",AQ179,IF(AQ178<>"","};","")) | AT49: =IF(AJ49<>"",AL49&IF(AJ50<>"",","," ")&REPT(" ",78-LEN(AL49))&"/* "&IF(C49<10,"0"&C49,C49)&" "&AJ49&REPT(" ",48-LEN(AJ49))&"*/",IF(AJ48<>"","};",""))
C50: =ROW()-ROW($C$6) -> 44 | D50: × | E50: × | F50: × | G50: × | H50: × | I50: × | J50: × | K50: × | L50: × | M50: × | N50: × | O50: × | P50: × | Q50: × | R50: × | S50: × | T50: × | U50: × | V50: × | W50: × | X50: × | Y50: × | Z50: × | AA50: × | AB50: × | AC50: × | AD50: × | AE50: × | AF50: × | AG50: × | AH50: × | AI50: × | AL50: =IF($AJ50="UNKNOWN"," (U1)ALERT_REQ_UNKNOWN"," (U1)"&"ALERT_REQ_"&$AW$17&"_"&IF($AW$6<>$AW$17,$AW$6&"_","")&AJ50) -> (U1)ALERT_REQ_S_TMBZR_BC_AD_ | AR50: =IF(AQ115<>"",AQ115,IF(AQ114<>"","};","")) | AS50: =IF(AQ180<>"",AQ180,IF(AQ179<>"","};","")) | AT50: =IF(AJ50<>"",AL50&IF(AJ51<>"",","," ")&REPT(" ",78-LEN(AL50))&"/* "&IF(C50<10,"0"&C50,C50)&" "&AJ50&REPT(" ",48-LEN(AJ50))&"*/",IF(AJ49<>"","};",""))
