Workbook
Name ■削除項目: #REF!
Name ■削除項目: #REF!
Name ChangeNoListDD: [1]集計表!$F$6:$F$11
Name DefaultFontType: #REF!
Name DotPitch: #REF!
Name 計画検討者: #REF!
Name 計画検討者: #REF!
Name 計画検討日: #REF!
Name 計画検討日: #REF!
Name 計画作成者: #REF!
Name 計画作成者: #REF!
Name 計画作成日: #REF!
Name 計画作成日: #REF!
Name 計画承認者: #REF!
Name 計画承認者: #REF!
Name 計画承認日: #REF!
Name 計画承認日: #REF!
Name 実施検討者: #REF!
Name 実施検討者: #REF!
Name 実施検討日: #REF!
Name 実施検討日: #REF!
Name 実施作成者: #REF!
Name 実施作成者: #REF!
Name 実施作成日: #REF!
Name 実施作成日: #REF!
Name 実施承認者: #REF!
Name 実施承認者: #REF!
Name 実施承認日: #REF!
Name 実施承認日: #REF!

Sheet 表紙（承認）
A9: =MID(CELL("filename",A1), FIND("[",CELL("filename",A1))+1, FIND("]",CELL("filename",A1))-FIND("[",CELL("filename",A1))-6) -> alert_S_ADTJA-CSTD-0-02-A-C0
Y26: (株)デンソー
Y27: 承認 | AD27: 検討 | AI27: 作成
AA30: <DN確認印> | AF30: <DN検討印>
Y34: デンソーテクノ（株） HMI3部2室
Y35: 承認 | AD35: 検討 | AI35: 作成
AA38: <DT確認印> | AF38: <DT検討印> | AK38: <DT検討印>
Y42: DENSO TECHNO PHIL. INC
Y43: 承認 | AD43: 検討 | AI43: 作成

Sheet 表紙
H2: コンポーネント | I2: Vom::Alert
D3: =REPLACE(LEFT(CELL("filename",$B$1),FIND(".xls",CELL("filename",$B$1))-1),1,FIND("[",CELL("filename",$B$1)),) -> alert_S_ADTJA-CSTD-0-02-A-C0 | H3: Gitリポジトリ | I3: https://aip01.dndev.net/bitbucket/scm/aip_tp/tmcapp_ict1_alert.git
E4: =DGET(B8:C14,"Ver.",H4:H5) -> 1.0.1 | H4: ROW
H5: =MAX(B9:B14) -> 2
C7: 更新履歴 | E7: 対象ソフトVer | G7: 承認欄 [DENSO] | M7: 承認欄 [NTTデータMSE] | S7: 承認欄 [DT]
B8: ROW | C8: Ver. | D8: 更新内容 | E8: Git(CommitID) | F8: Component Version | G8: 承認者 | H8: 承認日 | I8: 検討者 | J8: 検討日 | K8: 作成者 | L8: 作成日 | M8: 承認者 | N8: 承認日 | O8: 検討者 | P8: 検討日 | Q8: 作成者 | R8: 作成日 | S8: 承認者 | T8: 承認日 | U8: 検討者 | V8: 検討日 | W8: 作成者 | X8: 作成日
B9: =IF(C9=0,0,ROW()-ROW($B$8)) -> 1 | C9: 1.0.0 | D9: 新規作成 | E9: - | F9: 5.5.0 | G9: - | H9: - | I9: - | J9: - | K9: - | L9: - | M9: - | N9: - | O9: - | P9: - | Q9: - | R9: - | S9: - | T9: - | U9: - | V9: - | W9: DT Anna | X9: 45251
B10: =IF(C10=0,0,ROW()-ROW($B$8)) -> 2 | C10: 1.0.1 | D10: 品質総点検(R4)：Alert設計書の修正対応 ファイル名の変更（変更前：alert_S_ADTJA-CSTD-0-01-A-C0.xlsx） [Matrix]シート ・対象仕様書の変更 ・ロケーションの変更 | E10: - | F10: 5.5.0 | G10: - | H10: - | I10: - | J10: - | K10: - | L10: - | M10: - | N10: - | O10: - | P10: - | Q10: - | R10: - | S10: - | T10: - | U10: - | V10: - | W10: DTPH JM | X10: 45811
B11: =IF(C11=0,0,ROW()-ROW($B$8)) -> 0
B12: =IF(C12=0,0,ROW()-ROW($B$8)) -> 0
B13: =IF(C13=0,0,ROW()-ROW($B$8)) -> 0

Sheet はじめに
B2: １．本書の目的
C3: TMC Specを分析した結果で、Vom::Alertの実装に必要となる情報を抽出し、Alert Config Toolのインプットとする。
B6: ２．上位文書
C7: # | E7: path
C8: 0 | D8: Alert設計資料 | E8: https://aip01.dndev.net/svn/aip/tmcapp/sd/evidence/trunk/02_Design/01_Vom/Alert/03_Component/alert_design.pptx
B12: ３．用語の説明
C13: # | D13: 用語 | E13: 説明
C14: 0 | D14: Alert Config Tool | E14: TMC Specと本設計書のトレースをデータベース管理するTool。
C15: 1 | D15: TT | E15: Telltale
C16: 2 | D16: PD | E16: Pop-up Display
C17: 3 | D17: BC | E17: Buzzer/Chime
C18: 4 | D18: RW | E18: Remote Warning
C19: 5 | D19: CH | E19: Alert Channel。 各Specを分析した結果で決定されるモジュール内分割単位。
C20: 6 | D20: VOM | E20: Vehicle Operation Mode
B24: ４．各シートの説明
C25: # | D25: 用語 | E25: 説明
C26: 0 | D26: Matrix | E26: 対象となるTMC Specならびに分析した結果で決定されるAlert Channel情報について記載する。 Alert Config Toolのインプットとする。
C27: 1 | D27: CH_Design | E27: 対象のTMC Specにおいて、Vom::Alertが外部に提供する各CHの出力(REQ)について記載する。 機能判定欄については、出力先によって実施責務が異なるため、出力先毎に有無を記載する。 TT機能判定、BC機能判定、PD機能判定 ： VSV側にて参照 RW機能判定 ： Vom::Alertにて参照 TMC Specにて定義される機能有無判定の要否について抽出した結果で記載する。 ※機種(e.x.775B)毎の要否ではないため、対象機種に応じた更新(メンテナンス)は行わない。 PD欄については、Alert制御仕様書にて定義されるWarning Noを記載する。 Alert Config Toolのインプットとする。
C28: 2 | D28: Config_IF | E28: 対象のTMC Specにおいて、 Vom::Alertが使用する外部ドメインIF Vom::Alertが使用するConfig IF、定義 について記載する。 Alert Config Toolのインプットとする。
C29: 3 | D29: TT/BC | E29: シート名は各CH名を採用する。 対象のTMC Specを分析した結果で、各CHのインプット/アウトプットの判定条件について記載する。 コーディング時のインプットとする。
C30: 4 | D30: Reference | E30: 対象のTMC Specを分析した際の中間成果物。参考情報として記載。メンテナンス対象外。
C31: 5 | D31: History | E31: テンプレート変更履歴
B37: ５．入力セルの凡例
E38: ユーザ入力セル
E39: 自動計算セル

Sheet Matrix
B2: 対象仕様書 | D2: MET-S_ADTJA-CSTD-0-02-A-C0.xlsm
B3: ロケーション | D3: https://aip01.dndev.net/svn/met/toyota/std/rd/spec/19PFver3/tags/00.Product/v4.12.d/
B4: モジュール名 | D4: =表紙!D3&".c" -> alert_S_ADTJA-CSTD-0-02-A-C0.c
D5: =IF(LEN(表紙!D3&".c") = LENB(表紙!D3&".c"),"※モジュール名 全角チェックOK","※モジュール名 全角チェックNG：ファイル名に全角文字が使用されています！") -> ※モジュール名 全角チェックOK
B6: 機能名 | D6: =MID(D4, LEN("alert_") + 1, FIND("-",D4,1) - LEN("alert_") - 1) -> S_ADTJA
B7: 判定要素数 | D7: =COUNTA($D$13:$D$37) -> 10
B8: Matrix名 | D8: ="st_gp_ALERT_"&UPPER(D6)&"_MTRX" -> st_gp_ALERT_S_ADTJA_MTRX
B9: 初期化関数名 | D9: NULL
B10: 処理時間 | D10: -
B12: No | C12: CH Name | D12: VOM | E12: RW | F12: Srcchk | G12: RwTx | H12: CH | I12: REQ | K12: VOM | L12: 初期化関数名 | M12: CH名称中間データ
B13: 1 | C13: TT | D13: ALERT_VOM_IGN_ON | E13: － | F13: =IF($D13<>"","u4_s_Alert"&UPPER(LEFT($D$6,1))&LOWER(MID($D$6,2,100))&IF($D$7=1,"",N13)&"Srcchk","") -> u4_s_AlertS_adtjaTtSrcchk | G13: =IF($D13<>"",IF($E13="○","vd_s_Alert"&UPPER(LEFT($D$6,1))&LOWER(MID($D$6,2,100))&IF($D$7=1,"",N13)&"RwTx","NULL"),"") -> NULL | H13: =IF($D13<>"","ALERT_CH_"&UPPER($D$6)&IF($D$7=1,"","_"&UPPER($C13)),"") -> ALERT_CH_S_ADTJA_TT | I13: =IF($D13<>"","ALERT_REQ_"&UPPER($D$6)&IF($D$7=1,"","_"&UPPER($C13)),"") -> ALERT_REQ_S_ADTJA_TT | K13: ALERT_VOM_BAT_AO | L13: NULL | M13: =FIND("_",C13,1) -> #VALUE! | N13: =IF(IFERROR(M13,0),UPPER(LEFT(C13,1))&LOWER(MID(C13,2,M13-2))&UPPER(MID(C13,M13+1,1))&LOWER(MID(C13,M13+2,100)),UPPER(LEFT(C13,1))&LOWER(MID(C13,2,100))) -> Tt
B14: 2 | C14: TT_DMCR | D14: ALERT_VOM_IGN_ON | E14: － | F14: =IF($D14<>"","u4_s_Alert"&UPPER(LEFT($D$6,1))&LOWER(MID($D$6,2,100))&IF($D$7=1,"",N14)&"Srcchk","") -> u4_s_AlertS_adtjaTtDmcrSrcchk | G14: =IF($D14<>"",IF($E14="○","vd_s_Alert"&UPPER(LEFT($D$6,1))&LOWER(MID($D$6,2,100))&IF($D$7=1,"",N14)&"RwTx","NULL"),"") -> NULL | H14: =IF($D14<>"","ALERT_CH_"&UPPER($D$6)&IF($D$7=1,"","_"&UPPER($C14)),"") -> ALERT_CH_S_ADTJA_TT_DMCR | I14: =IF($D14<>"","ALERT_REQ_"&UPPER($D$6)&IF($D$7=1,"","_"&UPPER($C14)),"") -> ALERT_REQ_S_ADTJA_TT_DMCR | K14: ALERT_VOM_BAT_WT | L14: ="vd_g_Alert"&UPPER(LEFT(D6,1))&LOWER(MID(D6,2,100))&"Init" -> vd_g_AlertS_adtjaInit | M14: =FIND("_",C14,1) -> 3 | N14: =IF(IFERROR(M14,0),UPPER(LEFT(C14,1))&LOWER(MID(C14,2,M14-2))&UPPER(MID(C14,M14+1,1))&LOWER(MID(C14,M14+2,100)),UPPER(LEFT(C14,1))&LOWER(MID(C14,2,100))) -> TtDmcr
B15: 3 | C15: BC | D15: ALERT_VOM_IGN_ON | E15: － | F15: =IF($D15<>"","u4_s_Alert"&UPPER(LEFT($D$6,1))&LOWER(MID($D$6,2,100))&IF($D$7=1,"",N15)&"Srcchk","") -> u4_s_AlertS_adtjaBcSrcchk | G15: =IF($D15<>"",IF($E15="○","vd_s_Alert"&UPPER(LEFT($D$6,1))&LOWER(MID($D$6,2,100))&IF($D$7=1,"",N15)&"RwTx","NULL"),"") -> NULL | H15: =IF($D15<>"","ALERT_CH_"&UPPER($D$6)&IF($D$7=1,"","_"&UPPER($C15)),"") -> ALERT_CH_S_ADTJA_BC | I15: =IF($D15<>"","ALERT_REQ_"&UPPER($D$6)&IF($D$7=1,"","_"&UPPER($C15)),"") -> ALERT_REQ_S_ADTJA_BC | K15: ALERT_VOM_IGN_OFF | M15: =FIND("_",C15,1) -> #VALUE! | N15: =IF(IFERROR(M15,0),UPPER(LEFT(C15,1))&LOWER(MID(C15,2,M15-2))&UPPER(MID(C15,M15+1,1))&LOWER(MID(C15,M15+2,100)),UPPER(LEFT(C15,1))&LOWER(MID(C15,2,100))) -> Bc
B16: 4 | C16: PD | D16: ALERT_VOM_IGN_ON | E16: － | F16: =IF($D16<>"","u4_s_Alert"&UPPER(LEFT($D$6,1))&LOWER(MID($D$6,2,100))&IF($D$7=1,"",N16)&"Srcchk","") -> u4_s_AlertS_adtjaPdSrcchk | G16: =IF($D16<>"",IF($E16="○","vd_s_Alert"&UPPER(LEFT($D$6,1))&LOWER(MID($D$6,2,100))&IF($D$7=1,"",N16)&"RwTx","NULL"),"") -> NULL | H16: =IF($D16<>"","ALERT_CH_"&UPPER($D$6)&IF($D$7=1,"","_"&UPPER($C16)),"") -> ALERT_CH_S_ADTJA_PD | I16: =IF($D16<>"","ALERT_REQ_"&UPPER($D$6)&IF($D$7=1,"","_"&UPPER($C16)),"") -> ALERT_REQ_S_ADTJA_PD | K16: ALERT_VOM_IGN_OFF_WT | M16: =FIND("_",C16,1) -> #VALUE! | N16: =IF(IFERROR(M16,0),UPPER(LEFT(C16,1))&LOWER(MID(C16,2,M16-2))&UPPER(MID(C16,M16+1,1))&LOWER(MID(C16,M16+2,100)),UPPER(LEFT(C16,1))&LOWER(MID(C16,2,100))) -> Pd
B17: 5 | C17: PD_RQHN | D17: ALERT_VOM_IGN_ON | E17: － | F17: =IF($D17<>"","u4_s_Alert"&UPPER(LEFT($D$6,1))&LOWER(MID($D$6,2,100))&IF($D$7=1,"",N17)&"Srcchk","") -> u4_s_AlertS_adtjaPdRqhnSrcchk | G17: =IF($D17<>"",IF($E17="○","vd_s_Alert"&UPPER(LEFT($D$6,1))&LOWER(MID($D$6,2,100))&IF($D$7=1,"",N17)&"RwTx","NULL"),"") -> NULL | H17: =IF($D17<>"","ALERT_CH_"&UPPER($D$6)&IF($D$7=1,"","_"&UPPER($C17)),"") -> ALERT_CH_S_ADTJA_PD_RQHN | I17: =IF($D17<>"","ALERT_REQ_"&UPPER($D$6)&IF($D$7=1,"","_"&UPPER($C17)),"") -> ALERT_REQ_S_ADTJA_PD_RQHN | K17: ALERT_VOM_IGN_ON | M17: =FIND("_",C17,1) -> 3 | N17: =IF(IFERROR(M17,0),UPPER(LEFT(C17,1))&LOWER(MID(C17,2,M17-2))&UPPER(MID(C17,M17+1,1))&LOWER(MID(C17,M17+2,100)),UPPER(LEFT(C17,1))&LOWER(MID(C17,2,100))) -> PdRqhn
B18: 6 | C18: PD_EDHF | D18: ALERT_VOM_IGN_ON | E18: － | F18: =IF($D18<>"","u4_s_Alert"&UPPER(LEFT($D$6,1))&LOWER(MID($D$6,2,100))&IF($D$7=1,"",N18)&"Srcchk","") -> u4_s_AlertS_adtjaPdEdhfSrcchk | G18: =IF($D18<>"",IF($E18="○","vd_s_Alert"&UPPER(LEFT($D$6,1))&LOWER(MID($D$6,2,100))&IF($D$7=1,"",N18)&"RwTx","NULL"),"") -> NULL | H18: =IF($D18<>"","ALERT_CH_"&UPPER($D$6)&IF($D$7=1,"","_"&UPPER($C18)),"") -> ALERT_CH_S_ADTJA_PD_EDHF | I18: =IF($D18<>"","ALERT_REQ_"&UPPER($D$6)&IF($D$7=1,"","_"&UPPER($C18)),"") -> ALERT_REQ_S_ADTJA_PD_EDHF | K18: ALERT_VOM_VCS_ON | M18: =FIND("_",C18,1) -> 3 | N18: =IF(IFERROR(M18,0),UPPER(LEFT(C18,1))&LOWER(MID(C18,2,M18-2))&UPPER(MID(C18,M18+1,1))&LOWER(MID(C18,M18+2,100)),UPPER(LEFT(C18,1))&LOWER(MID(C18,2,100))) -> PdEdhf
B19: 7 | C19: PD_HFML | D19: ALERT_VOM_IGN_ON | E19: － | F19: =IF($D19<>"","u4_s_Alert"&UPPER(LEFT($D$6,1))&LOWER(MID($D$6,2,100))&IF($D$7=1,"",N19)&"Srcchk","") -> u4_s_AlertS_adtjaPdHfmlSrcchk | G19: =IF($D19<>"",IF($E19="○","vd_s_Alert"&UPPER(LEFT($D$6,1))&LOWER(MID($D$6,2,100))&IF($D$7=1,"",N19)&"RwTx","NULL"),"") -> NULL | H19: =IF($D19<>"","ALERT_CH_"&UPPER($D$6)&IF($D$7=1,"","_"&UPPER($C19)),"") -> ALERT_CH_S_ADTJA_PD_HFML | I19: =IF($D19<>"","ALERT_REQ_"&UPPER($D$6)&IF($D$7=1,"","_"&UPPER($C19)),"") -> ALERT_REQ_S_ADTJA_PD_HFML | K19: ALERT_VOM_VCS_ON | M19: =FIND("_",C19,1) -> 3 | N19: =IF(IFERROR(M19,0),UPPER(LEFT(C19,1))&LOWER(MID(C19,2,M19-2))&UPPER(MID(C19,M19+1,1))&LOWER(MID(C19,M19+2,100)),UPPER(LEFT(C19,1))&LOWER(MID(C19,2,100))) -> PdHfml
B20: 8 | C20: PD_STHF | D20: ALERT_VOM_IGN_ON | E20: － | F20: =IF($D20<>"","u4_s_Alert"&UPPER(LEFT($D$6,1))&LOWER(MID($D$6,2,100))&IF($D$7=1,"",N20)&"Srcchk","") -> u4_s_AlertS_adtjaPdSthfSrcchk | G20: =IF($D20<>"",IF($E20="○","vd_s_Alert"&UPPER(LEFT($D$6,1))&LOWER(MID($D$6,2,100))&IF($D$7=1,"",N20)&"RwTx","NULL"),"") -> NULL | H20: =IF($D20<>"","ALERT_CH_"&UPPER($D$6)&IF($D$7=1,"","_"&UPPER($C20)),"") -> ALERT_CH_S_ADTJA_PD_STHF | I20: =IF($D20<>"","ALERT_REQ_"&UPPER($D$6)&IF($D$7=1,"","_"&UPPER($C20)),"") -> ALERT_REQ_S_ADTJA_PD_STHF | K20: ALERT_VOM_VCS_ON | M20: =FIND("_",C20,1) -> 3 | N20: =IF(IFERROR(M20,0),UPPER(LEFT(C20,1))&LOWER(MID(C20,2,M20-2))&UPPER(MID(C20,M20+1,1))&LOWER(MID(C20,M20+2,100)),UPPER(LEFT(C20,1))&LOWER(MID(C20,2,100))) -> PdSthf
B21: 9 | C21: PD_DMCR | D21: ALERT_VOM_IGN_ON | E21: － | F21: =IF($D21<>"","u4_s_Alert"&UPPER(LEFT($D$6,1))&LOWER(MID($D$6,2,100))&IF($D$7=1,"",N21)&"Srcchk","") -> u4_s_AlertS_adtjaPdDmcrSrcchk | G21: =IF($D21<>"",IF($E21="○","vd_s_Alert"&UPPER(LEFT($D$6,1))&LOWER(MID($D$6,2,100))&IF($D$7=1,"",N21)&"RwTx","NULL"),"") -> NULL | H21: =IF($D21<>"","ALERT_CH_"&UPPER($D$6)&IF($D$7=1,"","_"&UPPER($C21)),"") -> ALERT_CH_S_ADTJA_PD_DMCR | I21: =IF($D21<>"","ALERT_REQ_"&UPPER($D$6)&IF($D$7=1,"","_"&UPPER($C21)),"") -> ALERT_REQ_S_ADTJA_PD_DMCR | K21: ALERT_VOM_VCS_ON | M21: =FIND("_",C21,1) -> 3 | N21: =IF(IFERROR(M21,0),UPPER(LEFT(C21,1))&LOWER(MID(C21,2,M21-2))&UPPER(MID(C21,M21+1,1))&LOWER(MID(C21,M21+2,100)),UPPER(LEFT(C21,1))&LOWER(MID(C21,2,100))) -> PdDmcr
B22: 10 | C22: PD_HFNL | D22: ALERT_VOM_IGN_ON | E22: － | F22: =IF($D22<>"","u4_s_Alert"&UPPER(LEFT($D$6,1))&LOWER(MID($D$6,2,100))&IF($D$7=1,"",N22)&"Srcchk","") -> u4_s_AlertS_adtjaPdHfnlSrcchk | G22: =IF($D22<>"",IF($E22="○","vd_s_Alert"&UPPER(LEFT($D$6,1))&LOWER(MID($D$6,2,100))&IF($D$7=1,"",N22)&"RwTx","NULL"),"") -> NULL | H22: =IF($D22<>"","ALERT_CH_"&UPPER($D$6)&IF($D$7=1,"","_"&UPPER($C22)),"") -> ALERT_CH_S_ADTJA_PD_HFNL | I22: =IF($D22<>"","ALERT_REQ_"&UPPER($D$6)&IF($D$7=1,"","_"&UPPER($C22)),"") -> ALERT_REQ_S_ADTJA_PD_HFNL | K22: ALERT_VOM_VCS_ON | M22: =FIND("_",C22,1) -> 3 | N22: =IF(IFERROR(M22,0),UPPER(LEFT(C22,1))&LOWER(MID(C22,2,M22-2))&UPPER(MID(C22,M22+1,1))&LOWER(MID(C22,M22+2,100)),UPPER(LEFT(C22,1))&LOWER(MID(C22,2,100))) -> PdHfnl
B23: 11 | F23: =IF($D23<>"","u4_s_Alert"&UPPER(LEFT($D$6,1))&LOWER(MID($D$6,2,100))&IF($D$7=1,"",N23)&"Srcchk","") | G23: =IF($D23<>"",IF($E23="○","vd_s_Alert"&UPPER(LEFT($D$6,1))&LOWER(MID($D$6,2,100))&IF($D$7=1,"",N23)&"RwTx","NULL"),"") | H23: =IF($D23<>"","ALERT_CH_"&UPPER($D$6)&IF($D$7=1,"","_"&UPPER($C23)),"") | I23: =IF($D23<>"","ALERT_REQ_"&UPPER($D$6)&IF($D$7=1,"","_"&UPPER($C23)),"") | K23: ALERT_VOM_VCS_ON | M23: =FIND("_",C23,1) -> #VALUE! | N23: =IF(IFERROR(M23,0),UPPER(LEFT(C23,1))&LOWER(MID(C23,2,M23-2))&UPPER(MID(C23,M23+1,1))&LOWER(MID(C23,M23+2,100)),UPPER(LEFT(C23,1))&LOWER(MID(C23,2,100)))
B24: 12 | F24: =IF($D24<>"","u4_s_Alert"&UPPER(LEFT($D$6,1))&LOWER(MID($D$6,2,100))&IF($D$7=1,"",N24)&"Srcchk","") | G24: =IF($D24<>"",IF($E24="○","vd_s_Alert"&UPPER(LEFT($D$6,1))&LOWER(MID($D$6,2,100))&IF($D$7=1,"",N24)&"RwTx","NULL"),"") | H24: =IF($D24<>"","ALERT_CH_"&UPPER($D$6)&IF($D$7=1,"","_"&UPPER($C24)),"") | I24: =IF($D24<>"","ALERT_REQ_"&UPPER($D$6)&IF($D$7=1,"","_"&UPPER($C24)),"") | K24: ALERT_VOM_VCS_ON | M24: =FIND("_",C24,1) -> #VALUE! | N24: =IF(IFERROR(M24,0),UPPER(LEFT(C24,1))&LOWER(MID(C24,2,M24-2))&UPPER(MID(C24,M24+1,1))&LOWER(MID(C24,M24+2,100)),UPPER(LEFT(C24,1))&LOWER(MID(C24,2,100)))
B25: 13 | F25: =IF($D25<>"","u4_s_Alert"&UPPER(LEFT($D$6,1))&LOWER(MID($D$6,2,100))&IF($D$7=1,"",N25)&"Srcchk","") | G25: =IF($D25<>"",IF($E25="○","vd_s_Alert"&UPPER(LEFT($D$6,1))&LOWER(MID($D$6,2,100))&IF($D$7=1,"",N25)&"RwTx","NULL"),"") | H25: =IF($D25<>"","ALERT_CH_"&UPPER($D$6)&IF($D$7=1,"","_"&UPPER($C25)),"") | I25: =IF($D25<>"","ALERT_REQ_"&UPPER($D$6)&IF($D$7=1,"","_"&UPPER($C25)),"") | K25: ALERT_VOM_VCS_ON | M25: =FIND("_",C25,1) -> #VALUE! | N25: =IF(IFERROR(M25,0),UPPER(LEFT(C25,1))&LOWER(MID(C25,2,M25-2))&UPPER(MID(C25,M25+1,1))&LOWER(MID(C25,M25+2,100)),UPPER(LEFT(C25,1))&LOWER(MID(C25,2,100)))
B26: 14 | F26: =IF($D26<>"","u4_s_Alert"&UPPER(LEFT($D$6,1))&LOWER(MID($D$6,2,100))&IF($D$7=1,"",N26)&"Srcchk","") | G26: =IF($D26<>"",IF($E26="○","vd_s_Alert"&UPPER(LEFT($D$6,1))&LOWER(MID($D$6,2,100))&IF($D$7=1,"",N26)&"RwTx","NULL"),"") | H26: =IF($D26<>"","ALERT_CH_"&UPPER($D$6)&IF($D$7=1,"","_"&UPPER($C26)),"") | I26: =IF($D26<>"","ALERT_REQ_"&UPPER($D$6)&IF($D$7=1,"","_"&UPPER($C26)),"") | K26: ALERT_VOM_VCS_ON | M26: =FIND("_",C26,1) -> #VALUE! | N26: =IF(IFERROR(M26,0),UPPER(LEFT(C26,1))&LOWER(MID(C26,2,M26-2))&UPPER(MID(C26,M26+1,1))&LOWER(MID(C26,M26+2,100)),UPPER(LEFT(C26,1))&LOWER(MID(C26,2,100)))
B27: 15 | F27: =IF($D27<>"","u4_s_Alert"&UPPER(LEFT($D$6,1))&LOWER(MID($D$6,2,100))&IF($D$7=1,"",N27)&"Srcchk","") | G27: =IF($D27<>"",IF($E27="○","vd_s_Alert"&UPPER(LEFT($D$6,1))&LOWER(MID($D$6,2,100))&IF($D$7=1,"",N27)&"RwTx","NULL"),"") | H27: =IF($D27<>"","ALERT_CH_"&UPPER($D$6)&IF($D$7=1,"","_"&UPPER($C27)),"") | I27: =IF($D27<>"","ALERT_REQ_"&UPPER($D$6)&IF($D$7=1,"","_"&UPPER($C27)),"") | K27: ALERT_VOM_VCS_ON | M27: =FIND("_",C27,1) -> #VALUE! | N27: =IF(IFERROR(M27,0),UPPER(LEFT(C27,1))&LOWER(MID(C27,2,M27-2))&UPPER(MID(C27,M27+1,1))&LOWER(MID(C27,M27+2,100)),UPPER(LEFT(C27,1))&LOWER(MID(C27,2,100)))
B28: 16 | F28: =IF($D28<>"","u4_s_Alert"&UPPER(LEFT($D$6,1))&LOWER(MID($D$6,2,100))&IF($D$7=1,"",N28)&"Srcchk","") | G28: =IF($D28<>"",IF($E28="○","vd_s_Alert"&UPPER(LEFT($D$6,1))&LOWER(MID($D$6,2,100))&IF($D$7=1,"",N28)&"RwTx","NULL"),"") | H28: =IF($D28<>"","ALERT_CH_"&UPPER($D$6)&IF($D$7=1,"","_"&UPPER($C28)),"") | I28: =IF($D28<>"","ALERT_REQ_"&UPPER($D$6)&IF($D$7=1,"","_"&UPPER($C28)),"") | K28: ALERT_VOM_VCS_ON | M28: =FIND("_",C28,1) -> #VALUE! | N28: =IF(IFERROR(M28,0),UPPER(LEFT(C28,1))&LOWER(MID(C28,2,M28-2))&UPPER(MID(C28,M28+1,1))&LOWER(MID(C28,M28+2,100)),UPPER(LEFT(C28,1))&LOWER(MID(C28,2,100)))
B29: 17 | F29: =IF($D29<>"","u4_s_Alert"&UPPER(LEFT($D$6,1))&LOWER(MID($D$6,2,100))&IF($D$7=1,"",N29)&"Srcchk","") | G29: =IF($D29<>"",IF($E29="○","vd_s_Alert"&UPPER(LEFT($D$6,1))&LOWER(MID($D$6,2,100))&IF($D$7=1,"",N29)&"RwTx","NULL"),"") | H29: =IF($D29<>"","ALERT_CH_"&UPPER($D$6)&IF($D$7=1,"","_"&UPPER($C29)),"") | I29: =IF($D29<>"","ALERT_REQ_"&UPPER($D$6)&IF($D$7=1,"","_"&UPPER($C29)),"") | K29: ALERT_VOM_VCS_ON | M29: =FIND("_",C29,1) -> #VALUE! | N29: =IF(IFERROR(M29,0),UPPER(LEFT(C29,1))&LOWER(MID(C29,2,M29-2))&UPPER(MID(C29,M29+1,1))&LOWER(MID(C29,M29+2,100)),UPPER(LEFT(C29,1))&LOWER(MID(C29,2,100)))
B30: 18 | F30: =IF($D30<>"","u4_s_Alert"&UPPER(LEFT($D$6,1))&LOWER(MID($D$6,2,100))&IF($D$7=1,"",N30)&"Srcchk","") | G30: =IF($D30<>"",IF($E30="○","vd_s_Alert"&UPPER(LEFT($D$6,1))&LOWER(MID($D$6,2,100))&IF($D$7=1,"",N30)&"RwTx","NULL"),"") | H30: =IF($D30<>"","ALERT_CH_"&UPPER($D$6)&IF($D$7=1,"","_"&UPPER($C30)),"") | I30: =IF($D30<>"","ALERT_REQ_"&UPPER($D$6)&IF($D$7=1,"","_"&UPPER($C30)),"") | K30: ALERT_VOM_VCS_ON | M30: =FIND("_",C30,1) -> #VALUE! | N30: =IF(IFERROR(M30,0),UPPER(LEFT(C30,1))&LOWER(MID(C30,2,M30-2))&UPPER(MID(C30,M30+1,1))&LOWER(MID(C30,M30+2,100)),UPPER(LEFT(C30,1))&LOWER(MID(C30,2,100)))
B31: 19 | F31: =IF($D31<>"","u4_s_Alert"&UPPER(LEFT($D$6,1))&LOWER(MID($D$6,2,100))&IF($D$7=1,"",N31)&"Srcchk","") | G31: =IF($D31<>"",IF($E31="○","vd_s_Alert"&UPPER(LEFT($D$6,1))&LOWER(MID($D$6,2,100))&IF($D$7=1,"",N31)&"RwTx","NULL"),"") | H31: =IF($D31<>"","ALERT_CH_"&UPPER($D$6)&IF($D$7=1,"","_"&UPPER($C31)),"") | I31: =IF($D31<>"","ALERT_REQ_"&UPPER($D$6)&IF($D$7=1,"","_"&UPPER($C31)),"") | K31: ALERT_VOM_VCS_ON | M31: =FIND("_",C31,1) -> #VALUE! | N31: =IF(IFERROR(M31,0),UPPER(LEFT(C31,1))&LOWER(MID(C31,2,M31-2))&UPPER(MID(C31,M31+1,1))&LOWER(MID(C31,M31+2,100)),UPPER(LEFT(C31,1))&LOWER(MID(C31,2,100)))
B32: 20 | F32: =IF($D32<>"","u4_s_Alert"&UPPER(LEFT($D$6,1))&LOWER(MID($D$6,2,100))&IF($D$7=1,"",N32)&"Srcchk","") | G32: =IF($D32<>"",IF($E32="○","vd_s_Alert"&UPPER(LEFT($D$6,1))&LOWER(MID($D$6,2,100))&IF($D$7=1,"",N32)&"RwTx","NULL"),"") | H32: =IF($D32<>"","ALERT_CH_"&UPPER($D$6)&IF($D$7=1,"","_"&UPPER($C32)),"") | I32: =IF($D32<>"","ALERT_REQ_"&UPPER($D$6)&IF($D$7=1,"","_"&UPPER($C32)),"") | K32: ALERT_VOM_VCS_ON | M32: =FIND("_",C32,1) -> #VALUE! | N32: =IF(IFERROR(M32,0),UPPER(LEFT(C32,1))&LOWER(MID(C32,2,M32-2))&UPPER(MID(C32,M32+1,1))&LOWER(MID(C32,M32+2,100)),UPPER(LEFT(C32,1))&LOWER(MID(C32,2,100)))
B33: 21 | F33: =IF($D33<>"","u4_s_Alert"&UPPER(LEFT($D$6,1))&LOWER(MID($D$6,2,100))&IF($D$7=1,"",N33)&"Srcchk","") | G33: =IF($D33<>"",IF($E33="○","vd_s_Alert"&UPPER(LEFT($D$6,1))&LOWER(MID($D$6,2,100))&IF($D$7=1,"",N33)&"RwTx","NULL"),"") | H33: =IF($D33<>"","ALERT_CH_"&UPPER($D$6)&IF($D$7=1,"","_"&UPPER($C33)),"") | I33: =IF($D33<>"","ALERT_REQ_"&UPPER($D$6)&IF($D$7=1,"","_"&UPPER($C33)),"") | K33: ALERT_VOM_VCS_ON | M33: =FIND("_",C33,1) -> #VALUE! | N33: =IF(IFERROR(M33,0),UPPER(LEFT(C33,1))&LOWER(MID(C33,2,M33-2))&UPPER(MID(C33,M33+1,1))&LOWER(MID(C33,M33+2,100)),UPPER(LEFT(C33,1))&LOWER(MID(C33,2,100)))
B34: 22 | F34: =IF($D34<>"","u4_s_Alert"&UPPER(LEFT($D$6,1))&LOWER(MID($D$6,2,100))&IF($D$7=1,"",N34)&"Srcchk","") | G34: =IF($D34<>"",IF($E34="○","vd_s_Alert"&UPPER(LEFT($D$6,1))&LOWER(MID($D$6,2,100))&IF($D$7=1,"",N34)&"RwTx","NULL"),"") | H34: =IF($D34<>"","ALERT_CH_"&UPPER($D$6)&IF($D$7=1,"","_"&UPPER($C34)),"") | I34: =IF($D34<>"","ALERT_REQ_"&UPPER($D$6)&IF($D$7=1,"","_"&UPPER($C34)),"") | K34: ALERT_VOM_VCS_ON | M34: =FIND("_",C34,1) -> #VALUE! | N34: =IF(IFERROR(M34,0),UPPER(LEFT(C34,1))&LOWER(MID(C34,2,M34-2))&UPPER(MID(C34,M34+1,1))&LOWER(MID(C34,M34+2,100)),UPPER(LEFT(C34,1))&LOWER(MID(C34,2,100)))
... B37: 25 | F37: =IF($D37<>"","u4_s_Alert"&UPPER(LEFT($D$6,1))&LOWER(MID($D$6,2,100))&IF($D$7=1,"",N37)&"Srcchk","") | G37: =IF($D37<>"",IF($E37="○","vd_s_Alert"&UPPER(LEFT($D$6,1))&LOWER(MID($D$6,2,100))&IF($D$7=1,"",N37)&"RwTx","NULL"),"") | H37: =IF($D37<>"","ALERT_CH_"&UPPER($D$6)&IF($D$7=1,"","_"&UPPER($C37)),"") | I37: =IF($D37<>"","ALERT_REQ_"&UPPER($D$6)&IF($D$7=1,"","_"&UPPER($C37)),"") | K37: ALERT_VOM_VCS_ON | M37: =FIND("_",C37,1) -> #VALUE! | N37: =IF(IFERROR(M37,0),UPPER(LEFT(C37,1))&LOWER(MID(C37,2,M37-2))&UPPER(MID(C37,M37+1,1))&LOWER(MID(C37,M37+2,100)),UPPER(LEFT(C37,1))&LOWER(MID(C37,2,100)))

Sheet Config_IF
B2: Other Domain Define | O2: Alert Config IF List
B3: No | C3: define Name | D3: class | E3: define | F3: comment | G3: 文字数 | O3: No | P3: Return | Q3: Config Function Name | R3: comment
B4: 0 | C4: なし | O4: 0 | P4: なし | Q4: なし
B5: 1 | E5: =IF($C5<>"","ALERT_" & D5 & "_ID_"&UPPER(Matrix!$D$6) & "_" & $C5,"") | G5: =IF(E5<>"",LEN(E5),"") | O5: 1
B6: 2 | E6: =IF($C6<>"","ALERT_" & D6 & "_ID_"&UPPER(Matrix!$D$6) & "_" & $C6,"") | G6: =IF(E6<>"",LEN(E6),"") | O6: 2
B7: 3 | E7: =IF($C7<>"","ALERT_" & D7 & "_ID_"&UPPER(Matrix!$D$6) & "_" & $C7,"") | G7: =IF(E7<>"",LEN(E7),"") | O7: 3
B8: 4 | E8: =IF($C8<>"","ALERT_" & D8 & "_ID_"&UPPER(Matrix!$D$6) & "_" & $C8,"") | G8: =IF(E8<>"",LEN(E8),"") | O8: 4
B9: 5 | E9: =IF($C9<>"","ALERT_" & D9 & "_ID_"&UPPER(Matrix!$D$6) & "_" & $C9,"") | G9: =IF(E9<>"",LEN(E9),"") | O9: 5
B10: 6 | E10: =IF($C10<>"","ALERT_" & D10 & "_ID_"&UPPER(Matrix!$D$6) & "_" & $C10,"") | G10: =IF(E10<>"",LEN(E10),"") | O10: 6
B11: 7 | E11: =IF($C11<>"","ALERT_" & D11 & "_ID_"&UPPER(Matrix!$D$6) & "_" & $C11,"") | G11: =IF(E11<>"",LEN(E11),"") | O11: 7
B12: 8 | E12: =IF($C12<>"","ALERT_" & D12 & "_ID_"&UPPER(Matrix!$D$6) & "_" & $C12,"") | G12: =IF(E12<>"",LEN(E12),"") | O12: 8
B13: 9 | E13: =IF($C13<>"","ALERT_" & D13 & "_ID_"&UPPER(Matrix!$D$6) & "_" & $C13,"") | G13: =IF(E13<>"",LEN(E13),"") | O13: 9
B14: 10 | E14: =IF($C14<>"","ALERT_" & D14 & "_ID_"&UPPER(Matrix!$D$6) & "_" & $C14,"") | G14: =IF(E14<>"",LEN(E14),"") | O14: 10
B15: 11 | E15: =IF($C15<>"","ALERT_" & D15 & "_ID_"&UPPER(Matrix!$D$6) & "_" & $C15,"") | G15: =IF(E15<>"",LEN(E15),"") | O15: 11
B16: 12 | E16: =IF($C16<>"","ALERT_" & D16 & "_ID_"&UPPER(Matrix!$D$6) & "_" & $C16,"") | G16: =IF(E16<>"",LEN(E16),"") | O16: 12
... B29: 25 | E29: =IF($C29<>"","ALERT_" & D29 & "_ID_"&UPPER(Matrix!$D$6) & "_" & $C29,"") | G29: =IF(E29<>"",LEN(E29),"") | O29: 25
B32: Alert Domain Define | O32: Constant Externs List
B33: No | C33: define Name | D33: calss | E33: define | F33: Value | G33: 文字数 | O33: No | P33: Type | Q33: Constant define | R33: comment
B34: 0 | C34: なし | F34: なし | O34: 0 | P34: なし | Q34: なし | R34: なし
B35: 1 | E35: =IF($C35<>"","ALERT_" & UPPER(Matrix!$D$6) & "_" & $C35,"") | G35: =IF(E35<>"",LEN(E35),"") | O35: 1
B36: 2 | E36: =IF($C36<>"","ALERT_" & UPPER(Matrix!$D$6) & "_" & $C36,"") | G36: =IF(E36<>"",LEN(E36),"") | O36: 2
B37: 3 | E37: =IF($C37<>"","ALERT_" & UPPER(Matrix!$D$6) & "_" & $C37,"") | G37: =IF(E37<>"",LEN(E37),"") | O37: 3
B38: 4 | E38: =IF($C38<>"","ALERT_" & UPPER(Matrix!$D$6) & "_" & $C38,"") | G38: =IF(E38<>"",LEN(E38),"") | O38: 4
B39: 5 | E39: =IF($C39<>"","ALERT_" & UPPER(Matrix!$D$6) & "_" & $C39,"") | G39: =IF(E39<>"",LEN(E39),"") | O39: 5
B40: 6 | E40: =IF($C40<>"","ALERT_" & UPPER(Matrix!$D$6) & "_" & $C40,"") | G40: =IF(E40<>"",LEN(E40),"") | O40: 6
B41: 7 | E41: =IF($C41<>"","ALERT_" & UPPER(Matrix!$D$6) & "_" & $C41,"") | G41: =IF(E41<>"",LEN(E41),"") | O41: 7
B42: 8 | E42: =IF($C42<>"","ALERT_" & UPPER(Matrix!$D$6) & "_" & $C42,"") | G42: =IF(E42<>"",LEN(E42),"") | O42: 8
B43: 9 | E43: =IF($C43<>"","ALERT_" & UPPER(Matrix!$D$6) & "_" & $C43,"") | G43: =IF(E43<>"",LEN(E43),"") | O43: 9
B44: 10 | E44: =IF($C44<>"","ALERT_" & UPPER(Matrix!$D$6) & "_" & $C44,"") | G44: =IF(E44<>"",LEN(E44),"") | O44: 10
B45: 11 | E45: =IF($C45<>"","ALERT_" & UPPER(Matrix!$D$6) & "_" & $C45,"") | G45: =IF(E45<>"",LEN(E45),"") | O45: 11
B46: 12 | E46: =IF($C46<>"","ALERT_" & UPPER(Matrix!$D$6) & "_" & $C46,"") | G46: =IF(E46<>"",LEN(E46),"") | O46: 12
... B59: 25 | E59: =IF($C59<>"","ALERT_" & UPPER(Matrix!$D$6) & "_" & $C59,"") | G59: =IF(E59<>"",LEN(E59),"") | O59: 25

Sheet CH_Design
C1: 出力なしは、ここでは定義しないこと。システム共通のALERT_REQ_UNKNOWNを使用するため。
B2: ALERT CH | C2: REQ | D2: Value | E2: TT機能判定 | F2: TT | G2: BC機能判定 | H2: BC | I2: PD機能判定 | J2: PD | K2: RW機能判定 | L2: RW | M2: 文字数 | N2: 定義名 | O2: Code for alert_mtrx.h
C3: UNKNOWN | U3: 電源状態一覧
B4: ALERT_CH_S_ADTJA_TT | C4: STNBY | D4: 0 | E4: なし | F4: ON(白) | G4: なし | H4: - | I4: なし | J4: - | K4: なし | L4: - | M4: =LEN(N4) -> 26 | N4: =VLOOKUP($B4,Matrix!$H$13:$I$37,2,FALSE)&"_"&C4 -> ALERT_REQ_S_ADTJA_TT_STNBY | O4: ="#define "&N4&REPT(" ",48-M4)&"("&D4&"U)" -> #define ALERT_REQ_S_ADTJA_TT_STNBY (0U) | U4: 電源状態一覧
B5: ALERT_CH_S_ADTJA_TT | C5: CTRL | D5: 1 | E5: なし | F5: ON(緑) | G5: なし | H5: - | I5: なし | J5: - | K5: なし | L5: - | M5: =LEN(N5) -> 25 | N5: =VLOOKUP($B5,Matrix!$H$13:$I$37,2,FALSE)&"_"&C5 -> ALERT_REQ_S_ADTJA_TT_CTRL | O5: ="#define "&N5&REPT(" ",48-M5)&"("&D5&"U)" -> #define ALERT_REQ_S_ADTJA_TT_CTRL (1U) | U5: ＋B
B6: ALERT_CH_S_ADTJA_TT | C6: MALFUNC | D6: 2 | E6: HOF_EXT | F6: ON(アンバー) | G6: なし | H6: - | I6: なし | J6: - | K6: なし | L6: - | M6: =LEN(N6) -> 28 | N6: =VLOOKUP($B6,Matrix!$H$13:$I$37,2,FALSE)&"_"&C6 -> ALERT_REQ_S_ADTJA_TT_MALFUNC | O6: ="#define "&N6&REPT(" ",48-M6)&"("&D6&"U)" -> #define ALERT_REQ_S_ADTJA_TT_MALFUNC (2U) | U6: IG-ON
B7: ALERT_CH_S_ADTJA_TT_DMCR | C7: STNBY | D7: 0 | E7: なし | F7: FLASH_1000_D50_OFF | G7: なし | H7: - | I7: なし | J7: - | K7: なし | L7: - | M7: =LEN(N7) -> 31 | N7: =VLOOKUP($B7,Matrix!$H$13:$I$37,2,FALSE)&"_"&C7 -> ALERT_REQ_S_ADTJA_TT_DMCR_STNBY | O7: ="#define "&N7&REPT(" ",48-M7)&"("&D7&"U)" -> #define ALERT_REQ_S_ADTJA_TT_DMCR_STNBY (0U) | U7: IG-OFF
B8: ALERT_CH_S_ADTJA_TT_DMCR | C8: REC | D8: 1 | E8: なし | F8: ON | G8: なし | H8: - | I8: なし | J8: - | K8: なし | L8: - | M8: =LEN(N8) -> 29 | N8: =VLOOKUP($B8,Matrix!$H$13:$I$37,2,FALSE)&"_"&C8 -> ALERT_REQ_S_ADTJA_TT_DMCR_REC | O8: ="#define "&N8&REPT(" ",48-M8)&"("&D8&"U)" -> #define ALERT_REQ_S_ADTJA_TT_DMCR_REC (1U) | U8: ACC-ON
B9: ALERT_CH_S_ADTJA_BC | C9: PTN1 | D9: 0 | E9: なし | F9: - | G9: なし | H9: S_ADTJA-CSTD-0-BZR01-REQ02- | I9: なし | J9: - | K9: なし | L9: - | M9: =LEN(N9) -> 25 | N9: =VLOOKUP($B9,Matrix!$H$13:$I$37,2,FALSE)&"_"&C9 -> ALERT_REQ_S_ADTJA_BC_PTN1 | O9: ="#define "&N9&REPT(" ",48-M9)&"("&D9&"U)" -> #define ALERT_REQ_S_ADTJA_BC_PTN1 (0U) | U9: ACC-OFF
B10: ALERT_CH_S_ADTJA_BC | C10: PTN2 | D10: 1 | E10: なし | F10: - | G10: なし | H10: S_ADTJA-CSTD-0-BZR01-REQ03- | I10: なし | J10: - | K10: なし | L10: - | M10: =LEN(N10) -> 25 | N10: =VLOOKUP($B10,Matrix!$H$13:$I$37,2,FALSE)&"_"&C10 -> ALERT_REQ_S_ADTJA_BC_PTN2 | O10: ="#define "&N10&REPT(" ",48-M10)&"("&D10&"U)" -> #define ALERT_REQ_S_ADTJA_BC_PTN2 (1U)
B11: ALERT_CH_S_ADTJA_BC | C11: PTN3 | D11: 2 | E11: なし | F11: - | G11: なし | H11: S_ADTJA-CSTD-0-BZR01-REQ04- | I11: なし | J11: - | K11: なし | L11: - | M11: =LEN(N11) -> 25 | N11: =VLOOKUP($B11,Matrix!$H$13:$I$37,2,FALSE)&"_"&C11 -> ALERT_REQ_S_ADTJA_BC_PTN3 | O11: ="#define "&N11&REPT(" ",48-M11)&"("&D11&"U)" -> #define ALERT_REQ_S_ADTJA_BC_PTN3 (2U)
B12: ALERT_CH_S_ADTJA_BC | C12: PTN4 | D12: 3 | E12: なし | F12: - | G12: なし | H12: S_ADTJA-CSTD-0-BZR01-REQ05- | I12: なし | J12: - | K12: なし | L12: - | M12: =LEN(N12) -> 25 | N12: =VLOOKUP($B12,Matrix!$H$13:$I$37,2,FALSE)&"_"&C12 -> ALERT_REQ_S_ADTJA_BC_PTN4 | O12: ="#define "&N12&REPT(" ",48-M12)&"("&D12&"U)" -> #define ALERT_REQ_S_ADTJA_BC_PTN4 (3U)
B13: ALERT_CH_S_ADTJA_BC | C13: PTN5 | D13: 4 | E13: なし | F13: - | G13: なし | H13: S_ADTJA-CSTD-0-BZR01-REQ06- | I13: なし | J13: - | K13: なし | L13: - | M13: =LEN(N13) -> 25 | N13: =VLOOKUP($B13,Matrix!$H$13:$I$37,2,FALSE)&"_"&C13 -> ALERT_REQ_S_ADTJA_BC_PTN5 | O13: ="#define "&N13&REPT(" ",48-M13)&"("&D13&"U)" -> #define ALERT_REQ_S_ADTJA_BC_PTN5 (4U)
B14: ALERT_CH_S_ADTJA_BC | C14: PTN6 | D14: 5 | E14: なし | F14: - | G14: なし | H14: S_ADTJA-CSTD-0-BZR01-REQ07- | I14: なし | J14: - | K14: なし | L14: - | M14: =LEN(N14) -> 25 | N14: =VLOOKUP($B14,Matrix!$H$13:$I$37,2,FALSE)&"_"&C14 -> ALERT_REQ_S_ADTJA_BC_PTN6 | O14: ="#define "&N14&REPT(" ",48-M14)&"("&D14&"U)" -> #define ALERT_REQ_S_ADTJA_BC_PTN6 (5U)
B15: ALERT_CH_S_ADTJA_BC | C15: PTN7 | D15: 6 | E15: なし | F15: - | G15: なし | H15: S_ADTJA-CSTD-0-BZR01-REQ08- | I15: なし | J15: - | K15: なし | L15: - | M15: =LEN(N15) -> 25 | N15: =VLOOKUP($B15,Matrix!$H$13:$I$37,2,FALSE)&"_"&C15 -> ALERT_REQ_S_ADTJA_BC_PTN7 | O15: ="#define "&N15&REPT(" ",48-M15)&"("&D15&"U)" -> #define ALERT_REQ_S_ADTJA_BC_PTN7 (6U)
B16: ALERT_CH_S_ADTJA_PD | C16: YESNO | D16: 0 | E16: なし | F16: - | G16: なし | H16: - | I16: なし | J16: S_ADTJA-CSTD-0-MEF01-REQ03- | K16: なし | L16: - | M16: =LEN(N16) -> 26 | N16: =VLOOKUP($B16,Matrix!$H$13:$I$37,2,FALSE)&"_"&C16 -> ALERT_REQ_S_ADTJA_PD_YESNO | O16: ="#define "&N16&REPT(" ",48-M16)&"("&D16&"U)" -> #define ALERT_REQ_S_ADTJA_PD_YESNO (0U)
B17: ALERT_CH_S_ADTJA_PD_RQHN | C17: PTN1 | D17: 0 | E17: なし | F17: - | G17: なし | H17: - | I17: なし | J17: S_ADTJA-CSTD-0-MEF01-REQ06-/S_ADTJA-CSTD-0-MEF01-REQ23-(HUD用) | K17: なし | L17: - | M17: =LEN(N17) -> 30 | N17: =VLOOKUP($B17,Matrix!$H$13:$I$37,2,FALSE)&"_"&C17 -> ALERT_REQ_S_ADTJA_PD_RQHN_PTN1 | O17: ="#define "&N17&REPT(" ",48-M17)&"("&D17&"U)" -> #define ALERT_REQ_S_ADTJA_PD_RQHN_PTN1 (0U)
B18: ALERT_CH_S_ADTJA_PD_RQHN | C18: PTN2 | D18: 1 | E18: なし | F18: - | G18: なし | H18: - | I18: なし | J18: S_ADTJA-CSTD-0-MEF01-REQ07-/S_ADTJA-CSTD-0-MEF01-REQ23-(HUD用) | K18: なし | L18: - | M18: =LEN(N18) -> 30 | N18: =VLOOKUP($B18,Matrix!$H$13:$I$37,2,FALSE)&"_"&C18 -> ALERT_REQ_S_ADTJA_PD_RQHN_PTN2 | O18: ="#define "&N18&REPT(" ",48-M18)&"("&D18&"U)" -> #define ALERT_REQ_S_ADTJA_PD_RQHN_PTN2 (1U)
B19: ALERT_CH_S_ADTJA_PD_RQHN | C19: PTN3 | D19: 2 | E19: なし | F19: - | G19: なし | H19: - | I19: なし | J19: S_ADTJA-CSTD-0-MEF01-REQ08-/S_ADTJA-CSTD-0-MEF01-REQ23-(HUD用) | K19: なし | L19: - | M19: =LEN(N19) -> 30 | N19: =VLOOKUP($B19,Matrix!$H$13:$I$37,2,FALSE)&"_"&C19 -> ALERT_REQ_S_ADTJA_PD_RQHN_PTN3 | O19: ="#define "&N19&REPT(" ",48-M19)&"("&D19&"U)" -> #define ALERT_REQ_S_ADTJA_PD_RQHN_PTN3 (2U)
B20: ALERT_CH_S_ADTJA_PD_RQHN | C20: PTN4 | D20: 3 | E20: なし | F20: - | G20: なし | H20: - | I20: なし | J20: S_ADTJA-CSTD-0-MEF01-REQ09-/S_ADTJA-CSTD-0-MEF01-REQ23-(HUD用) | K20: なし | L20: - | M20: =LEN(N20) -> 30 | N20: =VLOOKUP($B20,Matrix!$H$13:$I$37,2,FALSE)&"_"&C20 -> ALERT_REQ_S_ADTJA_PD_RQHN_PTN4 | O20: ="#define "&N20&REPT(" ",48-M20)&"("&D20&"U)" -> #define ALERT_REQ_S_ADTJA_PD_RQHN_PTN4 (3U)
B21: ALERT_CH_S_ADTJA_PD_RQHN | C21: PTN5 | D21: 4 | E21: なし | F21: - | G21: なし | H21: - | I21: なし | J21: S_ADTJA-CSTD-0-MEF01-REQ10-/S_ADTJA-CSTD-0-MEF01-REQ23-(HUD用) | K21: なし | L21: - | M21: =LEN(N21) -> 30 | N21: =VLOOKUP($B21,Matrix!$H$13:$I$37,2,FALSE)&"_"&C21 -> ALERT_REQ_S_ADTJA_PD_RQHN_PTN5 | O21: ="#define "&N21&REPT(" ",48-M21)&"("&D21&"U)" -> #define ALERT_REQ_S_ADTJA_PD_RQHN_PTN5 (4U)
... B40: ALERT_CH_S_ADTJA_PD_HFNL | C40: WRN4 | D40: 3 | E40: なし | F40: - | G40: なし | H40: - | I40: なし | J40: S_ADTJA-CSTD-0-MEF01-REQ28- | K40: なし | L40: - | M40: =LEN(N40) -> 30 | N40: =VLOOKUP($B40,Matrix!$H$13:$I$37,2,FALSE)&"_"&C40 -> ALERT_REQ_S_ADTJA_PD_HFNL_WRN4 | O40: ="#define "&N40&REPT(" ",48-M40)&"("&D40&"U)" -> #define ALERT_REQ_S_ADTJA_PD_HFNL_WRN4 (3U)
M41: =LEN(N41) -> #N/A | N41: =VLOOKUP($B41,Matrix!$H$13:$I$37,2,FALSE)&"_"&C41 -> #N/A | O41: ="#define "&N41&REPT(" ",48-M41)&"("&D41&"U)" -> #N/A
M42: =LEN(N42) -> #N/A | N42: =VLOOKUP($B42,Matrix!$H$13:$I$37,2,FALSE)&"_"&C42 -> #N/A | O42: ="#define "&N42&REPT(" ",48-M42)&"("&D42&"U)" -> #N/A
M43: =LEN(N43) -> #N/A | N43: =VLOOKUP($B43,Matrix!$H$13:$I$37,2,FALSE)&"_"&C43 -> #N/A | O43: ="#define "&N43&REPT(" ",48-M43)&"("&D43&"U)" -> #N/A
M44: =LEN(N44) -> #N/A | N44: =VLOOKUP($B44,Matrix!$H$13:$I$37,2,FALSE)&"_"&C44 -> #N/A | O44: ="#define "&N44&REPT(" ",48-M44)&"("&D44&"U)" -> #N/A
M45: =LEN(N45) -> #N/A | N45: =VLOOKUP($B45,Matrix!$H$13:$I$37,2,FALSE)&"_"&C45 -> #N/A | O45: ="#define "&N45&REPT(" ",48-M45)&"("&D45&"U)" -> #N/A
M46: =LEN(N46) -> #N/A | N46: =VLOOKUP($B46,Matrix!$H$13:$I$37,2,FALSE)&"_"&C46 -> #N/A | O46: ="#define "&N46&REPT(" ",48-M46)&"("&D46&"U)" -> #N/A
M47: =LEN(N47) -> #N/A | N47: =VLOOKUP($B47,Matrix!$H$13:$I$37,2,FALSE)&"_"&C47 -> #N/A | O47: ="#define "&N47&REPT(" ",48-M47)&"("&D47&"U)" -> #N/A
M48: =LEN(N48) -> #N/A | N48: =VLOOKUP($B48,Matrix!$H$13:$I$37,2,FALSE)&"_"&C48 -> #N/A | O48: ="#define "&N48&REPT(" ",48-M48)&"("&D48&"U)" -> #N/A
M49: =LEN(N49) -> #N/A | N49: =VLOOKUP($B49,Matrix!$H$13:$I$37,2,FALSE)&"_"&C49 -> #N/A | O49: ="#define "&N49&REPT(" ",48-M49)&"("&D49&"U)" -> #N/A
M50: =LEN(N50) -> #N/A | N50: =VLOOKUP($B50,Matrix!$H$13:$I$37,2,FALSE)&"_"&C50 -> #N/A | O50: ="#define "&N50&REPT(" ",48-M50)&"("&D50&"U)" -> #N/A
M51: =LEN(N51) -> #N/A | N51: =VLOOKUP($B51,Matrix!$H$13:$I$37,2,FALSE)&"_"&C51 -> #N/A | O51: ="#define "&N51&REPT(" ",48-M51)&"("&D51&"U)" -> #N/A
M52: =LEN(N52) -> #N/A | N52: =VLOOKUP($B52,Matrix!$H$13:$I$37,2,FALSE)&"_"&C52 -> #N/A | O52: ="#define "&N52&REPT(" ",48-M52)&"("&D52&"U)" -> #N/A
... M103: =LEN(N103) -> #N/A | N103: =VLOOKUP($B103,Matrix!$H$13:$I$37,2,FALSE)&"_"&C103 -> #N/A | O103: ="#define "&N103&REPT(" ",48-M103)&"("&D103&"U)" -> #N/A

Sheet TT
AH1: → | AI1: bit
B2: Table Type | C2: INDEX | D2: 31 | E2: 30 | F2: 29 | G2: 28 | H2: 27 | I2: 26 | J2: 25 | K2: 24 | L2: 23 | M2: 22 | N2: 21 | O2: 20 | P2: 19 | Q2: 18 | R2: 17 | S2: 16 | T2: 15 | U2: 14 | V2: 13 | W2: 12 | X2: 11 | Y2: 10 | Z2: 9 | AA2: 8 | AB2: 7 | AC2: 6 | AD2: 5 | AE2: 4 | AF2: 3 | AG2: 2 | AH2: 1 | AI2: 0 | AJ2: REQ
B3: =IF(OR(IF(COUNTIF(D6:AC69,"0")<>0,TRUE,FALSE),IF(COUNTIF(D6:AC69,"1")<>0,TRUE,FALSE)),"Search Table","Index Table") -> Index Table | D3: ALERT_VOM_RWT_EN | E3: [reserved] | F3: ALERT_VOM_VCS_ON | G3: ALERT_VOM_IGN_ON | H3: ALERT_VOM_IGN_OFF_WT | I3: ALERT_VOM_IGN_OFF | J3: ALERT_VOM_BAT_WT | K3: ALERT_VOM_BAT_AO | L3: [reserved] | M3: [reserved] | N3: [reserved] | O3: [reserved] | P3: [reserved] | Q3: [reserved] | R3: [reserved] | S3: [reserved] | T3: [reserved] | U3: [reserved] | V3: [reserved] | W3: [reserved] | X3: [reserved] | Y3: [reserved] | Z3: [reserved] | AA3: [reserved] | AB3: [reserved] | AC3: [reserved] | AD3: [reserved] | AE3: FCM1S92 | AG3: TJAINDI | AR3: シート名称は、CH Nameと同じにすること。 1CHしか存在しない場合、機能名と同じにすること。
A4: Master Table | AR4: 貼り付けコード
AR5: ="static const U4 "&AW8&"["&AW10&"]"&" = {" -> static const U4 u4_sp_ALERT_S_ADTJA_TT_CRIT[ALERT_S_ADTJA_TT_NUM_DST] = { | AS5: ="static const U4 "&$AW$9&"["&$AW$10&"] = {" -> static const U4 u4_sp_ALERT_S_ADTJA_TT_MASK[ALERT_S_ADTJA_TT_NUM_DST] = { | AT5: ="static const U1 "&$AW$11&"["&$AW$10&"] = {" -> static const U1 u1_sp_ALERT_S_ADTJA_TT_DST[ALERT_S_ADTJA_TT_NUM_DST] = { | AU5: ="const ST_ALERT_MTRX "&$AW$12&" = {" -> const ST_ALERT_MTRX st_gp_ALERT_S_ADTJA_MTRX[10] = { | AV5: ="#define "&AW10&REPT(" ",41-LEN(AW10))&"("&AW13&"U)" -> #define ALERT_S_ADTJA_TT_NUM_DST (32U)
B6: ="Table "&$AW$6 -> Table TT | C6: =ROW()-ROW($C$6) -> 0 | D6: × | E6: × | F6: × | G6: × | H6: × | I6: × | J6: × | K6: × | L6: × | M6: × | N6: × | O6: × | P6: × | Q6: × | R6: × | S6: × | T6: × | U6: × | V6: × | W6: × | X6: × | Y6: × | Z6: × | AA6: × | AB6: × | AC6: × | AD6: × | AE6: 0 | AF6: 0 | AG6: 0 | AH6: 0 | AI6: 0 | AJ6: UNKNOWN | AL6: =IF($AJ6="UNKNOWN"," (U1)ALERT_REQ_UNKNOWN"," (U1)"&"ALERT_REQ_"&$AW$17&"_"&IF($AW$6<>$AW$17,$AW$6&"_","")&AJ6) -> (U1)ALERT_REQ_UNKNOWN | AR6: =IF(AQ71<>"",AQ71,IF(AQ70<>"","};","")) -> (U4)0x00000000U, /* 00 UNKNOWN */ | AS6: =IF(AQ136<>"",AQ136,IF(AQ135<>"","};","")) -> (U4)0x0000001FU, /* 00 UNKNOWN */ | AT6: =IF(AJ6<>"",AL6&IF(AJ7<>"",","," ")&REPT(" ",78-LEN(AL6))&"/* "&IF(C6<10,"0"&C6,C6)&" "&AJ6&REPT(" ",48-LEN(AJ6))&"*/",IF(AJ5<>"","};","")) -> (U1)ALERT_REQ_UNKNOWN, /* 00 UNKNOWN */ | AU6: { | AV6: MtxSrch変数名 | AW6: =UPPER(RIGHT(CELL("filename",A1),LEN(CELL("filename",A1))-FIND("]",CELL("filename",A1)))) -> TT
C7: =ROW()-ROW($C$6) -> 1 | D7: × | E7: × | F7: × | G7: × | H7: × | I7: × | J7: × | K7: × | L7: × | M7: × | N7: × | O7: × | P7: × | Q7: × | R7: × | S7: × | T7: × | U7: × | V7: × | W7: × | X7: × | Y7: × | Z7: × | AA7: × | AB7: × | AC7: × | AD7: × | AE7: 0 | AF7: 0 | AG7: 0 | AH7: 0 | AI7: 1 | AJ7: STNBY | AL7: =IF($AJ7="UNKNOWN"," (U1)ALERT_REQ_UNKNOWN"," (U1)"&"ALERT_REQ_"&$AW$17&"_"&IF($AW$6<>$AW$17,$AW$6&"_","")&AJ7) -> (U1)ALERT_REQ_S_ADTJA_TT_STNBY | AR7: =IF(AQ72<>"",AQ72,IF(AQ71<>"","};","")) -> (U4)0x00000001U, /* 01 STNBY */ | AS7: =IF(AQ137<>"",AQ137,IF(AQ136<>"","};","")) -> (U4)0x0000001FU, /* 01 STNBY */ | AT7: =IF(AJ7<>"",AL7&IF(AJ8<>"",","," ")&REPT(" ",78-LEN(AL7))&"/* "&IF(C7<10,"0"&C7,C7)&" "&AJ7&REPT(" ",48-LEN(AJ7))&"*/",IF(AJ6<>"","};","")) -> (U1)ALERT_REQ_S_ADTJA_TT_STNBY, /* 01 STNBY */ | AU7: =" &"&$AW$14&","&REPT(" ",69-LEN($AW$14))&"/* fp_u4_SRC_CHK */" -> &u4_s_AlertS_adtjaTtSrcchk, /* fp_u4_SRC_CHK */ | AV7: Use MtxSrch | AW7: =IF(B3="Search Table",1,0) -> 0
C8: =ROW()-ROW($C$6) -> 2 | D8: × | E8: × | F8: × | G8: × | H8: × | I8: × | J8: × | K8: × | L8: × | M8: × | N8: × | O8: × | P8: × | Q8: × | R8: × | S8: × | T8: × | U8: × | V8: × | W8: × | X8: × | Y8: × | Z8: × | AA8: × | AB8: × | AC8: × | AD8: × | AE8: 0 | AF8: 0 | AG8: 0 | AH8: 1 | AI8: 0 | AJ8: CTRL | AL8: =IF($AJ8="UNKNOWN"," (U1)ALERT_REQ_UNKNOWN"," (U1)"&"ALERT_REQ_"&$AW$17&"_"&IF($AW$6<>$AW$17,$AW$6&"_","")&AJ8) -> (U1)ALERT_REQ_S_ADTJA_TT_CTRL | AR8: =IF(AQ73<>"",AQ73,IF(AQ72<>"","};","")) -> (U4)0x00000002U, /* 02 CTRL */ | AS8: =IF(AQ138<>"",AQ138,IF(AQ137<>"","};","")) -> (U4)0x0000001FU, /* 02 CTRL */ | AT8: =IF(AJ8<>"",AL8&IF(AJ9<>"",","," ")&REPT(" ",78-LEN(AL8))&"/* "&IF(C8<10,"0"&C8,C8)&" "&AJ8&REPT(" ",48-LEN(AJ8))&"*/",IF(AJ7<>"","};","")) -> (U1)ALERT_REQ_S_ADTJA_TT_CTRL, /* 02 CTRL */ | AU8: =IF($AW$15<>"NULL"," &"&$AW$15&","&REPT(" ",69-LEN($AW$15))&"/* fp_vd_XDST */"," vdp_PTR_NA, /* fp_vd_XDST */") -> vdp_PTR_NA, /* fp_vd_XDST */ | AV8: CRIT_NAME | AW8: ="u4_sp_ALERT_"&IF(AW6<>AW17,$AW$17&"_"&$AW$6,AW17)&"_CRIT" -> u4_sp_ALERT_S_ADTJA_TT_CRIT
C9: =ROW()-ROW($C$6) -> 3 | D9: × | E9: × | F9: × | G9: × | H9: × | I9: × | J9: × | K9: × | L9: × | M9: × | N9: × | O9: × | P9: × | Q9: × | R9: × | S9: × | T9: × | U9: × | V9: × | W9: × | X9: × | Y9: × | Z9: × | AA9: × | AB9: × | AC9: × | AD9: × | AE9: 0 | AF9: 0 | AG9: 0 | AH9: 1 | AI9: 1 | AJ9: MALFUNC | AL9: =IF($AJ9="UNKNOWN"," (U1)ALERT_REQ_UNKNOWN"," (U1)"&"ALERT_REQ_"&$AW$17&"_"&IF($AW$6<>$AW$17,$AW$6&"_","")&AJ9) -> (U1)ALERT_REQ_S_ADTJA_TT_MALFUNC | AR9: =IF(AQ74<>"",AQ74,IF(AQ73<>"","};","")) -> (U4)0x00000003U, /* 03 MALFUNC */ | AS9: =IF(AQ139<>"",AQ139,IF(AQ138<>"","};","")) -> (U4)0x0000001FU, /* 03 MALFUNC */ | AT9: =IF(AJ9<>"",AL9&IF(AJ10<>"",","," ")&REPT(" ",78-LEN(AL9))&"/* "&IF(C9<10,"0"&C9,C9)&" "&AJ9&REPT(" ",48-LEN(AJ9))&"*/",IF(AJ8<>"","};","")) -> (U1)ALERT_REQ_S_ADTJA_TT_MALFUNC, /* 03 MALFUNC */ | AV9: MASK_NAME | AW9: ="u4_sp_ALERT_"&IF(AW6<>AW17,$AW$17&"_"&$AW$6,AW17)&"_MASK" -> u4_sp_ALERT_S_ADTJA_TT_MASK
C10: =ROW()-ROW($C$6) -> 4 | D10: × | E10: × | F10: × | G10: × | H10: × | I10: × | J10: × | K10: × | L10: × | M10: × | N10: × | O10: × | P10: × | Q10: × | R10: × | S10: × | T10: × | U10: × | V10: × | W10: × | X10: × | Y10: × | Z10: × | AA10: × | AB10: × | AC10: × | AD10: × | AE10: 0 | AF10: 0 | AG10: 1 | AH10: 0 | AI10: 0 | AJ10: UNKNOWN | AL10: =IF($AJ10="UNKNOWN"," (U1)ALERT_REQ_UNKNOWN"," (U1)"&"ALERT_REQ_"&$AW$17&"_"&IF($AW$6<>$AW$17,$AW$6&"_","")&AJ10) -> (U1)ALERT_REQ_UNKNOWN | AR10: =IF(AQ75<>"",AQ75,IF(AQ74<>"","};","")) -> (U4)0x00000004U, /* 04 UNKNOWN */ | AS10: =IF(AQ140<>"",AQ140,IF(AQ139<>"","};","")) -> (U4)0x0000001FU, /* 04 UNKNOWN */ | AT10: =IF(AJ10<>"",AL10&IF(AJ11<>"",","," ")&REPT(" ",78-LEN(AL10))&"/* "&IF(C10<10,"0"&C10,C10)&" "&AJ10&REPT(" ",48-LEN(AJ10))&"*/",IF(AJ9<>"","};","")) -> (U1)ALERT_REQ_UNKNOWN, /* 04 UNKNOWN */ | AU10: =IF($AW$7=1," &"&$AW$9&"[0],"&REPT(" ",66-LEN($AW$9))&"/* u4p_MASK */"," (const U4 *)vdp_PTR_NA, /* u4p_MASK */") -> (const U4 *)vdp_PTR_NA, /* u4p_MASK */ | AV10: MTXSRCH_DEF | AW10: ="ALERT_"&IF(AW6<>AW17,$AW$17&"_"&$AW$6,AW17)&"_NUM_DST" -> ALERT_S_ADTJA_TT_NUM_DST
C11: =ROW()-ROW($C$6) -> 5 | D11: × | E11: × | F11: × | G11: × | H11: × | I11: × | J11: × | K11: × | L11: × | M11: × | N11: × | O11: × | P11: × | Q11: × | R11: × | S11: × | T11: × | U11: × | V11: × | W11: × | X11: × | Y11: × | Z11: × | AA11: × | AB11: × | AC11: × | AD11: × | AE11: 0 | AF11: 0 | AG11: 1 | AH11: 0 | AI11: 1 | AJ11: UNKNOWN | AL11: =IF($AJ11="UNKNOWN"," (U1)ALERT_REQ_UNKNOWN"," (U1)"&"ALERT_REQ_"&$AW$17&"_"&IF($AW$6<>$AW$17,$AW$6&"_","")&AJ11) -> (U1)ALERT_REQ_UNKNOWN | AR11: =IF(AQ76<>"",AQ76,IF(AQ75<>"","};","")) -> (U4)0x00000005U, /* 05 UNKNOWN */ | AS11: =IF(AQ141<>"",AQ141,IF(AQ140<>"","};","")) -> (U4)0x0000001FU, /* 05 UNKNOWN */ | AT11: =IF(AJ11<>"",AL11&IF(AJ12<>"",","," ")&REPT(" ",78-LEN(AL11))&"/* "&IF(C11<10,"0"&C11,C11)&" "&AJ11&REPT(" ",48-LEN(AJ11))&"*/",IF(AJ10<>"","};","")) -> (U1)ALERT_REQ_UNKNOWN, /* 05 UNKNOWN */ | AU11: =IF($AW$7=1," &"&$AW$8&"[0],"&REPT(" ",66-LEN($AW$8))&"/* u4p_CRIT */"," (const U4 *)vdp_PTR_NA, /* u4p_CRIT */") -> (const U4 *)vdp_PTR_NA, /* u4p_CRIT */ | AV11: MTXSRCH_OUT_DEF | AW11: ="u1_sp_ALERT_"&IF(AW6<>AW17,$AW$17&"_"&$AW$6,AW17)&"_DST" -> u1_sp_ALERT_S_ADTJA_TT_DST
C12: =ROW()-ROW($C$6) -> 6 | D12: × | E12: × | F12: × | G12: × | H12: × | I12: × | J12: × | K12: × | L12: × | M12: × | N12: × | O12: × | P12: × | Q12: × | R12: × | S12: × | T12: × | U12: × | V12: × | W12: × | X12: × | Y12: × | Z12: × | AA12: × | AB12: × | AC12: × | AD12: × | AE12: 0 | AF12: 0 | AG12: 1 | AH12: 1 | AI12: 0 | AJ12: UNKNOWN | AL12: =IF($AJ12="UNKNOWN"," (U1)ALERT_REQ_UNKNOWN"," (U1)"&"ALERT_REQ_"&$AW$17&"_"&IF($AW$6<>$AW$17,$AW$6&"_","")&AJ12) -> (U1)ALERT_REQ_UNKNOWN | AR12: =IF(AQ77<>"",AQ77,IF(AQ76<>"","};","")) -> (U4)0x00000006U, /* 06 UNKNOWN */ | AS12: =IF(AQ142<>"",AQ142,IF(AQ141<>"","};","")) -> (U4)0x0000001FU, /* 06 UNKNOWN */ | AT12: =IF(AJ12<>"",AL12&IF(AJ13<>"",","," ")&REPT(" ",78-LEN(AL12))&"/* "&IF(C12<10,"0"&C12,C12)&" "&AJ12&REPT(" ",48-LEN(AJ12))&"*/",IF(AJ11<>"","};","")) -> (U1)ALERT_REQ_UNKNOWN, /* 06 UNKNOWN */ | AV12: ALERT_MTRX_NAME | AW12: =Matrix!D8&"["&Matrix!D7&"]" -> st_gp_ALERT_S_ADTJA_MTRX[10]
C13: =ROW()-ROW($C$6) -> 7 | D13: × | E13: × | F13: × | G13: × | H13: × | I13: × | J13: × | K13: × | L13: × | M13: × | N13: × | O13: × | P13: × | Q13: × | R13: × | S13: × | T13: × | U13: × | V13: × | W13: × | X13: × | Y13: × | Z13: × | AA13: × | AB13: × | AC13: × | AD13: × | AE13: 0 | AF13: 0 | AG13: 1 | AH13: 1 | AI13: 1 | AJ13: UNKNOWN | AL13: =IF($AJ13="UNKNOWN"," (U1)ALERT_REQ_UNKNOWN"," (U1)"&"ALERT_REQ_"&$AW$17&"_"&IF($AW$6<>$AW$17,$AW$6&"_","")&AJ13) -> (U1)ALERT_REQ_UNKNOWN | AR13: =IF(AQ78<>"",AQ78,IF(AQ77<>"","};","")) -> (U4)0x00000007U, /* 07 UNKNOWN */ | AS13: =IF(AQ143<>"",AQ143,IF(AQ142<>"","};","")) -> (U4)0x0000001FU, /* 07 UNKNOWN */ | AT13: =IF(AJ13<>"",AL13&IF(AJ14<>"",","," ")&REPT(" ",78-LEN(AL13))&"/* "&IF(C13<10,"0"&C13,C13)&" "&AJ13&REPT(" ",48-LEN(AJ13))&"*/",IF(AJ12<>"","};","")) -> (U1)ALERT_REQ_UNKNOWN, /* 07 UNKNOWN */ | AU13: =" &"&$AW$11&"[0],"&REPT(" ",66-LEN($AW$11))&"/* u1p_DST */" -> &u1_sp_ALERT_S_ADTJA_TT_DST[0], /* u1p_DST */ | AV13: SRCH_NUM | AW13: =COUNTA($AJ$6:$AJ$69) -> 32
C14: =ROW()-ROW($C$6) -> 8 | D14: × | E14: × | F14: × | G14: × | H14: × | I14: × | J14: × | K14: × | L14: × | M14: × | N14: × | O14: × | P14: × | Q14: × | R14: × | S14: × | T14: × | U14: × | V14: × | W14: × | X14: × | Y14: × | Z14: × | AA14: × | AB14: × | AC14: × | AD14: × | AE14: 0 | AF14: 1 | AG14: 0 | AH14: 0 | AI14: 0 | AJ14: UNKNOWN | AL14: =IF($AJ14="UNKNOWN"," (U1)ALERT_REQ_UNKNOWN"," (U1)"&"ALERT_REQ_"&$AW$17&"_"&IF($AW$6<>$AW$17,$AW$6&"_","")&AJ14) -> (U1)ALERT_REQ_UNKNOWN | AR14: =IF(AQ79<>"",AQ79,IF(AQ78<>"","};","")) -> (U4)0x00000008U, /* 08 UNKNOWN */ | AS14: =IF(AQ144<>"",AQ144,IF(AQ143<>"","};","")) -> (U4)0x0000001FU, /* 08 UNKNOWN */ | AT14: =IF(AJ14<>"",AL14&IF(AJ15<>"",","," ")&REPT(" ",78-LEN(AL14))&"/* "&IF(C14<10,"0"&C14,C14)&" "&AJ14&REPT(" ",48-LEN(AJ14))&"*/",IF(AJ13<>"","};","")) -> (U1)ALERT_REQ_UNKNOWN, /* 08 UNKNOWN */ | AU14: =" (U2)"&$AW$10&","&REPT(" ",66-LEN($AW$10))&"/* u2_num_srch */" -> (U2)ALERT_S_ADTJA_TT_NUM_DST, /* u2_num_srch */ | AV14: SRC CHK | AW14: =IF(AW6<>AW17,VLOOKUP(AW6,Matrix!$C$13:$G$37,4,FALSE),Matrix!F13) -> u4_s_AlertS_adtjaTtSrcchk
C15: =ROW()-ROW($C$6) -> 9 | D15: × | E15: × | F15: × | G15: × | H15: × | I15: × | J15: × | K15: × | L15: × | M15: × | N15: × | O15: × | P15: × | Q15: × | R15: × | S15: × | T15: × | U15: × | V15: × | W15: × | X15: × | Y15: × | Z15: × | AA15: × | AB15: × | AC15: × | AD15: × | AE15: 0 | AF15: 1 | AG15: 0 | AH15: 0 | AI15: 1 | AJ15: UNKNOWN | AL15: =IF($AJ15="UNKNOWN"," (U1)ALERT_REQ_UNKNOWN"," (U1)"&"ALERT_REQ_"&$AW$17&"_"&IF($AW$6<>$AW$17,$AW$6&"_","")&AJ15) -> (U1)ALERT_REQ_UNKNOWN | AR15: =IF(AQ80<>"",AQ80,IF(AQ79<>"","};","")) -> (U4)0x00000009U, /* 09 UNKNOWN */ | AS15: =IF(AQ145<>"",AQ145,IF(AQ144<>"","};","")) -> (U4)0x0000001FU, /* 09 UNKNOWN */ | AT15: =IF(AJ15<>"",AL15&IF(AJ16<>"",","," ")&REPT(" ",78-LEN(AL15))&"/* "&IF(C15<10,"0"&C15,C15)&" "&AJ15&REPT(" ",48-LEN(AJ15))&"*/",IF(AJ14<>"","};","")) -> (U1)ALERT_REQ_UNKNOWN, /* 09 UNKNOWN */ | AU15: =" (U1)"&$AW$16&REPT(" ",67-LEN($AW$16))&"/* u1_vom_act */" -> (U1)ALERT_VOM_IGN_ON /* u1_vom_act */ | AV15: RWTX | AW15: =IF(AW6<>AW17,VLOOKUP(AW6,Matrix!$C$13:$G$37,5,FALSE),Matrix!G13) -> NULL
C16: =ROW()-ROW($C$6) -> 10 | D16: × | E16: × | F16: × | G16: × | H16: × | I16: × | J16: × | K16: × | L16: × | M16: × | N16: × | O16: × | P16: × | Q16: × | R16: × | S16: × | T16: × | U16: × | V16: × | W16: × | X16: × | Y16: × | Z16: × | AA16: × | AB16: × | AC16: × | AD16: × | AE16: 0 | AF16: 1 | AG16: 0 | AH16: 1 | AI16: 0 | AJ16: UNKNOWN | AL16: =IF($AJ16="UNKNOWN"," (U1)ALERT_REQ_UNKNOWN"," (U1)"&"ALERT_REQ_"&$AW$17&"_"&IF($AW$6<>$AW$17,$AW$6&"_","")&AJ16) -> (U1)ALERT_REQ_UNKNOWN | AR16: =IF(AQ81<>"",AQ81,IF(AQ80<>"","};","")) -> (U4)0x0000000AU, /* 10 UNKNOWN */ | AS16: =IF(AQ146<>"",AQ146,IF(AQ145<>"","};","")) -> (U4)0x0000001FU, /* 10 UNKNOWN */ | AT16: =IF(AJ16<>"",AL16&IF(AJ17<>"",","," ")&REPT(" ",78-LEN(AL16))&"/* "&IF(C16<10,"0"&C16,C16)&" "&AJ16&REPT(" ",48-LEN(AJ16))&"*/",IF(AJ15<>"","};","")) -> (U1)ALERT_REQ_UNKNOWN, /* 10 UNKNOWN */ | AU16: } | AV16: ACT | AW16: =IF(AW6<>AW17,VLOOKUP(AW6,Matrix!$C$13:$G$37,2,FALSE),Matrix!D13) -> ALERT_VOM_IGN_ON
C17: =ROW()-ROW($C$6) -> 11 | D17: × | E17: × | F17: × | G17: × | H17: × | I17: × | J17: × | K17: × | L17: × | M17: × | N17: × | O17: × | P17: × | Q17: × | R17: × | S17: × | T17: × | U17: × | V17: × | W17: × | X17: × | Y17: × | Z17: × | AA17: × | AB17: × | AC17: × | AD17: × | AE17: 0 | AF17: 1 | AG17: 0 | AH17: 1 | AI17: 1 | AJ17: UNKNOWN | AL17: =IF($AJ17="UNKNOWN"," (U1)ALERT_REQ_UNKNOWN"," (U1)"&"ALERT_REQ_"&$AW$17&"_"&IF($AW$6<>$AW$17,$AW$6&"_","")&AJ17) -> (U1)ALERT_REQ_UNKNOWN | AR17: =IF(AQ82<>"",AQ82,IF(AQ81<>"","};","")) -> (U4)0x0000000BU, /* 11 UNKNOWN */ | AS17: =IF(AQ147<>"",AQ147,IF(AQ146<>"","};","")) -> (U4)0x0000001FU, /* 11 UNKNOWN */ | AT17: =IF(AJ17<>"",AL17&IF(AJ18<>"",","," ")&REPT(" ",78-LEN(AL17))&"/* "&IF(C17<10,"0"&C17,C17)&" "&AJ17&REPT(" ",48-LEN(AJ17))&"*/",IF(AJ16<>"","};","")) -> (U1)ALERT_REQ_UNKNOWN, /* 11 UNKNOWN */ | AU17: }; | AV17: ALERT_MTRX変数名 | AW17: =UPPER(Matrix!$D$6) -> S_ADTJA
C18: =ROW()-ROW($C$6) -> 12 | D18: × | E18: × | F18: × | G18: × | H18: × | I18: × | J18: × | K18: × | L18: × | M18: × | N18: × | O18: × | P18: × | Q18: × | R18: × | S18: × | T18: × | U18: × | V18: × | W18: × | X18: × | Y18: × | Z18: × | AA18: × | AB18: × | AC18: × | AD18: × | AE18: 0 | AF18: 1 | AG18: 1 | AH18: 0 | AI18: 0 | AJ18: UNKNOWN | AL18: =IF($AJ18="UNKNOWN"," (U1)ALERT_REQ_UNKNOWN"," (U1)"&"ALERT_REQ_"&$AW$17&"_"&IF($AW$6<>$AW$17,$AW$6&"_","")&AJ18) -> (U1)ALERT_REQ_UNKNOWN | AR18: =IF(AQ83<>"",AQ83,IF(AQ82<>"","};","")) -> (U4)0x0000000CU, /* 12 UNKNOWN */ | AS18: =IF(AQ148<>"",AQ148,IF(AQ147<>"","};","")) -> (U4)0x0000001FU, /* 12 UNKNOWN */ | AT18: =IF(AJ18<>"",AL18&IF(AJ19<>"",","," ")&REPT(" ",78-LEN(AL18))&"/* "&IF(C18<10,"0"&C18,C18)&" "&AJ18&REPT(" ",48-LEN(AJ18))&"*/",IF(AJ17<>"","};","")) -> (U1)ALERT_REQ_UNKNOWN, /* 12 UNKNOWN */
C19: =ROW()-ROW($C$6) -> 13 | D19: × | E19: × | F19: × | G19: × | H19: × | I19: × | J19: × | K19: × | L19: × | M19: × | N19: × | O19: × | P19: × | Q19: × | R19: × | S19: × | T19: × | U19: × | V19: × | W19: × | X19: × | Y19: × | Z19: × | AA19: × | AB19: × | AC19: × | AD19: × | AE19: 0 | AF19: 1 | AG19: 1 | AH19: 0 | AI19: 1 | AJ19: UNKNOWN | AL19: =IF($AJ19="UNKNOWN"," (U1)ALERT_REQ_UNKNOWN"," (U1)"&"ALERT_REQ_"&$AW$17&"_"&IF($AW$6<>$AW$17,$AW$6&"_","")&AJ19) -> (U1)ALERT_REQ_UNKNOWN | AR19: =IF(AQ84<>"",AQ84,IF(AQ83<>"","};","")) -> (U4)0x0000000DU, /* 13 UNKNOWN */ | AS19: =IF(AQ149<>"",AQ149,IF(AQ148<>"","};","")) -> (U4)0x0000001FU, /* 13 UNKNOWN */ | AT19: =IF(AJ19<>"",AL19&IF(AJ20<>"",","," ")&REPT(" ",78-LEN(AL19))&"/* "&IF(C19<10,"0"&C19,C19)&" "&AJ19&REPT(" ",48-LEN(AJ19))&"*/",IF(AJ18<>"","};","")) -> (U1)ALERT_REQ_UNKNOWN, /* 13 UNKNOWN */
C20: =ROW()-ROW($C$6) -> 14 | D20: × | E20: × | F20: × | G20: × | H20: × | I20: × | J20: × | K20: × | L20: × | M20: × | N20: × | O20: × | P20: × | Q20: × | R20: × | S20: × | T20: × | U20: × | V20: × | W20: × | X20: × | Y20: × | Z20: × | AA20: × | AB20: × | AC20: × | AD20: × | AE20: 0 | AF20: 1 | AG20: 1 | AH20: 1 | AI20: 0 | AJ20: UNKNOWN | AL20: =IF($AJ20="UNKNOWN"," (U1)ALERT_REQ_UNKNOWN"," (U1)"&"ALERT_REQ_"&$AW$17&"_"&IF($AW$6<>$AW$17,$AW$6&"_","")&AJ20) -> (U1)ALERT_REQ_UNKNOWN | AR20: =IF(AQ85<>"",AQ85,IF(AQ84<>"","};","")) -> (U4)0x0000000EU, /* 14 UNKNOWN */ | AS20: =IF(AQ150<>"",AQ150,IF(AQ149<>"","};","")) -> (U4)0x0000001FU, /* 14 UNKNOWN */ | AT20: =IF(AJ20<>"",AL20&IF(AJ21<>"",","," ")&REPT(" ",78-LEN(AL20))&"/* "&IF(C20<10,"0"&C20,C20)&" "&AJ20&REPT(" ",48-LEN(AJ20))&"*/",IF(AJ19<>"","};","")) -> (U1)ALERT_REQ_UNKNOWN, /* 14 UNKNOWN */
C21: =ROW()-ROW($C$6) -> 15 | D21: × | E21: × | F21: × | G21: × | H21: × | I21: × | J21: × | K21: × | L21: × | M21: × | N21: × | O21: × | P21: × | Q21: × | R21: × | S21: × | T21: × | U21: × | V21: × | W21: × | X21: × | Y21: × | Z21: × | AA21: × | AB21: × | AC21: × | AD21: × | AE21: 0 | AF21: 1 | AG21: 1 | AH21: 1 | AI21: 1 | AJ21: UNKNOWN | AL21: =IF($AJ21="UNKNOWN"," (U1)ALERT_REQ_UNKNOWN"," (U1)"&"ALERT_REQ_"&$AW$17&"_"&IF($AW$6<>$AW$17,$AW$6&"_","")&AJ21) -> (U1)ALERT_REQ_UNKNOWN | AR21: =IF(AQ86<>"",AQ86,IF(AQ85<>"","};","")) -> (U4)0x0000000FU, /* 15 UNKNOWN */ | AS21: =IF(AQ151<>"",AQ151,IF(AQ150<>"","};","")) -> (U4)0x0000001FU, /* 15 UNKNOWN */ | AT21: =IF(AJ21<>"",AL21&IF(AJ22<>"",","," ")&REPT(" ",78-LEN(AL21))&"/* "&IF(C21<10,"0"&C21,C21)&" "&AJ21&REPT(" ",48-LEN(AJ21))&"*/",IF(AJ20<>"","};","")) -> (U1)ALERT_REQ_UNKNOWN, /* 15 UNKNOWN */
C22: =ROW()-ROW($C$6) -> 16 | D22: × | E22: × | F22: × | G22: × | H22: × | I22: × | J22: × | K22: × | L22: × | M22: × | N22: × | O22: × | P22: × | Q22: × | R22: × | S22: × | T22: × | U22: × | V22: × | W22: × | X22: × | Y22: × | Z22: × | AA22: × | AB22: × | AC22: × | AD22: × | AE22: 1 | AF22: 0 | AG22: 0 | AH22: 0 | AI22: 0 | AJ22: MALFUNC | AL22: =IF($AJ22="UNKNOWN"," (U1)ALERT_REQ_UNKNOWN"," (U1)"&"ALERT_REQ_"&$AW$17&"_"&IF($AW$6<>$AW$17,$AW$6&"_","")&AJ22) -> (U1)ALERT_REQ_S_ADTJA_TT_MALFUNC | AR22: =IF(AQ87<>"",AQ87,IF(AQ86<>"","};","")) -> (U4)0x00000010U, /* 16 MALFUNC */ | AS22: =IF(AQ152<>"",AQ152,IF(AQ151<>"","};","")) -> (U4)0x0000001FU, /* 16 MALFUNC */ | AT22: =IF(AJ22<>"",AL22&IF(AJ23<>"",","," ")&REPT(" ",78-LEN(AL22))&"/* "&IF(C22<10,"0"&C22,C22)&" "&AJ22&REPT(" ",48-LEN(AJ22))&"*/",IF(AJ21<>"","};","")) -> (U1)ALERT_REQ_S_ADTJA_TT_MALFUNC, /* 16 MALFUNC */
C23: =ROW()-ROW($C$6) -> 17 | D23: × | E23: × | F23: × | G23: × | H23: × | I23: × | J23: × | K23: × | L23: × | M23: × | N23: × | O23: × | P23: × | Q23: × | R23: × | S23: × | T23: × | U23: × | V23: × | W23: × | X23: × | Y23: × | Z23: × | AA23: × | AB23: × | AC23: × | AD23: × | AE23: 1 | AF23: 0 | AG23: 0 | AH23: 0 | AI23: 1 | AJ23: MALFUNC | AL23: =IF($AJ23="UNKNOWN"," (U1)ALERT_REQ_UNKNOWN"," (U1)"&"ALERT_REQ_"&$AW$17&"_"&IF($AW$6<>$AW$17,$AW$6&"_","")&AJ23) -> (U1)ALERT_REQ_S_ADTJA_TT_MALFUNC | AR23: =IF(AQ88<>"",AQ88,IF(AQ87<>"","};","")) -> (U4)0x00000011U, /* 17 MALFUNC */ | AS23: =IF(AQ153<>"",AQ153,IF(AQ152<>"","};","")) -> (U4)0x0000001FU, /* 17 MALFUNC */ | AT23: =IF(AJ23<>"",AL23&IF(AJ24<>"",","," ")&REPT(" ",78-LEN(AL23))&"/* "&IF(C23<10,"0"&C23,C23)&" "&AJ23&REPT(" ",48-LEN(AJ23))&"*/",IF(AJ22<>"","};","")) -> (U1)ALERT_REQ_S_ADTJA_TT_MALFUNC, /* 17 MALFUNC */
C24: =ROW()-ROW($C$6) -> 18 | D24: × | E24: × | F24: × | G24: × | H24: × | I24: × | J24: × | K24: × | L24: × | M24: × | N24: × | O24: × | P24: × | Q24: × | R24: × | S24: × | T24: × | U24: × | V24: × | W24: × | X24: × | Y24: × | Z24: × | AA24: × | AB24: × | AC24: × | AD24: × | AE24: 1 | AF24: 0 | AG24: 0 | AH24: 1 | AI24: 0 | AJ24: MALFUNC | AL24: =IF($AJ24="UNKNOWN"," (U1)ALERT_REQ_UNKNOWN"," (U1)"&"ALERT_REQ_"&$AW$17&"_"&IF($AW$6<>$AW$17,$AW$6&"_","")&AJ24) -> (U1)ALERT_REQ_S_ADTJA_TT_MALFUNC | AR24: =IF(AQ89<>"",AQ89,IF(AQ88<>"","};","")) -> (U4)0x00000012U, /* 18 MALFUNC */ | AS24: =IF(AQ154<>"",AQ154,IF(AQ153<>"","};","")) -> (U4)0x0000001FU, /* 18 MALFUNC */ | AT24: =IF(AJ24<>"",AL24&IF(AJ25<>"",","," ")&REPT(" ",78-LEN(AL24))&"/* "&IF(C24<10,"0"&C24,C24)&" "&AJ24&REPT(" ",48-LEN(AJ24))&"*/",IF(AJ23<>"","};","")) -> (U1)ALERT_REQ_S_ADTJA_TT_MALFUNC, /* 18 MALFUNC */
C25: =ROW()-ROW($C$6) -> 19 | D25: × | E25: × | F25: × | G25: × | H25: × | I25: × | J25: × | K25: × | L25: × | M25: × | N25: × | O25: × | P25: × | Q25: × | R25: × | S25: × | T25: × | U25: × | V25: × | W25: × | X25: × | Y25: × | Z25: × | AA25: × | AB25: × | AC25: × | AD25: × | AE25: 1 | AF25: 0 | AG25: 0 | AH25: 1 | AI25: 1 | AJ25: MALFUNC | AL25: =IF($AJ25="UNKNOWN"," (U1)ALERT_REQ_UNKNOWN"," (U1)"&"ALERT_REQ_"&$AW$17&"_"&IF($AW$6<>$AW$17,$AW$6&"_","")&AJ25) -> (U1)ALERT_REQ_S_ADTJA_TT_MALFUNC | AR25: =IF(AQ90<>"",AQ90,IF(AQ89<>"","};","")) -> (U4)0x00000013U, /* 19 MALFUNC */ | AS25: =IF(AQ155<>"",AQ155,IF(AQ154<>"","};","")) -> (U4)0x0000001FU, /* 19 MALFUNC */ | AT25: =IF(AJ25<>"",AL25&IF(AJ26<>"",","," ")&REPT(" ",78-LEN(AL25))&"/* "&IF(C25<10,"0"&C25,C25)&" "&AJ25&REPT(" ",48-LEN(AJ25))&"*/",IF(AJ24<>"","};","")) -> (U1)ALERT_REQ_S_ADTJA_TT_MALFUNC, /* 19 MALFUNC */
C26: =ROW()-ROW($C$6) -> 20 | D26: × | E26: × | F26: × | G26: × | H26: × | I26: × | J26: × | K26: × | L26: × | M26: × | N26: × | O26: × | P26: × | Q26: × | R26: × | S26: × | T26: × | U26: × | V26: × | W26: × | X26: × | Y26: × | Z26: × | AA26: × | AB26: × | AC26: × | AD26: × | AE26: 1 | AF26: 0 | AG26: 1 | AH26: 0 | AI26: 0 | AJ26: MALFUNC | AL26: =IF($AJ26="UNKNOWN"," (U1)ALERT_REQ_UNKNOWN"," (U1)"&"ALERT_REQ_"&$AW$17&"_"&IF($AW$6<>$AW$17,$AW$6&"_","")&AJ26) -> (U1)ALERT_REQ_S_ADTJA_TT_MALFUNC | AR26: =IF(AQ91<>"",AQ91,IF(AQ90<>"","};","")) -> (U4)0x00000014U, /* 20 MALFUNC */ | AS26: =IF(AQ156<>"",AQ156,IF(AQ155<>"","};","")) -> (U4)0x0000001FU, /* 20 MALFUNC */ | AT26: =IF(AJ26<>"",AL26&IF(AJ27<>"",","," ")&REPT(" ",78-LEN(AL26))&"/* "&IF(C26<10,"0"&C26,C26)&" "&AJ26&REPT(" ",48-LEN(AJ26))&"*/",IF(AJ25<>"","};","")) -> (U1)ALERT_REQ_S_ADTJA_TT_MALFUNC, /* 20 MALFUNC */
C27: =ROW()-ROW($C$6) -> 21 | D27: × | E27: × | F27: × | G27: × | H27: × | I27: × | J27: × | K27: × | L27: × | M27: × | N27: × | O27: × | P27: × | Q27: × | R27: × | S27: × | T27: × | U27: × | V27: × | W27: × | X27: × | Y27: × | Z27: × | AA27: × | AB27: × | AC27: × | AD27: × | AE27: 1 | AF27: 0 | AG27: 1 | AH27: 0 | AI27: 1 | AJ27: MALFUNC | AL27: =IF($AJ27="UNKNOWN"," (U1)ALERT_REQ_UNKNOWN"," (U1)"&"ALERT_REQ_"&$AW$17&"_"&IF($AW$6<>$AW$17,$AW$6&"_","")&AJ27) -> (U1)ALERT_REQ_S_ADTJA_TT_MALFUNC | AR27: =IF(AQ92<>"",AQ92,IF(AQ91<>"","};","")) -> (U4)0x00000015U, /* 21 MALFUNC */ | AS27: =IF(AQ157<>"",AQ157,IF(AQ156<>"","};","")) -> (U4)0x0000001FU, /* 21 MALFUNC */ | AT27: =IF(AJ27<>"",AL27&IF(AJ28<>"",","," ")&REPT(" ",78-LEN(AL27))&"/* "&IF(C27<10,"0"&C27,C27)&" "&AJ27&REPT(" ",48-LEN(AJ27))&"*/",IF(AJ26<>"","};","")) -> (U1)ALERT_REQ_S_ADTJA_TT_MALFUNC, /* 21 MALFUNC */
C28: =ROW()-ROW($C$6) -> 22 | D28: × | E28: × | F28: × | G28: × | H28: × | I28: × | J28: × | K28: × | L28: × | M28: × | N28: × | O28: × | P28: × | Q28: × | R28: × | S28: × | T28: × | U28: × | V28: × | W28: × | X28: × | Y28: × | Z28: × | AA28: × | AB28: × | AC28: × | AD28: × | AE28: 1 | AF28: 0 | AG28: 1 | AH28: 1 | AI28: 0 | AJ28: MALFUNC | AL28: =IF($AJ28="UNKNOWN"," (U1)ALERT_REQ_UNKNOWN"," (U1)"&"ALERT_REQ_"&$AW$17&"_"&IF($AW$6<>$AW$17,$AW$6&"_","")&AJ28) -> (U1)ALERT_REQ_S_ADTJA_TT_MALFUNC | AR28: =IF(AQ93<>"",AQ93,IF(AQ92<>"","};","")) -> (U4)0x00000016U, /* 22 MALFUNC */ | AS28: =IF(AQ158<>"",AQ158,IF(AQ157<>"","};","")) -> (U4)0x0000001FU, /* 22 MALFUNC */ | AT28: =IF(AJ28<>"",AL28&IF(AJ29<>"",","," ")&REPT(" ",78-LEN(AL28))&"/* "&IF(C28<10,"0"&C28,C28)&" "&AJ28&REPT(" ",48-LEN(AJ28))&"*/",IF(AJ27<>"","};","")) -> (U1)ALERT_REQ_S_ADTJA_TT_MALFUNC, /* 22 MALFUNC */
C29: =ROW()-ROW($C$6) -> 23 | D29: × | E29: × | F29: × | G29: × | H29: × | I29: × | J29: × | K29: × | L29: × | M29: × | N29: × | O29: × | P29: × | Q29: × | R29: × | S29: × | T29: × | U29: × | V29: × | W29: × | X29: × | Y29: × | Z29: × | AA29: × | AB29: × | AC29: × | AD29: × | AE29: 1 | AF29: 0 | AG29: 1 | AH29: 1 | AI29: 1 | AJ29: MALFUNC | AL29: =IF($AJ29="UNKNOWN"," (U1)ALERT_REQ_UNKNOWN"," (U1)"&"ALERT_REQ_"&$AW$17&"_"&IF($AW$6<>$AW$17,$AW$6&"_","")&AJ29) -> (U1)ALERT_REQ_S_ADTJA_TT_MALFUNC | AR29: =IF(AQ94<>"",AQ94,IF(AQ93<>"","};","")) -> (U4)0x00000017U, /* 23 MALFUNC */ | AS29: =IF(AQ159<>"",AQ159,IF(AQ158<>"","};","")) -> (U4)0x0000001FU, /* 23 MALFUNC */ | AT29: =IF(AJ29<>"",AL29&IF(AJ30<>"",","," ")&REPT(" ",78-LEN(AL29))&"/* "&IF(C29<10,"0"&C29,C29)&" "&AJ29&REPT(" ",48-LEN(AJ29))&"*/",IF(AJ28<>"","};","")) -> (U1)ALERT_REQ_S_ADTJA_TT_MALFUNC, /* 23 MALFUNC */
... C37: =ROW()-ROW($C$6) -> 31 | D37: × | E37: × | F37: × | G37: × | H37: × | I37: × | J37: × | K37: × | L37: × | M37: × | N37: × | O37: × | P37: × | Q37: × | R37: × | S37: × | T37: × | U37: × | V37: × | W37: × | X37: × | Y37: × | Z37: × | AA37: × | AB37: × | AC37: × | AD37: × | AE37: 1 | AF37: 1 | AG37: 1 | AH37: 1 | AI37: 1 | AJ37: MALFUNC | AL37: =IF($AJ37="UNKNOWN"," (U1)ALERT_REQ_UNKNOWN"," (U1)"&"ALERT_REQ_"&$AW$17&"_"&IF($AW$6<>$AW$17,$AW$6&"_","")&AJ37) -> (U1)ALERT_REQ_S_ADTJA_TT_MALFUNC | AR37: =IF(AQ102<>"",AQ102,IF(AQ101<>"","};","")) -> (U4)0x0000001FU /* 31 MALFUNC */ | AS37: =IF(AQ167<>"",AQ167,IF(AQ166<>"","};","")) -> (U4)0x0000001FU /* 31 MALFUNC */ | AT37: =IF(AJ37<>"",AL37&IF(AJ38<>"",","," ")&REPT(" ",78-LEN(AL37))&"/* "&IF(C37<10,"0"&C37,C37)&" "&AJ37&REPT(" ",48-LEN(AJ37))&"*/",IF(AJ36<>"","};","")) -> (U1)ALERT_REQ_S_ADTJA_TT_MALFUNC /* 31 MALFUNC */
C38: =ROW()-ROW($C$6) -> 32 | D38: × | E38: × | F38: × | G38: × | H38: × | I38: × | J38: × | K38: × | L38: × | M38: × | N38: × | O38: × | P38: × | Q38: × | R38: × | S38: × | T38: × | U38: × | V38: × | W38: × | X38: × | Y38: × | Z38: × | AA38: × | AB38: × | AC38: × | AD38: × | AE38: × | AF38: × | AG38: × | AH38: × | AI38: × | AL38: =IF($AJ38="UNKNOWN"," (U1)ALERT_REQ_UNKNOWN"," (U1)"&"ALERT_REQ_"&$AW$17&"_"&IF($AW$6<>$AW$17,$AW$6&"_","")&AJ38) -> (U1)ALERT_REQ_S_ADTJA_TT_ | AR38: =IF(AQ103<>"",AQ103,IF(AQ102<>"","};","")) -> }; | AS38: =IF(AQ168<>"",AQ168,IF(AQ167<>"","};","")) -> }; | AT38: =IF(AJ38<>"",AL38&IF(AJ39<>"",","," ")&REPT(" ",78-LEN(AL38))&"/* "&IF(C38<10,"0"&C38,C38)&" "&AJ38&REPT(" ",48-LEN(AJ38))&"*/",IF(AJ37<>"","};","")) -> };
