Workbook
Name A: #REF!
Name B: #REF!
Name d: #REF!
Name DefaultFontType: #REF!
Name DotPitch: #REF!
Name K: #REF!
Name LED: #REF!
Name ｓ: #REF!
Name Sheet_dspmaincfg_Top: #REF!
Name Sheet_ユーザーカスタマイズ手順_Top: #REF!
Name Sheet_基礎知識_dispdomain: #REF!
Name Sheet_基礎知識_dispdomain_Diagram: #REF!
Name Sheet_基礎知識_dspmgr: #REF!
Name Sheet_基礎知識_dspmgr_Contents: #REF!
Name Sheet_基礎知識_dspmgr_STM: #REF!
Name Sheet_基礎知識_dspmgr_Struct: #REF!
Name Sheet_基礎知識_dspmgr_SwCancel: #REF!
Name Sheet_基礎知識_mainscrl: #REF!
Name Sheet_基礎知識_mainscrl_Contents: #REF!
Name Sheet_基礎知識_mainscrl_MainSub: #REF!
Name Sheet_基礎知識_mainscrl_Struct: #REF!
Name Sheet_基礎知識_swdtctr: #REF!
Name Sheet_基礎知識_Top: #REF!
Name xlo1: #REF!
Name xlo2: #REF!
Name xlo3: #REF!
Name xlo4: #REF!
Name xup1: #REF!
Name xup2: #REF!
Name xup3: #REF!
Name xup4: #REF!
Name ylo1: #REF!
Name ylo2: #REF!
Name ylo3: #REF!
Name ylo4: #REF!
Name yup1: #REF!
Name yup2: #REF!
Name yup3: #REF!
Name yup4: #REF!
Name テスト: #REF!
Name 関数名_確定_BON: '[4]Config - dspmgr'!#REF!
Name 関数名_確定_IGOFF: '[4]Config - dspmgr'!#REF!
Name 関数名_確定_IGON: '[4]Config - dspmgr'!#REF!
Name 関数名_確定_WKUP: '[4]Config - dspmgr'!#REF!
Name 関数名_確定_状態遷移_0: '[4]Config - dspmgr'!#REF!
Name 関数名_確定_状態遷移_1: '[4]Config - dspmgr'!#REF!
Name 関数名_確定_状態遷移_2: '[4]Config - dspmgr'!#REF!
Name 関数名_確定_状態遷移_3: '[4]Config - dspmgr'!#REF!
Name 関数名_確定_状態遷移_4: '[4]Config - dspmgr'!#REF!
Name 関数名_確定_定期: '[4]Config - dspmgr'!#REF!
Name 駆動回路: #REF!
Name 品番: #REF!

Sheet 表紙（承認欄）
T13: =MID(CELL("filename",A1),FIND("[",CELL("filename",A1))+1,FIND("]",CELL("filename",A1))-FIND("[",CELL("filename",A1))-1) -> alert_P_OILPRE-CSTD-0-05-A-C0.xlsx
Y34: (株)NTTデータMSE
Y35: 承認 | AD35: 検討 | AI35: 作成
AA38: <DN確認印> | AF38: <DN検討印> | AK38: <OS作成印>
Y42: デンソーテクノ(株)
Y43: 承認 | AD43: 検討 | AI43: 作成
AA46: <DT確認印> | AF46: <DT検討印> | AK46: <DT作成印>
Y50: DENSO TECHNO PHIL. INC
Y51: 承認 | AD51: 検討 | AI51: 作成
AA54: <OS確認印> | AF54: <OS検討印> | AK54: <OS作成印>

Sheet 表紙
H2: コンポーネント | I2: Vom::Alert
D3: =REPLACE(LEFT(CELL("filename",$B$1),FIND(".xls",CELL("filename",$B$1))-1),1,FIND("[",CELL("filename",$B$1)),) -> alert_P_OILPRE-CSTD-0-05-A-C0 | H3: Gitリポジトリ | I3: https://aip01.dndev.net/bitbucket/scm/aip_tp/tmcapp_ict1_alert.git
E4: =DGET(B8:C16,"Ver.",H4:H5) -> 1.3.1 | H4: ROW
H5: =MAX(B9:B16) -> 5
C7: 更新履歴 | E7: 対象ソフトVer | G7: 承認欄 [DENSO] | M7: 承認欄 [NTTデータMSE] | S7: 承認欄 [DT]
B8: ROW | C8: Ver. | D8: 更新内容 | E8: Git(CommitID) | F8: Component Version | G8: 承認者 | H8: 承認日 | I8: 検討者 | J8: 検討日 | K8: 作成者 | L8: 作成日 | M8: 承認者 | N8: 承認日 | O8: 検討者 | P8: 検討日 | Q8: 作成者 | R8: 作成日 | S8: 承認者 | T8: 承認日 | U8: 検討者 | V8: 検討日 | W8: 作成者 | X8: 作成日
B9: =IF(C9=0,0,ROW()-ROW($B$8)) -> 1 | C9: 1.0.0 | D9: 新規作成(流用元：alert_P_OILPRE-CSTD-0-03-B-C0.xlsx) 840B CV対応 [Matrix]シート ・対象仕様書 ・ロケーション修正 [Reference]シート ・各キャプチャ画像を840B CV仕様書の画像に変更 ・通信途絶時間の変更をコメントで記載 | E9: - | F9: 5.5.0 | G9: - | H9: - | I9: - | J9: - | K9: - | L9: - | Q9: 大藤 | R9: 44264
B10: =IF(C10=0,0,ROW()-ROW($B$8)) -> 2 | C10: 1.1.0 | D10: 840B ジカ線判定追加対応 [Matrix]シート ・ロケーション修正 [Config_IF]シート ・u1_g_AlertOilpreSw()を追加 [Reference]シート ・吹き出しコメント追記 | E10: - | F10: 5.5.0 | G10: - | H10: - | I10: - | J10: - | K10: - | L10: - | Q10: 永原 | R10: 44511
B11: =IF(C11=0,0,ROW()-ROW($B$8)) -> 3 | C11: 1.2.0 | D11: 面企画#2 1A対応 (流用元：alert_P_OILPRE-CSTD-0-03-C-C0.xlsx) ・設計書のリビジョンをRev20に更新 [Matrix]シート ・対象仕様書、ロケーション変更 [WRN]シート ・B_OILPL_SIG=11b時、REQ=WRN_FLSHのパターンについて、IGP_PDC_SIG=1bの条件を追加 [Reference]シート ・キャプチャ更新 ・オイルプレッシャ警告判定 REQ, 振る舞い 変更 | E11: - | F11: 5.5.0 | G11: - | H11: - | I11: - | J11: - | K11: - | L11: - | Q11: 大野 | R11: 44776
B12: =IF(C12=0,0,ROW()-ROW($B$8)) -> 4 | C12: 1.3.0 | D12: 19PFv3 CV内部結合1対応 (流用元：alert_P_OILPRE-CSTD-0-03-E-C0.xlsx) [Matrix]シート ・対象仕様書、ロケーション変更 [Config_IF]シート ・u1_g_AlertOilpreSw(void)のコンフィグ関数の削除 [Reference]シート ・キャプチャ更新 ・じか線入力の補足内容を更新 | E12: - | F12: 5.5.0 | G12: - | H12: - | I12: - | J12: - | K12: - | L12: - | Q12: DTPH Glen | R12: 45209
B13: =IF(C13=0,0,ROW()-ROW($B$8)) -> 5 | C13: 1.3.1 | D13: 品質総点検(R4)：Alert設計書の修正対応 ファイル名の変更（変更前：alert_P_OILPRE-CSTD-0-03-F-C0.xlsx [Matrix]シート ・対象仕様書の変更 ・ロケーションの変更 [Reference]シート ・マクロ定義の補足情報の追加 →対象マクロ： ALERT_P_OILPRE_RXSTAT_** ALERT_P_OILPRE_THRSH_EHV_ECO ALERT_P_OILPRE_JDG_NUM [Reference2(RPM)]シート ・マクロ定義の補足情報の追加 →対象マクロ： ALERT_P_OILPRE_RPM_** | E13: - | F13: - | G13: - | H13: - | I13: - | J13: - | K13: - | L13: - | M13: - | N13: - | O13: - | P13: - | Q13: - | R13: - | S13: - | T13: - | U13: - | V13: - | W13: DTPH JM | X13: 45811
B14: =IF(C14=0,0,ROW()-ROW($B$8)) -> 0
B15: =IF(C15=0,0,ROW()-ROW($B$8)) -> 0

Sheet はじめに
B2: １．本書の目的
C3: TMC Specを分析した結果で、Vom::Alertの実装に必要となる情報を抽出し、Alert Config Toolのインプットとする。
B6: ２．上位文書
C7: # | E7: path
C8: 0 | D8: Alert設計資料 | E8: https://aip01.dndev.net/svn/aip/tmcapp/sd/evidence/trunk/02_Design/01_Vom/Alert/03_Component/alert_design.pptx
B12: ３．用語の説明
C13: # | D13: 用語 | E13: 説明
C14: 0 | D14: Alert Config Tool | E14: TMC Specと本設計書のトレースをデータベース管理するTool。
C15: 1 | D15: TT | E15: Telltale
C16: 2 | D16: PD | E16: Pop-up Display
C17: 3 | D17: BC | E17: Buzzer/Chime
C18: 4 | D18: RW | E18: Remote Warning
C19: 5 | D19: CH | E19: Alert Channel。 各Specを分析した結果で決定されるモジュール内分割単位。
C20: 6 | D20: VOM | E20: Vehicle Operation Mode
B24: ４．各シートの説明
C25: # | D25: 用語 | E25: 説明
C26: 0 | D26: Matrix | E26: 対象となるTMC Specならびに分析した結果で決定されるAlert Channel情報について記載する。 Alert Config Toolのインプットとする。
C27: 1 | D27: CH_Design | E27: 対象のTMC Specにおいて、Vom::Alertが外部に提供する各CHの出力(REQ)について記載する。 機能判定欄については、出力先によって実施責務が異なるため、出力先毎に有無を記載する。 TT機能判定、BC機能判定、PD機能判定 ： VSV側にて参照 RW機能判定 ： Vom::Alertにて参照 TMC Specにて定義される機能有無判定の要否について抽出した結果で記載する。 ※機種(e.x.775B)毎の要否ではないため、対象機種に応じた更新(メンテナンス)は行わない。 PD欄については、Alert制御仕様書にて定義されるWarning Noを記載する。 Alert Config Toolのインプットとする。
C28: 2 | D28: Config_IF | E28: 対象のTMC Specにおいて、 Vom::Alertが使用する外部ドメインIF Vom::Alertが使用するConfig IF、定義 について記載する。 Alert Config Toolのインプットとする。
C29: 3 | D29: TT/BC | E29: シート名は各CH名を採用する。 対象のTMC Specを分析した結果で、各CHのインプット/アウトプットの判定条件について記載する。 コーディング時のインプットとする。
C30: 4 | D30: Reference | E30: 対象のTMC Specを分析した際の中間成果物。参考情報として記載。メンテナンス対象外。
C31: 5 | D31: History | E31: テンプレート変更履歴
B37: ５．入力セルの凡例
E38: ユーザ入力セル
E39: 自動計算セル

Sheet Matrix
B2: 対象仕様書 | D2: MET-P_OILPRE-CSTD-0-05-A-C0.xlsm
B3: ロケーション | D3: https://aip01.dndev.net/svn/met/toyota/std/rd/spec/19PFver3/tags/00.Product/v4.12.d/
B4: モジュール名 | D4: =表紙!D3&".c" -> alert_P_OILPRE-CSTD-0-05-A-C0.c
D5: =IF(LEN(表紙!D3&".c") = LENB(表紙!D3&".c"),"※モジュール名 全角チェックOK","※モジュール名 全角チェックNG：ファイル名に全角文字が使用されています！") -> ※モジュール名 全角チェックOK
B6: 機能名 | D6: =MID(D4, LEN("alert_") + 1, FIND("-",D4,1) - LEN("alert_") - 1) -> P_OILPRE
B7: 判定要素数 | D7: =COUNTA($D$13:$D$37) -> 2
B8: Matrix名 | D8: ="st_gp_ALERT_"&UPPER(D6)&"_MTRX" -> st_gp_ALERT_P_OILPRE_MTRX
B9: 初期化関数名 | D9: vd_g_AlertP_oilpreInit
B10: 処理時間 | D10: -
B12: No | C12: CH Name | D12: VOM | E12: RW | F12: Srcchk | G12: RwTx | H12: CH | I12: REQ | K12: VOM | L12: 初期化関数名 | M12: CH名称中間データ
B13: 1 | C13: WRN | D13: ALERT_VOM_IGN_ON | E13: ○ | F13: =IF($D13<>"","u4_s_Alert"&UPPER(LEFT($D$6,1))&LOWER(MID($D$6,2,100))&IF($D$7=1,"",N13)&"Srcchk","") -> u4_s_AlertP_oilpreWrnSrcchk | G13: =IF($D13<>"",IF($E13="○","vd_s_Alert"&UPPER(LEFT($D$6,1))&LOWER(MID($D$6,2,100))&IF($D$7=1,"",N13)&"RwTx","NULL"),"") -> vd_s_AlertP_oilpreWrnRwTx | H13: =IF($D13<>"","ALERT_CH_"&UPPER($D$6)&IF($D$7=1,"","_"&UPPER($C13)),"") -> ALERT_CH_P_OILPRE_WRN | I13: =IF($D13<>"","ALERT_REQ_"&UPPER($D$6)&IF($D$7=1,"","_"&UPPER($C13)),"") -> ALERT_REQ_P_OILPRE_WRN | K13: ALERT_VOM_BAT_AO | L13: NULL | M13: =FIND("_",C13,1) -> #VALUE! | N13: =IF(IFERROR(M13,0),UPPER(LEFT(C13,1))&LOWER(MID(C13,2,M13-2))&UPPER(MID(C13,M13+1,1))&LOWER(MID(C13,M13+2,100)),UPPER(LEFT(C13,1))&LOWER(MID(C13,2,100))) -> Wrn
B14: 2 | C14: BC | D14: ALERT_VOM_IGN_ON | E14: － | F14: =IF($D14<>"","u4_s_Alert"&UPPER(LEFT($D$6,1))&LOWER(MID($D$6,2,100))&IF($D$7=1,"",N14)&"Srcchk","") -> u4_s_AlertP_oilpreBcSrcchk | G14: =IF($D14<>"",IF($E14="○","vd_s_Alert"&UPPER(LEFT($D$6,1))&LOWER(MID($D$6,2,100))&IF($D$7=1,"",N14)&"RwTx","NULL"),"") -> NULL | H14: =IF($D14<>"","ALERT_CH_"&UPPER($D$6)&IF($D$7=1,"","_"&UPPER($C14)),"") -> ALERT_CH_P_OILPRE_BC | I14: =IF($D14<>"","ALERT_REQ_"&UPPER($D$6)&IF($D$7=1,"","_"&UPPER($C14)),"") -> ALERT_REQ_P_OILPRE_BC | K14: ALERT_VOM_BAT_WT | L14: ="vd_g_Alert"&UPPER(LEFT(D6,1))&LOWER(MID(D6,2,100))&"Init" -> vd_g_AlertP_oilpreInit | M14: =FIND("_",C14,1) -> #VALUE! | N14: =IF(IFERROR(M14,0),UPPER(LEFT(C14,1))&LOWER(MID(C14,2,M14-2))&UPPER(MID(C14,M14+1,1))&LOWER(MID(C14,M14+2,100)),UPPER(LEFT(C14,1))&LOWER(MID(C14,2,100))) -> Bc
B15: 3 | F15: =IF($D15<>"","u4_s_Alert"&UPPER(LEFT($D$6,1))&LOWER(MID($D$6,2,100))&IF($D$7=1,"",N15)&"Srcchk","") | G15: =IF($D15<>"",IF($E15="○","vd_s_Alert"&UPPER(LEFT($D$6,1))&LOWER(MID($D$6,2,100))&IF($D$7=1,"",N15)&"RwTx","NULL"),"") | H15: =IF($D15<>"","ALERT_CH_"&UPPER($D$6)&IF($D$7=1,"","_"&UPPER($C15)),"") | I15: =IF($D15<>"","ALERT_REQ_"&UPPER($D$6)&IF($D$7=1,"","_"&UPPER($C15)),"") | K15: ALERT_VOM_IGN_OFF | M15: =FIND("_",C15,1) -> #VALUE! | N15: =IF(IFERROR(M15,0),UPPER(LEFT(C15,1))&LOWER(MID(C15,2,M15-2))&UPPER(MID(C15,M15+1,1))&LOWER(MID(C15,M15+2,100)),UPPER(LEFT(C15,1))&LOWER(MID(C15,2,100)))
B16: 4 | F16: =IF($D16<>"","u4_s_Alert"&UPPER(LEFT($D$6,1))&LOWER(MID($D$6,2,100))&IF($D$7=1,"",N16)&"Srcchk","") | G16: =IF($D16<>"",IF($E16="○","vd_s_Alert"&UPPER(LEFT($D$6,1))&LOWER(MID($D$6,2,100))&IF($D$7=1,"",N16)&"RwTx","NULL"),"") | H16: =IF($D16<>"","ALERT_CH_"&UPPER($D$6)&IF($D$7=1,"","_"&UPPER($C16)),"") | I16: =IF($D16<>"","ALERT_REQ_"&UPPER($D$6)&IF($D$7=1,"","_"&UPPER($C16)),"") | K16: ALERT_VOM_IGN_OFF_WT | M16: =FIND("_",C16,1) -> #VALUE! | N16: =IF(IFERROR(M16,0),UPPER(LEFT(C16,1))&LOWER(MID(C16,2,M16-2))&UPPER(MID(C16,M16+1,1))&LOWER(MID(C16,M16+2,100)),UPPER(LEFT(C16,1))&LOWER(MID(C16,2,100)))
B17: 5 | F17: =IF($D17<>"","u4_s_Alert"&UPPER(LEFT($D$6,1))&LOWER(MID($D$6,2,100))&IF($D$7=1,"",N17)&"Srcchk","") | G17: =IF($D17<>"",IF($E17="○","vd_s_Alert"&UPPER(LEFT($D$6,1))&LOWER(MID($D$6,2,100))&IF($D$7=1,"",N17)&"RwTx","NULL"),"") | H17: =IF($D17<>"","ALERT_CH_"&UPPER($D$6)&IF($D$7=1,"","_"&UPPER($C17)),"") | I17: =IF($D17<>"","ALERT_REQ_"&UPPER($D$6)&IF($D$7=1,"","_"&UPPER($C17)),"") | K17: ALERT_VOM_IGN_ON | M17: =FIND("_",C17,1) -> #VALUE! | N17: =IF(IFERROR(M17,0),UPPER(LEFT(C17,1))&LOWER(MID(C17,2,M17-2))&UPPER(MID(C17,M17+1,1))&LOWER(MID(C17,M17+2,100)),UPPER(LEFT(C17,1))&LOWER(MID(C17,2,100)))
B18: 6 | F18: =IF($D18<>"","u4_s_Alert"&UPPER(LEFT($D$6,1))&LOWER(MID($D$6,2,100))&IF($D$7=1,"",N18)&"Srcchk","") | G18: =IF($D18<>"",IF($E18="○","vd_s_Alert"&UPPER(LEFT($D$6,1))&LOWER(MID($D$6,2,100))&IF($D$7=1,"",N18)&"RwTx","NULL"),"") | H18: =IF($D18<>"","ALERT_CH_"&UPPER($D$6)&IF($D$7=1,"","_"&UPPER($C18)),"") | I18: =IF($D18<>"","ALERT_REQ_"&UPPER($D$6)&IF($D$7=1,"","_"&UPPER($C18)),"") | K18: ALERT_VOM_VCS_ON | M18: =FIND("_",C18,1) -> #VALUE! | N18: =IF(IFERROR(M18,0),UPPER(LEFT(C18,1))&LOWER(MID(C18,2,M18-2))&UPPER(MID(C18,M18+1,1))&LOWER(MID(C18,M18+2,100)),UPPER(LEFT(C18,1))&LOWER(MID(C18,2,100)))
B19: 7 | F19: =IF($D19<>"","u4_s_Alert"&UPPER(LEFT($D$6,1))&LOWER(MID($D$6,2,100))&IF($D$7=1,"",N19)&"Srcchk","") | G19: =IF($D19<>"",IF($E19="○","vd_s_Alert"&UPPER(LEFT($D$6,1))&LOWER(MID($D$6,2,100))&IF($D$7=1,"",N19)&"RwTx","NULL"),"") | H19: =IF($D19<>"","ALERT_CH_"&UPPER($D$6)&IF($D$7=1,"","_"&UPPER($C19)),"") | I19: =IF($D19<>"","ALERT_REQ_"&UPPER($D$6)&IF($D$7=1,"","_"&UPPER($C19)),"") | K19: ALERT_VOM_VCS_ON | M19: =FIND("_",C19,1) -> #VALUE! | N19: =IF(IFERROR(M19,0),UPPER(LEFT(C19,1))&LOWER(MID(C19,2,M19-2))&UPPER(MID(C19,M19+1,1))&LOWER(MID(C19,M19+2,100)),UPPER(LEFT(C19,1))&LOWER(MID(C19,2,100)))
B20: 8 | F20: =IF($D20<>"","u4_s_Alert"&UPPER(LEFT($D$6,1))&LOWER(MID($D$6,2,100))&IF($D$7=1,"",N20)&"Srcchk","") | G20: =IF($D20<>"",IF($E20="○","vd_s_Alert"&UPPER(LEFT($D$6,1))&LOWER(MID($D$6,2,100))&IF($D$7=1,"",N20)&"RwTx","NULL"),"") | H20: =IF($D20<>"","ALERT_CH_"&UPPER($D$6)&IF($D$7=1,"","_"&UPPER($C20)),"") | I20: =IF($D20<>"","ALERT_REQ_"&UPPER($D$6)&IF($D$7=1,"","_"&UPPER($C20)),"") | K20: ALERT_VOM_VCS_ON | M20: =FIND("_",C20,1) -> #VALUE! | N20: =IF(IFERROR(M20,0),UPPER(LEFT(C20,1))&LOWER(MID(C20,2,M20-2))&UPPER(MID(C20,M20+1,1))&LOWER(MID(C20,M20+2,100)),UPPER(LEFT(C20,1))&LOWER(MID(C20,2,100)))
B21: 9 | F21: =IF($D21<>"","u4_s_Alert"&UPPER(LEFT($D$6,1))&LOWER(MID($D$6,2,100))&IF($D$7=1,"",N21)&"Srcchk","") | G21: =IF($D21<>"",IF($E21="○","vd_s_Alert"&UPPER(LEFT($D$6,1))&LOWER(MID($D$6,2,100))&IF($D$7=1,"",N21)&"RwTx","NULL"),"") | H21: =IF($D21<>"","ALERT_CH_"&UPPER($D$6)&IF($D$7=1,"","_"&UPPER($C21)),"") | I21: =IF($D21<>"","ALERT_REQ_"&UPPER($D$6)&IF($D$7=1,"","_"&UPPER($C21)),"") | K21: ALERT_VOM_VCS_ON | M21: =FIND("_",C21,1) -> #VALUE! | N21: =IF(IFERROR(M21,0),UPPER(LEFT(C21,1))&LOWER(MID(C21,2,M21-2))&UPPER(MID(C21,M21+1,1))&LOWER(MID(C21,M21+2,100)),UPPER(LEFT(C21,1))&LOWER(MID(C21,2,100)))
B22: 10 | F22: =IF($D22<>"","u4_s_Alert"&UPPER(LEFT($D$6,1))&LOWER(MID($D$6,2,100))&IF($D$7=1,"",N22)&"Srcchk","") | G22: =IF($D22<>"",IF($E22="○","vd_s_Alert"&UPPER(LEFT($D$6,1))&LOWER(MID($D$6,2,100))&IF($D$7=1,"",N22)&"RwTx","NULL"),"") | H22: =IF($D22<>"","ALERT_CH_"&UPPER($D$6)&IF($D$7=1,"","_"&UPPER($C22)),"") | I22: =IF($D22<>"","ALERT_REQ_"&UPPER($D$6)&IF($D$7=1,"","_"&UPPER($C22)),"") | K22: ALERT_VOM_VCS_ON | M22: =FIND("_",C22,1) -> #VALUE! | N22: =IF(IFERROR(M22,0),UPPER(LEFT(C22,1))&LOWER(MID(C22,2,M22-2))&UPPER(MID(C22,M22+1,1))&LOWER(MID(C22,M22+2,100)),UPPER(LEFT(C22,1))&LOWER(MID(C22,2,100)))
B23: 11 | F23: =IF($D23<>"","u4_s_Alert"&UPPER(LEFT($D$6,1))&LOWER(MID($D$6,2,100))&IF($D$7=1,"",N23)&"Srcchk","") | G23: =IF($D23<>"",IF($E23="○","vd_s_Alert"&UPPER(LEFT($D$6,1))&LOWER(MID($D$6,2,100))&IF($D$7=1,"",N23)&"RwTx","NULL"),"") | H23: =IF($D23<>"","ALERT_CH_"&UPPER($D$6)&IF($D$7=1,"","_"&UPPER($C23)),"") | I23: =IF($D23<>"","ALERT_REQ_"&UPPER($D$6)&IF($D$7=1,"","_"&UPPER($C23)),"") | K23: ALERT_VOM_VCS_ON | M23: =FIND("_",C23,1) -> #VALUE! | N23: =IF(IFERROR(M23,0),UPPER(LEFT(C23,1))&LOWER(MID(C23,2,M23-2))&UPPER(MID(C23,M23+1,1))&LOWER(MID(C23,M23+2,100)),UPPER(LEFT(C23,1))&LOWER(MID(C23,2,100)))
B24: 12 | F24: =IF($D24<>"","u4_s_Alert"&UPPER(LEFT($D$6,1))&LOWER(MID($D$6,2,100))&IF($D$7=1,"",N24)&"Srcchk","") | G24: =IF($D24<>"",IF($E24="○","vd_s_Alert"&UPPER(LEFT($D$6,1))&LOWER(MID($D$6,2,100))&IF($D$7=1,"",N24)&"RwTx","NULL"),"") | H24: =IF($D24<>"","ALERT_CH_"&UPPER($D$6)&IF($D$7=1,"","_"&UPPER($C24)),"") | I24: =IF($D24<>"","ALERT_REQ_"&UPPER($D$6)&IF($D$7=1,"","_"&UPPER($C24)),"") | K24: ALERT_VOM_VCS_ON | M24: =FIND("_",C24,1) -> #VALUE! | N24: =IF(IFERROR(M24,0),UPPER(LEFT(C24,1))&LOWER(MID(C24,2,M24-2))&UPPER(MID(C24,M24+1,1))&LOWER(MID(C24,M24+2,100)),UPPER(LEFT(C24,1))&LOWER(MID(C24,2,100)))
B25: 13 | F25: =IF($D25<>"","u4_s_Alert"&UPPER(LEFT($D$6,1))&LOWER(MID($D$6,2,100))&IF($D$7=1,"",N25)&"Srcchk","") | G25: =IF($D25<>"",IF($E25="○","vd_s_Alert"&UPPER(LEFT($D$6,1))&LOWER(MID($D$6,2,100))&IF($D$7=1,"",N25)&"RwTx","NULL"),"") | H25: =IF($D25<>"","ALERT_CH_"&UPPER($D$6)&IF($D$7=1,"","_"&UPPER($C25)),"") | I25: =IF($D25<>"","ALERT_REQ_"&UPPER($D$6)&IF($D$7=1,"","_"&UPPER($C25)),"") | K25: ALERT_VOM_VCS_ON | M25: =FIND("_",C25,1) -> #VALUE! | N25: =IF(IFERROR(M25,0),UPPER(LEFT(C25,1))&LOWER(MID(C25,2,M25-2))&UPPER(MID(C25,M25+1,1))&LOWER(MID(C25,M25+2,100)),UPPER(LEFT(C25,1))&LOWER(MID(C25,2,100)))
B26: 14 | F26: =IF($D26<>"","u4_s_Alert"&UPPER(LEFT($D$6,1))&LOWER(MID($D$6,2,100))&IF($D$7=1,"",N26)&"Srcchk","") | G26: =IF($D26<>"",IF($E26="○","vd_s_Alert"&UPPER(LEFT($D$6,1))&LOWER(MID($D$6,2,100))&IF($D$7=1,"",N26)&"RwTx","NULL"),"") | H26: =IF($D26<>"","ALERT_CH_"&UPPER($D$6)&IF($D$7=1,"","_"&UPPER($C26)),"") | I26: =IF($D26<>"","ALERT_REQ_"&UPPER($D$6)&IF($D$7=1,"","_"&UPPER($C26)),"") | K26: ALERT_VOM_VCS_ON | M26: =FIND("_",C26,1) -> #VALUE! | N26: =IF(IFERROR(M26,0),UPPER(LEFT(C26,1))&LOWER(MID(C26,2,M26-2))&UPPER(MID(C26,M26+1,1))&LOWER(MID(C26,M26+2,100)),UPPER(LEFT(C26,1))&LOWER(MID(C26,2,100)))
... B37: 25 | F37: =IF($D37<>"","u4_s_Alert"&UPPER(LEFT($D$6,1))&LOWER(MID($D$6,2,100))&IF($D$7=1,"",N37)&"Srcchk","") | G37: =IF($D37<>"",IF($E37="○","vd_s_Alert"&UPPER(LEFT($D$6,1))&LOWER(MID($D$6,2,100))&IF($D$7=1,"",N37)&"RwTx","NULL"),"") | H37: =IF($D37<>"","ALERT_CH_"&UPPER($D$6)&IF($D$7=1,"","_"&UPPER($C37)),"") | I37: =IF($D37<>"","ALERT_REQ_"&UPPER($D$6)&IF($D$7=1,"","_"&UPPER($C37)),"") | K37: ALERT_VOM_VCS_ON | M37: =FIND("_",C37,1) -> #VALUE! | N37: =IF(IFERROR(M37,0),UPPER(LEFT(C37,1))&LOWER(MID(C37,2,M37-2))&UPPER(MID(C37,M37+1,1))&LOWER(MID(C37,M37+2,100)),UPPER(LEFT(C37,1))&LOWER(MID(C37,2,100)))

Sheet Config_IF
B2: Other Domain Define | O2: Alert Config IF List
B3: No | C3: define Name | D3: class | E3: define | F3: comment | G3: 文字数 | O3: No | P3: Return | Q3: Config Function Name | R3: comment
B4: 0 | C4: なし | O4: 0 | P4: なし | Q4: なし
B5: 1 | C5: OP_SW | D5: HW | E5: =IF($C5<>"","ALERT_" & D5 & "_ID_"&UPPER(Matrix!$D$6) & "_" & $C5,"") -> ALERT_HW_ID_P_OILPRE_OP_SW | F5: 油圧SW。JIRA:METHUD800B-6568 | G5: =IF(E5<>"",LEN(E5),"") -> 26 | O5: 1
B6: 2 | E6: =IF($C6<>"","ALERT_" & D6 & "_ID_"&UPPER(Matrix!$D$6) & "_" & $C6,"") | G6: =IF(E6<>"",LEN(E6),"") | O6: 2
B7: 3 | E7: =IF($C7<>"","ALERT_" & D7 & "_ID_"&UPPER(Matrix!$D$6) & "_" & $C7,"") | G7: =IF(E7<>"",LEN(E7),"") | O7: 3
B8: 4 | E8: =IF($C8<>"","ALERT_" & D8 & "_ID_"&UPPER(Matrix!$D$6) & "_" & $C8,"") | G8: =IF(E8<>"",LEN(E8),"") | O8: 4
B9: 5 | E9: =IF($C9<>"","ALERT_" & D9 & "_ID_"&UPPER(Matrix!$D$6) & "_" & $C9,"") | G9: =IF(E9<>"",LEN(E9),"") | O9: 5
B10: 6 | E10: =IF($C10<>"","ALERT_" & D10 & "_ID_"&UPPER(Matrix!$D$6) & "_" & $C10,"") | G10: =IF(E10<>"",LEN(E10),"") | O10: 6
B11: 7 | E11: =IF($C11<>"","ALERT_" & D11 & "_ID_"&UPPER(Matrix!$D$6) & "_" & $C11,"") | G11: =IF(E11<>"",LEN(E11),"") | O11: 7
B12: 8 | E12: =IF($C12<>"","ALERT_" & D12 & "_ID_"&UPPER(Matrix!$D$6) & "_" & $C12,"") | G12: =IF(E12<>"",LEN(E12),"") | O12: 8
B13: 9 | E13: =IF($C13<>"","ALERT_" & D13 & "_ID_"&UPPER(Matrix!$D$6) & "_" & $C13,"") | G13: =IF(E13<>"",LEN(E13),"") | O13: 9
B14: 10 | E14: =IF($C14<>"","ALERT_" & D14 & "_ID_"&UPPER(Matrix!$D$6) & "_" & $C14,"") | G14: =IF(E14<>"",LEN(E14),"") | O14: 10
B15: 11 | E15: =IF($C15<>"","ALERT_" & D15 & "_ID_"&UPPER(Matrix!$D$6) & "_" & $C15,"") | G15: =IF(E15<>"",LEN(E15),"") | O15: 11
B16: 12 | E16: =IF($C16<>"","ALERT_" & D16 & "_ID_"&UPPER(Matrix!$D$6) & "_" & $C16,"") | G16: =IF(E16<>"",LEN(E16),"") | O16: 12
B17: 13 | E17: =IF($C17<>"","ALERT_" & D17 & "_ID_"&UPPER(Matrix!$D$6) & "_" & $C17,"") | G17: =IF(E17<>"",LEN(E17),"") | O17: 13
... B29: 25 | E29: =IF($C29<>"","ALERT_" & D29 & "_ID_"&UPPER(Matrix!$D$6) & "_" & $C29,"") | G29: =IF(E29<>"",LEN(E29),"") | O29: 25
B32: Alert Domain Define | O32: Constant Externs List
B33: No | C33: define Name | D33: calss | E33: define | F33: Value | G33: 文字数 | O33: No | P33: Type | Q33: Constant define | R33: comment
B34: 0 | C34: なし | F34: なし | O34: 0 | P34: なし | Q34: なし | R34: なし
B35: 1 | E35: =IF($C35<>"","ALERT_" & UPPER(Matrix!$D$6) & "_" & $C35,"") | G35: =IF(E35<>"",LEN(E35),"") | O35: 1
B36: 2 | E36: =IF($C36<>"","ALERT_" & UPPER(Matrix!$D$6) & "_" & $C36,"") | G36: =IF(E36<>"",LEN(E36),"") | O36: 2
B37: 3 | E37: =IF($C37<>"","ALERT_" & UPPER(Matrix!$D$6) & "_" & $C37,"") | G37: =IF(E37<>"",LEN(E37),"") | O37: 3
B38: 4 | E38: =IF($C38<>"","ALERT_" & UPPER(Matrix!$D$6) & "_" & $C38,"") | G38: =IF(E38<>"",LEN(E38),"") | O38: 4
B39: 5 | E39: =IF($C39<>"","ALERT_" & UPPER(Matrix!$D$6) & "_" & $C39,"") | G39: =IF(E39<>"",LEN(E39),"") | O39: 5
B40: 6 | E40: =IF($C40<>"","ALERT_" & UPPER(Matrix!$D$6) & "_" & $C40,"") | G40: =IF(E40<>"",LEN(E40),"") | O40: 6
B41: 7 | E41: =IF($C41<>"","ALERT_" & UPPER(Matrix!$D$6) & "_" & $C41,"") | G41: =IF(E41<>"",LEN(E41),"") | O41: 7
B42: 8 | E42: =IF($C42<>"","ALERT_" & UPPER(Matrix!$D$6) & "_" & $C42,"") | G42: =IF(E42<>"",LEN(E42),"") | O42: 8
B43: 9 | E43: =IF($C43<>"","ALERT_" & UPPER(Matrix!$D$6) & "_" & $C43,"") | G43: =IF(E43<>"",LEN(E43),"") | O43: 9
B44: 10 | E44: =IF($C44<>"","ALERT_" & UPPER(Matrix!$D$6) & "_" & $C44,"") | G44: =IF(E44<>"",LEN(E44),"") | O44: 10
B45: 11 | E45: =IF($C45<>"","ALERT_" & UPPER(Matrix!$D$6) & "_" & $C45,"") | G45: =IF(E45<>"",LEN(E45),"") | O45: 11
B46: 12 | E46: =IF($C46<>"","ALERT_" & UPPER(Matrix!$D$6) & "_" & $C46,"") | G46: =IF(E46<>"",LEN(E46),"") | O46: 12
... B59: 25 | E59: =IF($C59<>"","ALERT_" & UPPER(Matrix!$D$6) & "_" & $C59,"") | G59: =IF(E59<>"",LEN(E59),"") | O59: 25

Sheet CH_Design
C1: 出力なしは、ここでは定義しないこと。システム共通のALERT_REQ_UNKNOWNを使用するため。
B2: ALERT CH | C2: REQ | D2: Value | E2: TT機能判定 | F2: TT | G2: BC機能判定 | H2: BC | I2: PD機能判定 | J2: PD | K2: RW機能判定 | L2: RW | M2: 文字数 | N2: 定義名 | O2: Code for alert_mtrx.h
C3: UNKNOWN | U3: 電源状態一覧
B4: ALERT_CH_P_OILPRE_WRN | C4: TT_ON | D4: 0 | E4: なし | F4: ON(油圧警告灯) | G4: なし | H4: - | I4: なし | J4: - | K4: なし | L4: - | M4: =LEN(N4) -> 28 | N4: =VLOOKUP($B4,Matrix!$H$13:$I$37,2,FALSE)&"_"&C4 -> ALERT_REQ_P_OILPRE_WRN_TT_ON | O4: ="#define "&N4&REPT(" ",48-M4)&"("&D4&"U)" -> #define ALERT_REQ_P_OILPRE_WRN_TT_ON (0U) | U4: 電源状態一覧
B5: ALERT_CH_P_OILPRE_WRN | C5: WRN_ON | D5: 1 | E5: なし | F5: ON(油圧警告灯),FLASH_1000_D80_ON(停車警告灯) | G5: なし | H5: - | I5: なし | J5: P_OILPRE-CSTD-0-MEF01-REQ01 | K5: なし | L5: OPW | M5: =LEN(N5) -> 29 | N5: =VLOOKUP($B5,Matrix!$H$13:$I$37,2,FALSE)&"_"&C5 -> ALERT_REQ_P_OILPRE_WRN_WRN_ON | O5: ="#define "&N5&REPT(" ",48-M5)&"("&D5&"U)" -> #define ALERT_REQ_P_OILPRE_WRN_WRN_ON (1U) | U5: ＋B
B6: ALERT_CH_P_OILPRE_WRN | C6: WRN_FLSH | D6: 2 | E6: なし | F6: FLASH_400_D50_ON(油圧警告灯),FLASH_1000_D80_ON(停車警告灯) | G6: なし | H6: - | I6: なし | J6: P_OILPRE-CSTD-0-MEF01-REQ01 | K6: なし | L6: OPW | M6: =LEN(N6) -> 31 | N6: =VLOOKUP($B6,Matrix!$H$13:$I$37,2,FALSE)&"_"&C6 -> ALERT_REQ_P_OILPRE_WRN_WRN_FLSH | O6: ="#define "&N6&REPT(" ",48-M6)&"("&D6&"U)" -> #define ALERT_REQ_P_OILPRE_WRN_WRN_FLSH (2U) | U6: IG-ON
B7: ALERT_CH_P_OILPRE_WRN | C7: WRN_OFF | D7: 3 | E7: なし | F7: FLASH_1000_D80_ON(停車警告灯) | G7: なし | H7: - | I7: なし | J7: P_OILPRE-CSTD-0-MEF01-REQ01 | K7: なし | L7: OPW | M7: =LEN(N7) -> 30 | N7: =VLOOKUP($B7,Matrix!$H$13:$I$37,2,FALSE)&"_"&C7 -> ALERT_REQ_P_OILPRE_WRN_WRN_OFF | O7: ="#define "&N7&REPT(" ",48-M7)&"("&D7&"U)" -> #define ALERT_REQ_P_OILPRE_WRN_WRN_OFF (3U) | U7: IG-OFF
B8: ALERT_CH_P_OILPRE_BC | C8: ON | D8: 0 | E8: なし | F8: - | G8: なし | H8: P_OILPRE-CSTD-0-BZR01-REQ01 | I8: なし | J8: - | K8: なし | L8: - | M8: =LEN(N8) -> 24 | N8: =VLOOKUP($B8,Matrix!$H$13:$I$37,2,FALSE)&"_"&C8 -> ALERT_REQ_P_OILPRE_BC_ON | O8: ="#define "&N8&REPT(" ",48-M8)&"("&D8&"U)" -> #define ALERT_REQ_P_OILPRE_BC_ON (0U) | U8: ACC-ON
M9: =LEN(N9) -> #N/A | N9: =VLOOKUP($B9,Matrix!$H$13:$I$37,2,FALSE)&"_"&C9 -> #N/A | O9: ="#define "&N9&REPT(" ",48-M9)&"("&D9&"U)" -> #N/A | U9: ACC-OFF
M10: =LEN(N10) -> #N/A | N10: =VLOOKUP($B10,Matrix!$H$13:$I$37,2,FALSE)&"_"&C10 -> #N/A | O10: ="#define "&N10&REPT(" ",48-M10)&"("&D10&"U)" -> #N/A
M11: =LEN(N11) -> #N/A | N11: =VLOOKUP($B11,Matrix!$H$13:$I$37,2,FALSE)&"_"&C11 -> #N/A | O11: ="#define "&N11&REPT(" ",48-M11)&"("&D11&"U)" -> #N/A
M12: =LEN(N12) -> #N/A | N12: =VLOOKUP($B12,Matrix!$H$13:$I$37,2,FALSE)&"_"&C12 -> #N/A | O12: ="#define "&N12&REPT(" ",48-M12)&"("&D12&"U)" -> #N/A
M13: =LEN(N13) -> #N/A | N13: =VLOOKUP($B13,Matrix!$H$13:$I$37,2,FALSE)&"_"&C13 -> #N/A | O13: ="#define "&N13&REPT(" ",48-M13)&"("&D13&"U)" -> #N/A
M14: =LEN(N14) -> #N/A | N14: =VLOOKUP($B14,Matrix!$H$13:$I$37,2,FALSE)&"_"&C14 -> #N/A | O14: ="#define "&N14&REPT(" ",48-M14)&"("&D14&"U)" -> #N/A
M15: =LEN(N15) -> #N/A | N15: =VLOOKUP($B15,Matrix!$H$13:$I$37,2,FALSE)&"_"&C15 -> #N/A | O15: ="#define "&N15&REPT(" ",48-M15)&"("&D15&"U)" -> #N/A
M16: =LEN(N16) -> #N/A | N16: =VLOOKUP($B16,Matrix!$H$13:$I$37,2,FALSE)&"_"&C16 -> #N/A | O16: ="#define "&N16&REPT(" ",48-M16)&"("&D16&"U)" -> #N/A
M17: =LEN(N17) -> #N/A | N17: =VLOOKUP($B17,Matrix!$H$13:$I$37,2,FALSE)&"_"&C17 -> #N/A | O17: ="#define "&N17&REPT(" ",48-M17)&"("&D17&"U)" -> #N/A
M18: =LEN(N18) -> #N/A | N18: =VLOOKUP($B18,Matrix!$H$13:$I$37,2,FALSE)&"_"&C18 -> #N/A | O18: ="#define "&N18&REPT(" ",48-M18)&"("&D18&"U)" -> #N/A
M19: =LEN(N19) -> #N/A | N19: =VLOOKUP($B19,Matrix!$H$13:$I$37,2,FALSE)&"_"&C19 -> #N/A | O19: ="#define "&N19&REPT(" ",48-M19)&"("&D19&"U)" -> #N/A
M20: =LEN(N20) -> #N/A | N20: =VLOOKUP($B20,Matrix!$H$13:$I$37,2,FALSE)&"_"&C20 -> #N/A | O20: ="#define "&N20&REPT(" ",48-M20)&"("&D20&"U)" -> #N/A
M21: =LEN(N21) -> #N/A | N21: =VLOOKUP($B21,Matrix!$H$13:$I$37,2,FALSE)&"_"&C21 -> #N/A | O21: ="#define "&N21&REPT(" ",48-M21)&"("&D21&"U)" -> #N/A
... M103: =LEN(N103) -> #N/A | N103: =VLOOKUP($B103,Matrix!$H$13:$I$37,2,FALSE)&"_"&C103 -> #N/A | O103: ="#define "&N103&REPT(" ",48-M103)&"("&D103&"U)" -> #N/A

Sheet WRN
AH1: → | AI1: bit
B2: Table Type | C2: INDEX | D2: 31 | E2: 30 | F2: 29 | G2: 28 | H2: 27 | I2: 26 | J2: 25 | K2: 24 | L2: 23 | M2: 22 | N2: 21 | O2: 20 | P2: 19 | Q2: 18 | R2: 17 | S2: 16 | T2: 15 | U2: 14 | V2: 13 | W2: 12 | X2: 11 | Y2: 10 | Z2: 9 | AA2: 8 | AB2: 7 | AC2: 6 | AD2: 5 | AE2: 4 | AF2: 3 | AG2: 2 | AH2: 1 | AI2: 0 | AJ2: REQ
B3: =IF(OR(IF(COUNTIF(D6:AC69,"0")<>0,TRUE,FALSE),IF(COUNTIF(D6:AC69,"1")<>0,TRUE,FALSE)),"Search Table","Index Table") -> Search Table | D3: ALERT_VOM_RWT_EN | E3: [reserved] | F3: ALERT_VOM_VCS_ON | G3: ALERT_VOM_IGN_ON | H3: ALERT_VOM_IGN_OFF_WT | I3: ALERT_VOM_IGN_OFF | J3: ALERT_VOM_BAT_WT | K3: ALERT_VOM_BAT_AO | L3: [reserved] | M3: [reserved] | N3: [reserved] | O3: [reserved] | P3: [reserved] | Q3: [reserved] | R3: [reserved] | S3: [reserved] | T3: [reserved] | U3: [reserved] | V3: [reserved] | W3: [reserved] | X3: [reserved] | Y3: B_OILPL_SIG | AA3: IGP_PDC_SIG | AB3: OP_SW | AC3: RPM | AE3: MOPSINH_SIG/OPLMPMSK_SIG | AF3: OPTDLY | AG3: PREV_REQ | AR3: シート名称は、CH Nameと同じにすること。 1CHしか存在しない場合、機能名と同じにすること。
A4: Master Table | AR4: 貼り付けコード
AR5: ="static const U4 "&AW8&"["&AW10&"]"&" = {" -> static const U4 u4_sp_ALERT_P_OILPRE_WRN_CRIT[ALERT_P_OILPRE_WRN_NUM_DST] = { | AS5: ="static const U4 "&$AW$9&"["&$AW$10&"] = {" -> static const U4 u4_sp_ALERT_P_OILPRE_WRN_MASK[ALERT_P_OILPRE_WRN_NUM_DST] = { | AT5: ="static const U1 "&$AW$11&"["&$AW$10&"] = {" -> static const U1 u1_sp_ALERT_P_OILPRE_WRN_DST[ALERT_P_OILPRE_WRN_NUM_DST] = { | AU5: ="const ST_ALERT_MTRX "&$AW$12&" = {" -> const ST_ALERT_MTRX st_gp_ALERT_P_OILPRE_MTRX[2] = { | AV5: ="#define "&AW10&REPT(" ",41-LEN(AW10))&"("&AW13&"U)" -> #define ALERT_P_OILPRE_WRN_NUM_DST (31U)
B6: ="Table "&$AW$6 -> Table WRN | C6: =ROW()-ROW($C$6) -> 0 | D6: × | E6: × | F6: × | G6: × | H6: × | I6: × | J6: × | K6: × | L6: × | M6: × | N6: × | O6: × | P6: × | Q6: × | R6: × | S6: × | T6: × | U6: × | V6: × | W6: × | X6: × | Y6: 0 | Z6: × | AA6: × | AB6: 1 | AC6: 0 | AD6: × | AE6: 0 | AF6: × | AG6: 0 | AH6: 0 | AI6: 0 | AJ6: TT_ON | AL6: =IF($AJ6="UNKNOWN"," (U1)ALERT_REQ_UNKNOWN"," (U1)"&"ALERT_REQ_"&$AW$17&"_"&IF($AW$6<>$AW$17,$AW$6&"_","")&AJ6) -> (U1)ALERT_REQ_P_OILPRE_WRN_TT_ON | AR6: =IF(AQ71<>"",AQ71,IF(AQ70<>"","};","")) -> (U4)0x00000080U, /* 00 TT_ON */ | AS6: =IF(AQ136<>"",AQ136,IF(AQ135<>"","};","")) -> (U4)0x000004D7U, /* 00 TT_ON */ | AT6: =IF(AJ6<>"",AL6&IF(AJ7<>"",","," ")&REPT(" ",78-LEN(AL6))&"/* "&IF(C6<10,"0"&C6,C6)&" "&AJ6&REPT(" ",48-LEN(AJ6))&"*/",IF(AJ5<>"","};","")) -> (U1)ALERT_REQ_P_OILPRE_WRN_TT_ON, /* 00 TT_ON */ | AU6: { | AV6: MtxSrch変数名 | AW6: =UPPER(RIGHT(CELL("filename",A1),LEN(CELL("filename",A1))-FIND("]",CELL("filename",A1)))) -> WRN
C7: =ROW()-ROW($C$6) -> 1 | D7: × | E7: × | F7: × | G7: × | H7: × | I7: × | J7: × | K7: × | L7: × | M7: × | N7: × | O7: × | P7: × | Q7: × | R7: × | S7: × | T7: × | U7: × | V7: × | W7: × | X7: × | Y7: 0 | Z7: × | AA7: 1 | AB7: 1 | AC7: 0 | AD7: × | AE7: 0 | AF7: × | AG7: 0 | AH7: 0 | AI7: 1 | AJ7: WRN_ON | AL7: =IF($AJ7="UNKNOWN"," (U1)ALERT_REQ_UNKNOWN"," (U1)"&"ALERT_REQ_"&$AW$17&"_"&IF($AW$6<>$AW$17,$AW$6&"_","")&AJ7) -> (U1)ALERT_REQ_P_OILPRE_WRN_WRN_ON | AR7: =IF(AQ72<>"",AQ72,IF(AQ71<>"","};","")) -> (U4)0x00000181U, /* 01 WRN_ON */ | AS7: =IF(AQ137<>"",AQ137,IF(AQ136<>"","};","")) -> (U4)0x000005D7U, /* 01 WRN_ON */ | AT7: =IF(AJ7<>"",AL7&IF(AJ8<>"",","," ")&REPT(" ",78-LEN(AL7))&"/* "&IF(C7<10,"0"&C7,C7)&" "&AJ7&REPT(" ",48-LEN(AJ7))&"*/",IF(AJ6<>"","};","")) -> (U1)ALERT_REQ_P_OILPRE_WRN_WRN_ON, /* 01 WRN_ON */ | AU7: =" &"&$AW$14&","&REPT(" ",69-LEN($AW$14))&"/* fp_u4_SRC_CHK */" -> &u4_s_AlertP_oilpreWrnSrcchk, /* fp_u4_SRC_CHK */ | AV7: Use MtxSrch | AW7: =IF(B3="Search Table",1,0) -> 1
C8: =ROW()-ROW($C$6) -> 2 | D8: × | E8: × | F8: × | G8: × | H8: × | I8: × | J8: × | K8: × | L8: × | M8: × | N8: × | O8: × | P8: × | Q8: × | R8: × | S8: × | T8: × | U8: × | V8: × | W8: × | X8: × | Y8: 0 | Z8: × | AA8: 1 | AB8: 1 | AC8: 0 | AD8: 0 | AE8: 1 | AF8: × | AG8: 0 | AH8: 0 | AI8: 1 | AJ8: WRN_OFF | AL8: =IF($AJ8="UNKNOWN"," (U1)ALERT_REQ_UNKNOWN"," (U1)"&"ALERT_REQ_"&$AW$17&"_"&IF($AW$6<>$AW$17,$AW$6&"_","")&AJ8) -> (U1)ALERT_REQ_P_OILPRE_WRN_WRN_OFF | AR8: =IF(AQ73<>"",AQ73,IF(AQ72<>"","};","")) -> (U4)0x00000191U, /* 02 WRN_OFF */ | AS8: =IF(AQ138<>"",AQ138,IF(AQ137<>"","};","")) -> (U4)0x000005F7U, /* 02 WRN_OFF */ | AT8: =IF(AJ8<>"",AL8&IF(AJ9<>"",","," ")&REPT(" ",78-LEN(AL8))&"/* "&IF(C8<10,"0"&C8,C8)&" "&AJ8&REPT(" ",48-LEN(AJ8))&"*/",IF(AJ7<>"","};","")) -> (U1)ALERT_REQ_P_OILPRE_WRN_WRN_OFF, /* 02 WRN_OFF */ | AU8: =IF($AW$15<>"NULL"," &"&$AW$15&","&REPT(" ",69-LEN($AW$15))&"/* fp_vd_XDST */"," vdp_PTR_NA, /* fp_vd_XDST */") -> &vd_s_AlertP_oilpreWrnRwTx, /* fp_vd_XDST */ | AV8: CRIT_NAME | AW8: ="u4_sp_ALERT_"&IF(AW6<>AW17,$AW$17&"_"&$AW$6,AW17)&"_CRIT" -> u4_sp_ALERT_P_OILPRE_WRN_CRIT
C9: =ROW()-ROW($C$6) -> 3 | D9: × | E9: × | F9: × | G9: × | H9: × | I9: × | J9: × | K9: × | L9: × | M9: × | N9: × | O9: × | P9: × | Q9: × | R9: × | S9: × | T9: × | U9: × | V9: × | W9: × | X9: × | Y9: 0 | Z9: × | AA9: 1 | AB9: 1 | AC9: 0 | AD9: 0 | AE9: × | AF9: × | AG9: 0 | AH9: 1 | AI9: 0 | AJ9: WRN_FLSH | AL9: =IF($AJ9="UNKNOWN"," (U1)ALERT_REQ_UNKNOWN"," (U1)"&"ALERT_REQ_"&$AW$17&"_"&IF($AW$6<>$AW$17,$AW$6&"_","")&AJ9) -> (U1)ALERT_REQ_P_OILPRE_WRN_WRN_FLSH | AR9: =IF(AQ74<>"",AQ74,IF(AQ73<>"","};","")) -> (U4)0x00000182U, /* 03 WRN_FLSH */ | AS9: =IF(AQ139<>"",AQ139,IF(AQ138<>"","};","")) -> (U4)0x000005E7U, /* 03 WRN_FLSH */ | AT9: =IF(AJ9<>"",AL9&IF(AJ10<>"",","," ")&REPT(" ",78-LEN(AL9))&"/* "&IF(C9<10,"0"&C9,C9)&" "&AJ9&REPT(" ",48-LEN(AJ9))&"*/",IF(AJ8<>"","};","")) -> (U1)ALERT_REQ_P_OILPRE_WRN_WRN_FLSH, /* 03 WRN_FLSH */ | AV9: MASK_NAME | AW9: ="u4_sp_ALERT_"&IF(AW6<>AW17,$AW$17&"_"&$AW$6,AW17)&"_MASK" -> u4_sp_ALERT_P_OILPRE_WRN_MASK
C10: =ROW()-ROW($C$6) -> 4 | D10: × | E10: × | F10: × | G10: × | H10: × | I10: × | J10: × | K10: × | L10: × | M10: × | N10: × | O10: × | P10: × | Q10: × | R10: × | S10: × | T10: × | U10: × | V10: × | W10: × | X10: × | Y10: 0 | Z10: × | AA10: 1 | AB10: 1 | AC10: 0 | AD10: 0 | AE10: × | AF10: × | AG10: 0 | AH10: 1 | AI10: 1 | AJ10: WRN_OFF | AL10: =IF($AJ10="UNKNOWN"," (U1)ALERT_REQ_UNKNOWN"," (U1)"&"ALERT_REQ_"&$AW$17&"_"&IF($AW$6<>$AW$17,$AW$6&"_","")&AJ10) -> (U1)ALERT_REQ_P_OILPRE_WRN_WRN_OFF | AR10: =IF(AQ75<>"",AQ75,IF(AQ74<>"","};","")) -> (U4)0x00000183U, /* 04 WRN_OFF */ | AS10: =IF(AQ140<>"",AQ140,IF(AQ139<>"","};","")) -> (U4)0x000005E7U, /* 04 WRN_OFF */ | AT10: =IF(AJ10<>"",AL10&IF(AJ11<>"",","," ")&REPT(" ",78-LEN(AL10))&"/* "&IF(C10<10,"0"&C10,C10)&" "&AJ10&REPT(" ",48-LEN(AJ10))&"*/",IF(AJ9<>"","};","")) -> (U1)ALERT_REQ_P_OILPRE_WRN_WRN_OFF, /* 04 WRN_OFF */ | AU10: =IF($AW$7=1," &"&$AW$9&"[0],"&REPT(" ",66-LEN($AW$9))&"/* u4p_MASK */"," (const U4 *)vdp_PTR_NA, /* u4p_MASK */") -> &u4_sp_ALERT_P_OILPRE_WRN_MASK[0], /* u4p_MASK */ | AV10: MTXSRCH_DEF | AW10: ="ALERT_"&IF(AW6<>AW17,$AW$17&"_"&$AW$6,AW17)&"_NUM_DST" -> ALERT_P_OILPRE_WRN_NUM_DST
C11: =ROW()-ROW($C$6) -> 5 | D11: × | E11: × | F11: × | G11: × | H11: × | I11: × | J11: × | K11: × | L11: × | M11: × | N11: × | O11: × | P11: × | Q11: × | R11: × | S11: × | T11: × | U11: × | V11: × | W11: × | X11: × | Y11: 0 | Z11: × | AA11: 1 | AB11: 1 | AC11: 0 | AD11: 1 | AE11: 0 | AF11: × | AG11: 0 | AH11: 1 | AI11: × | AJ11: WRN_ON | AL11: =IF($AJ11="UNKNOWN"," (U1)ALERT_REQ_UNKNOWN"," (U1)"&"ALERT_REQ_"&$AW$17&"_"&IF($AW$6<>$AW$17,$AW$6&"_","")&AJ11) -> (U1)ALERT_REQ_P_OILPRE_WRN_WRN_ON | AR11: =IF(AQ76<>"",AQ76,IF(AQ75<>"","};","")) -> (U4)0x000001A2U, /* 05 WRN_ON */ | AS11: =IF(AQ141<>"",AQ141,IF(AQ140<>"","};","")) -> (U4)0x000005F6U, /* 05 WRN_ON */ | AT11: =IF(AJ11<>"",AL11&IF(AJ12<>"",","," ")&REPT(" ",78-LEN(AL11))&"/* "&IF(C11<10,"0"&C11,C11)&" "&AJ11&REPT(" ",48-LEN(AJ11))&"*/",IF(AJ10<>"","};","")) -> (U1)ALERT_REQ_P_OILPRE_WRN_WRN_ON, /* 05 WRN_ON */ | AU11: =IF($AW$7=1," &"&$AW$8&"[0],"&REPT(" ",66-LEN($AW$8))&"/* u4p_CRIT */"," (const U4 *)vdp_PTR_NA, /* u4p_CRIT */") -> &u4_sp_ALERT_P_OILPRE_WRN_CRIT[0], /* u4p_CRIT */ | AV11: MTXSRCH_OUT_DEF | AW11: ="u1_sp_ALERT_"&IF(AW6<>AW17,$AW$17&"_"&$AW$6,AW17)&"_DST" -> u1_sp_ALERT_P_OILPRE_WRN_DST
C12: =ROW()-ROW($C$6) -> 6 | D12: × | E12: × | F12: × | G12: × | H12: × | I12: × | J12: × | K12: × | L12: × | M12: × | N12: × | O12: × | P12: × | Q12: × | R12: × | S12: × | T12: × | U12: × | V12: × | W12: × | X12: × | Y12: 0 | Z12: × | AA12: × | AB12: 1 | AC12: 0 | AD12: 1 | AE12: 0 | AF12: × | AG12: 1 | AH12: × | AI12: × | AJ12: TT_ON | AL12: =IF($AJ12="UNKNOWN"," (U1)ALERT_REQ_UNKNOWN"," (U1)"&"ALERT_REQ_"&$AW$17&"_"&IF($AW$6<>$AW$17,$AW$6&"_","")&AJ12) -> (U1)ALERT_REQ_P_OILPRE_WRN_TT_ON | AR12: =IF(AQ77<>"",AQ77,IF(AQ76<>"","};","")) -> (U4)0x000000A4U, /* 06 TT_ON */ | AS12: =IF(AQ142<>"",AQ142,IF(AQ141<>"","};","")) -> (U4)0x000004F4U, /* 06 TT_ON */ | AT12: =IF(AJ12<>"",AL12&IF(AJ13<>"",","," ")&REPT(" ",78-LEN(AL12))&"/* "&IF(C12<10,"0"&C12,C12)&" "&AJ12&REPT(" ",48-LEN(AJ12))&"*/",IF(AJ11<>"","};","")) -> (U1)ALERT_REQ_P_OILPRE_WRN_TT_ON, /* 06 TT_ON */ | AV12: ALERT_MTRX_NAME | AW12: =Matrix!D8&"["&Matrix!D7&"]" -> st_gp_ALERT_P_OILPRE_MTRX[2]
C13: =ROW()-ROW($C$6) -> 7 | D13: × | E13: × | F13: × | G13: × | H13: × | I13: × | J13: × | K13: × | L13: × | M13: × | N13: × | O13: × | P13: × | Q13: × | R13: × | S13: × | T13: × | U13: × | V13: × | W13: × | X13: × | Y13: 0 | Z13: × | AA13: 1 | AB13: 1 | AC13: 0 | AD13: 1 | AE13: 1 | AF13: × | AG13: 0 | AH13: × | AI13: 1 | AJ13: WRN_OFF | AL13: =IF($AJ13="UNKNOWN"," (U1)ALERT_REQ_UNKNOWN"," (U1)"&"ALERT_REQ_"&$AW$17&"_"&IF($AW$6<>$AW$17,$AW$6&"_","")&AJ13) -> (U1)ALERT_REQ_P_OILPRE_WRN_WRN_OFF | AR13: =IF(AQ78<>"",AQ78,IF(AQ77<>"","};","")) -> (U4)0x000001B1U, /* 07 WRN_OFF */ | AS13: =IF(AQ143<>"",AQ143,IF(AQ142<>"","};","")) -> (U4)0x000005F5U, /* 07 WRN_OFF */ | AT13: =IF(AJ13<>"",AL13&IF(AJ14<>"",","," ")&REPT(" ",78-LEN(AL13))&"/* "&IF(C13<10,"0"&C13,C13)&" "&AJ13&REPT(" ",48-LEN(AJ13))&"*/",IF(AJ12<>"","};","")) -> (U1)ALERT_REQ_P_OILPRE_WRN_WRN_OFF, /* 07 WRN_OFF */ | AU13: =" &"&$AW$11&"[0],"&REPT(" ",66-LEN($AW$11))&"/* u1p_DST */" -> &u1_sp_ALERT_P_OILPRE_WRN_DST[0], /* u1p_DST */ | AV13: SRCH_NUM | AW13: =COUNTA($AJ$6:$AJ$69) -> 31
C14: =ROW()-ROW($C$6) -> 8 | D14: × | E14: × | F14: × | G14: × | H14: × | I14: × | J14: × | K14: × | L14: × | M14: × | N14: × | O14: × | P14: × | Q14: × | R14: × | S14: × | T14: × | U14: × | V14: × | W14: × | X14: × | Y14: 0 | Z14: × | AA14: 1 | AB14: 1 | AC14: 0 | AD14: 1 | AE14: 1 | AF14: × | AG14: 0 | AH14: 1 | AI14: 0 | AJ14: WRN_FLSH | AL14: =IF($AJ14="UNKNOWN"," (U1)ALERT_REQ_UNKNOWN"," (U1)"&"ALERT_REQ_"&$AW$17&"_"&IF($AW$6<>$AW$17,$AW$6&"_","")&AJ14) -> (U1)ALERT_REQ_P_OILPRE_WRN_WRN_FLSH | AR14: =IF(AQ79<>"",AQ79,IF(AQ78<>"","};","")) -> (U4)0x000001B2U, /* 08 WRN_FLSH */ | AS14: =IF(AQ144<>"",AQ144,IF(AQ143<>"","};","")) -> (U4)0x000005F7U, /* 08 WRN_FLSH */ | AT14: =IF(AJ14<>"",AL14&IF(AJ15<>"",","," ")&REPT(" ",78-LEN(AL14))&"/* "&IF(C14<10,"0"&C14,C14)&" "&AJ14&REPT(" ",48-LEN(AJ14))&"*/",IF(AJ13<>"","};","")) -> (U1)ALERT_REQ_P_OILPRE_WRN_WRN_FLSH, /* 08 WRN_FLSH */ | AU14: =" (U2)"&$AW$10&","&REPT(" ",66-LEN($AW$10))&"/* u2_num_srch */" -> (U2)ALERT_P_OILPRE_WRN_NUM_DST, /* u2_num_srch */ | AV14: SRC CHK | AW14: =IF(AW6<>AW17,VLOOKUP(AW6,Matrix!$C$13:$G$37,4,FALSE),Matrix!F13) -> u4_s_AlertP_oilpreWrnSrcchk
C15: =ROW()-ROW($C$6) -> 9 | D15: × | E15: × | F15: × | G15: × | H15: × | I15: × | J15: × | K15: × | L15: × | M15: × | N15: × | O15: × | P15: × | Q15: × | R15: × | S15: × | T15: × | U15: × | V15: × | W15: × | X15: × | Y15: 0 | Z15: × | AA15: × | AB15: 1 | AC15: 1 | AD15: 0 | AE15: 0 | AF15: 0 | AG15: 0 | AH15: 0 | AI15: 0 | AJ15: TT_ON | AL15: =IF($AJ15="UNKNOWN"," (U1)ALERT_REQ_UNKNOWN"," (U1)"&"ALERT_REQ_"&$AW$17&"_"&IF($AW$6<>$AW$17,$AW$6&"_","")&AJ15) -> (U1)ALERT_REQ_P_OILPRE_WRN_TT_ON | AR15: =IF(AQ80<>"",AQ80,IF(AQ79<>"","};","")) -> (U4)0x000000C0U, /* 09 TT_ON */ | AS15: =IF(AQ145<>"",AQ145,IF(AQ144<>"","};","")) -> (U4)0x000004FFU, /* 09 TT_ON */ | AT15: =IF(AJ15<>"",AL15&IF(AJ16<>"",","," ")&REPT(" ",78-LEN(AL15))&"/* "&IF(C15<10,"0"&C15,C15)&" "&AJ15&REPT(" ",48-LEN(AJ15))&"*/",IF(AJ14<>"","};","")) -> (U1)ALERT_REQ_P_OILPRE_WRN_TT_ON, /* 09 TT_ON */ | AU15: =" (U1)"&$AW$16&REPT(" ",67-LEN($AW$16))&"/* u1_vom_act */" -> (U1)ALERT_VOM_IGN_ON /* u1_vom_act */ | AV15: RWTX | AW15: =IF(AW6<>AW17,VLOOKUP(AW6,Matrix!$C$13:$G$37,5,FALSE),Matrix!G13) -> vd_s_AlertP_oilpreWrnRwTx
C16: =ROW()-ROW($C$6) -> 10 | D16: × | E16: × | F16: × | G16: × | H16: × | I16: × | J16: × | K16: × | L16: × | M16: × | N16: × | O16: × | P16: × | Q16: × | R16: × | S16: × | T16: × | U16: × | V16: × | W16: × | X16: × | Y16: 0 | Z16: × | AA16: 1 | AB16: 1 | AC16: 1 | AD16: 0 | AE16: 0 | AF16: 0 | AG16: 0 | AH16: 0 | AI16: 1 | AJ16: WRN_ON | AL16: =IF($AJ16="UNKNOWN"," (U1)ALERT_REQ_UNKNOWN"," (U1)"&"ALERT_REQ_"&$AW$17&"_"&IF($AW$6<>$AW$17,$AW$6&"_","")&AJ16) -> (U1)ALERT_REQ_P_OILPRE_WRN_WRN_ON | AR16: =IF(AQ81<>"",AQ81,IF(AQ80<>"","};","")) -> (U4)0x000001C1U, /* 10 WRN_ON */ | AS16: =IF(AQ146<>"",AQ146,IF(AQ145<>"","};","")) -> (U4)0x000005FFU, /* 10 WRN_ON */ | AT16: =IF(AJ16<>"",AL16&IF(AJ17<>"",","," ")&REPT(" ",78-LEN(AL16))&"/* "&IF(C16<10,"0"&C16,C16)&" "&AJ16&REPT(" ",48-LEN(AJ16))&"*/",IF(AJ15<>"","};","")) -> (U1)ALERT_REQ_P_OILPRE_WRN_WRN_ON, /* 10 WRN_ON */ | AU16: } | AV16: ACT | AW16: =IF(AW6<>AW17,VLOOKUP(AW6,Matrix!$C$13:$G$37,2,FALSE),Matrix!D13) -> ALERT_VOM_IGN_ON
C17: =ROW()-ROW($C$6) -> 11 | D17: × | E17: × | F17: × | G17: × | H17: × | I17: × | J17: × | K17: × | L17: × | M17: × | N17: × | O17: × | P17: × | Q17: × | R17: × | S17: × | T17: × | U17: × | V17: × | W17: × | X17: × | Y17: 0 | Z17: × | AA17: 1 | AB17: 1 | AC17: 1 | AD17: 0 | AE17: × | AF17: 0 | AG17: 0 | AH17: 1 | AI17: 0 | AJ17: WRN_FLSH | AL17: =IF($AJ17="UNKNOWN"," (U1)ALERT_REQ_UNKNOWN"," (U1)"&"ALERT_REQ_"&$AW$17&"_"&IF($AW$6<>$AW$17,$AW$6&"_","")&AJ17) -> (U1)ALERT_REQ_P_OILPRE_WRN_WRN_FLSH | AR17: =IF(AQ82<>"",AQ82,IF(AQ81<>"","};","")) -> (U4)0x000001C2U, /* 11 WRN_FLSH */ | AS17: =IF(AQ147<>"",AQ147,IF(AQ146<>"","};","")) -> (U4)0x000005EFU, /* 11 WRN_FLSH */ | AT17: =IF(AJ17<>"",AL17&IF(AJ18<>"",","," ")&REPT(" ",78-LEN(AL17))&"/* "&IF(C17<10,"0"&C17,C17)&" "&AJ17&REPT(" ",48-LEN(AJ17))&"*/",IF(AJ16<>"","};","")) -> (U1)ALERT_REQ_P_OILPRE_WRN_WRN_FLSH, /* 11 WRN_FLSH */ | AU17: }; | AV17: ALERT_MTRX変数名 | AW17: =UPPER(Matrix!$D$6) -> P_OILPRE
C18: =ROW()-ROW($C$6) -> 12 | D18: × | E18: × | F18: × | G18: × | H18: × | I18: × | J18: × | K18: × | L18: × | M18: × | N18: × | O18: × | P18: × | Q18: × | R18: × | S18: × | T18: × | U18: × | V18: × | W18: × | X18: × | Y18: 0 | Z18: × | AA18: 1 | AB18: 1 | AC18: 1 | AD18: 0 | AE18: 0 | AF18: 0 | AG18: 0 | AH18: 1 | AI18: 1 | AJ18: WRN_OFF | AL18: =IF($AJ18="UNKNOWN"," (U1)ALERT_REQ_UNKNOWN"," (U1)"&"ALERT_REQ_"&$AW$17&"_"&IF($AW$6<>$AW$17,$AW$6&"_","")&AJ18) -> (U1)ALERT_REQ_P_OILPRE_WRN_WRN_OFF | AR18: =IF(AQ83<>"",AQ83,IF(AQ82<>"","};","")) -> (U4)0x000001C3U, /* 12 WRN_OFF */ | AS18: =IF(AQ148<>"",AQ148,IF(AQ147<>"","};","")) -> (U4)0x000005FFU, /* 12 WRN_OFF */ | AT18: =IF(AJ18<>"",AL18&IF(AJ19<>"",","," ")&REPT(" ",78-LEN(AL18))&"/* "&IF(C18<10,"0"&C18,C18)&" "&AJ18&REPT(" ",48-LEN(AJ18))&"*/",IF(AJ17<>"","};","")) -> (U1)ALERT_REQ_P_OILPRE_WRN_WRN_OFF, /* 12 WRN_OFF */
C19: =ROW()-ROW($C$6) -> 13 | D19: × | E19: × | F19: × | G19: × | H19: × | I19: × | J19: × | K19: × | L19: × | M19: × | N19: × | O19: × | P19: × | Q19: × | R19: × | S19: × | T19: × | U19: × | V19: × | W19: × | X19: × | Y19: 0 | Z19: × | AA19: 1 | AB19: 1 | AC19: 1 | AD19: 0 | AE19: × | AF19: 1 | AG19: × | AH19: × | AI19: × | AJ19: WRN_FLSH | AL19: =IF($AJ19="UNKNOWN"," (U1)ALERT_REQ_UNKNOWN"," (U1)"&"ALERT_REQ_"&$AW$17&"_"&IF($AW$6<>$AW$17,$AW$6&"_","")&AJ19) -> (U1)ALERT_REQ_P_OILPRE_WRN_WRN_FLSH | AR19: =IF(AQ84<>"",AQ84,IF(AQ83<>"","};","")) -> (U4)0x000001C8U, /* 13 WRN_FLSH */ | AS19: =IF(AQ149<>"",AQ149,IF(AQ148<>"","};","")) -> (U4)0x000005E8U, /* 13 WRN_FLSH */ | AT19: =IF(AJ19<>"",AL19&IF(AJ20<>"",","," ")&REPT(" ",78-LEN(AL19))&"/* "&IF(C19<10,"0"&C19,C19)&" "&AJ19&REPT(" ",48-LEN(AJ19))&"*/",IF(AJ18<>"","};","")) -> (U1)ALERT_REQ_P_OILPRE_WRN_WRN_FLSH, /* 13 WRN_FLSH */
C20: =ROW()-ROW($C$6) -> 14 | D20: × | E20: × | F20: × | G20: × | H20: × | I20: × | J20: × | K20: × | L20: × | M20: × | N20: × | O20: × | P20: × | Q20: × | R20: × | S20: × | T20: × | U20: × | V20: × | W20: × | X20: × | Y20: 0 | Z20: × | AA20: 1 | AB20: 1 | AC20: 1 | AD20: 0 | AE20: 1 | AF20: 0 | AG20: 0 | AH20: × | AI20: 1 | AJ20: WRN_OFF | AL20: =IF($AJ20="UNKNOWN"," (U1)ALERT_REQ_UNKNOWN"," (U1)"&"ALERT_REQ_"&$AW$17&"_"&IF($AW$6<>$AW$17,$AW$6&"_","")&AJ20) -> (U1)ALERT_REQ_P_OILPRE_WRN_WRN_OFF | AR20: =IF(AQ85<>"",AQ85,IF(AQ84<>"","};","")) -> (U4)0x000001D1U, /* 14 WRN_OFF */ | AS20: =IF(AQ150<>"",AQ150,IF(AQ149<>"","};","")) -> (U4)0x000005FDU, /* 14 WRN_OFF */ | AT20: =IF(AJ20<>"",AL20&IF(AJ21<>"",","," ")&REPT(" ",78-LEN(AL20))&"/* "&IF(C20<10,"0"&C20,C20)&" "&AJ20&REPT(" ",48-LEN(AJ20))&"*/",IF(AJ19<>"","};","")) -> (U1)ALERT_REQ_P_OILPRE_WRN_WRN_OFF, /* 14 WRN_OFF */
C21: =ROW()-ROW($C$6) -> 15 | D21: × | E21: × | F21: × | G21: × | H21: × | I21: × | J21: × | K21: × | L21: × | M21: × | N21: × | O21: × | P21: × | Q21: × | R21: × | S21: × | T21: × | U21: × | V21: × | W21: × | X21: × | Y21: 1 | Z21: 0 | AA21: 0 | AB21: × | AC21: × | AD21: × | AE21: × | AF21: × | AG21: × | AH21: × | AI21: × | AJ21: TT_ON | AL21: =IF($AJ21="UNKNOWN"," (U1)ALERT_REQ_UNKNOWN"," (U1)"&"ALERT_REQ_"&$AW$17&"_"&IF($AW$6<>$AW$17,$AW$6&"_","")&AJ21) -> (U1)ALERT_REQ_P_OILPRE_WRN_TT_ON | AR21: =IF(AQ86<>"",AQ86,IF(AQ85<>"","};","")) -> (U4)0x00000400U, /* 15 TT_ON */ | AS21: =IF(AQ151<>"",AQ151,IF(AQ150<>"","};","")) -> (U4)0x00000700U, /* 15 TT_ON */ | AT21: =IF(AJ21<>"",AL21&IF(AJ22<>"",","," ")&REPT(" ",78-LEN(AL21))&"/* "&IF(C21<10,"0"&C21,C21)&" "&AJ21&REPT(" ",48-LEN(AJ21))&"*/",IF(AJ20<>"","};","")) -> (U1)ALERT_REQ_P_OILPRE_WRN_TT_ON, /* 15 TT_ON */
C22: =ROW()-ROW($C$6) -> 16 | D22: × | E22: × | F22: × | G22: × | H22: × | I22: × | J22: × | K22: × | L22: × | M22: × | N22: × | O22: × | P22: × | Q22: × | R22: × | S22: × | T22: × | U22: × | V22: × | W22: × | X22: × | Y22: 1 | Z22: 0 | AA22: 1 | AB22: 0 | AC22: × | AD22: × | AE22: × | AF22: × | AG22: × | AH22: × | AI22: × | AJ22: TT_ON | AL22: =IF($AJ22="UNKNOWN"," (U1)ALERT_REQ_UNKNOWN"," (U1)"&"ALERT_REQ_"&$AW$17&"_"&IF($AW$6<>$AW$17,$AW$6&"_","")&AJ22) -> (U1)ALERT_REQ_P_OILPRE_WRN_TT_ON | AR22: =IF(AQ87<>"",AQ87,IF(AQ86<>"","};","")) -> (U4)0x00000500U, /* 16 TT_ON */ | AS22: =IF(AQ152<>"",AQ152,IF(AQ151<>"","};","")) -> (U4)0x00000780U, /* 16 TT_ON */ | AT22: =IF(AJ22<>"",AL22&IF(AJ23<>"",","," ")&REPT(" ",78-LEN(AL22))&"/* "&IF(C22<10,"0"&C22,C22)&" "&AJ22&REPT(" ",48-LEN(AJ22))&"*/",IF(AJ21<>"","};","")) -> (U1)ALERT_REQ_P_OILPRE_WRN_TT_ON, /* 16 TT_ON */
C23: =ROW()-ROW($C$6) -> 17 | D23: × | E23: × | F23: × | G23: × | H23: × | I23: × | J23: × | K23: × | L23: × | M23: × | N23: × | O23: × | P23: × | Q23: × | R23: × | S23: × | T23: × | U23: × | V23: × | W23: × | X23: × | Y23: 1 | Z23: 0 | AA23: 1 | AB23: 1 | AC23: 0 | AD23: × | AE23: × | AF23: × | AG23: 0 | AH23: 0 | AI23: 0 | AJ23: TT_ON | AL23: =IF($AJ23="UNKNOWN"," (U1)ALERT_REQ_UNKNOWN"," (U1)"&"ALERT_REQ_"&$AW$17&"_"&IF($AW$6<>$AW$17,$AW$6&"_","")&AJ23) -> (U1)ALERT_REQ_P_OILPRE_WRN_TT_ON | AR23: =IF(AQ88<>"",AQ88,IF(AQ87<>"","};","")) -> (U4)0x00000580U, /* 17 TT_ON */ | AS23: =IF(AQ153<>"",AQ153,IF(AQ152<>"","};","")) -> (U4)0x000007C7U, /* 17 TT_ON */ | AT23: =IF(AJ23<>"",AL23&IF(AJ24<>"",","," ")&REPT(" ",78-LEN(AL23))&"/* "&IF(C23<10,"0"&C23,C23)&" "&AJ23&REPT(" ",48-LEN(AJ23))&"*/",IF(AJ22<>"","};","")) -> (U1)ALERT_REQ_P_OILPRE_WRN_TT_ON, /* 17 TT_ON */
C24: =ROW()-ROW($C$6) -> 18 | D24: × | E24: × | F24: × | G24: × | H24: × | I24: × | J24: × | K24: × | L24: × | M24: × | N24: × | O24: × | P24: × | Q24: × | R24: × | S24: × | T24: × | U24: × | V24: × | W24: × | X24: × | Y24: 1 | Z24: 0 | AA24: 1 | AB24: 1 | AC24: 0 | AD24: 0 | AE24: × | AF24: × | AG24: 0 | AH24: × | AI24: 1 | AJ24: WRN_ON | AL24: =IF($AJ24="UNKNOWN"," (U1)ALERT_REQ_UNKNOWN"," (U1)"&"ALERT_REQ_"&$AW$17&"_"&IF($AW$6<>$AW$17,$AW$6&"_","")&AJ24) -> (U1)ALERT_REQ_P_OILPRE_WRN_WRN_ON | AR24: =IF(AQ89<>"",AQ89,IF(AQ88<>"","};","")) -> (U4)0x00000581U, /* 18 WRN_ON */ | AS24: =IF(AQ154<>"",AQ154,IF(AQ153<>"","};","")) -> (U4)0x000007E5U, /* 18 WRN_ON */ | AT24: =IF(AJ24<>"",AL24&IF(AJ25<>"",","," ")&REPT(" ",78-LEN(AL24))&"/* "&IF(C24<10,"0"&C24,C24)&" "&AJ24&REPT(" ",48-LEN(AJ24))&"*/",IF(AJ23<>"","};","")) -> (U1)ALERT_REQ_P_OILPRE_WRN_WRN_ON, /* 18 WRN_ON */
C25: =ROW()-ROW($C$6) -> 19 | D25: × | E25: × | F25: × | G25: × | H25: × | I25: × | J25: × | K25: × | L25: × | M25: × | N25: × | O25: × | P25: × | Q25: × | R25: × | S25: × | T25: × | U25: × | V25: × | W25: × | X25: × | Y25: 1 | Z25: 0 | AA25: 1 | AB25: 1 | AC25: 0 | AD25: 0 | AE25: × | AF25: × | AG25: 0 | AH25: 1 | AI25: 0 | AJ25: WRN_FLSH | AL25: =IF($AJ25="UNKNOWN"," (U1)ALERT_REQ_UNKNOWN"," (U1)"&"ALERT_REQ_"&$AW$17&"_"&IF($AW$6<>$AW$17,$AW$6&"_","")&AJ25) -> (U1)ALERT_REQ_P_OILPRE_WRN_WRN_FLSH | AR25: =IF(AQ90<>"",AQ90,IF(AQ89<>"","};","")) -> (U4)0x00000582U, /* 19 WRN_FLSH */ | AS25: =IF(AQ155<>"",AQ155,IF(AQ154<>"","};","")) -> (U4)0x000007E7U, /* 19 WRN_FLSH */ | AT25: =IF(AJ25<>"",AL25&IF(AJ26<>"",","," ")&REPT(" ",78-LEN(AL25))&"/* "&IF(C25<10,"0"&C25,C25)&" "&AJ25&REPT(" ",48-LEN(AJ25))&"*/",IF(AJ24<>"","};","")) -> (U1)ALERT_REQ_P_OILPRE_WRN_WRN_FLSH, /* 19 WRN_FLSH */
C26: =ROW()-ROW($C$6) -> 20 | D26: × | E26: × | F26: × | G26: × | H26: × | I26: × | J26: × | K26: × | L26: × | M26: × | N26: × | O26: × | P26: × | Q26: × | R26: × | S26: × | T26: × | U26: × | V26: × | W26: × | X26: × | Y26: 1 | Z26: 0 | AA26: 1 | AB26: 1 | AC26: 0 | AD26: × | AE26: × | AF26: × | AG26: 1 | AH26: × | AI26: × | AJ26: TT_ON | AL26: =IF($AJ26="UNKNOWN"," (U1)ALERT_REQ_UNKNOWN"," (U1)"&"ALERT_REQ_"&$AW$17&"_"&IF($AW$6<>$AW$17,$AW$6&"_","")&AJ26) -> (U1)ALERT_REQ_P_OILPRE_WRN_TT_ON | AR26: =IF(AQ91<>"",AQ91,IF(AQ90<>"","};","")) -> (U4)0x00000584U, /* 20 TT_ON */ | AS26: =IF(AQ156<>"",AQ156,IF(AQ155<>"","};","")) -> (U4)0x000007C4U, /* 20 TT_ON */ | AT26: =IF(AJ26<>"",AL26&IF(AJ27<>"",","," ")&REPT(" ",78-LEN(AL26))&"/* "&IF(C26<10,"0"&C26,C26)&" "&AJ26&REPT(" ",48-LEN(AJ26))&"*/",IF(AJ25<>"","};","")) -> (U1)ALERT_REQ_P_OILPRE_WRN_TT_ON, /* 20 TT_ON */
C27: =ROW()-ROW($C$6) -> 21 | D27: × | E27: × | F27: × | G27: × | H27: × | I27: × | J27: × | K27: × | L27: × | M27: × | N27: × | O27: × | P27: × | Q27: × | R27: × | S27: × | T27: × | U27: × | V27: × | W27: × | X27: × | Y27: 1 | Z27: 0 | AA27: 1 | AB27: 1 | AC27: 0 | AD27: 1 | AE27: × | AF27: × | AG27: 0 | AH27: 0 | AI27: 1 | AJ27: WRN_ON | AL27: =IF($AJ27="UNKNOWN"," (U1)ALERT_REQ_UNKNOWN"," (U1)"&"ALERT_REQ_"&$AW$17&"_"&IF($AW$6<>$AW$17,$AW$6&"_","")&AJ27) -> (U1)ALERT_REQ_P_OILPRE_WRN_WRN_ON | AR27: =IF(AQ92<>"",AQ92,IF(AQ91<>"","};","")) -> (U4)0x000005A1U, /* 21 WRN_ON */ | AS27: =IF(AQ157<>"",AQ157,IF(AQ156<>"","};","")) -> (U4)0x000007E7U, /* 21 WRN_ON */ | AT27: =IF(AJ27<>"",AL27&IF(AJ28<>"",","," ")&REPT(" ",78-LEN(AL27))&"/* "&IF(C27<10,"0"&C27,C27)&" "&AJ27&REPT(" ",48-LEN(AJ27))&"*/",IF(AJ26<>"","};","")) -> (U1)ALERT_REQ_P_OILPRE_WRN_WRN_ON, /* 21 WRN_ON */
C28: =ROW()-ROW($C$6) -> 22 | D28: × | E28: × | F28: × | G28: × | H28: × | I28: × | J28: × | K28: × | L28: × | M28: × | N28: × | O28: × | P28: × | Q28: × | R28: × | S28: × | T28: × | U28: × | V28: × | W28: × | X28: × | Y28: 1 | Z28: 0 | AA28: 1 | AB28: 1 | AC28: 0 | AD28: 1 | AE28: 0 | AF28: × | AG28: 0 | AH28: 1 | AI28: × | AJ28: WRN_ON | AL28: =IF($AJ28="UNKNOWN"," (U1)ALERT_REQ_UNKNOWN"," (U1)"&"ALERT_REQ_"&$AW$17&"_"&IF($AW$6<>$AW$17,$AW$6&"_","")&AJ28) -> (U1)ALERT_REQ_P_OILPRE_WRN_WRN_ON | AR28: =IF(AQ93<>"",AQ93,IF(AQ92<>"","};","")) -> (U4)0x000005A2U, /* 22 WRN_ON */ | AS28: =IF(AQ158<>"",AQ158,IF(AQ157<>"","};","")) -> (U4)0x000007F6U, /* 22 WRN_ON */ | AT28: =IF(AJ28<>"",AL28&IF(AJ29<>"",","," ")&REPT(" ",78-LEN(AL28))&"/* "&IF(C28<10,"0"&C28,C28)&" "&AJ28&REPT(" ",48-LEN(AJ28))&"*/",IF(AJ27<>"","};","")) -> (U1)ALERT_REQ_P_OILPRE_WRN_WRN_ON, /* 22 WRN_ON */
C29: =ROW()-ROW($C$6) -> 23 | D29: × | E29: × | F29: × | G29: × | H29: × | I29: × | J29: × | K29: × | L29: × | M29: × | N29: × | O29: × | P29: × | Q29: × | R29: × | S29: × | T29: × | U29: × | V29: × | W29: × | X29: × | Y29: 1 | Z29: 0 | AA29: 1 | AB29: 1 | AC29: 0 | AD29: 1 | AE29: 1 | AF29: × | AG29: 0 | AH29: 1 | AI29: 0 | AJ29: WRN_FLSH | AL29: =IF($AJ29="UNKNOWN"," (U1)ALERT_REQ_UNKNOWN"," (U1)"&"ALERT_REQ_"&$AW$17&"_"&IF($AW$6<>$AW$17,$AW$6&"_","")&AJ29) -> (U1)ALERT_REQ_P_OILPRE_WRN_WRN_FLSH | AR29: =IF(AQ94<>"",AQ94,IF(AQ93<>"","};","")) -> (U4)0x000005B2U, /* 23 WRN_FLSH */ | AS29: =IF(AQ159<>"",AQ159,IF(AQ158<>"","};","")) -> (U4)0x000007F7U, /* 23 WRN_FLSH */ | AT29: =IF(AJ29<>"",AL29&IF(AJ30<>"",","," ")&REPT(" ",78-LEN(AL29))&"/* "&IF(C29<10,"0"&C29,C29)&" "&AJ29&REPT(" ",48-LEN(AJ29))&"*/",IF(AJ28<>"","};","")) -> (U1)ALERT_REQ_P_OILPRE_WRN_WRN_FLSH, /* 23 WRN_FLSH */
C30: =ROW()-ROW($C$6) -> 24 | D30: × | E30: × | F30: × | G30: × | H30: × | I30: × | J30: × | K30: × | L30: × | M30: × | N30: × | O30: × | P30: × | Q30: × | R30: × | S30: × | T30: × | U30: × | V30: × | W30: × | X30: × | Y30: 1 | Z30: 0 | AA30: 1 | AB30: 1 | AC30: 0 | AD30: 1 | AE30: 1 | AF30: × | AG30: 0 | AH30: 1 | AI30: 1 | AJ30: WRN_ON | AL30: =IF($AJ30="UNKNOWN"," (U1)ALERT_REQ_UNKNOWN"," (U1)"&"ALERT_REQ_"&$AW$17&"_"&IF($AW$6<>$AW$17,$AW$6&"_","")&AJ30) -> (U1)ALERT_REQ_P_OILPRE_WRN_WRN_ON | AR30: =IF(AQ95<>"",AQ95,IF(AQ94<>"","};","")) -> (U4)0x000005B3U, /* 24 WRN_ON */ | AS30: =IF(AQ160<>"",AQ160,IF(AQ159<>"","};","")) -> (U4)0x000007F7U, /* 24 WRN_ON */ | AT30: =IF(AJ30<>"",AL30&IF(AJ31<>"",","," ")&REPT(" ",78-LEN(AL30))&"/* "&IF(C30<10,"0"&C30,C30)&" "&AJ30&REPT(" ",48-LEN(AJ30))&"*/",IF(AJ29<>"","};","")) -> (U1)ALERT_REQ_P_OILPRE_WRN_WRN_ON, /* 24 WRN_ON */
C31: =ROW()-ROW($C$6) -> 25 | D31: × | E31: × | F31: × | G31: × | H31: × | I31: × | J31: × | K31: × | L31: × | M31: × | N31: × | O31: × | P31: × | Q31: × | R31: × | S31: × | T31: × | U31: × | V31: × | W31: × | X31: × | Y31: 1 | Z31: 0 | AA31: 1 | AB31: 1 | AC31: 1 | AD31: 0 | AE31: × | AF31: 0 | AG31: 0 | AH31: 0 | AI31: 0 | AJ31: TT_ON | AL31: =IF($AJ31="UNKNOWN"," (U1)ALERT_REQ_UNKNOWN"," (U1)"&"ALERT_REQ_"&$AW$17&"_"&IF($AW$6<>$AW$17,$AW$6&"_","")&AJ31) -> (U1)ALERT_REQ_P_OILPRE_WRN_TT_ON | AR31: =IF(AQ96<>"",AQ96,IF(AQ95<>"","};","")) -> (U4)0x000005C0U, /* 25 TT_ON */ | AS31: =IF(AQ161<>"",AQ161,IF(AQ160<>"","};","")) -> (U4)0x000007EFU, /* 25 TT_ON */ | AT31: =IF(AJ31<>"",AL31&IF(AJ32<>"",","," ")&REPT(" ",78-LEN(AL31))&"/* "&IF(C31<10,"0"&C31,C31)&" "&AJ31&REPT(" ",48-LEN(AJ31))&"*/",IF(AJ30<>"","};","")) -> (U1)ALERT_REQ_P_OILPRE_WRN_TT_ON, /* 25 TT_ON */
C32: =ROW()-ROW($C$6) -> 26 | D32: × | E32: × | F32: × | G32: × | H32: × | I32: × | J32: × | K32: × | L32: × | M32: × | N32: × | O32: × | P32: × | Q32: × | R32: × | S32: × | T32: × | U32: × | V32: × | W32: × | X32: × | Y32: 1 | Z32: 0 | AA32: 1 | AB32: 1 | AC32: 1 | AD32: 0 | AE32: × | AF32: 0 | AG32: 0 | AH32: × | AI32: 1 | AJ32: WRN_ON | AL32: =IF($AJ32="UNKNOWN"," (U1)ALERT_REQ_UNKNOWN"," (U1)"&"ALERT_REQ_"&$AW$17&"_"&IF($AW$6<>$AW$17,$AW$6&"_","")&AJ32) -> (U1)ALERT_REQ_P_OILPRE_WRN_WRN_ON | AR32: =IF(AQ97<>"",AQ97,IF(AQ96<>"","};","")) -> (U4)0x000005C1U, /* 26 WRN_ON */ | AS32: =IF(AQ162<>"",AQ162,IF(AQ161<>"","};","")) -> (U4)0x000007EDU, /* 26 WRN_ON */ | AT32: =IF(AJ32<>"",AL32&IF(AJ33<>"",","," ")&REPT(" ",78-LEN(AL32))&"/* "&IF(C32<10,"0"&C32,C32)&" "&AJ32&REPT(" ",48-LEN(AJ32))&"*/",IF(AJ31<>"","};","")) -> (U1)ALERT_REQ_P_OILPRE_WRN_WRN_ON, /* 26 WRN_ON */
C33: =ROW()-ROW($C$6) -> 27 | D33: × | E33: × | F33: × | G33: × | H33: × | I33: × | J33: × | K33: × | L33: × | M33: × | N33: × | O33: × | P33: × | Q33: × | R33: × | S33: × | T33: × | U33: × | V33: × | W33: × | X33: × | Y33: 1 | Z33: 0 | AA33: 1 | AB33: 1 | AC33: 1 | AD33: 0 | AE33: × | AF33: 0 | AG33: 0 | AH33: 1 | AI33: 0 | AJ33: WRN_FLSH | AL33: =IF($AJ33="UNKNOWN"," (U1)ALERT_REQ_UNKNOWN"," (U1)"&"ALERT_REQ_"&$AW$17&"_"&IF($AW$6<>$AW$17,$AW$6&"_","")&AJ33) -> (U1)ALERT_REQ_P_OILPRE_WRN_WRN_FLSH | AR33: =IF(AQ98<>"",AQ98,IF(AQ97<>"","};","")) -> (U4)0x000005C2U, /* 27 WRN_FLSH */ | AS33: =IF(AQ163<>"",AQ163,IF(AQ162<>"","};","")) -> (U4)0x000007EFU, /* 27 WRN_FLSH */ | AT33: =IF(AJ33<>"",AL33&IF(AJ34<>"",","," ")&REPT(" ",78-LEN(AL33))&"/* "&IF(C33<10,"0"&C33,C33)&" "&AJ33&REPT(" ",48-LEN(AJ33))&"*/",IF(AJ32<>"","};","")) -> (U1)ALERT_REQ_P_OILPRE_WRN_WRN_FLSH, /* 27 WRN_FLSH */
C34: =ROW()-ROW($C$6) -> 28 | D34: × | E34: × | F34: × | G34: × | H34: × | I34: × | J34: × | K34: × | L34: × | M34: × | N34: × | O34: × | P34: × | Q34: × | R34: × | S34: × | T34: × | U34: × | V34: × | W34: × | X34: × | Y34: 1 | Z34: 0 | AA34: 1 | AB34: 1 | AC34: 1 | AD34: 0 | AE34: × | AF34: 0 | AG34: 1 | AH34: × | AI34: × | AJ34: TT_ON | AL34: =IF($AJ34="UNKNOWN"," (U1)ALERT_REQ_UNKNOWN"," (U1)"&"ALERT_REQ_"&$AW$17&"_"&IF($AW$6<>$AW$17,$AW$6&"_","")&AJ34) -> (U1)ALERT_REQ_P_OILPRE_WRN_TT_ON | AR34: =IF(AQ99<>"",AQ99,IF(AQ98<>"","};","")) -> (U4)0x000005C4U, /* 28 TT_ON */ | AS34: =IF(AQ164<>"",AQ164,IF(AQ163<>"","};","")) -> (U4)0x000007ECU, /* 28 TT_ON */ | AT34: =IF(AJ34<>"",AL34&IF(AJ35<>"",","," ")&REPT(" ",78-LEN(AL34))&"/* "&IF(C34<10,"0"&C34,C34)&" "&AJ34&REPT(" ",48-LEN(AJ34))&"*/",IF(AJ33<>"","};","")) -> (U1)ALERT_REQ_P_OILPRE_WRN_TT_ON, /* 28 TT_ON */
C35: =ROW()-ROW($C$6) -> 29 | D35: × | E35: × | F35: × | G35: × | H35: × | I35: × | J35: × | K35: × | L35: × | M35: × | N35: × | O35: × | P35: × | Q35: × | R35: × | S35: × | T35: × | U35: × | V35: × | W35: × | X35: × | Y35: 1 | Z35: 0 | AA35: 1 | AB35: 1 | AC35: 1 | AD35: 0 | AE35: × | AF35: 1 | AG35: × | AH35: × | AI35: × | AJ35: WRN_FLSH | AL35: =IF($AJ35="UNKNOWN"," (U1)ALERT_REQ_UNKNOWN"," (U1)"&"ALERT_REQ_"&$AW$17&"_"&IF($AW$6<>$AW$17,$AW$6&"_","")&AJ35) -> (U1)ALERT_REQ_P_OILPRE_WRN_WRN_FLSH | AR35: =IF(AQ100<>"",AQ100,IF(AQ99<>"","};","")) -> (U4)0x000005C8U, /* 29 WRN_FLSH */ | AS35: =IF(AQ165<>"",AQ165,IF(AQ164<>"","};","")) -> (U4)0x000007E8U, /* 29 WRN_FLSH */ | AT35: =IF(AJ35<>"",AL35&IF(AJ36<>"",","," ")&REPT(" ",78-LEN(AL35))&"/* "&IF(C35<10,"0"&C35,C35)&" "&AJ35&REPT(" ",48-LEN(AJ35))&"*/",IF(AJ34<>"","};","")) -> (U1)ALERT_REQ_P_OILPRE_WRN_WRN_FLSH, /* 29 WRN_FLSH */
C36: =ROW()-ROW($C$6) -> 30 | D36: × | E36: × | F36: × | G36: × | H36: × | I36: × | J36: × | K36: × | L36: × | M36: × | N36: × | O36: × | P36: × | Q36: × | R36: × | S36: × | T36: × | U36: × | V36: × | W36: × | X36: × | Y36: 1 | Z36: 1 | AA36: 1 | AB36: × | AC36: × | AD36: × | AE36: × | AF36: × | AG36: × | AH36: × | AI36: × | AJ36: WRN_FLSH | AL36: =IF($AJ36="UNKNOWN"," (U1)ALERT_REQ_UNKNOWN"," (U1)"&"ALERT_REQ_"&$AW$17&"_"&IF($AW$6<>$AW$17,$AW$6&"_","")&AJ36) -> (U1)ALERT_REQ_P_OILPRE_WRN_WRN_FLSH | AR36: =IF(AQ101<>"",AQ101,IF(AQ100<>"","};","")) -> (U4)0x00000700U /* 30 WRN_FLSH */ | AS36: =IF(AQ166<>"",AQ166,IF(AQ165<>"","};","")) -> (U4)0x00000700U /* 30 WRN_FLSH */ | AT36: =IF(AJ36<>"",AL36&IF(AJ37<>"",","," ")&REPT(" ",78-LEN(AL36))&"/* "&IF(C36<10,"0"&C36,C36)&" "&AJ36&REPT(" ",48-LEN(AJ36))&"*/",IF(AJ35<>"","};","")) -> (U1)ALERT_REQ_P_OILPRE_WRN_WRN_FLSH /* 30 WRN_FLSH */
C37: =ROW()-ROW($C$6) -> 31 | D37: × | E37: × | F37: × | G37: × | H37: × | I37: × | J37: × | K37: × | L37: × | M37: × | N37: × | O37: × | P37: × | Q37: × | R37: × | S37: × | T37: × | U37: × | V37: × | W37: × | X37: × | Y37: × | Z37: × | AA37: × | AB37: × | AC37: × | AD37: × | AE37: × | AF37: × | AG37: × | AH37: × | AI37: × | AL37: =IF($AJ37="UNKNOWN"," (U1)ALERT_REQ_UNKNOWN"," (U1)"&"ALERT_REQ_"&$AW$17&"_"&IF($AW$6<>$AW$17,$AW$6&"_","")&AJ37) -> (U1)ALERT_REQ_P_OILPRE_WRN_ | AR37: =IF(AQ102<>"",AQ102,IF(AQ101<>"","};","")) -> }; | AS37: =IF(AQ167<>"",AQ167,IF(AQ166<>"","};","")) -> }; | AT37: =IF(AJ37<>"",AL37&IF(AJ38<>"",","," ")&REPT(" ",78-LEN(AL37))&"/* "&IF(C37<10,"0"&C37,C37)&" "&AJ37&REPT(" ",48-LEN(AJ37))&"*/",IF(AJ36<>"","};","")) -> };
C38: =ROW()-ROW($C$6) -> 32 | D38: × | E38: × | F38: × | G38: × | H38: × | I38: × | J38: × | K38: × | L38: × | M38: × | N38: × | O38: × | P38: × | Q38: × | R38: × | S38: × | T38: × | U38: × | V38: × | W38: × | X38: × | Y38: × | Z38: × | AA38: × | AB38: × | AC38: × | AD38: × | AE38: × | AF38: × | AG38: × | AH38: × | AI38: × | AL38: =IF($AJ38="UNKNOWN"," (U1)ALERT_REQ_UNKNOWN"," (U1)"&"ALERT_REQ_"&$AW$17&"_"&IF($AW$6<>$AW$17,$AW$6&"_","")&AJ38) -> (U1)ALERT_REQ_P_OILPRE_WRN_ | AR38: =IF(AQ103<>"",AQ103,IF(AQ102<>"","};","")) | AS38: =IF(AQ168<>"",AQ168,IF(AQ167<>"","};","")) | AT38: =IF(AJ38<>"",AL38&IF(AJ39<>"",","," ")&REPT(" ",78-LEN(AL38))&"/* "&IF(C38<10,"0"&C38,C38)&" "&AJ38&REPT(" ",48-LEN(AJ38))&"*/",IF(AJ37<>"","};",""))
C39: =ROW()-ROW($C$6) -> 33 | D39: × | E39: × | F39: × | G39: × | H39: × | I39: × | J39: × | K39: × | L39: × | M39: × | N39: × | O39: × | P39: × | Q39: × | R39: × | S39: × | T39: × | U39: × | V39: × | W39: × | X39: × | Y39: × | Z39: × | AA39: × | AB39: × | AC39: × | AD39: × | AE39: × | AF39: × | AG39: × | AH39: × | AI39: × | AL39: =IF($AJ39="UNKNOWN"," (U1)ALERT_REQ_UNKNOWN"," (U1)"&"ALERT_REQ_"&$AW$17&"_"&IF($AW$6<>$AW$17,$AW$6&"_","")&AJ39) -> (U1)ALERT_REQ_P_OILPRE_WRN_ | AR39: =IF(AQ104<>"",AQ104,IF(AQ103<>"","};","")) | AS39: =IF(AQ169<>"",AQ169,IF(AQ168<>"","};","")) | AT39: =IF(AJ39<>"",AL39&IF(AJ40<>"",","," ")&REPT(" ",78-LEN(AL39))&"/* "&IF(C39<10,"0"&C39,C39)&" "&AJ39&REPT(" ",48-LEN(AJ39))&"*/",IF(AJ38<>"","};",""))
C40: =ROW()-ROW($C$6) -> 34 | D40: × | E40: × | F40: × | G40: × | H40: × | I40: × | J40: × | K40: × | L40: × | M40: × | N40: × | O40: × | P40: × | Q40: × | R40: × | S40: × | T40: × | U40: × | V40: × | W40: × | X40: × | Y40: × | Z40: × | AA40: × | AB40: × | AC40: × | AD40: × | AE40: × | AF40: × | AG40: × | AH40: × | AI40: × | AL40: =IF($AJ40="UNKNOWN"," (U1)ALERT_REQ_UNKNOWN"," (U1)"&"ALERT_REQ_"&$AW$17&"_"&IF($AW$6<>$AW$17,$AW$6&"_","")&AJ40) -> (U1)ALERT_REQ_P_OILPRE_WRN_ | AR40: =IF(AQ105<>"",AQ105,IF(AQ104<>"","};","")) | AS40: =IF(AQ170<>"",AQ170,IF(AQ169<>"","};","")) | AT40: =IF(AJ40<>"",AL40&IF(AJ41<>"",","," ")&REPT(" ",78-LEN(AL40))&"/* "&IF(C40<10,"0"&C40,C40)&" "&AJ40&REPT(" ",48-LEN(AJ40))&"*/",IF(AJ39<>"","};",""))
...

Sheet BC
AH1: → | AI1: bit
B2: Table Type | C2: INDEX | D2: 31 | E2: 30 | F2: 29 | G2: 28 | H2: 27 | I2: 26 | J2: 25 | K2: 24 | L2: 23 | M2: 22 | N2: 21 | O2: 20 | P2: 19 | Q2: 18 | R2: 17 | S2: 16 | T2: 15 | U2: 14 | V2: 13 | W2: 12 | X2: 11 | Y2: 10 | Z2: 9 | AA2: 8 | AB2: 7 | AC2: 6 | AD2: 5 | AE2: 4 | AF2: 3 | AG2: 2 | AH2: 1 | AI2: 0 | AJ2: REQ
B3: =IF(OR(IF(COUNTIF(D6:AC69,"0")<>0,TRUE,FALSE),IF(COUNTIF(D6:AC69,"1")<>0,TRUE,FALSE)),"Search Table","Index Table") -> Index Table | D3: ALERT_VOM_RWT_EN | E3: [reserved] | F3: ALERT_VOM_VCS_ON | G3: ALERT_VOM_IGN_ON | H3: ALERT_VOM_IGN_OFF_WT | I3: ALERT_VOM_IGN_OFF | J3: ALERT_VOM_BAT_WT | K3: ALERT_VOM_BAT_AO | L3: [reserved] | M3: [reserved] | N3: [reserved] | O3: [reserved] | P3: [reserved] | Q3: [reserved] | R3: [reserved] | S3: [reserved] | T3: [reserved] | U3: [reserved] | V3: [reserved] | W3: [reserved] | X3: [reserved] | Y3: [reserved] | Z3: [reserved] | AA3: [reserved] | AB3: [reserved] | AC3: [reserved] | AD3: B_OILPL_SIG | AF3: IGP_PDC_SIG | AG3: RPM | AH3: OPTDLY | AI3: PREV_REQ | AR3: シート名称は、CH Nameと同じにすること。 1CHしか存在しない場合、機能名と同じにすること。
A4: Master Table | AR4: 貼り付けコード
